{
  "version": 8,
  "blockIdVersion": 11,
  "anchorX": 2,
  "anchorY": 5,
  "anchorZ": 0,
  "blocks": [
    {
      "x": -6,
      "y": 15,
      "z": -4,
      "name": "Plant_Leaves_Cherry_Full"
    },
    {
      "x": -6,
      "y": 15,
      "z": -3,
      "name": "Plant_Leaves_Cherry_Full"
    },
    {
      "x": -6,
      "y": 15,
      "z": -2,
      "name": "Plant_Leaves_Cherry_Full"
    },
    {
      "x": -6,
      "y": 14,
      "z": -1,
      "name": "Plant_Leaves_Cherry_Full"
    },
    {
      "x": -6,
      "y": 14,
      "z": 0,
      "name": "Plant_Leaves_Cherry_Full"
    },
    {
      "x": -6,
      "y": 14,
      "z": 1,
      "name": "Plant_Leaves_Cherry_Full"
    },
    {
      "x": -5,
      "y": 14,
      "z": -5,
      "name": "Plant_Leaves_Cherry_Full"
    },
    {
      "x": -5,
      "y": 15,
      "z": -4,
      "name": "Plant_Leaves_Cherry_Full"
    },
    {
      "x": -5,
      "y": 15,
      "z": -3,
      "name": "Plant_Leaves_Cherry_Full"
    },
    {
      "x": -5,
      "y": 14,
      "z": -2,
      "name": "Wood_Wisteria_Wild_Branch_Long",
      "rotation": 5
    },
    {
      "x": -5,
      "y": 15,
      "z": -2,
      "name": "Plant_Leaves_Cherry_Full"
    },
    {
      "x": -5,
      "y": 15,
      "z": -1,
      "name": "Plant_Leaves_Cherry_Full"
    },
    {
      "x": -5,
      "y": 14,
      "z": 0,
      "name": "Plant_Leaves_Cherry_Full"
    },
    {
      "x": -5,
      "y": 13,
      "z": 1,
      "name": "Plant_Leaves_Cherry_Full"
    },
    {
      "x": -5,
      "y": 14,
      "z": 1,
      "name": "Plant_Leaves_Cherry_Full"
    },
    {
      "x": -5,
      "y": 13,
      "z": 2,
      "name": "Plant_Leaves_Cherry_Full"
    },
    {
      "x": -4,
      "y": 13,
      "z": -6,
      "name": "Plant_Leaves_Cherry_Full"
    },
    {
      "x": -4,
      "y": 14,
      "z": -6,
      "name": "Plant_Leaves_Cherry_Full"
    },
    {
      "x": -4,
      "y": 14,
      "z": -5,
      "name": "Plant_Leaves_Cherry_Full"
    },
    {
      "x": -4,
      "y": 14,
      "z": -4,
      "name": "Plant_Leaves_Cherry_Full"
    },
    {
      "x": -4,
      "y": 15,
      "z": -4,
      "name": "Plant_Leaves_Cherry_Full"
    },
    {
      "x": -4,
      "y": 14,
      "z": -3,
      "name": "Wood_Wisteria_Wild_Branch_Long",
      "rotation": 4
    },
    {
      "x": -4,
      "y": 15,
      "z": -3,
      "name": "Plant_Leaves_Cherry_Full"
    },
    {
      "x": -4,
      "y": 14,
      "z": -2,
      "name": "Wood_Cherry_Trunk_Full"
    },
    {
      "x": -4,
      "y": 15,
      "z": -2,
      "name": "Plant_Leaves_Cherry_Full"
    },
    {
      "x": -4,
      "y": 14,
      "z": -1,
      "name": "Plant_Leaves_Cherry_Full"
    },
    {
      "x": -4,
      "y": 15,
      "z": -1,
      "name": "Plant_Leaves_Cherry_Full"
    },
    {
      "x": -4,
      "y": 16,
      "z": -1,
      "name": "Plant_Leaves_Cherry_Full"
    },
    {
      "x": -4,
      "y": 14,
      "z": 0,
      "name": "Plant_Leaves_Cherry_Full"
    },
    {
      "x": -4,
      "y": 15,
      "z": 0,
      "name": "Plant_Leaves_Cherry_Full"
    },
    {
      "x": -4,
      "y": 13,
      "z": 1,
      "name": "Plant_Leaves_Cherry_Full"
    },
    {
      "x": -4,
      "y": 14,
      "z": 1,
      "name": "Plant_Leaves_Cherry_Full"
    },
    {
      "x": -4,
      "y": 13,
      "z": 2,
      "name": "Plant_Leaves_Cherry_Full"
    },
    {
      "x": -3,
      "y": 13,
      "z": -6,
      "name": "Plant_Leaves_Cherry_Full"
    },
    {
      "x": -3,
      "y": 14,
      "z": -6,
      "name": "Plant_Leaves_Cherry_Full"
    },
    {
      "x": -3,
      "y": 14,
      "z": -5,
      "name": "Plant_Leaves_Cherry_Full"
    },
    {
      "x": -3,
      "y": 15,
      "z": -5,
      "name": "Plant_Leaves_Cherry_Full"
    },
    {
      "x": -3,
      "y": 15,
      "z": -3,
      "name": "Plant_Leaves_Cherry_Full"
    },
    {
      "x": -3,
      "y": 14,
      "z": -2,
      "name": "Wood_Cherry_Trunk_Full"
    },
    {
      "x": -3,
      "y": 15,
      "z": -2,
      "name": "Plant_Leaves_Cherry_Full"
    },
    {
      "x": -3,
      "y": 14,
      "z": -1,
      "name": "Plant_Leaves_Cherry_Full"
    },
    {
      "x": -3,
      "y": 15,
      "z": -1,
      "name": "Plant_Leaves_Cherry_Full"
    },
    {
      "x": -3,
      "y": 16,
      "z": -1,
      "name": "Plant_Leaves_Cherry_Full"
    },
    {
      "x": -3,
      "y": 14,
      "z": 0,
      "name": "Plant_Leaves_Cherry_Full"
    },
    {
      "x": -3,
      "y": 15,
      "z": 0,
      "name": "Plant_Leaves_Cherry_Full"
    },
    {
      "x": -3,
      "y": 13,
      "z": 1,
      "name": "Plant_Leaves_Cherry_Full"
    },
    {
      "x": -3,
      "y": 14,
      "z": 1,
      "name": "Plant_Leaves_Cherry_Full"
    },
    {
      "x": -3,
      "y": 13,
      "z": 2,
      "name": "Plant_Leaves_Cherry_Full"
    },
    {
      "x": -2,
      "y": 14,
      "z": -6,
      "name": "Plant_Leaves_Cherry_Full"
    },
    {
      "x": -2,
      "y": 14,
      "z": -5,
      "name": "Plant_Leaves_Cherry_Full"
    },
    {
      "x": -2,
      "y": 15,
      "z": -5,
      "name": "Plant_Leaves_Cherry_Full"
    },
    {
      "x": -2,
      "y": 14,
      "z": -4,
      "name": "Plant_Leaves_Cherry_Full"
    },
    {
      "x": -2,
      "y": 15,
      "z": -4,
      "name": "Plant_Leaves_Cherry_Full"
    },
    {
      "x": -2,
      "y": 15,
      "z": -3,
      "name": "Plant_Leaves_Cherry_Full"
    },
    {
      "x": -2,
      "y": 13,
      "z": -2,
      "name": "Wood_Cherry_Trunk_Full"
    },
    {
      "x": -2,
      "y": 14,
      "z": -2,
      "name": "Wood_Cherry_Trunk_Full"
    },
    {
      "x": -2,
      "y": 15,
      "z": -2,
      "name": "Plant_Leaves_Cherry_Full"
    },
    {
      "x": -2,
      "y": 13,
      "z": -1,
      "name": "Wood_Cherry_Trunk_Full"
    },
    {
      "x": -2,
      "y": 14,
      "z": -1,
      "name": "Plant_Leaves_Cherry_Full"
    },
    {
      "x": -2,
      "y": 15,
      "z": -1,
      "name": "Plant_Leaves_Cherry_Full"
    },
    {
      "x": -2,
      "y": 12,
      "z": 0,
      "name": "Wood_Cherry_Trunk_Full"
    },
    {
      "x": -2,
      "y": 13,
      "z": 0,
      "name": "Wood_Cherry_Trunk_Full"
    },
    {
      "x": -2,
      "y": 14,
      "z": 0,
      "name": "Plant_Leaves_Cherry_Full"
    },
    {
      "x": -2,
      "y": 15,
      "z": 0,
      "name": "Plant_Leaves_Cherry_Full"
    },
    {
      "x": -2,
      "y": 11,
      "z": 1,
      "name": "Wood_Cherry_Trunk_Full"
    },
    {
      "x": -2,
      "y": 12,
      "z": 1,
      "name": "Wood_Cherry_Trunk_Full"
    },
    {
      "x": -2,
      "y": 13,
      "z": 1,
      "name": "Plant_Leaves_Cherry_Full"
    },
    {
      "x": -2,
      "y": 14,
      "z": 1,
      "name": "Plant_Leaves_Cherry_Full"
    },
    {
      "x": -1,
      "y": 14,
      "z": -6,
      "name": "Plant_Leaves_Cherry_Full"
    },
    {
      "x": -1,
      "y": 13,
      "z": -5,
      "name": "Plant_Leaves_Cherry_Full"
    },
    {
      "x": -1,
      "y": 14,
      "z": -5,
      "name": "Plant_Leaves_Cherry_Full"
    },
    {
      "x": -1,
      "y": 13,
      "z": -4,
      "name": "Plant_Leaves_Cherry_Full"
    },
    {
      "x": -1,
      "y": 14,
      "z": -4,
      "name": "Plant_Leaves_Cherry_Full"
    },
    {
      "x": -1,
      "y": 14,
      "z": -3,
      "name": "Plant_Leaves_Cherry_Full"
    },
    {
      "x": -1,
      "y": 15,
      "z": -3,
      "name": "Plant_Leaves_Cherry_Full"
    },
    {
      "x": -1,
      "y": 12,
      "z": -2,
      "name": "Plant_Leaves_Cherry_Full"
    },
    {
      "x": -1,
      "y": 14,
      "z": -2,
      "name": "Plant_Leaves_Cherry_Full"
    },
    {
      "x": -1,
      "y": 15,
      "z": -2,
      "name": "Plant_Leaves_Cherry_Full"
    },
    {
      "x": -1,
      "y": 14,
      "z": -1,
      "name": "Plant_Leaves_Cherry_Full"
    },
    {
      "x": -1,
      "y": 15,
      "z": -1,
      "name": "Plant_Leaves_Cherry_Full"
    },
    {
      "x": -1,
      "y": 14,
      "z": 0,
      "name": "Plant_Leaves_Cherry_Full"
    },
    {
      "x": -1,
      "y": 11,
      "z": 1,
      "name": "Wood_Cherry_Trunk_Full"
    },
    {
      "x": -1,
      "y": 12,
      "z": 1,
      "name": "Wood_Cherry_Trunk_Full"
    },
    {
      "x": -1,
      "y": 13,
      "z": 1,
      "name": "Plant_Leaves_Cherry_Full"
    },
    {
      "x": -1,
      "y": 12,
      "z": 2,
      "name": "Wood_Cherry_Trunk_Full"
    },
    {
      "x": -1,
      "y": 13,
      "z": 2,
      "name": "Wood_Cherry_Trunk_Full"
    },
    {
      "x": -1,
      "y": 13,
      "z": 3,
      "name": "Plant_Leaves_Cherry_Full"
    },
    {
      "x": -1,
      "y": 13,
      "z": 4,
      "name": "Plant_Leaves_Cherry_Full"
    },
    {
      "x": 0,
      "y": 14,
      "z": -4,
      "name": "Plant_Leaves_Cherry_Full"
    },
    {
      "x": 0,
      "y": 15,
      "z": -3,
      "name": "Plant_Leaves_Cherry_Full"
    },
    {
      "x": 0,
      "y": 12,
      "z": -2,
      "name": "Plant_Leaves_Cherry_Full"
    },
    {
      "x": 0,
      "y": 15,
      "z": -2,
      "name": "Plant_Leaves_Cherry_Full"
    },
    {
      "x": 0,
      "y": 11,
      "z": 0,
      "name": "Wood_Cherry_Trunk_Full"
    },
    {
      "x": 0,
      "y": 11,
      "z": 1,
      "name": "Wood_Cherry_Trunk_Full"
    },
    {
      "x": 0,
      "y": 13,
      "z": 1,
      "name": "Plant_Leaves_Cherry_Full"
    },
    {
      "x": 0,
      "y": 13,
      "z": 2,
      "name": "Wood_Cherry_Trunk_Full"
    },
    {
      "x": 0,
      "y": 14,
      "z": 2,
      "name": "Plant_Leaves_Cherry_Full"
    },
    {
      "x": 0,
      "y": 13,
      "z": 3,
      "name": "Wood_Cherry_Trunk_Full"
    },
    {
      "x": 0,
      "y": 14,
      "z": 3,
      "name": "Plant_Leaves_Cherry_Full"
    },
    {
      "x": 0,
      "y": 13,
      "z": 4,
      "name": "Plant_Leaves_Cherry_Full"
    },
    {
      "x": 0,
      "y": 13,
      "z": 5,
      "name": "Plant_Leaves_Cherry_Full"
    },
    {
      "x": 1,
      "y": 12,
      "z": -4,
      "name": "Plant_Leaves_Cherry_Full"
    },
    {
      "x": 1,
      "y": 12,
      "z": -3,
      "name": "Plant_Leaves_Cherry_Full"
    },
    {
      "x": 1,
      "y": 13,
      "z": -3,
      "name": "Plant_Leaves_Cherry_Full"
    },
    {
      "x": 1,
      "y": 12,
      "z": -2,
      "name": "Plant_Leaves_Cherry_Full"
    },
    {
      "x": 1,
      "y": 13,
      "z": -2,
      "name": "Plant_Leaves_Cherry_Full"
    },
    {
      "x": 1,
      "y": 11,
      "z": -1,
      "name": "Wood_Cherry_Trunk_Full"
    },
    {
      "x": 1,
      "y": 12,
      "z": -1,
      "name": "Wood_Cherry_Trunk_Full"
    },
    {
      "x": 1,
      "y": 13,
      "z": -1,
      "name": "Plant_Leaves_Cherry_Full"
    },
    {
      "x": 1,
      "y": 1,
      "z": 0,
      "name": "Wood_Cherry_Roots"
    },
    {
      "x": 1,
      "y": 2,
      "z": 0,
      "name": "Wood_Cherry_Trunk_Full"
    },
    {
      "x": 1,
      "y": 3,
      "z": 0,
      "name": "Wood_Cherry_Trunk_Full"
    },
    {
      "x": 1,
      "y": 4,
      "z": 0,
      "name": "Wood_Cherry_Trunk_Full"
    },
    {
      "x": 1,
      "y": 5,
      "z": 0,
      "name": "Wood_Cherry_Trunk_Full"
    },
    {
      "x": 1,
      "y": 6,
      "z": 0,
      "name": "Wood_Cherry_Trunk_Full"
    },
    {
      "x": 1,
      "y": 9,
      "z": 0,
      "name": "Wood_Cherry_Trunk_Full"
    },
    {
      "x": 1,
      "y": 10,
      "z": 0,
      "name": "Wood_Cherry_Trunk"
    },
    {
      "x": 1,
      "y": 11,
      "z": 0,
      "name": "Wood_Cherry_Trunk_Full"
    },
    {
      "x": 1,
      "y": 12,
      "z": 0,
      "name": "Plant_Leaves_Cherry_Full"
    },
    {
      "x": 1,
      "y": 3,
      "z": 1,
      "name": "Wood_Cherry_Trunk_Full"
    },
    {
      "x": 1,
      "y": 4,
      "z": 1,
      "name": "Wood_Cherry_Trunk"
    },
    {
      "x": 1,
      "y": 5,
      "z": 1,
      "name": "Wood_Cherry_Trunk_Full"
    },
    {
      "x": 1,
      "y": 12,
      "z": 1,
      "name": "Plant_Leaves_Cherry_Full"
    },
    {
      "x": 1,
      "y": 13,
      "z": 1,
      "name": "Plant_Leaves_Cherry_Full"
    },
    {
      "x": 1,
      "y": 12,
      "z": 2,
      "name": "Plant_Leaves_Cherry_Full"
    },
    {
      "x": 1,
      "y": 13,
      "z": 2,
      "name": "Plant_Leaves_Cherry_Full"
    },
    {
      "x": 1,
      "y": 13,
      "z": 3,
      "name": "Wood_Cherry_Trunk_Full"
    },
    {
      "x": 1,
      "y": 12,
      "z": 4,
      "name": "Plant_Leaves_Cherry_Full"
    },
    {
      "x": 1,
      "y": 13,
      "z": 4,
      "name": "Plant_Leaves_Cherry_Full"
    },
    {
      "x": 1,
      "y": 14,
      "z": 4,
      "name": "Plant_Leaves_Cherry_Full"
    },
    {
      "x": 1,
      "y": 13,
      "z": 5,
      "name": "Plant_Leaves_Cherry_Full"
    },
    {
      "x": 1,
      "y": 13,
      "z": 6,
      "name": "Plant_Leaves_Cherry_Full"
    },
    {
      "x": 2,
      "y": 12,
      "z": -5,
      "name": "Plant_Leaves_Cherry_Full"
    },
    {
      "x": 2,
      "y": 12,
      "z": -4,
      "name": "Plant_Leaves_Cherry_Full"
    },
    {
      "x": 2,
      "y": 12,
      "z": -3,
      "name": "Plant_Leaves_Cherry_Full"
    },
    {
      "x": 2,
      "y": 13,
      "z": -3,
      "name": "Plant_Leaves_Cherry_Full"
    },
    {
      "x": 2,
      "y": 12,
      "z": -2,
      "name": "Wood_Cherry_Trunk_Full"
    },
    {
      "x": 2,
      "y": 13,
      "z": -2,
      "name": "Plant_Leaves_Cherry_Full"
    },
    {
      "x": 2,
      "y": 12,
      "z": -1,
      "name": "Wood_Cherry_Trunk_Full"
    },
    {
      "x": 2,
      "y": 13,
      "z": -1,
      "name": "Plant_Leaves_Cherry_Full"
    },
    {
      "x": 2,
      "y": 4,
      "z": 0,
      "name": "Wood_Cherry_Trunk"
    },
    {
      "x": 2,
      "y": 5,
      "z": 0,
      "name": "Wood_Cherry_Trunk"
    },
    {
      "x": 2,
      "y": 6,
      "z": 0,
      "name": "Wood_Cherry_Trunk"
    },
    {
      "x": 2,
      "y": 7,
      "z": 0,
      "name": "Wood_Cherry_Trunk"
    },
    {
      "x": 2,
      "y": 8,
      "z": 0,
      "name": "Wood_Cherry_Trunk"
    },
    {
      "x": 2,
      "y": 9,
      "z": 0,
      "name": "Wood_Cherry_Trunk_Full"
    },
    {
      "x": 2,
      "y": 12,
      "z": 0,
      "name": "Plant_Leaves_Cherry_Full"
    },
    {
      "x": 2,
      "y": 13,
      "z": 0,
      "name": "Plant_Leaves_Cherry_Full"
    },
    {
      "x": 2,
      "y": 3,
      "z": 1,
      "name": "Wood_Cherry_Trunk_Full"
    },
    {
      "x": 2,
      "y": 4,
      "z": 1,
      "name": "Wood_Cherry_Trunk"
    },
    {
      "x": 2,
      "y": 5,
      "z": 1,
      "name": "Wood_Cherry_Trunk_Full"
    },
    {
      "x": 2,
      "y": 12,
      "z": 1,
      "name": "Plant_Leaves_Cherry_Full"
    },
    {
      "x": 2,
      "y": 0,
      "z": 2,
      "name": "Wood_Cherry_Roots"
    },
    {
      "x": 2,
      "y": 1,
      "z": 2,
      "name": "Wood_Cherry_Trunk_Full"
    },
    {
      "x": 2,
      "y": 2,
      "z": 2,
      "name": "Wood_Cherry_Trunk_Full"
    },
    {
      "x": 2,
      "y": 3,
      "z": 2,
      "name": "Wood_Cherry_Trunk_Full"
    },
    {
      "x": 2,
      "y": 4,
      "z": 2,
      "name": "Wood_Cherry_Trunk_Full"
    },
    {
      "x": 2,
      "y": 12,
      "z": 2,
      "name": "Plant_Leaves_Cherry_Full"
    },
    {
      "x": 2,
      "y": 13,
      "z": 2,
      "name": "Plant_Leaves_Cherry_Full"
    },
    {
      "x": 2,
      "y": 14,
      "z": 2,
      "name": "Plant_Leaves_Cherry_Full"
    },
    {
      "x": 2,
      "y": 12,
      "z": 3,
      "name": "Plant_Leaves_Cherry_Full"
    },
    {
      "x": 2,
      "y": 13,
      "z": 3,
      "name": "Wood_Cherry_Trunk_Full"
    },
    {
      "x": 2,
      "y": 14,
      "z": 3,
      "name": "Plant_Leaves_Cherry_Full"
    },
    {
      "x": 2,
      "y": 12,
      "z": 4,
      "name": "Plant_Leaves_Cherry_Full"
    },
    {
      "x": 2,
      "y": 13,
      "z": 4,
      "name": "Plant_Leaves_Cherry_Full"
    },
    {
      "x": 2,
      "y": 14,
      "z": 4,
      "name": "Plant_Leaves_Cherry_Full"
    },
    {
      "x": 2,
      "y": 12,
      "z": 5,
      "name": "Plant_Leaves_Cherry_Full"
    },
    {
      "x": 2,
      "y": 13,
      "z": 5,
      "name": "Plant_Leaves_Cherry_Full"
    },
    {
      "x": 2,
      "y": 14,
      "z": 5,
      "name": "Plant_Leaves_Cherry_Full"
    },
    {
      "x": 2,
      "y": 13,
      "z": 6,
      "name": "Plant_Leaves_Cherry_Full"
    },
    {
      "x": 3,
      "y": 12,
      "z": -6,
      "name": "Plant_Leaves_Cherry_Full"
    },
    {
      "x": 3,
      "y": 12,
      "z": -5,
      "name": "Plant_Leaves_Cherry_Full"
    },
    {
      "x": 3,
      "y": 12,
      "z": -4,
      "name": "Plant_Leaves_Cherry_Full"
    },
    {
      "x": 3,
      "y": 13,
      "z": -4,
      "name": "Plant_Leaves_Cherry_Full"
    },
    {
      "x": 3,
      "y": 12,
      "z": -3,
      "name": "Wood_Wisteria_Wild_Branch_Long",
      "rotation": 4
    },
    {
      "x": 3,
      "y": 13,
      "z": -3,
      "name": "Plant_Leaves_Cherry_Full"
    },
    {
      "x": 3,
      "y": 12,
      "z": -2,
      "name": "Wood_Cherry_Trunk_Full"
    },
    {
      "x": 3,
      "y": 2,
      "z": -1,
      "name": "Wood_Cherry_Roots"
    },
    {
      "x": 3,
      "y": 3,
      "z": -1,
      "name": "Wood_Cherry_Trunk_Full"
    },
    {
      "x": 3,
      "y": 4,
      "z": -1,
      "name": "Wood_Cherry_Trunk_Full"
    },
    {
      "x": 3,
      "y": 5,
      "z": -1,
      "name": "Wood_Cherry_Trunk"
    },
    {
      "x": 3,
      "y": 6,
      "z": -1,
      "name": "Wood_Cherry_Trunk_Full"
    },
    {
      "x": 3,
      "y": 12,
      "z": -1,
      "name": "Plant_Leaves_Cherry_Full"
    },
    {
      "x": 3,
      "y": 13,
      "z": -1,
      "name": "Plant_Leaves_Cherry_Full"
    },
    {
      "x": 3,
      "y": 6,
      "z": 0,
      "name": "Wood_Cherry_Trunk"
    },
    {
      "x": 3,
      "y": 7,
      "z": 0,
      "name": "Wood_Cherry_Trunk_Full"
    },
    {
      "x": 3,
      "y": 12,
      "z": 0,
      "name": "Plant_Leaves_Cherry_Full"
    },
    {
      "x": 3,
      "y": 6,
      "z": 1,
      "name": "Wood_Cherry_Trunk_Full"
    },
    {
      "x": 3,
      "y": 11,
      "z": 1,
      "name": "Plant_Leaves_Cherry_Full"
    },
    {
      "x": 3,
      "y": 12,
      "z": 1,
      "name": "Plant_Leaves_Cherry_Full"
    },
    {
      "x": 3,
      "y": 12,
      "z": 2,
      "name": "Plant_Leaves_Cherry_Full"
    },
    {
      "x": 3,
      "y": 13,
      "z": 2,
      "name": "Plant_Leaves_Cherry_Full"
    },
    {
      "x": 3,
      "y": 12,
      "z": 3,
      "name": "Plant_Leaves_Cherry_Full"
    },
    {
      "x": 3,
      "y": 13,
      "z": 3,
      "name": "Plant_Leaves_Cherry_Full"
    },
    {
      "x": 3,
      "y": 13,
      "z": 4,
      "name": "Plant_Leaves_Cherry_Full"
    },
    {
      "x": 3,
      "y": 14,
      "z": 4,
      "name": "Plant_Leaves_Cherry_Full"
    },
    {
      "x": 3,
      "y": 13,
      "z": 5,
      "name": "Plant_Leaves_Cherry_Full"
    },
    {
      "x": 3,
      "y": 13,
      "z": 6,
      "name": "Plant_Leaves_Cherry_Full"
    },
    {
      "x": 4,
      "y": 12,
      "z": -5,
      "name": "Plant_Leaves_Cherry_Full"
    },
    {
      "x": 4,
      "y": 12,
      "z": -4,
      "name": "Plant_Leaves_Cherry_Full"
    },
    {
      "x": 4,
      "y": 13,
      "z": -4,
      "name": "Plant_Leaves_Cherry_Full"
    },
    {
      "x": 4,
      "y": 12,
      "z": -3,
      "name": "Plant_Leaves_Cherry_Full"
    },
    {
      "x": 4,
      "y": 12,
      "z": -2,
      "name": "Plant_Leaves_Cherry_Full"
    },
    {
      "x": 4,
      "y": 13,
      "z": -2,
      "name": "Plant_Leaves_Cherry_Full"
    },
    {
      "x": 4,
      "y": 12,
      "z": -1,
      "name": "Plant_Leaves_Cherry_Full"
    },
    {
      "x": 4,
      "y": 13,
      "z": -1,
      "name": "Plant_Leaves_Cherry_Full"
    },
    {
      "x": 4,
      "y": 11,
      "z": 0,
      "name": "Plant_Leaves_Cherry_Full"
    },
    {
      "x": 4,
      "y": 12,
      "z": 0,
      "name": "Plant_Leaves_Cherry_Full"
    },
    {
      "x": 4,
      "y": 11,
      "z": 1,
      "name": "Plant_Leaves_Cherry_Full"
    },
    {
      "x": 4,
      "y": 12,
      "z": 2,
      "name": "Plant_Leaves_Cherry_Full"
    },
    {
      "x": 4,
      "y": 12,
      "z": 3,
      "name": "Plant_Leaves_Cherry_Full"
    },
    {
      "x": 4,
      "y": 13,
      "z": 4,
      "name": "Plant_Leaves_Cherry_Full"
    },
    {
      "x": 4,
      "y": 13,
      "z": 5,
      "name": "Plant_Leaves_Cherry_Full"
    },
    {
      "x": 5,
      "y": 11,
      "z": -3,
      "name": "Plant_Leaves_Cherry_Full"
    },
    {
      "x": 5,
      "y": 12,
      "z": -3,
      "name": "Plant_Leaves_Cherry_Full"
    },
    {
      "x": 5,
      "y": 11,
      "z": -2,
      "name": "Plant_Leaves_Cherry_Full"
    },
    {
      "x": 5,
      "y": 12,
      "z": -2,
      "name": "Plant_Leaves_Cherry_Full"
    },
    {
      "x": 5,
      "y": 12,
      "z": -1,
      "name": "Plant_Leaves_Cherry_Full"
    },
    {
      "x": 5,
      "y": 11,
      "z": 0,
      "name": "Plant_Leaves_Cherry_Full"
    },
    {
      "x": 5,
      "y": 12,
      "z": 0,
      "name": "Plant_Leaves_Cherry_Full"
    },
    {
      "x": 6,
      "y": 11,
      "z": -2,
      "name": "Plant_Leaves_Cherry_Full"
    },
    {
      "x": 6,
      "y": 12,
      "z": -2,
      "name": "Plant_Leaves_Cherry_Full"
    }
  ],
  "fluids": [
    {
      "x": -6,
      "y": 15,
      "z": -4,
      "name": "Empty",
      "level": 0
    },
    {
      "x": -6,
      "y": 15,
      "z": -3,
      "name": "Empty",
      "level": 0
    },
    {
      "x": -6,
      "y": 15,
      "z": -2,
      "name": "Empty",
      "level": 0
    },
    {
      "x": -6,
      "y": 14,
      "z": -1,
      "name": "Empty",
      "level": 0
    },
    {
      "x": -6,
      "y": 14,
      "z": 0,
      "name": "Empty",
      "level": 0
    },
    {
      "x": -6,
      "y": 14,
      "z": 1,
      "name": "Empty",
      "level": 0
    },
    {
      "x": -5,
      "y": 14,
      "z": -5,
      "name": "Empty",
      "level": 0
    },
    {
      "x": -5,
      "y": 15,
      "z": -4,
      "name": "Empty",
      "level": 0
    },
    {
      "x": -5,
      "y": 15,
      "z": -3,
      "name": "Empty",
      "level": 0
    },
    {
      "x": -5,
      "y": 14,
      "z": -2,
      "name": "Empty",
      "level": 0
    },
    {
      "x": -5,
      "y": 15,
      "z": -2,
      "name": "Empty",
      "level": 0
    },
    {
      "x": -5,
      "y": 15,
      "z": -1,
      "name": "Empty",
      "level": 0
    },
    {
      "x": -5,
      "y": 14,
      "z": 0,
      "name": "Empty",
      "level": 0
    },
    {
      "x": -5,
      "y": 13,
      "z": 1,
      "name": "Empty",
      "level": 0
    },
    {
      "x": -5,
      "y": 14,
      "z": 1,
      "name": "Empty",
      "level": 0
    },
    {
      "x": -5,
      "y": 13,
      "z": 2,
      "name": "Empty",
      "level": 0
    },
    {
      "x": -4,
      "y": 13,
      "z": -6,
      "name": "Empty",
      "level": 0
    },
    {
      "x": -4,
      "y": 14,
      "z": -6,
      "name": "Empty",
      "level": 0
    },
    {
      "x": -4,
      "y": 14,
      "z": -5,
      "name": "Empty",
      "level": 0
    },
    {
      "x": -4,
      "y": 14,
      "z": -4,
      "name": "Empty",
      "level": 0
    },
    {
      "x": -4,
      "y": 15,
      "z": -4,
      "name": "Empty",
      "level": 0
    },
    {
      "x": -4,
      "y": 14,
      "z": -3,
      "name": "Empty",
      "level": 0
    },
    {
      "x": -4,
      "y": 15,
      "z": -3,
      "name": "Empty",
      "level": 0
    },
    {
      "x": -4,
      "y": 14,
      "z": -2,
      "name": "Empty",
      "level": 0
    },
    {
      "x": -4,
      "y": 15,
      "z": -2,
      "name": "Empty",
      "level": 0
    },
    {
      "x": -4,
      "y": 14,
      "z": -1,
      "name": "Empty",
      "level": 0
    },
    {
      "x": -4,
      "y": 15,
      "z": -1,
      "name": "Empty",
      "level": 0
    },
    {
      "x": -4,
      "y": 16,
      "z": -1,
      "name": "Empty",
      "level": 0
    },
    {
      "x": -4,
      "y": 14,
      "z": 0,
      "name": "Empty",
      "level": 0
    },
    {
      "x": -4,
      "y": 15,
      "z": 0,
      "name": "Empty",
      "level": 0
    },
    {
      "x": -4,
      "y": 13,
      "z": 1,
      "name": "Empty",
      "level": 0
    },
    {
      "x": -4,
      "y": 14,
      "z": 1,
      "name": "Empty",
      "level": 0
    },
    {
      "x": -4,
      "y": 13,
      "z": 2,
      "name": "Empty",
      "level": 0
    },
    {
      "x": -3,
      "y": 13,
      "z": -6,
      "name": "Empty",
      "level": 0
    },
    {
      "x": -3,
      "y": 14,
      "z": -6,
      "name": "Empty",
      "level": 0
    },
    {
      "x": -3,
      "y": 14,
      "z": -5,
      "name": "Empty",
      "level": 0
    },
    {
      "x": -3,
      "y": 15,
      "z": -5,
      "name": "Empty",
      "level": 0
    },
    {
      "x": -3,
      "y": 15,
      "z": -3,
      "name": "Empty",
      "level": 0
    },
    {
      "x": -3,
      "y": 14,
      "z": -2,
      "name": "Empty",
      "level": 0
    },
    {
      "x": -3,
      "y": 15,
      "z": -2,
      "name": "Empty",
      "level": 0
    },
    {
      "x": -3,
      "y": 14,
      "z": -1,
      "name": "Empty",
      "level": 0
    },
    {
      "x": -3,
      "y": 15,
      "z": -1,
      "name": "Empty",
      "level": 0
    },
    {
      "x": -3,
      "y": 16,
      "z": -1,
      "name": "Empty",
      "level": 0
    },
    {
      "x": -3,
      "y": 14,
      "z": 0,
      "name": "Empty",
      "level": 0
    },
    {
      "x": -3,
      "y": 15,
      "z": 0,
      "name": "Empty",
      "level": 0
    },
    {
      "x": -3,
      "y": 13,
      "z": 1,
      "name": "Empty",
      "level": 0
    },
    {
      "x": -3,
      "y": 14,
      "z": 1,
      "name": "Empty",
      "level": 0
    },
    {
      "x": -3,
      "y": 13,
      "z": 2,
      "name": "Empty",
      "level": 0
    },
    {
      "x": -2,
      "y": 14,
      "z": -6,
      "name": "Empty",
      "level": 0
    },
    {
      "x": -2,
      "y": 14,
      "z": -5,
      "name": "Empty",
      "level": 0
    },
    {
      "x": -2,
      "y": 15,
      "z": -5,
      "name": "Empty",
      "level": 0
    },
    {
      "x": -2,
      "y": 14,
      "z": -4,
      "name": "Empty",
      "level": 0
    },
    {
      "x": -2,
      "y": 15,
      "z": -4,
      "name": "Empty",
      "level": 0
    },
    {
      "x": -2,
      "y": 15,
      "z": -3,
      "name": "Empty",
      "level": 0
    },
    {
      "x": -2,
      "y": 13,
      "z": -2,
      "name": "Empty",
      "level": 0
    },
    {
      "x": -2,
      "y": 14,
      "z": -2,
      "name": "Empty",
      "level": 0
    },
    {
      "x": -2,
      "y": 15,
      "z": -2,
      "name": "Empty",
      "level": 0
    },
    {
      "x": -2,
      "y": 13,
      "z": -1,
      "name": "Empty",
      "level": 0
    },
    {
      "x": -2,
      "y": 14,
      "z": -1,
      "name": "Empty",
      "level": 0
    },
    {
      "x": -2,
      "y": 15,
      "z": -1,
      "name": "Empty",
      "level": 0
    },
    {
      "x": -2,
      "y": 12,
      "z": 0,
      "name": "Empty",
      "level": 0
    },
    {
      "x": -2,
      "y": 13,
      "z": 0,
      "name": "Empty",
      "level": 0
    },
    {
      "x": -2,
      "y": 14,
      "z": 0,
      "name": "Empty",
      "level": 0
    },
    {
      "x": -2,
      "y": 15,
      "z": 0,
      "name": "Empty",
      "level": 0
    },
    {
      "x": -2,
      "y": 11,
      "z": 1,
      "name": "Empty",
      "level": 0
    },
    {
      "x": -2,
      "y": 12,
      "z": 1,
      "name": "Empty",
      "level": 0
    },
    {
      "x": -2,
      "y": 13,
      "z": 1,
      "name": "Empty",
      "level": 0
    },
    {
      "x": -2,
      "y": 14,
      "z": 1,
      "name": "Empty",
      "level": 0
    },
    {
      "x": -1,
      "y": 14,
      "z": -6,
      "name": "Empty",
      "level": 0
    },
    {
      "x": -1,
      "y": 13,
      "z": -5,
      "name": "Empty",
      "level": 0
    },
    {
      "x": -1,
      "y": 14,
      "z": -5,
      "name": "Empty",
      "level": 0
    },
    {
      "x": -1,
      "y": 13,
      "z": -4,
      "name": "Empty",
      "level": 0
    },
    {
      "x": -1,
      "y": 14,
      "z": -4,
      "name": "Empty",
      "level": 0
    },
    {
      "x": -1,
      "y": 14,
      "z": -3,
      "name": "Empty",
      "level": 0
    },
    {
      "x": -1,
      "y": 15,
      "z": -3,
      "name": "Empty",
      "level": 0
    },
    {
      "x": -1,
      "y": 12,
      "z": -2,
      "name": "Empty",
      "level": 0
    },
    {
      "x": -1,
      "y": 14,
      "z": -2,
      "name": "Empty",
      "level": 0
    },
    {
      "x": -1,
      "y": 15,
      "z": -2,
      "name": "Empty",
      "level": 0
    },
    {
      "x": -1,
      "y": 14,
      "z": -1,
      "name": "Empty",
      "level": 0
    },
    {
      "x": -1,
      "y": 15,
      "z": -1,
      "name": "Empty",
      "level": 0
    },
    {
      "x": -1,
      "y": 14,
      "z": 0,
      "name": "Empty",
      "level": 0
    },
    {
      "x": -1,
      "y": 11,
      "z": 1,
      "name": "Empty",
      "level": 0
    },
    {
      "x": -1,
      "y": 12,
      "z": 1,
      "name": "Empty",
      "level": 0
    },
    {
      "x": -1,
      "y": 13,
      "z": 1,
      "name": "Empty",
      "level": 0
    },
    {
      "x": -1,
      "y": 12,
      "z": 2,
      "name": "Empty",
      "level": 0
    },
    {
      "x": -1,
      "y": 13,
      "z": 2,
      "name": "Empty",
      "level": 0
    },
    {
      "x": -1,
      "y": 13,
      "z": 3,
      "name": "Empty",
      "level": 0
    },
    {
      "x": -1,
      "y": 13,
      "z": 4,
      "name": "Empty",
      "level": 0
    },
    {
      "x": 0,
      "y": 14,
      "z": -4,
      "name": "Empty",
      "level": 0
    },
    {
      "x": 0,
      "y": 15,
      "z": -3,
      "name": "Empty",
      "level": 0
    },
    {
      "x": 0,
      "y": 12,
      "z": -2,
      "name": "Empty",
      "level": 0
    },
    {
      "x": 0,
      "y": 15,
      "z": -2,
      "name": "Empty",
      "level": 0
    },
    {
      "x": 0,
      "y": 11,
      "z": 0,
      "name": "Empty",
      "level": 0
    },
    {
      "x": 0,
      "y": 11,
      "z": 1,
      "name": "Empty",
      "level": 0
    },
    {
      "x": 0,
      "y": 13,
      "z": 1,
      "name": "Empty",
      "level": 0
    },
    {
      "x": 0,
      "y": 13,
      "z": 2,
      "name": "Empty",
      "level": 0
    },
    {
      "x": 0,
      "y": 14,
      "z": 2,
      "name": "Empty",
      "level": 0
    },
    {
      "x": 0,
      "y": 13,
      "z": 3,
      "name": "Empty",
      "level": 0
    },
    {
      "x": 0,
      "y": 14,
      "z": 3,
      "name": "Empty",
      "level": 0
    },
    {
      "x": 0,
      "y": 13,
      "z": 4,
      "name": "Empty",
      "level": 0
    },
    {
      "x": 0,
      "y": 13,
      "z": 5,
      "name": "Empty",
      "level": 0
    },
    {
      "x": 1,
      "y": 12,
      "z": -4,
      "name": "Empty",
      "level": 0
    },
    {
      "x": 1,
      "y": 12,
      "z": -3,
      "name": "Empty",
      "level": 0
    },
    {
      "x": 1,
      "y": 13,
      "z": -3,
      "name": "Empty",
      "level": 0
    },
    {
      "x": 1,
      "y": 12,
      "z": -2,
      "name": "Empty",
      "level": 0
    },
    {
      "x": 1,
      "y": 13,
      "z": -2,
      "name": "Empty",
      "level": 0
    },
    {
      "x": 1,
      "y": 11,
      "z": -1,
      "name": "Empty",
      "level": 0
    },
    {
      "x": 1,
      "y": 12,
      "z": -1,
      "name": "Empty",
      "level": 0
    },
    {
      "x": 1,
      "y": 13,
      "z": -1,
      "name": "Empty",
      "level": 0
    },
    {
      "x": 1,
      "y": 1,
      "z": 0,
      "name": "Empty",
      "level": 0
    },
    {
      "x": 1,
      "y": 2,
      "z": 0,
      "name": "Empty",
      "level": 0
    },
    {
      "x": 1,
      "y": 3,
      "z": 0,
      "name": "Empty",
      "level": 0
    },
    {
      "x": 1,
      "y": 4,
      "z": 0,
      "name": "Empty",
      "level": 0
    },
    {
      "x": 1,
      "y": 5,
      "z": 0,
      "name": "Empty",
      "level": 0
    },
    {
      "x": 1,
      "y": 6,
      "z": 0,
      "name": "Empty",
      "level": 0
    },
    {
      "x": 1,
      "y": 9,
      "z": 0,
      "name": "Empty",
      "level": 0
    },
    {
      "x": 1,
      "y": 10,
      "z": 0,
      "name": "Empty",
      "level": 0
    },
    {
      "x": 1,
      "y": 11,
      "z": 0,
      "name": "Empty",
      "level": 0
    },
    {
      "x": 1,
      "y": 12,
      "z": 0,
      "name": "Empty",
      "level": 0
    },
    {
      "x": 1,
      "y": 3,
      "z": 1,
      "name": "Empty",
      "level": 0
    },
    {
      "x": 1,
      "y": 4,
      "z": 1,
      "name": "Empty",
      "level": 0
    },
    {
      "x": 1,
      "y": 5,
      "z": 1,
      "name": "Empty",
      "level": 0
    },
    {
      "x": 1,
      "y": 12,
      "z": 1,
      "name": "Empty",
      "level": 0
    },
    {
      "x": 1,
      "y": 13,
      "z": 1,
      "name": "Empty",
      "level": 0
    },
    {
      "x": 1,
      "y": 12,
      "z": 2,
      "name": "Empty",
      "level": 0
    },
    {
      "x": 1,
      "y": 13,
      "z": 2,
      "name": "Empty",
      "level": 0
    },
    {
      "x": 1,
      "y": 13,
      "z": 3,
      "name": "Empty",
      "level": 0
    },
    {
      "x": 1,
      "y": 12,
      "z": 4,
      "name": "Empty",
      "level": 0
    },
    {
      "x": 1,
      "y": 13,
      "z": 4,
      "name": "Empty",
      "level": 0
    },
    {
      "x": 1,
      "y": 14,
      "z": 4,
      "name": "Empty",
      "level": 0
    },
    {
      "x": 1,
      "y": 13,
      "z": 5,
      "name": "Empty",
      "level": 0
    },
    {
      "x": 1,
      "y": 13,
      "z": 6,
      "name": "Empty",
      "level": 0
    },
    {
      "x": 2,
      "y": 12,
      "z": -5,
      "name": "Empty",
      "level": 0
    },
    {
      "x": 2,
      "y": 12,
      "z": -4,
      "name": "Empty",
      "level": 0
    },
    {
      "x": 2,
      "y": 12,
      "z": -3,
      "name": "Empty",
      "level": 0
    },
    {
      "x": 2,
      "y": 13,
      "z": -3,
      "name": "Empty",
      "level": 0
    },
    {
      "x": 2,
      "y": 12,
      "z": -2,
      "name": "Empty",
      "level": 0
    },
    {
      "x": 2,
      "y": 13,
      "z": -2,
      "name": "Empty",
      "level": 0
    },
    {
      "x": 2,
      "y": 12,
      "z": -1,
      "name": "Empty",
      "level": 0
    },
    {
      "x": 2,
      "y": 13,
      "z": -1,
      "name": "Empty",
      "level": 0
    },
    {
      "x": 2,
      "y": 4,
      "z": 0,
      "name": "Empty",
      "level": 0
    },
    {
      "x": 2,
      "y": 5,
      "z": 0,
      "name": "Empty",
      "level": 0
    },
    {
      "x": 2,
      "y": 6,
      "z": 0,
      "name": "Empty",
      "level": 0
    },
    {
      "x": 2,
      "y": 7,
      "z": 0,
      "name": "Empty",
      "level": 0
    },
    {
      "x": 2,
      "y": 8,
      "z": 0,
      "name": "Empty",
      "level": 0
    },
    {
      "x": 2,
      "y": 9,
      "z": 0,
      "name": "Empty",
      "level": 0
    },
    {
      "x": 2,
      "y": 12,
      "z": 0,
      "name": "Empty",
      "level": 0
    },
    {
      "x": 2,
      "y": 13,
      "z": 0,
      "name": "Empty",
      "level": 0
    },
    {
      "x": 2,
      "y": 3,
      "z": 1,
      "name": "Empty",
      "level": 0
    },
    {
      "x": 2,
      "y": 4,
      "z": 1,
      "name": "Empty",
      "level": 0
    },
    {
      "x": 2,
      "y": 5,
      "z": 1,
      "name": "Empty",
      "level": 0
    },
    {
      "x": 2,
      "y": 12,
      "z": 1,
      "name": "Empty",
      "level": 0
    },
    {
      "x": 2,
      "y": 0,
      "z": 2,
      "name": "Empty",
      "level": 0
    },
    {
      "x": 2,
      "y": 1,
      "z": 2,
      "name": "Empty",
      "level": 0
    },
    {
      "x": 2,
      "y": 2,
      "z": 2,
      "name": "Empty",
      "level": 0
    },
    {
      "x": 2,
      "y": 3,
      "z": 2,
      "name": "Empty",
      "level": 0
    },
    {
      "x": 2,
      "y": 4,
      "z": 2,
      "name": "Empty",
      "level": 0
    },
    {
      "x": 2,
      "y": 12,
      "z": 2,
      "name": "Empty",
      "level": 0
    },
    {
      "x": 2,
      "y": 13,
      "z": 2,
      "name": "Empty",
      "level": 0
    },
    {
      "x": 2,
      "y": 14,
      "z": 2,
      "name": "Empty",
      "level": 0
    },
    {
      "x": 2,
      "y": 12,
      "z": 3,
      "name": "Empty",
      "level": 0
    },
    {
      "x": 2,
      "y": 13,
      "z": 3,
      "name": "Empty",
      "level": 0
    },
    {
      "x": 2,
      "y": 14,
      "z": 3,
      "name": "Empty",
      "level": 0
    },
    {
      "x": 2,
      "y": 12,
      "z": 4,
      "name": "Empty",
      "level": 0
    },
    {
      "x": 2,
      "y": 13,
      "z": 4,
      "name": "Empty",
      "level": 0
    },
    {
      "x": 2,
      "y": 14,
      "z": 4,
      "name": "Empty",
      "level": 0
    },
    {
      "x": 2,
      "y": 12,
      "z": 5,
      "name": "Empty",
      "level": 0
    },
    {
      "x": 2,
      "y": 13,
      "z": 5,
      "name": "Empty",
      "level": 0
    },
    {
      "x": 2,
      "y": 14,
      "z": 5,
      "name": "Empty",
      "level": 0
    },
    {
      "x": 2,
      "y": 13,
      "z": 6,
      "name": "Empty",
      "level": 0
    },
    {
      "x": 3,
      "y": 12,
      "z": -6,
      "name": "Empty",
      "level": 0
    },
    {
      "x": 3,
      "y": 12,
      "z": -5,
      "name": "Empty",
      "level": 0
    },
    {
      "x": 3,
      "y": 12,
      "z": -4,
      "name": "Empty",
      "level": 0
    },
    {
      "x": 3,
      "y": 13,
      "z": -4,
      "name": "Empty",
      "level": 0
    },
    {
      "x": 3,
      "y": 12,
      "z": -3,
      "name": "Empty",
      "level": 0
    },
    {
      "x": 3,
      "y": 13,
      "z": -3,
      "name": "Empty",
      "level": 0
    },
    {
      "x": 3,
      "y": 12,
      "z": -2,
      "name": "Empty",
      "level": 0
    },
    {
      "x": 3,
      "y": 2,
      "z": -1,
      "name": "Empty",
      "level": 0
    },
    {
      "x": 3,
      "y": 3,
      "z": -1,
      "name": "Empty",
      "level": 0
    },
    {
      "x": 3,
      "y": 4,
      "z": -1,
      "name": "Empty",
      "level": 0
    },
    {
      "x": 3,
      "y": 5,
      "z": -1,
      "name": "Empty",
      "level": 0
    },
    {
      "x": 3,
      "y": 6,
      "z": -1,
      "name": "Empty",
      "level": 0
    },
    {
      "x": 3,
      "y": 12,
      "z": -1,
      "name": "Empty",
      "level": 0
    },
    {
      "x": 3,
      "y": 13,
      "z": -1,
      "name": "Empty",
      "level": 0
    },
    {
      "x": 3,
      "y": 6,
      "z": 0,
      "name": "Empty",
      "level": 0
    },
    {
      "x": 3,
      "y": 7,
      "z": 0,
      "name": "Empty",
      "level": 0
    },
    {
      "x": 3,
      "y": 12,
      "z": 0,
      "name": "Empty",
      "level": 0
    },
    {
      "x": 3,
      "y": 6,
      "z": 1,
      "name": "Empty",
      "level": 0
    },
    {
      "x": 3,
      "y": 11,
      "z": 1,
      "name": "Empty",
      "level": 0
    },
    {
      "x": 3,
      "y": 12,
      "z": 1,
      "name": "Empty",
      "level": 0
    },
    {
      "x": 3,
      "y": 12,
      "z": 2,
      "name": "Empty",
      "level": 0
    },
    {
      "x": 3,
      "y": 13,
      "z": 2,
      "name": "Empty",
      "level": 0
    },
    {
      "x": 3,
      "y": 12,
      "z": 3,
      "name": "Empty",
      "level": 0
    },
    {
      "x": 3,
      "y": 13,
      "z": 3,
      "name": "Empty",
      "level": 0
    },
    {
      "x": 3,
      "y": 13,
      "z": 4,
      "name": "Empty",
      "level": 0
    },
    {
      "x": 3,
      "y": 14,
      "z": 4,
      "name": "Empty",
      "level": 0
    },
    {
      "x": 3,
      "y": 13,
      "z": 5,
      "name": "Empty",
      "level": 0
    },
    {
      "x": 3,
      "y": 13,
      "z": 6,
      "name": "Empty",
      "level": 0
    },
    {
      "x": 4,
      "y": 12,
      "z": -5,
      "name": "Empty",
      "level": 0
    },
    {
      "x": 4,
      "y": 12,
      "z": -4,
      "name": "Empty",
      "level": 0
    },
    {
      "x": 4,
      "y": 13,
      "z": -4,
      "name": "Empty",
      "level": 0
    },
    {
      "x": 4,
      "y": 12,
      "z": -3,
      "name": "Empty",
      "level": 0
    },
    {
      "x": 4,
      "y": 12,
      "z": -2,
      "name": "Empty",
      "level": 0
    },
    {
      "x": 4,
      "y": 13,
      "z": -2,
      "name": "Empty",
      "level": 0
    },
    {
      "x": 4,
      "y": 12,
      "z": -1,
      "name": "Empty",
      "level": 0
    },
    {
      "x": 4,
      "y": 13,
      "z": -1,
      "name": "Empty",
      "level": 0
    },
    {
      "x": 4,
      "y": 11,
      "z": 0,
      "name": "Empty",
      "level": 0
    },
    {
      "x": 4,
      "y": 12,
      "z": 0,
      "name": "Empty",
      "level": 0
    },
    {
      "x": 4,
      "y": 11,
      "z": 1,
      "name": "Empty",
      "level": 0
    },
    {
      "x": 4,
      "y": 12,
      "z": 2,
      "name": "Empty",
      "level": 0
    },
    {
      "x": 4,
      "y": 12,
      "z": 3,
      "name": "Empty",
      "level": 0
    },
    {
      "x": 4,
      "y": 13,
      "z": 4,
      "name": "Empty",
      "level": 0
    },
    {
      "x": 4,
      "y": 13,
      "z": 5,
      "name": "Empty",
      "level": 0
    },
    {
      "x": 5,
      "y": 11,
      "z": -3,
      "name": "Empty",
      "level": 0
    },
    {
      "x": 5,
      "y": 12,
      "z": -3,
      "name": "Empty",
      "level": 0
    },
    {
      "x": 5,
      "y": 11,
      "z": -2,
      "name": "Empty",
      "level": 0
    },
    {
      "x": 5,
      "y": 12,
      "z": -2,
      "name": "Empty",
      "level": 0
    },
    {
      "x": 5,
      "y": 12,
      "z": -1,
      "name": "Empty",
      "level": 0
    },
    {
      "x": 5,
      "y": 11,
      "z": 0,
      "name": "Empty",
      "level": 0
    },
    {
      "x": 5,
      "y": 12,
      "z": 0,
      "name": "Empty",
      "level": 0
    },
    {
      "x": 6,
      "y": 11,
      "z": -2,
      "name": "Empty",
      "level": 0
    },
    {
      "x": 6,
      "y": 12,
      "z": -2,
      "name": "Empty",
      "level": 0
    }
  ]
}