{
  "version": 8,
  "blockIdVersion": 11,
  "anchorX": 4,
  "anchorY": 4,
  "anchorZ": 3,
  "blocks": [
    {
      "x": -6,
      "y": 12,
      "z": 0,
      "name": "Plant_Leaves_Cherry_Full"
    },
    {
      "x": -6,
      "y": 12,
      "z": 1,
      "name": "Plant_Leaves_Cherry_Full"
    },
    {
      "x": -6,
      "y": 13,
      "z": 1,
      "name": "Plant_Leaves_Cherry_Full"
    },
    {
      "x": -6,
      "y": 13,
      "z": 2,
      "name": "Plant_Leaves_Cherry_Full"
    },
    {
      "x": -6,
      "y": 13,
      "z": 3,
      "name": "Plant_Leaves_Cherry_Full"
    },
    {
      "x": -5,
      "y": 12,
      "z": -1,
      "name": "Plant_Leaves_Cherry_Full"
    },
    {
      "x": -5,
      "y": 13,
      "z": 0,
      "name": "Plant_Leaves_Cherry_Full"
    },
    {
      "x": -5,
      "y": 13,
      "z": 1,
      "name": "Plant_Leaves_Cherry_Full"
    },
    {
      "x": -5,
      "y": 14,
      "z": 1,
      "name": "Plant_Leaves_Cherry_Full"
    },
    {
      "x": -5,
      "y": 14,
      "z": 2,
      "name": "Plant_Leaves_Cherry_Full"
    },
    {
      "x": -5,
      "y": 13,
      "z": 3,
      "name": "Plant_Leaves_Cherry_Full"
    },
    {
      "x": -5,
      "y": 14,
      "z": 3,
      "name": "Plant_Leaves_Cherry_Full"
    },
    {
      "x": -4,
      "y": 12,
      "z": -1,
      "name": "Plant_Leaves_Cherry_Full"
    },
    {
      "x": -4,
      "y": 13,
      "z": 0,
      "name": "Plant_Leaves_Cherry_Full"
    },
    {
      "x": -4,
      "y": 14,
      "z": 0,
      "name": "Plant_Leaves_Cherry_Full"
    },
    {
      "x": -4,
      "y": 14,
      "z": 1,
      "name": "Wood_Wisteria_Wild_Branch_Long",
      "rotation": 5
    },
    {
      "x": -4,
      "y": 15,
      "z": 1,
      "name": "Plant_Leaves_Cherry_Full"
    },
    {
      "x": -4,
      "y": 14,
      "z": 2,
      "name": "Plant_Leaves_Cherry_Full"
    },
    {
      "x": -4,
      "y": 14,
      "z": 3,
      "name": "Plant_Leaves_Cherry_Full"
    },
    {
      "x": -3,
      "y": 14,
      "z": -2,
      "name": "Plant_Leaves_Cherry_Full"
    },
    {
      "x": -3,
      "y": 12,
      "z": -1,
      "name": "Plant_Leaves_Cherry_Full"
    },
    {
      "x": -3,
      "y": 14,
      "z": -1,
      "name": "Plant_Leaves_Cherry_Full"
    },
    {
      "x": -3,
      "y": 14,
      "z": 0,
      "name": "Plant_Leaves_Cherry_Full"
    },
    {
      "x": -3,
      "y": 14,
      "z": 1,
      "name": "Wood_Cherry_Trunk_Full"
    },
    {
      "x": -3,
      "y": 15,
      "z": 1,
      "name": "Plant_Leaves_Cherry_Full"
    },
    {
      "x": -3,
      "y": 13,
      "z": 2,
      "name": "Plant_Leaves_Cherry_Full"
    },
    {
      "x": -3,
      "y": 14,
      "z": 2,
      "name": "Plant_Leaves_Cherry_Full"
    },
    {
      "x": -3,
      "y": 13,
      "z": 3,
      "name": "Plant_Leaves_Cherry_Full"
    },
    {
      "x": -3,
      "y": 14,
      "z": 3,
      "name": "Plant_Leaves_Cherry_Full"
    },
    {
      "x": -3,
      "y": 14,
      "z": 4,
      "name": "Plant_Leaves_Cherry_Full"
    },
    {
      "x": -3,
      "y": 13,
      "z": 5,
      "name": "Plant_Leaves_Cherry_Full"
    },
    {
      "x": -3,
      "y": 14,
      "z": 5,
      "name": "Plant_Leaves_Cherry_Full"
    },
    {
      "x": -3,
      "y": 14,
      "z": 6,
      "name": "Plant_Leaves_Cherry_Full"
    },
    {
      "x": -2,
      "y": 14,
      "z": -4,
      "name": "Plant_Leaves_Cherry_Full"
    },
    {
      "x": -2,
      "y": 14,
      "z": -3,
      "name": "Plant_Leaves_Cherry_Full"
    },
    {
      "x": -2,
      "y": 14,
      "z": -2,
      "name": "Plant_Leaves_Cherry_Full"
    },
    {
      "x": -2,
      "y": 13,
      "z": -1,
      "name": "Plant_Leaves_Cherry_Full"
    },
    {
      "x": -2,
      "y": 14,
      "z": -1,
      "name": "Plant_Leaves_Cherry_Full"
    },
    {
      "x": -2,
      "y": 12,
      "z": 0,
      "name": "Plant_Leaves_Cherry_Full"
    },
    {
      "x": -2,
      "y": 13,
      "z": 0,
      "name": "Plant_Leaves_Cherry_Full"
    },
    {
      "x": -2,
      "y": 14,
      "z": 0,
      "name": "Plant_Leaves_Cherry_Full"
    },
    {
      "x": -2,
      "y": 14,
      "z": 1,
      "name": "Wood_Cherry_Trunk_Full"
    },
    {
      "x": -2,
      "y": 15,
      "z": 1,
      "name": "Plant_Leaves_Cherry_Full"
    },
    {
      "x": -2,
      "y": 14,
      "z": 2,
      "name": "Wood_Cherry_Trunk_Full"
    },
    {
      "x": -2,
      "y": 15,
      "z": 2,
      "name": "Plant_Leaves_Cherry_Full"
    },
    {
      "x": -2,
      "y": 13,
      "z": 3,
      "name": "Plant_Leaves_Cherry_Full"
    },
    {
      "x": -2,
      "y": 14,
      "z": 3,
      "name": "Plant_Leaves_Cherry_Full"
    },
    {
      "x": -2,
      "y": 14,
      "z": 4,
      "name": "Plant_Leaves_Cherry_Full"
    },
    {
      "x": -2,
      "y": 13,
      "z": 5,
      "name": "Wood_Wisteria_Wild_Branch_Long",
      "rotation": 5
    },
    {
      "x": -2,
      "y": 14,
      "z": 5,
      "name": "Plant_Leaves_Cherry_Full"
    },
    {
      "x": -2,
      "y": 13,
      "z": 6,
      "name": "Plant_Leaves_Cherry_Full"
    },
    {
      "x": -2,
      "y": 14,
      "z": 6,
      "name": "Plant_Leaves_Cherry_Full"
    },
    {
      "x": -1,
      "y": 13,
      "z": -4,
      "name": "Plant_Leaves_Cherry_Full"
    },
    {
      "x": -1,
      "y": 14,
      "z": -4,
      "name": "Plant_Leaves_Cherry_Full"
    },
    {
      "x": -1,
      "y": 13,
      "z": -3,
      "name": "Plant_Leaves_Cherry_Full"
    },
    {
      "x": -1,
      "y": 14,
      "z": -3,
      "name": "Plant_Leaves_Cherry_Full"
    },
    {
      "x": -1,
      "y": 14,
      "z": -2,
      "name": "Plant_Leaves_Cherry_Full"
    },
    {
      "x": -1,
      "y": 15,
      "z": -2,
      "name": "Plant_Leaves_Cherry_Full"
    },
    {
      "x": -1,
      "y": 14,
      "z": -1,
      "name": "Plant_Leaves_Cherry_Full"
    },
    {
      "x": -1,
      "y": 15,
      "z": -1,
      "name": "Plant_Leaves_Cherry_Full"
    },
    {
      "x": -1,
      "y": 12,
      "z": 0,
      "name": "Plant_Leaves_Cherry_Full"
    },
    {
      "x": -1,
      "y": 13,
      "z": 0,
      "name": "Plant_Leaves_Cherry_Full"
    },
    {
      "x": -1,
      "y": 14,
      "z": 0,
      "name": "Plant_Leaves_Cherry_Full"
    },
    {
      "x": -1,
      "y": 15,
      "z": 0,
      "name": "Plant_Leaves_Cherry_Full"
    },
    {
      "x": -1,
      "y": 14,
      "z": 1,
      "name": "Plant_Leaves_Cherry_Full"
    },
    {
      "x": -1,
      "y": 13,
      "z": 2,
      "name": "Wood_Cherry_Trunk_Full"
    },
    {
      "x": -1,
      "y": 14,
      "z": 2,
      "name": "Wood_Cherry_Trunk_Full",
      "rotation": 4
    },
    {
      "x": -1,
      "y": 15,
      "z": 2,
      "name": "Plant_Leaves_Cherry_Full"
    },
    {
      "x": -1,
      "y": 13,
      "z": 3,
      "name": "Wood_Cherry_Trunk_Full"
    },
    {
      "x": -1,
      "y": 14,
      "z": 3,
      "name": "Plant_Leaves_Cherry_Full"
    },
    {
      "x": -1,
      "y": 13,
      "z": 4,
      "name": "Wood_Cherry_Trunk_Full"
    },
    {
      "x": -1,
      "y": 13,
      "z": 5,
      "name": "Wood_Cherry_Trunk_Full"
    },
    {
      "x": -1,
      "y": 14,
      "z": 5,
      "name": "Plant_Leaves_Cherry_Full"
    },
    {
      "x": -1,
      "y": 12,
      "z": 6,
      "name": "Plant_Leaves_Cherry_Full"
    },
    {
      "x": -1,
      "y": 13,
      "z": 6,
      "name": "Plant_Leaves_Cherry_Full"
    },
    {
      "x": -1,
      "y": 14,
      "z": 6,
      "name": "Plant_Leaves_Cherry_Full"
    },
    {
      "x": 0,
      "y": 13,
      "z": -5,
      "name": "Plant_Leaves_Cherry_Full"
    },
    {
      "x": 0,
      "y": 13,
      "z": -4,
      "name": "Plant_Leaves_Cherry_Full"
    },
    {
      "x": 0,
      "y": 14,
      "z": -4,
      "name": "Plant_Leaves_Cherry_Full"
    },
    {
      "x": 0,
      "y": 13,
      "z": -3,
      "name": "Wood_Wisteria_Wild_Branch_Long",
      "rotation": 4
    },
    {
      "x": 0,
      "y": 15,
      "z": -3,
      "name": "Plant_Leaves_Cherry_Full"
    },
    {
      "x": 0,
      "y": 13,
      "z": -2,
      "name": "Wood_Cherry_Trunk_Full"
    },
    {
      "x": 0,
      "y": 14,
      "z": -2,
      "name": "Plant_Leaves_Cherry_Full"
    },
    {
      "x": 0,
      "y": 13,
      "z": -1,
      "name": "Wood_Cherry_Trunk_Full"
    },
    {
      "x": 0,
      "y": 14,
      "z": -1,
      "name": "Plant_Leaves_Cherry_Full"
    },
    {
      "x": 0,
      "y": 15,
      "z": -1,
      "name": "Plant_Leaves_Cherry_Full"
    },
    {
      "x": 0,
      "y": 14,
      "z": 0,
      "name": "Plant_Leaves_Cherry_Full"
    },
    {
      "x": 0,
      "y": 14,
      "z": 1,
      "name": "Plant_Leaves_Cherry_Full"
    },
    {
      "x": 0,
      "y": 13,
      "z": 2,
      "name": "Wood_Cherry_Trunk_Full"
    },
    {
      "x": 0,
      "y": 14,
      "z": 2,
      "name": "Plant_Leaves_Cherry_Full"
    },
    {
      "x": 0,
      "y": 13,
      "z": 3,
      "name": "Plant_Leaves_Cherry_Full"
    },
    {
      "x": 0,
      "y": 14,
      "z": 3,
      "name": "Plant_Leaves_Cherry_Full"
    },
    {
      "x": 0,
      "y": 13,
      "z": 4,
      "name": "Plant_Leaves_Cherry_Full"
    },
    {
      "x": 0,
      "y": 14,
      "z": 4,
      "name": "Plant_Leaves_Cherry_Full"
    },
    {
      "x": 0,
      "y": 12,
      "z": 5,
      "name": "Plant_Leaves_Cherry_Full"
    },
    {
      "x": 0,
      "y": 13,
      "z": 5,
      "name": "Plant_Leaves_Cherry_Full"
    },
    {
      "x": 0,
      "y": 14,
      "z": 5,
      "name": "Plant_Leaves_Cherry_Full"
    },
    {
      "x": 0,
      "y": 13,
      "z": 6,
      "name": "Plant_Leaves_Cherry_Full"
    },
    {
      "x": 1,
      "y": 13,
      "z": -5,
      "name": "Plant_Leaves_Cherry_Full"
    },
    {
      "x": 1,
      "y": 13,
      "z": -4,
      "name": "Plant_Leaves_Cherry_Full"
    },
    {
      "x": 1,
      "y": 14,
      "z": -4,
      "name": "Plant_Leaves_Cherry_Full"
    },
    {
      "x": 1,
      "y": 14,
      "z": -3,
      "name": "Plant_Leaves_Cherry_Full"
    },
    {
      "x": 1,
      "y": 14,
      "z": -2,
      "name": "Plant_Leaves_Cherry_Full"
    },
    {
      "x": 1,
      "y": 13,
      "z": -1,
      "name": "Wood_Cherry_Trunk_Full"
    },
    {
      "x": 1,
      "y": 15,
      "z": -1,
      "name": "Plant_Leaves_Cherry_Full"
    },
    {
      "x": 1,
      "y": 13,
      "z": 0,
      "name": "Wood_Cherry_Trunk_Full"
    },
    {
      "x": 1,
      "y": 14,
      "z": 0,
      "name": "Plant_Leaves_Cherry_Full"
    },
    {
      "x": 1,
      "y": 10,
      "z": 1,
      "name": "Wood_Cherry_Trunk_Full"
    },
    {
      "x": 1,
      "y": 11,
      "z": 1,
      "name": "Wood_Cherry_Trunk_Full"
    },
    {
      "x": 1,
      "y": 12,
      "z": 1,
      "name": "Wood_Cherry_Trunk_Full"
    },
    {
      "x": 1,
      "y": 13,
      "z": 1,
      "name": "Wood_Cherry_Trunk_Full"
    },
    {
      "x": 1,
      "y": 14,
      "z": 1,
      "name": "Plant_Leaves_Cherry_Full"
    },
    {
      "x": 1,
      "y": 12,
      "z": 2,
      "name": "Wood_Cherry_Trunk_Full"
    },
    {
      "x": 1,
      "y": 13,
      "z": 2,
      "name": "Wood_Cherry_Trunk_Full"
    },
    {
      "x": 1,
      "y": 14,
      "z": 2,
      "name": "Plant_Leaves_Cherry_Full"
    },
    {
      "x": 1,
      "y": 13,
      "z": 3,
      "name": "Plant_Leaves_Cherry_Full"
    },
    {
      "x": 1,
      "y": 12,
      "z": 4,
      "name": "Plant_Leaves_Cherry_Full"
    },
    {
      "x": 1,
      "y": 13,
      "z": 4,
      "name": "Plant_Leaves_Cherry_Full"
    },
    {
      "x": 1,
      "y": 12,
      "z": 5,
      "name": "Plant_Leaves_Cherry_Full"
    },
    {
      "x": 2,
      "y": 13,
      "z": -5,
      "name": "Plant_Leaves_Cherry_Full"
    },
    {
      "x": 2,
      "y": 13,
      "z": -4,
      "name": "Plant_Leaves_Cherry_Full"
    },
    {
      "x": 2,
      "y": 14,
      "z": -4,
      "name": "Plant_Leaves_Cherry_Full"
    },
    {
      "x": 2,
      "y": 14,
      "z": -3,
      "name": "Plant_Leaves_Cherry_Full"
    },
    {
      "x": 2,
      "y": 14,
      "z": -2,
      "name": "Plant_Leaves_Cherry_Full"
    },
    {
      "x": 2,
      "y": 12,
      "z": -1,
      "name": "Plant_Leaves_Cherry_Full"
    },
    {
      "x": 2,
      "y": 14,
      "z": -1,
      "name": "Plant_Leaves_Cherry_Full"
    },
    {
      "x": 2,
      "y": 15,
      "z": -1,
      "name": "Plant_Leaves_Cherry_Full"
    },
    {
      "x": 2,
      "y": 13,
      "z": 0,
      "name": "Plant_Leaves_Cherry_Full"
    },
    {
      "x": 2,
      "y": 14,
      "z": 0,
      "name": "Plant_Leaves_Cherry_Full"
    },
    {
      "x": 2,
      "y": 15,
      "z": 0,
      "name": "Plant_Leaves_Cherry_Full"
    },
    {
      "x": 2,
      "y": 10,
      "z": 1,
      "name": "Wood_Cherry_Trunk_Full"
    },
    {
      "x": 2,
      "y": 13,
      "z": 1,
      "name": "Plant_Leaves_Cherry_Full"
    },
    {
      "x": 2,
      "y": 14,
      "z": 1,
      "name": "Plant_Leaves_Cherry_Full"
    },
    {
      "x": 2,
      "y": 10,
      "z": 2,
      "name": "Wood_Cherry_Trunk_Full"
    },
    {
      "x": 2,
      "y": 12,
      "z": 2,
      "name": "Wood_Cherry_Trunk_Full"
    },
    {
      "x": 2,
      "y": 13,
      "z": 2,
      "name": "Plant_Leaves_Cherry_Full"
    },
    {
      "x": 2,
      "y": 12,
      "z": 3,
      "name": "Plant_Leaves_Cherry_Full"
    },
    {
      "x": 2,
      "y": 13,
      "z": 3,
      "name": "Plant_Leaves_Cherry_Full"
    },
    {
      "x": 3,
      "y": 13,
      "z": -4,
      "name": "Plant_Leaves_Cherry_Full"
    },
    {
      "x": 3,
      "y": 13,
      "z": -3,
      "name": "Plant_Leaves_Cherry_Full"
    },
    {
      "x": 3,
      "y": 14,
      "z": -3,
      "name": "Plant_Leaves_Cherry_Full"
    },
    {
      "x": 3,
      "y": 12,
      "z": -2,
      "name": "Plant_Leaves_Cherry_Full"
    },
    {
      "x": 3,
      "y": 13,
      "z": -2,
      "name": "Plant_Leaves_Cherry_Full"
    },
    {
      "x": 3,
      "y": 14,
      "z": -2,
      "name": "Plant_Leaves_Cherry_Full"
    },
    {
      "x": 3,
      "y": 12,
      "z": -1,
      "name": "Plant_Leaves_Cherry_Full"
    },
    {
      "x": 3,
      "y": 13,
      "z": -1,
      "name": "Plant_Leaves_Cherry_Full"
    },
    {
      "x": 3,
      "y": 14,
      "z": -1,
      "name": "Plant_Leaves_Cherry_Full"
    },
    {
      "x": 3,
      "y": 13,
      "z": 0,
      "name": "Wood_Cherry_Trunk_Full"
    },
    {
      "x": 3,
      "y": 14,
      "z": 0,
      "name": "Plant_Leaves_Cherry_Full"
    },
    {
      "x": 3,
      "y": 12,
      "z": 1,
      "name": "Wood_Cherry_Trunk_Full"
    },
    {
      "x": 3,
      "y": 13,
      "z": 1,
      "name": "Wood_Cherry_Trunk_Full"
    },
    {
      "x": 3,
      "y": 14,
      "z": 1,
      "name": "Plant_Leaves_Cherry_Full"
    },
    {
      "x": 3,
      "y": 8,
      "z": 2,
      "name": "Wood_Cherry_Trunk_Full"
    },
    {
      "x": 3,
      "y": 9,
      "z": 2,
      "name": "Wood_Cherry_Trunk"
    },
    {
      "x": 3,
      "y": 10,
      "z": 2,
      "name": "Wood_Cherry_Trunk_Full"
    },
    {
      "x": 3,
      "y": 12,
      "z": 2,
      "name": "Wood_Cherry_Trunk_Full"
    },
    {
      "x": 3,
      "y": 3,
      "z": 3,
      "name": "Wood_Cherry_Trunk_Full"
    },
    {
      "x": 3,
      "y": 4,
      "z": 3,
      "name": "Wood_Cherry_Trunk_Full"
    },
    {
      "x": 3,
      "y": 8,
      "z": 3,
      "name": "Wood_Cherry_Trunk_Full"
    },
    {
      "x": 3,
      "y": 12,
      "z": 3,
      "name": "Plant_Leaves_Cherry_Full"
    },
    {
      "x": 3,
      "y": 13,
      "z": 3,
      "name": "Plant_Leaves_Cherry_Full"
    },
    {
      "x": 3,
      "y": 12,
      "z": 4,
      "name": "Plant_Leaves_Cherry_Full"
    },
    {
      "x": 3,
      "y": 13,
      "z": 4,
      "name": "Plant_Leaves_Cherry_Full"
    },
    {
      "x": 4,
      "y": 12,
      "z": -2,
      "name": "Plant_Leaves_Cherry_Full"
    },
    {
      "x": 4,
      "y": 13,
      "z": -2,
      "name": "Plant_Leaves_Cherry_Full"
    },
    {
      "x": 4,
      "y": 12,
      "z": -1,
      "name": "Plant_Leaves_Cherry_Full"
    },
    {
      "x": 4,
      "y": 13,
      "z": -1,
      "name": "Plant_Leaves_Cherry_Full"
    },
    {
      "x": 4,
      "y": 13,
      "z": 0,
      "name": "Wood_Cherry_Trunk_Full"
    },
    {
      "x": 4,
      "y": 14,
      "z": 0,
      "name": "Plant_Leaves_Cherry_Full"
    },
    {
      "x": 4,
      "y": 12,
      "z": 1,
      "name": "Plant_Leaves_Cherry_Full"
    },
    {
      "x": 4,
      "y": 13,
      "z": 1,
      "name": "Plant_Leaves_Cherry_Full"
    },
    {
      "x": 4,
      "y": 1,
      "z": 2,
      "name": "Wood_Cherry_Trunk_Full"
    },
    {
      "x": 4,
      "y": 2,
      "z": 2,
      "name": "Wood_Cherry_Trunk"
    },
    {
      "x": 4,
      "y": 3,
      "z": 2,
      "name": "Wood_Cherry_Trunk"
    },
    {
      "x": 4,
      "y": 4,
      "z": 2,
      "name": "Wood_Cherry_Trunk"
    },
    {
      "x": 4,
      "y": 5,
      "z": 2,
      "name": "Wood_Cherry_Trunk_Full"
    },
    {
      "x": 4,
      "y": 12,
      "z": 2,
      "name": "Wood_Cherry_Trunk_Full"
    },
    {
      "x": 4,
      "y": 13,
      "z": 2,
      "name": "Plant_Leaves_Cherry_Full"
    },
    {
      "x": 4,
      "y": 3,
      "z": 3,
      "name": "Wood_Cherry_Trunk"
    },
    {
      "x": 4,
      "y": 4,
      "z": 3,
      "name": "Wood_Cherry_Trunk"
    },
    {
      "x": 4,
      "y": 5,
      "z": 3,
      "name": "Wood_Cherry_Trunk"
    },
    {
      "x": 4,
      "y": 6,
      "z": 3,
      "name": "Wood_Cherry_Trunk"
    },
    {
      "x": 4,
      "y": 7,
      "z": 3,
      "name": "Wood_Cherry_Trunk"
    },
    {
      "x": 4,
      "y": 8,
      "z": 3,
      "name": "Wood_Cherry_Trunk_Full"
    },
    {
      "x": 4,
      "y": 12,
      "z": 3,
      "name": "Wood_Cherry_Trunk_Full"
    },
    {
      "x": 4,
      "y": 13,
      "z": 3,
      "name": "Wood_Cherry_Trunk_Full",
      "rotation": 4
    },
    {
      "x": 4,
      "y": 14,
      "z": 3,
      "name": "Plant_Leaves_Cherry_Full"
    },
    {
      "x": 4,
      "y": 4,
      "z": 4,
      "name": "Wood_Cherry_Trunk"
    },
    {
      "x": 4,
      "y": 5,
      "z": 4,
      "name": "Wood_Cherry_Trunk_Full"
    },
    {
      "x": 4,
      "y": 12,
      "z": 4,
      "name": "Plant_Leaves_Cherry_Full"
    },
    {
      "x": 4,
      "y": 12,
      "z": 5,
      "name": "Plant_Leaves_Cherry_Full"
    },
    {
      "x": 4,
      "y": 13,
      "z": 5,
      "name": "Plant_Leaves_Cherry_Full"
    },
    {
      "x": 5,
      "y": 12,
      "z": -1,
      "name": "Plant_Leaves_Cherry_Full"
    },
    {
      "x": 5,
      "y": 13,
      "z": -1,
      "name": "Plant_Leaves_Cherry_Full"
    },
    {
      "x": 5,
      "y": 13,
      "z": 0,
      "name": "Wood_Wisteria_Wild_Branch_Long",
      "rotation": 5
    },
    {
      "x": 5,
      "y": 13,
      "z": 1,
      "name": "Plant_Leaves_Cherry_Full"
    },
    {
      "x": 5,
      "y": 12,
      "z": 2,
      "name": "Plant_Leaves_Cherry_Full"
    },
    {
      "x": 5,
      "y": 13,
      "z": 2,
      "name": "Plant_Leaves_Cherry_Full"
    },
    {
      "x": 5,
      "y": 5,
      "z": 3,
      "name": "Wood_Cherry_Trunk"
    },
    {
      "x": 5,
      "y": 6,
      "z": 3,
      "name": "Wood_Cherry_Trunk_Full"
    },
    {
      "x": 5,
      "y": 13,
      "z": 3,
      "name": "Wood_Cherry_Trunk_Full"
    },
    {
      "x": 5,
      "y": 14,
      "z": 3,
      "name": "Plant_Leaves_Cherry_Full"
    },
    {
      "x": 5,
      "y": 0,
      "z": 4,
      "name": "Wood_Cherry_Trunk_Full"
    },
    {
      "x": 5,
      "y": 1,
      "z": 4,
      "name": "Wood_Cherry_Trunk"
    },
    {
      "x": 5,
      "y": 2,
      "z": 4,
      "name": "Wood_Cherry_Trunk"
    },
    {
      "x": 5,
      "y": 3,
      "z": 4,
      "name": "Wood_Cherry_Trunk"
    },
    {
      "x": 5,
      "y": 4,
      "z": 4,
      "name": "Wood_Cherry_Trunk_Full"
    },
    {
      "x": 5,
      "y": 13,
      "z": 4,
      "name": "Wood_Wisteria_Wild_Branch_Long",
      "rotation": 4
    },
    {
      "x": 5,
      "y": 14,
      "z": 4,
      "name": "Plant_Leaves_Cherry_Full"
    },
    {
      "x": 5,
      "y": 12,
      "z": 5,
      "name": "Plant_Leaves_Cherry_Full"
    },
    {
      "x": 5,
      "y": 13,
      "z": 5,
      "name": "Plant_Leaves_Cherry_Full"
    },
    {
      "x": 6,
      "y": 12,
      "z": -1,
      "name": "Plant_Leaves_Cherry_Full"
    },
    {
      "x": 6,
      "y": 13,
      "z": 0,
      "name": "Plant_Leaves_Cherry_Full"
    },
    {
      "x": 6,
      "y": 13,
      "z": 1,
      "name": "Plant_Leaves_Cherry_Full"
    },
    {
      "x": 6,
      "y": 12,
      "z": 2,
      "name": "Plant_Leaves_Cherry_Full"
    },
    {
      "x": 6,
      "y": 13,
      "z": 2,
      "name": "Plant_Leaves_Cherry_Full"
    },
    {
      "x": 6,
      "y": 13,
      "z": 3,
      "name": "Wood_Wisteria_Wild_Branch_Long",
      "rotation": 5
    },
    {
      "x": 6,
      "y": 12,
      "z": 4,
      "name": "Plant_Leaves_Cherry_Full"
    },
    {
      "x": 6,
      "y": 13,
      "z": 4,
      "name": "Plant_Leaves_Cherry_Full"
    },
    {
      "x": 6,
      "y": 12,
      "z": 5,
      "name": "Plant_Leaves_Cherry_Full"
    },
    {
      "x": 7,
      "y": 12,
      "z": -1,
      "name": "Plant_Leaves_Cherry_Full"
    },
    {
      "x": 7,
      "y": 12,
      "z": 0,
      "name": "Plant_Leaves_Cherry_Full"
    },
    {
      "x": 7,
      "y": 13,
      "z": 0,
      "name": "Plant_Leaves_Cherry_Full"
    },
    {
      "x": 7,
      "y": 13,
      "z": 1,
      "name": "Plant_Leaves_Cherry_Full"
    },
    {
      "x": 7,
      "y": 13,
      "z": 2,
      "name": "Plant_Leaves_Cherry_Full"
    },
    {
      "x": 7,
      "y": 12,
      "z": 3,
      "name": "Plant_Leaves_Cherry_Full"
    },
    {
      "x": 7,
      "y": 13,
      "z": 3,
      "name": "Plant_Leaves_Cherry_Full"
    },
    {
      "x": 7,
      "y": 12,
      "z": 4,
      "name": "Plant_Leaves_Cherry_Full"
    },
    {
      "x": 7,
      "y": 13,
      "z": 4,
      "name": "Plant_Leaves_Cherry_Full"
    }
  ],
  "fluids": [
    {
      "x": -6,
      "y": 12,
      "z": 0,
      "name": "Empty",
      "level": 0
    },
    {
      "x": -6,
      "y": 12,
      "z": 1,
      "name": "Empty",
      "level": 0
    },
    {
      "x": -6,
      "y": 13,
      "z": 1,
      "name": "Empty",
      "level": 0
    },
    {
      "x": -6,
      "y": 13,
      "z": 2,
      "name": "Empty",
      "level": 0
    },
    {
      "x": -6,
      "y": 13,
      "z": 3,
      "name": "Empty",
      "level": 0
    },
    {
      "x": -5,
      "y": 12,
      "z": -1,
      "name": "Empty",
      "level": 0
    },
    {
      "x": -5,
      "y": 13,
      "z": 0,
      "name": "Empty",
      "level": 0
    },
    {
      "x": -5,
      "y": 13,
      "z": 1,
      "name": "Empty",
      "level": 0
    },
    {
      "x": -5,
      "y": 14,
      "z": 1,
      "name": "Empty",
      "level": 0
    },
    {
      "x": -5,
      "y": 14,
      "z": 2,
      "name": "Empty",
      "level": 0
    },
    {
      "x": -5,
      "y": 13,
      "z": 3,
      "name": "Empty",
      "level": 0
    },
    {
      "x": -5,
      "y": 14,
      "z": 3,
      "name": "Empty",
      "level": 0
    },
    {
      "x": -4,
      "y": 12,
      "z": -1,
      "name": "Empty",
      "level": 0
    },
    {
      "x": -4,
      "y": 13,
      "z": 0,
      "name": "Empty",
      "level": 0
    },
    {
      "x": -4,
      "y": 14,
      "z": 0,
      "name": "Empty",
      "level": 0
    },
    {
      "x": -4,
      "y": 14,
      "z": 1,
      "name": "Empty",
      "level": 0
    },
    {
      "x": -4,
      "y": 15,
      "z": 1,
      "name": "Empty",
      "level": 0
    },
    {
      "x": -4,
      "y": 14,
      "z": 2,
      "name": "Empty",
      "level": 0
    },
    {
      "x": -4,
      "y": 14,
      "z": 3,
      "name": "Empty",
      "level": 0
    },
    {
      "x": -3,
      "y": 14,
      "z": -2,
      "name": "Empty",
      "level": 0
    },
    {
      "x": -3,
      "y": 12,
      "z": -1,
      "name": "Empty",
      "level": 0
    },
    {
      "x": -3,
      "y": 14,
      "z": -1,
      "name": "Empty",
      "level": 0
    },
    {
      "x": -3,
      "y": 14,
      "z": 0,
      "name": "Empty",
      "level": 0
    },
    {
      "x": -3,
      "y": 14,
      "z": 1,
      "name": "Empty",
      "level": 0
    },
    {
      "x": -3,
      "y": 15,
      "z": 1,
      "name": "Empty",
      "level": 0
    },
    {
      "x": -3,
      "y": 13,
      "z": 2,
      "name": "Empty",
      "level": 0
    },
    {
      "x": -3,
      "y": 14,
      "z": 2,
      "name": "Empty",
      "level": 0
    },
    {
      "x": -3,
      "y": 13,
      "z": 3,
      "name": "Empty",
      "level": 0
    },
    {
      "x": -3,
      "y": 14,
      "z": 3,
      "name": "Empty",
      "level": 0
    },
    {
      "x": -3,
      "y": 14,
      "z": 4,
      "name": "Empty",
      "level": 0
    },
    {
      "x": -3,
      "y": 13,
      "z": 5,
      "name": "Empty",
      "level": 0
    },
    {
      "x": -3,
      "y": 14,
      "z": 5,
      "name": "Empty",
      "level": 0
    },
    {
      "x": -3,
      "y": 14,
      "z": 6,
      "name": "Empty",
      "level": 0
    },
    {
      "x": -2,
      "y": 14,
      "z": -4,
      "name": "Empty",
      "level": 0
    },
    {
      "x": -2,
      "y": 14,
      "z": -3,
      "name": "Empty",
      "level": 0
    },
    {
      "x": -2,
      "y": 14,
      "z": -2,
      "name": "Empty",
      "level": 0
    },
    {
      "x": -2,
      "y": 13,
      "z": -1,
      "name": "Empty",
      "level": 0
    },
    {
      "x": -2,
      "y": 14,
      "z": -1,
      "name": "Empty",
      "level": 0
    },
    {
      "x": -2,
      "y": 12,
      "z": 0,
      "name": "Empty",
      "level": 0
    },
    {
      "x": -2,
      "y": 13,
      "z": 0,
      "name": "Empty",
      "level": 0
    },
    {
      "x": -2,
      "y": 14,
      "z": 0,
      "name": "Empty",
      "level": 0
    },
    {
      "x": -2,
      "y": 14,
      "z": 1,
      "name": "Empty",
      "level": 0
    },
    {
      "x": -2,
      "y": 15,
      "z": 1,
      "name": "Empty",
      "level": 0
    },
    {
      "x": -2,
      "y": 14,
      "z": 2,
      "name": "Empty",
      "level": 0
    },
    {
      "x": -2,
      "y": 15,
      "z": 2,
      "name": "Empty",
      "level": 0
    },
    {
      "x": -2,
      "y": 13,
      "z": 3,
      "name": "Empty",
      "level": 0
    },
    {
      "x": -2,
      "y": 14,
      "z": 3,
      "name": "Empty",
      "level": 0
    },
    {
      "x": -2,
      "y": 14,
      "z": 4,
      "name": "Empty",
      "level": 0
    },
    {
      "x": -2,
      "y": 13,
      "z": 5,
      "name": "Empty",
      "level": 0
    },
    {
      "x": -2,
      "y": 14,
      "z": 5,
      "name": "Empty",
      "level": 0
    },
    {
      "x": -2,
      "y": 13,
      "z": 6,
      "name": "Empty",
      "level": 0
    },
    {
      "x": -2,
      "y": 14,
      "z": 6,
      "name": "Empty",
      "level": 0
    },
    {
      "x": -1,
      "y": 13,
      "z": -4,
      "name": "Empty",
      "level": 0
    },
    {
      "x": -1,
      "y": 14,
      "z": -4,
      "name": "Empty",
      "level": 0
    },
    {
      "x": -1,
      "y": 13,
      "z": -3,
      "name": "Empty",
      "level": 0
    },
    {
      "x": -1,
      "y": 14,
      "z": -3,
      "name": "Empty",
      "level": 0
    },
    {
      "x": -1,
      "y": 14,
      "z": -2,
      "name": "Empty",
      "level": 0
    },
    {
      "x": -1,
      "y": 15,
      "z": -2,
      "name": "Empty",
      "level": 0
    },
    {
      "x": -1,
      "y": 14,
      "z": -1,
      "name": "Empty",
      "level": 0
    },
    {
      "x": -1,
      "y": 15,
      "z": -1,
      "name": "Empty",
      "level": 0
    },
    {
      "x": -1,
      "y": 12,
      "z": 0,
      "name": "Empty",
      "level": 0
    },
    {
      "x": -1,
      "y": 13,
      "z": 0,
      "name": "Empty",
      "level": 0
    },
    {
      "x": -1,
      "y": 14,
      "z": 0,
      "name": "Empty",
      "level": 0
    },
    {
      "x": -1,
      "y": 15,
      "z": 0,
      "name": "Empty",
      "level": 0
    },
    {
      "x": -1,
      "y": 14,
      "z": 1,
      "name": "Empty",
      "level": 0
    },
    {
      "x": -1,
      "y": 13,
      "z": 2,
      "name": "Empty",
      "level": 0
    },
    {
      "x": -1,
      "y": 14,
      "z": 2,
      "name": "Empty",
      "level": 0
    },
    {
      "x": -1,
      "y": 15,
      "z": 2,
      "name": "Empty",
      "level": 0
    },
    {
      "x": -1,
      "y": 13,
      "z": 3,
      "name": "Empty",
      "level": 0
    },
    {
      "x": -1,
      "y": 14,
      "z": 3,
      "name": "Empty",
      "level": 0
    },
    {
      "x": -1,
      "y": 13,
      "z": 4,
      "name": "Empty",
      "level": 0
    },
    {
      "x": -1,
      "y": 13,
      "z": 5,
      "name": "Empty",
      "level": 0
    },
    {
      "x": -1,
      "y": 14,
      "z": 5,
      "name": "Empty",
      "level": 0
    },
    {
      "x": -1,
      "y": 12,
      "z": 6,
      "name": "Empty",
      "level": 0
    },
    {
      "x": -1,
      "y": 13,
      "z": 6,
      "name": "Empty",
      "level": 0
    },
    {
      "x": -1,
      "y": 14,
      "z": 6,
      "name": "Empty",
      "level": 0
    },
    {
      "x": 0,
      "y": 13,
      "z": -5,
      "name": "Empty",
      "level": 0
    },
    {
      "x": 0,
      "y": 13,
      "z": -4,
      "name": "Empty",
      "level": 0
    },
    {
      "x": 0,
      "y": 14,
      "z": -4,
      "name": "Empty",
      "level": 0
    },
    {
      "x": 0,
      "y": 13,
      "z": -3,
      "name": "Empty",
      "level": 0
    },
    {
      "x": 0,
      "y": 15,
      "z": -3,
      "name": "Empty",
      "level": 0
    },
    {
      "x": 0,
      "y": 13,
      "z": -2,
      "name": "Empty",
      "level": 0
    },
    {
      "x": 0,
      "y": 14,
      "z": -2,
      "name": "Empty",
      "level": 0
    },
    {
      "x": 0,
      "y": 13,
      "z": -1,
      "name": "Empty",
      "level": 0
    },
    {
      "x": 0,
      "y": 14,
      "z": -1,
      "name": "Empty",
      "level": 0
    },
    {
      "x": 0,
      "y": 15,
      "z": -1,
      "name": "Empty",
      "level": 0
    },
    {
      "x": 0,
      "y": 14,
      "z": 0,
      "name": "Empty",
      "level": 0
    },
    {
      "x": 0,
      "y": 14,
      "z": 1,
      "name": "Empty",
      "level": 0
    },
    {
      "x": 0,
      "y": 13,
      "z": 2,
      "name": "Empty",
      "level": 0
    },
    {
      "x": 0,
      "y": 14,
      "z": 2,
      "name": "Empty",
      "level": 0
    },
    {
      "x": 0,
      "y": 13,
      "z": 3,
      "name": "Empty",
      "level": 0
    },
    {
      "x": 0,
      "y": 14,
      "z": 3,
      "name": "Empty",
      "level": 0
    },
    {
      "x": 0,
      "y": 13,
      "z": 4,
      "name": "Empty",
      "level": 0
    },
    {
      "x": 0,
      "y": 14,
      "z": 4,
      "name": "Empty",
      "level": 0
    },
    {
      "x": 0,
      "y": 12,
      "z": 5,
      "name": "Empty",
      "level": 0
    },
    {
      "x": 0,
      "y": 13,
      "z": 5,
      "name": "Empty",
      "level": 0
    },
    {
      "x": 0,
      "y": 14,
      "z": 5,
      "name": "Empty",
      "level": 0
    },
    {
      "x": 0,
      "y": 13,
      "z": 6,
      "name": "Empty",
      "level": 0
    },
    {
      "x": 1,
      "y": 13,
      "z": -5,
      "name": "Empty",
      "level": 0
    },
    {
      "x": 1,
      "y": 13,
      "z": -4,
      "name": "Empty",
      "level": 0
    },
    {
      "x": 1,
      "y": 14,
      "z": -4,
      "name": "Empty",
      "level": 0
    },
    {
      "x": 1,
      "y": 14,
      "z": -3,
      "name": "Empty",
      "level": 0
    },
    {
      "x": 1,
      "y": 14,
      "z": -2,
      "name": "Empty",
      "level": 0
    },
    {
      "x": 1,
      "y": 13,
      "z": -1,
      "name": "Empty",
      "level": 0
    },
    {
      "x": 1,
      "y": 15,
      "z": -1,
      "name": "Empty",
      "level": 0
    },
    {
      "x": 1,
      "y": 13,
      "z": 0,
      "name": "Empty",
      "level": 0
    },
    {
      "x": 1,
      "y": 14,
      "z": 0,
      "name": "Empty",
      "level": 0
    },
    {
      "x": 1,
      "y": 10,
      "z": 1,
      "name": "Empty",
      "level": 0
    },
    {
      "x": 1,
      "y": 11,
      "z": 1,
      "name": "Empty",
      "level": 0
    },
    {
      "x": 1,
      "y": 12,
      "z": 1,
      "name": "Empty",
      "level": 0
    },
    {
      "x": 1,
      "y": 13,
      "z": 1,
      "name": "Empty",
      "level": 0
    },
    {
      "x": 1,
      "y": 14,
      "z": 1,
      "name": "Empty",
      "level": 0
    },
    {
      "x": 1,
      "y": 12,
      "z": 2,
      "name": "Empty",
      "level": 0
    },
    {
      "x": 1,
      "y": 13,
      "z": 2,
      "name": "Empty",
      "level": 0
    },
    {
      "x": 1,
      "y": 14,
      "z": 2,
      "name": "Empty",
      "level": 0
    },
    {
      "x": 1,
      "y": 13,
      "z": 3,
      "name": "Empty",
      "level": 0
    },
    {
      "x": 1,
      "y": 12,
      "z": 4,
      "name": "Empty",
      "level": 0
    },
    {
      "x": 1,
      "y": 13,
      "z": 4,
      "name": "Empty",
      "level": 0
    },
    {
      "x": 1,
      "y": 12,
      "z": 5,
      "name": "Empty",
      "level": 0
    },
    {
      "x": 2,
      "y": 13,
      "z": -5,
      "name": "Empty",
      "level": 0
    },
    {
      "x": 2,
      "y": 13,
      "z": -4,
      "name": "Empty",
      "level": 0
    },
    {
      "x": 2,
      "y": 14,
      "z": -4,
      "name": "Empty",
      "level": 0
    },
    {
      "x": 2,
      "y": 14,
      "z": -3,
      "name": "Empty",
      "level": 0
    },
    {
      "x": 2,
      "y": 14,
      "z": -2,
      "name": "Empty",
      "level": 0
    },
    {
      "x": 2,
      "y": 12,
      "z": -1,
      "name": "Empty",
      "level": 0
    },
    {
      "x": 2,
      "y": 14,
      "z": -1,
      "name": "Empty",
      "level": 0
    },
    {
      "x": 2,
      "y": 15,
      "z": -1,
      "name": "Empty",
      "level": 0
    },
    {
      "x": 2,
      "y": 13,
      "z": 0,
      "name": "Empty",
      "level": 0
    },
    {
      "x": 2,
      "y": 14,
      "z": 0,
      "name": "Empty",
      "level": 0
    },
    {
      "x": 2,
      "y": 15,
      "z": 0,
      "name": "Empty",
      "level": 0
    },
    {
      "x": 2,
      "y": 10,
      "z": 1,
      "name": "Empty",
      "level": 0
    },
    {
      "x": 2,
      "y": 13,
      "z": 1,
      "name": "Empty",
      "level": 0
    },
    {
      "x": 2,
      "y": 14,
      "z": 1,
      "name": "Empty",
      "level": 0
    },
    {
      "x": 2,
      "y": 10,
      "z": 2,
      "name": "Empty",
      "level": 0
    },
    {
      "x": 2,
      "y": 12,
      "z": 2,
      "name": "Empty",
      "level": 0
    },
    {
      "x": 2,
      "y": 13,
      "z": 2,
      "name": "Empty",
      "level": 0
    },
    {
      "x": 2,
      "y": 12,
      "z": 3,
      "name": "Empty",
      "level": 0
    },
    {
      "x": 2,
      "y": 13,
      "z": 3,
      "name": "Empty",
      "level": 0
    },
    {
      "x": 3,
      "y": 13,
      "z": -4,
      "name": "Empty",
      "level": 0
    },
    {
      "x": 3,
      "y": 13,
      "z": -3,
      "name": "Empty",
      "level": 0
    },
    {
      "x": 3,
      "y": 14,
      "z": -3,
      "name": "Empty",
      "level": 0
    },
    {
      "x": 3,
      "y": 12,
      "z": -2,
      "name": "Empty",
      "level": 0
    },
    {
      "x": 3,
      "y": 13,
      "z": -2,
      "name": "Empty",
      "level": 0
    },
    {
      "x": 3,
      "y": 14,
      "z": -2,
      "name": "Empty",
      "level": 0
    },
    {
      "x": 3,
      "y": 12,
      "z": -1,
      "name": "Empty",
      "level": 0
    },
    {
      "x": 3,
      "y": 13,
      "z": -1,
      "name": "Empty",
      "level": 0
    },
    {
      "x": 3,
      "y": 14,
      "z": -1,
      "name": "Empty",
      "level": 0
    },
    {
      "x": 3,
      "y": 13,
      "z": 0,
      "name": "Empty",
      "level": 0
    },
    {
      "x": 3,
      "y": 14,
      "z": 0,
      "name": "Empty",
      "level": 0
    },
    {
      "x": 3,
      "y": 12,
      "z": 1,
      "name": "Empty",
      "level": 0
    },
    {
      "x": 3,
      "y": 13,
      "z": 1,
      "name": "Empty",
      "level": 0
    },
    {
      "x": 3,
      "y": 14,
      "z": 1,
      "name": "Empty",
      "level": 0
    },
    {
      "x": 3,
      "y": 8,
      "z": 2,
      "name": "Empty",
      "level": 0
    },
    {
      "x": 3,
      "y": 9,
      "z": 2,
      "name": "Empty",
      "level": 0
    },
    {
      "x": 3,
      "y": 10,
      "z": 2,
      "name": "Empty",
      "level": 0
    },
    {
      "x": 3,
      "y": 12,
      "z": 2,
      "name": "Empty",
      "level": 0
    },
    {
      "x": 3,
      "y": 3,
      "z": 3,
      "name": "Empty",
      "level": 0
    },
    {
      "x": 3,
      "y": 4,
      "z": 3,
      "name": "Empty",
      "level": 0
    },
    {
      "x": 3,
      "y": 8,
      "z": 3,
      "name": "Empty",
      "level": 0
    },
    {
      "x": 3,
      "y": 12,
      "z": 3,
      "name": "Empty",
      "level": 0
    },
    {
      "x": 3,
      "y": 13,
      "z": 3,
      "name": "Empty",
      "level": 0
    },
    {
      "x": 3,
      "y": 12,
      "z": 4,
      "name": "Empty",
      "level": 0
    },
    {
      "x": 3,
      "y": 13,
      "z": 4,
      "name": "Empty",
      "level": 0
    },
    {
      "x": 4,
      "y": 12,
      "z": -2,
      "name": "Empty",
      "level": 0
    },
    {
      "x": 4,
      "y": 13,
      "z": -2,
      "name": "Empty",
      "level": 0
    },
    {
      "x": 4,
      "y": 12,
      "z": -1,
      "name": "Empty",
      "level": 0
    },
    {
      "x": 4,
      "y": 13,
      "z": -1,
      "name": "Empty",
      "level": 0
    },
    {
      "x": 4,
      "y": 13,
      "z": 0,
      "name": "Empty",
      "level": 0
    },
    {
      "x": 4,
      "y": 14,
      "z": 0,
      "name": "Empty",
      "level": 0
    },
    {
      "x": 4,
      "y": 12,
      "z": 1,
      "name": "Empty",
      "level": 0
    },
    {
      "x": 4,
      "y": 13,
      "z": 1,
      "name": "Empty",
      "level": 0
    },
    {
      "x": 4,
      "y": 1,
      "z": 2,
      "name": "Empty",
      "level": 0
    },
    {
      "x": 4,
      "y": 2,
      "z": 2,
      "name": "Empty",
      "level": 0
    },
    {
      "x": 4,
      "y": 3,
      "z": 2,
      "name": "Empty",
      "level": 0
    },
    {
      "x": 4,
      "y": 4,
      "z": 2,
      "name": "Empty",
      "level": 0
    },
    {
      "x": 4,
      "y": 5,
      "z": 2,
      "name": "Empty",
      "level": 0
    },
    {
      "x": 4,
      "y": 12,
      "z": 2,
      "name": "Empty",
      "level": 0
    },
    {
      "x": 4,
      "y": 13,
      "z": 2,
      "name": "Empty",
      "level": 0
    },
    {
      "x": 4,
      "y": 3,
      "z": 3,
      "name": "Empty",
      "level": 0
    },
    {
      "x": 4,
      "y": 4,
      "z": 3,
      "name": "Empty",
      "level": 0
    },
    {
      "x": 4,
      "y": 5,
      "z": 3,
      "name": "Empty",
      "level": 0
    },
    {
      "x": 4,
      "y": 6,
      "z": 3,
      "name": "Empty",
      "level": 0
    },
    {
      "x": 4,
      "y": 7,
      "z": 3,
      "name": "Empty",
      "level": 0
    },
    {
      "x": 4,
      "y": 8,
      "z": 3,
      "name": "Empty",
      "level": 0
    },
    {
      "x": 4,
      "y": 12,
      "z": 3,
      "name": "Empty",
      "level": 0
    },
    {
      "x": 4,
      "y": 13,
      "z": 3,
      "name": "Empty",
      "level": 0
    },
    {
      "x": 4,
      "y": 14,
      "z": 3,
      "name": "Empty",
      "level": 0
    },
    {
      "x": 4,
      "y": 4,
      "z": 4,
      "name": "Empty",
      "level": 0
    },
    {
      "x": 4,
      "y": 5,
      "z": 4,
      "name": "Empty",
      "level": 0
    },
    {
      "x": 4,
      "y": 12,
      "z": 4,
      "name": "Empty",
      "level": 0
    },
    {
      "x": 4,
      "y": 12,
      "z": 5,
      "name": "Empty",
      "level": 0
    },
    {
      "x": 4,
      "y": 13,
      "z": 5,
      "name": "Empty",
      "level": 0
    },
    {
      "x": 5,
      "y": 12,
      "z": -1,
      "name": "Empty",
      "level": 0
    },
    {
      "x": 5,
      "y": 13,
      "z": -1,
      "name": "Empty",
      "level": 0
    },
    {
      "x": 5,
      "y": 13,
      "z": 0,
      "name": "Empty",
      "level": 0
    },
    {
      "x": 5,
      "y": 13,
      "z": 1,
      "name": "Empty",
      "level": 0
    },
    {
      "x": 5,
      "y": 12,
      "z": 2,
      "name": "Empty",
      "level": 0
    },
    {
      "x": 5,
      "y": 13,
      "z": 2,
      "name": "Empty",
      "level": 0
    },
    {
      "x": 5,
      "y": 5,
      "z": 3,
      "name": "Empty",
      "level": 0
    },
    {
      "x": 5,
      "y": 6,
      "z": 3,
      "name": "Empty",
      "level": 0
    },
    {
      "x": 5,
      "y": 13,
      "z": 3,
      "name": "Empty",
      "level": 0
    },
    {
      "x": 5,
      "y": 14,
      "z": 3,
      "name": "Empty",
      "level": 0
    },
    {
      "x": 5,
      "y": 0,
      "z": 4,
      "name": "Empty",
      "level": 0
    },
    {
      "x": 5,
      "y": 1,
      "z": 4,
      "name": "Empty",
      "level": 0
    },
    {
      "x": 5,
      "y": 2,
      "z": 4,
      "name": "Empty",
      "level": 0
    },
    {
      "x": 5,
      "y": 3,
      "z": 4,
      "name": "Empty",
      "level": 0
    },
    {
      "x": 5,
      "y": 4,
      "z": 4,
      "name": "Empty",
      "level": 0
    },
    {
      "x": 5,
      "y": 13,
      "z": 4,
      "name": "Empty",
      "level": 0
    },
    {
      "x": 5,
      "y": 14,
      "z": 4,
      "name": "Empty",
      "level": 0
    },
    {
      "x": 5,
      "y": 12,
      "z": 5,
      "name": "Empty",
      "level": 0
    },
    {
      "x": 5,
      "y": 13,
      "z": 5,
      "name": "Empty",
      "level": 0
    },
    {
      "x": 6,
      "y": 12,
      "z": -1,
      "name": "Empty",
      "level": 0
    },
    {
      "x": 6,
      "y": 13,
      "z": 0,
      "name": "Empty",
      "level": 0
    },
    {
      "x": 6,
      "y": 13,
      "z": 1,
      "name": "Empty",
      "level": 0
    },
    {
      "x": 6,
      "y": 12,
      "z": 2,
      "name": "Empty",
      "level": 0
    },
    {
      "x": 6,
      "y": 13,
      "z": 2,
      "name": "Empty",
      "level": 0
    },
    {
      "x": 6,
      "y": 13,
      "z": 3,
      "name": "Empty",
      "level": 0
    },
    {
      "x": 6,
      "y": 12,
      "z": 4,
      "name": "Empty",
      "level": 0
    },
    {
      "x": 6,
      "y": 13,
      "z": 4,
      "name": "Empty",
      "level": 0
    },
    {
      "x": 6,
      "y": 12,
      "z": 5,
      "name": "Empty",
      "level": 0
    },
    {
      "x": 7,
      "y": 12,
      "z": -1,
      "name": "Empty",
      "level": 0
    },
    {
      "x": 7,
      "y": 12,
      "z": 0,
      "name": "Empty",
      "level": 0
    },
    {
      "x": 7,
      "y": 13,
      "z": 0,
      "name": "Empty",
      "level": 0
    },
    {
      "x": 7,
      "y": 13,
      "z": 1,
      "name": "Empty",
      "level": 0
    },
    {
      "x": 7,
      "y": 13,
      "z": 2,
      "name": "Empty",
      "level": 0
    },
    {
      "x": 7,
      "y": 12,
      "z": 3,
      "name": "Empty",
      "level": 0
    },
    {
      "x": 7,
      "y": 13,
      "z": 3,
      "name": "Empty",
      "level": 0
    },
    {
      "x": 7,
      "y": 12,
      "z": 4,
      "name": "Empty",
      "level": 0
    },
    {
      "x": 7,
      "y": 13,
      "z": 4,
      "name": "Empty",
      "level": 0
    }
  ]
}