{
  "version": 8,
  "blockIdVersion": 11,
  "anchorX": 0,
  "anchorY": 0,
  "anchorZ": 0,
  "blocks": [
    {
      "x": -14,
      "y": 9,
      "z": -4,
      "name": "Soil_Dirt_Cold"
    },
    {
      "x": -14,
      "y": 10,
      "z": -4,
      "name": "Soil_Dirt_Cold"
    },
    {
      "x": -14,
      "y": 11,
      "z": -4,
      "name": "Soil_Dirt_Cold"
    },
    {
      "x": -14,
      "y": 12,
      "z": -4,
      "name": "Soil_Dirt_Cold"
    },
    {
      "x": -14,
      "y": 7,
      "z": -3,
      "name": "Rock_Stone"
    },
    {
      "x": -14,
      "y": 8,
      "z": -3,
      "name": "Rock_Stone"
    },
    {
      "x": -14,
      "y": 9,
      "z": -3,
      "name": "Rock_Stone"
    },
    {
      "x": -14,
      "y": 10,
      "z": -3,
      "name": "Rock_Stone"
    },
    {
      "x": -14,
      "y": 11,
      "z": -3,
      "name": "Rock_Stone"
    },
    {
      "x": -14,
      "y": 12,
      "z": -3,
      "name": "Rock_Stone"
    },
    {
      "x": -14,
      "y": 13,
      "z": -3,
      "name": "Soil_Dirt_Cold"
    },
    {
      "x": -14,
      "y": 14,
      "z": -3,
      "name": "Soil_Dirt_Cold"
    },
    {
      "x": -14,
      "y": 15,
      "z": -3,
      "name": "Soil_Grass_Cold"
    },
    {
      "x": -14,
      "y": 5,
      "z": -2,
      "name": "Rock_Stone"
    },
    {
      "x": -14,
      "y": 6,
      "z": -2,
      "name": "Rock_Stone"
    },
    {
      "x": -14,
      "y": 7,
      "z": -2,
      "name": "Rock_Stone"
    },
    {
      "x": -14,
      "y": 8,
      "z": -2,
      "name": "Rock_Stone"
    },
    {
      "x": -14,
      "y": 9,
      "z": -2,
      "name": "Rock_Stone"
    },
    {
      "x": -14,
      "y": 10,
      "z": -2,
      "name": "Rock_Stone"
    },
    {
      "x": -14,
      "y": 11,
      "z": -2,
      "name": "Rock_Stone"
    },
    {
      "x": -14,
      "y": 12,
      "z": -2,
      "name": "Rock_Stone"
    },
    {
      "x": -14,
      "y": 13,
      "z": -2,
      "name": "Rock_Stone"
    },
    {
      "x": -14,
      "y": 14,
      "z": -2,
      "name": "Rock_Stone"
    },
    {
      "x": -14,
      "y": 15,
      "z": -2,
      "name": "Soil_Dirt_Cold"
    },
    {
      "x": -14,
      "y": 16,
      "z": -2,
      "name": "Soil_Dirt_Cold"
    },
    {
      "x": -14,
      "y": 17,
      "z": -2,
      "name": "Soil_Grass_Cold"
    },
    {
      "x": -14,
      "y": 31,
      "z": -2,
      "name": "Rock_Stone"
    },
    {
      "x": -14,
      "y": 32,
      "z": -2,
      "name": "Rock_Stone"
    },
    {
      "x": -14,
      "y": 33,
      "z": -2,
      "name": "Rock_Stone"
    },
    {
      "x": -14,
      "y": 34,
      "z": -2,
      "name": "Rock_Stone"
    },
    {
      "x": -14,
      "y": 35,
      "z": -2,
      "name": "Rock_Stone"
    },
    {
      "x": -14,
      "y": 36,
      "z": -2,
      "name": "Rock_Stone"
    },
    {
      "x": -14,
      "y": 4,
      "z": -1,
      "name": "Rock_Stone"
    },
    {
      "x": -14,
      "y": 5,
      "z": -1,
      "name": "Rock_Stone"
    },
    {
      "x": -14,
      "y": 6,
      "z": -1,
      "name": "Rock_Stone"
    },
    {
      "x": -14,
      "y": 7,
      "z": -1,
      "name": "Rock_Stone"
    },
    {
      "x": -14,
      "y": 8,
      "z": -1,
      "name": "Rock_Stone"
    },
    {
      "x": -14,
      "y": 9,
      "z": -1,
      "name": "Rock_Stone"
    },
    {
      "x": -14,
      "y": 10,
      "z": -1,
      "name": "Rock_Stone"
    },
    {
      "x": -14,
      "y": 11,
      "z": -1,
      "name": "Rock_Stone"
    },
    {
      "x": -14,
      "y": 12,
      "z": -1,
      "name": "Rock_Stone"
    },
    {
      "x": -14,
      "y": 13,
      "z": -1,
      "name": "Rock_Stone"
    },
    {
      "x": -14,
      "y": 14,
      "z": -1,
      "name": "Rock_Stone"
    },
    {
      "x": -14,
      "y": 15,
      "z": -1,
      "name": "Rock_Stone"
    },
    {
      "x": -14,
      "y": 16,
      "z": -1,
      "name": "Rock_Stone"
    },
    {
      "x": -14,
      "y": 17,
      "z": -1,
      "name": "Rock_Stone"
    },
    {
      "x": -14,
      "y": 18,
      "z": -1,
      "name": "Soil_Dirt_Cold"
    },
    {
      "x": -14,
      "y": 19,
      "z": -1,
      "name": "Soil_Dirt_Cold"
    },
    {
      "x": -14,
      "y": 20,
      "z": -1,
      "name": "Soil_Grass_Cold"
    },
    {
      "x": -14,
      "y": 30,
      "z": -1,
      "name": "Rock_Stone"
    },
    {
      "x": -14,
      "y": 31,
      "z": -1,
      "name": "Rock_Stone"
    },
    {
      "x": -14,
      "y": 32,
      "z": -1,
      "name": "Rock_Stone"
    },
    {
      "x": -14,
      "y": 33,
      "z": -1,
      "name": "Rock_Stone"
    },
    {
      "x": -14,
      "y": 34,
      "z": -1,
      "name": "Rock_Stone"
    },
    {
      "x": -14,
      "y": 35,
      "z": -1,
      "name": "Rock_Stone"
    },
    {
      "x": -14,
      "y": 36,
      "z": -1,
      "name": "Rock_Stone"
    },
    {
      "x": -14,
      "y": 37,
      "z": -1,
      "name": "Rock_Stone"
    },
    {
      "x": -14,
      "y": 38,
      "z": -1,
      "name": "Rock_Stone"
    },
    {
      "x": -14,
      "y": 39,
      "z": -1,
      "name": "Rock_Stone"
    },
    {
      "x": -14,
      "y": 40,
      "z": -1,
      "name": "Rock_Stone"
    },
    {
      "x": -14,
      "y": 41,
      "z": -1,
      "name": "Rock_Stone"
    },
    {
      "x": -14,
      "y": 42,
      "z": -1,
      "name": "Rock_Stone"
    },
    {
      "x": -14,
      "y": 43,
      "z": -1,
      "name": "Rock_Stone"
    },
    {
      "x": -14,
      "y": 4,
      "z": 0,
      "name": "Rock_Stone"
    },
    {
      "x": -14,
      "y": 5,
      "z": 0,
      "name": "Rock_Stone"
    },
    {
      "x": -14,
      "y": 6,
      "z": 0,
      "name": "Rock_Stone"
    },
    {
      "x": -14,
      "y": 7,
      "z": 0,
      "name": "Rock_Stone"
    },
    {
      "x": -14,
      "y": 8,
      "z": 0,
      "name": "Rock_Stone"
    },
    {
      "x": -14,
      "y": 9,
      "z": 0,
      "name": "Rock_Stone"
    },
    {
      "x": -14,
      "y": 10,
      "z": 0,
      "name": "Rock_Stone"
    },
    {
      "x": -14,
      "y": 11,
      "z": 0,
      "name": "Rock_Stone"
    },
    {
      "x": -14,
      "y": 12,
      "z": 0,
      "name": "Rock_Stone"
    },
    {
      "x": -14,
      "y": 13,
      "z": 0,
      "name": "Rock_Stone"
    },
    {
      "x": -14,
      "y": 14,
      "z": 0,
      "name": "Rock_Stone"
    },
    {
      "x": -14,
      "y": 15,
      "z": 0,
      "name": "Rock_Stone"
    },
    {
      "x": -14,
      "y": 16,
      "z": 0,
      "name": "Rock_Stone"
    },
    {
      "x": -14,
      "y": 17,
      "z": 0,
      "name": "Rock_Stone"
    },
    {
      "x": -14,
      "y": 18,
      "z": 0,
      "name": "Rock_Stone"
    },
    {
      "x": -14,
      "y": 19,
      "z": 0,
      "name": "Rock_Stone"
    },
    {
      "x": -14,
      "y": 20,
      "z": 0,
      "name": "Soil_Dirt_Cold"
    },
    {
      "x": -14,
      "y": 21,
      "z": 0,
      "name": "Soil_Grass_Cold"
    },
    {
      "x": -14,
      "y": 28,
      "z": 0,
      "name": "Rock_Stone"
    },
    {
      "x": -14,
      "y": 29,
      "z": 0,
      "name": "Rock_Stone"
    },
    {
      "x": -14,
      "y": 30,
      "z": 0,
      "name": "Rock_Stone"
    },
    {
      "x": -14,
      "y": 31,
      "z": 0,
      "name": "Rock_Stone"
    },
    {
      "x": -14,
      "y": 32,
      "z": 0,
      "name": "Rock_Stone"
    },
    {
      "x": -14,
      "y": 33,
      "z": 0,
      "name": "Rock_Stone"
    },
    {
      "x": -14,
      "y": 34,
      "z": 0,
      "name": "Rock_Stone"
    },
    {
      "x": -14,
      "y": 35,
      "z": 0,
      "name": "Rock_Stone"
    },
    {
      "x": -14,
      "y": 36,
      "z": 0,
      "name": "Rock_Stone"
    },
    {
      "x": -14,
      "y": 37,
      "z": 0,
      "name": "Rock_Stone"
    },
    {
      "x": -14,
      "y": 38,
      "z": 0,
      "name": "Rock_Stone"
    },
    {
      "x": -14,
      "y": 39,
      "z": 0,
      "name": "Rock_Stone"
    },
    {
      "x": -14,
      "y": 40,
      "z": 0,
      "name": "Rock_Stone"
    },
    {
      "x": -14,
      "y": 41,
      "z": 0,
      "name": "Rock_Stone"
    },
    {
      "x": -14,
      "y": 42,
      "z": 0,
      "name": "Rock_Stone"
    },
    {
      "x": -14,
      "y": 43,
      "z": 0,
      "name": "Rock_Stone"
    },
    {
      "x": -14,
      "y": 44,
      "z": 0,
      "name": "Rock_Stone"
    },
    {
      "x": -14,
      "y": 45,
      "z": 0,
      "name": "Rock_Stone"
    },
    {
      "x": -14,
      "y": 3,
      "z": 1,
      "name": "Rock_Stone"
    },
    {
      "x": -14,
      "y": 4,
      "z": 1,
      "name": "Rock_Stone"
    },
    {
      "x": -14,
      "y": 5,
      "z": 1,
      "name": "Rock_Stone"
    },
    {
      "x": -14,
      "y": 6,
      "z": 1,
      "name": "Rock_Stone"
    },
    {
      "x": -14,
      "y": 7,
      "z": 1,
      "name": "Rock_Stone"
    },
    {
      "x": -14,
      "y": 8,
      "z": 1,
      "name": "Rock_Stone"
    },
    {
      "x": -14,
      "y": 9,
      "z": 1,
      "name": "Rock_Stone"
    },
    {
      "x": -14,
      "y": 10,
      "z": 1,
      "name": "Rock_Stone"
    },
    {
      "x": -14,
      "y": 11,
      "z": 1,
      "name": "Rock_Stone"
    },
    {
      "x": -14,
      "y": 12,
      "z": 1,
      "name": "Rock_Stone"
    },
    {
      "x": -14,
      "y": 13,
      "z": 1,
      "name": "Rock_Stone"
    },
    {
      "x": -14,
      "y": 14,
      "z": 1,
      "name": "Rock_Stone"
    },
    {
      "x": -14,
      "y": 15,
      "z": 1,
      "name": "Rock_Stone"
    },
    {
      "x": -14,
      "y": 16,
      "z": 1,
      "name": "Rock_Stone"
    },
    {
      "x": -14,
      "y": 17,
      "z": 1,
      "name": "Rock_Stone"
    },
    {
      "x": -14,
      "y": 18,
      "z": 1,
      "name": "Rock_Stone"
    },
    {
      "x": -14,
      "y": 19,
      "z": 1,
      "name": "Rock_Stone"
    },
    {
      "x": -14,
      "y": 20,
      "z": 1,
      "name": "Rock_Stone"
    },
    {
      "x": -14,
      "y": 21,
      "z": 1,
      "name": "Soil_Dirt_Cold"
    },
    {
      "x": -14,
      "y": 22,
      "z": 1,
      "name": "Soil_Grass_Cold"
    },
    {
      "x": -14,
      "y": 28,
      "z": 1,
      "name": "Rock_Stone"
    },
    {
      "x": -14,
      "y": 29,
      "z": 1,
      "name": "Rock_Stone"
    },
    {
      "x": -14,
      "y": 30,
      "z": 1,
      "name": "Rock_Stone"
    },
    {
      "x": -14,
      "y": 31,
      "z": 1,
      "name": "Rock_Stone"
    },
    {
      "x": -14,
      "y": 32,
      "z": 1,
      "name": "Rock_Stone"
    },
    {
      "x": -14,
      "y": 33,
      "z": 1,
      "name": "Rock_Stone"
    },
    {
      "x": -14,
      "y": 34,
      "z": 1,
      "name": "Rock_Stone"
    },
    {
      "x": -14,
      "y": 35,
      "z": 1,
      "name": "Rock_Stone"
    },
    {
      "x": -14,
      "y": 36,
      "z": 1,
      "name": "Rock_Stone"
    },
    {
      "x": -14,
      "y": 37,
      "z": 1,
      "name": "Rock_Stone"
    },
    {
      "x": -14,
      "y": 38,
      "z": 1,
      "name": "Rock_Stone"
    },
    {
      "x": -14,
      "y": 39,
      "z": 1,
      "name": "Rock_Stone"
    },
    {
      "x": -14,
      "y": 40,
      "z": 1,
      "name": "Rock_Stone"
    },
    {
      "x": -14,
      "y": 41,
      "z": 1,
      "name": "Rock_Stone"
    },
    {
      "x": -14,
      "y": 42,
      "z": 1,
      "name": "Rock_Stone"
    },
    {
      "x": -14,
      "y": 43,
      "z": 1,
      "name": "Rock_Stone"
    },
    {
      "x": -14,
      "y": 44,
      "z": 1,
      "name": "Rock_Stone"
    },
    {
      "x": -14,
      "y": 45,
      "z": 1,
      "name": "Rock_Stone"
    },
    {
      "x": -14,
      "y": 46,
      "z": 1,
      "name": "Rock_Stone"
    },
    {
      "x": -14,
      "y": 47,
      "z": 1,
      "name": "Rock_Stone"
    },
    {
      "x": -14,
      "y": 48,
      "z": 1,
      "name": "Rock_Stone"
    },
    {
      "x": -14,
      "y": 3,
      "z": 2,
      "name": "Rock_Stone"
    },
    {
      "x": -14,
      "y": 4,
      "z": 2,
      "name": "Rock_Stone"
    },
    {
      "x": -14,
      "y": 5,
      "z": 2,
      "name": "Rock_Stone"
    },
    {
      "x": -14,
      "y": 6,
      "z": 2,
      "name": "Rock_Stone"
    },
    {
      "x": -14,
      "y": 7,
      "z": 2,
      "name": "Rock_Stone"
    },
    {
      "x": -14,
      "y": 8,
      "z": 2,
      "name": "Rock_Stone"
    },
    {
      "x": -14,
      "y": 9,
      "z": 2,
      "name": "Rock_Stone"
    },
    {
      "x": -14,
      "y": 10,
      "z": 2,
      "name": "Rock_Stone"
    },
    {
      "x": -14,
      "y": 11,
      "z": 2,
      "name": "Rock_Stone"
    },
    {
      "x": -14,
      "y": 12,
      "z": 2,
      "name": "Rock_Stone"
    },
    {
      "x": -14,
      "y": 13,
      "z": 2,
      "name": "Rock_Stone"
    },
    {
      "x": -14,
      "y": 14,
      "z": 2,
      "name": "Rock_Stone"
    },
    {
      "x": -14,
      "y": 15,
      "z": 2,
      "name": "Rock_Stone"
    },
    {
      "x": -14,
      "y": 16,
      "z": 2,
      "name": "Rock_Stone"
    },
    {
      "x": -14,
      "y": 17,
      "z": 2,
      "name": "Rock_Stone"
    },
    {
      "x": -14,
      "y": 18,
      "z": 2,
      "name": "Rock_Stone"
    },
    {
      "x": -14,
      "y": 19,
      "z": 2,
      "name": "Rock_Stone"
    },
    {
      "x": -14,
      "y": 20,
      "z": 2,
      "name": "Rock_Stone"
    },
    {
      "x": -14,
      "y": 21,
      "z": 2,
      "name": "Soil_Dirt_Cold"
    },
    {
      "x": -14,
      "y": 22,
      "z": 2,
      "name": "Soil_Grass_Cold"
    },
    {
      "x": -14,
      "y": 27,
      "z": 2,
      "name": "Rock_Stone"
    },
    {
      "x": -14,
      "y": 28,
      "z": 2,
      "name": "Rock_Stone"
    },
    {
      "x": -14,
      "y": 29,
      "z": 2,
      "name": "Rock_Stone"
    },
    {
      "x": -14,
      "y": 30,
      "z": 2,
      "name": "Rock_Stone"
    },
    {
      "x": -14,
      "y": 31,
      "z": 2,
      "name": "Rock_Stone"
    },
    {
      "x": -14,
      "y": 32,
      "z": 2,
      "name": "Rock_Stone"
    },
    {
      "x": -14,
      "y": 33,
      "z": 2,
      "name": "Rock_Stone"
    },
    {
      "x": -14,
      "y": 34,
      "z": 2,
      "name": "Rock_Stone"
    },
    {
      "x": -14,
      "y": 35,
      "z": 2,
      "name": "Rock_Stone"
    },
    {
      "x": -14,
      "y": 36,
      "z": 2,
      "name": "Rock_Stone"
    },
    {
      "x": -14,
      "y": 37,
      "z": 2,
      "name": "Rock_Stone"
    },
    {
      "x": -14,
      "y": 38,
      "z": 2,
      "name": "Rock_Stone"
    },
    {
      "x": -14,
      "y": 39,
      "z": 2,
      "name": "Rock_Stone"
    },
    {
      "x": -14,
      "y": 40,
      "z": 2,
      "name": "Rock_Stone"
    },
    {
      "x": -14,
      "y": 41,
      "z": 2,
      "name": "Rock_Stone"
    },
    {
      "x": -14,
      "y": 42,
      "z": 2,
      "name": "Rock_Stone"
    },
    {
      "x": -14,
      "y": 43,
      "z": 2,
      "name": "Rock_Stone"
    },
    {
      "x": -14,
      "y": 44,
      "z": 2,
      "name": "Rock_Stone"
    },
    {
      "x": -14,
      "y": 45,
      "z": 2,
      "name": "Rock_Stone"
    },
    {
      "x": -14,
      "y": 46,
      "z": 2,
      "name": "Rock_Stone"
    },
    {
      "x": -14,
      "y": 47,
      "z": 2,
      "name": "Rock_Stone"
    },
    {
      "x": -14,
      "y": 48,
      "z": 2,
      "name": "Rock_Stone"
    },
    {
      "x": -14,
      "y": 49,
      "z": 2,
      "name": "Rock_Stone"
    },
    {
      "x": -14,
      "y": 5,
      "z": 3,
      "name": "Rock_Stone"
    },
    {
      "x": -14,
      "y": 6,
      "z": 3,
      "name": "Rock_Stone"
    },
    {
      "x": -14,
      "y": 7,
      "z": 3,
      "name": "Rock_Stone"
    },
    {
      "x": -14,
      "y": 8,
      "z": 3,
      "name": "Rock_Stone"
    },
    {
      "x": -14,
      "y": 9,
      "z": 3,
      "name": "Rock_Stone"
    },
    {
      "x": -14,
      "y": 10,
      "z": 3,
      "name": "Rock_Stone"
    },
    {
      "x": -14,
      "y": 11,
      "z": 3,
      "name": "Rock_Stone"
    },
    {
      "x": -14,
      "y": 12,
      "z": 3,
      "name": "Rock_Stone"
    },
    {
      "x": -14,
      "y": 13,
      "z": 3,
      "name": "Rock_Stone"
    },
    {
      "x": -14,
      "y": 14,
      "z": 3,
      "name": "Rock_Stone"
    },
    {
      "x": -14,
      "y": 15,
      "z": 3,
      "name": "Rock_Stone"
    },
    {
      "x": -14,
      "y": 16,
      "z": 3,
      "name": "Rock_Stone"
    },
    {
      "x": -14,
      "y": 17,
      "z": 3,
      "name": "Soil_Dirt_Cold"
    },
    {
      "x": -14,
      "y": 18,
      "z": 3,
      "name": "Soil_Dirt_Cold"
    },
    {
      "x": -14,
      "y": 19,
      "z": 3,
      "name": "Soil_Dirt_Cold"
    },
    {
      "x": -14,
      "y": 20,
      "z": 3,
      "name": "Soil_Dirt_Cold"
    },
    {
      "x": -14,
      "y": 21,
      "z": 3,
      "name": "Soil_Grass_Cold"
    },
    {
      "x": -14,
      "y": 26,
      "z": 3,
      "name": "Rock_Stone"
    },
    {
      "x": -14,
      "y": 27,
      "z": 3,
      "name": "Rock_Stone"
    },
    {
      "x": -14,
      "y": 28,
      "z": 3,
      "name": "Rock_Stone"
    },
    {
      "x": -14,
      "y": 29,
      "z": 3,
      "name": "Rock_Stone"
    },
    {
      "x": -14,
      "y": 30,
      "z": 3,
      "name": "Rock_Stone"
    },
    {
      "x": -14,
      "y": 31,
      "z": 3,
      "name": "Rock_Stone"
    },
    {
      "x": -14,
      "y": 32,
      "z": 3,
      "name": "Rock_Stone"
    },
    {
      "x": -14,
      "y": 33,
      "z": 3,
      "name": "Rock_Stone"
    },
    {
      "x": -14,
      "y": 34,
      "z": 3,
      "name": "Rock_Stone"
    },
    {
      "x": -14,
      "y": 35,
      "z": 3,
      "name": "Rock_Stone"
    },
    {
      "x": -14,
      "y": 36,
      "z": 3,
      "name": "Rock_Stone"
    },
    {
      "x": -14,
      "y": 37,
      "z": 3,
      "name": "Rock_Stone"
    },
    {
      "x": -14,
      "y": 38,
      "z": 3,
      "name": "Rock_Stone"
    },
    {
      "x": -14,
      "y": 39,
      "z": 3,
      "name": "Rock_Stone"
    },
    {
      "x": -14,
      "y": 40,
      "z": 3,
      "name": "Rock_Stone"
    },
    {
      "x": -14,
      "y": 41,
      "z": 3,
      "name": "Rock_Stone"
    },
    {
      "x": -14,
      "y": 42,
      "z": 3,
      "name": "Rock_Stone"
    },
    {
      "x": -14,
      "y": 43,
      "z": 3,
      "name": "Rock_Stone"
    },
    {
      "x": -14,
      "y": 44,
      "z": 3,
      "name": "Rock_Stone"
    },
    {
      "x": -14,
      "y": 45,
      "z": 3,
      "name": "Rock_Stone"
    },
    {
      "x": -14,
      "y": 46,
      "z": 3,
      "name": "Rock_Stone"
    },
    {
      "x": -14,
      "y": 47,
      "z": 3,
      "name": "Rock_Stone"
    },
    {
      "x": -14,
      "y": 48,
      "z": 3,
      "name": "Rock_Stone"
    },
    {
      "x": -14,
      "y": 49,
      "z": 3,
      "name": "Rock_Stone"
    },
    {
      "x": -14,
      "y": 7,
      "z": 4,
      "name": "Rock_Stone"
    },
    {
      "x": -14,
      "y": 8,
      "z": 4,
      "name": "Rock_Stone"
    },
    {
      "x": -14,
      "y": 9,
      "z": 4,
      "name": "Rock_Stone"
    },
    {
      "x": -14,
      "y": 10,
      "z": 4,
      "name": "Rock_Stone"
    },
    {
      "x": -14,
      "y": 11,
      "z": 4,
      "name": "Rock_Stone"
    },
    {
      "x": -14,
      "y": 12,
      "z": 4,
      "name": "Rock_Stone"
    },
    {
      "x": -14,
      "y": 13,
      "z": 4,
      "name": "Rock_Stone"
    },
    {
      "x": -14,
      "y": 14,
      "z": 4,
      "name": "Soil_Dirt_Cold"
    },
    {
      "x": -14,
      "y": 15,
      "z": 4,
      "name": "Soil_Dirt_Cold"
    },
    {
      "x": -14,
      "y": 16,
      "z": 4,
      "name": "Soil_Dirt_Cold"
    },
    {
      "x": -14,
      "y": 17,
      "z": 4,
      "name": "Soil_Dirt_Cold"
    },
    {
      "x": -14,
      "y": 18,
      "z": 4,
      "name": "Soil_Grass_Cold"
    },
    {
      "x": -14,
      "y": 26,
      "z": 4,
      "name": "Rock_Stone"
    },
    {
      "x": -14,
      "y": 27,
      "z": 4,
      "name": "Rock_Stone"
    },
    {
      "x": -14,
      "y": 28,
      "z": 4,
      "name": "Rock_Stone"
    },
    {
      "x": -14,
      "y": 29,
      "z": 4,
      "name": "Rock_Stone"
    },
    {
      "x": -14,
      "y": 30,
      "z": 4,
      "name": "Rock_Stone"
    },
    {
      "x": -14,
      "y": 31,
      "z": 4,
      "name": "Rock_Stone"
    },
    {
      "x": -14,
      "y": 32,
      "z": 4,
      "name": "Rock_Stone"
    },
    {
      "x": -14,
      "y": 33,
      "z": 4,
      "name": "Rock_Stone"
    },
    {
      "x": -14,
      "y": 34,
      "z": 4,
      "name": "Rock_Stone"
    },
    {
      "x": -14,
      "y": 35,
      "z": 4,
      "name": "Rock_Stone"
    },
    {
      "x": -14,
      "y": 36,
      "z": 4,
      "name": "Rock_Stone"
    },
    {
      "x": -14,
      "y": 37,
      "z": 4,
      "name": "Rock_Stone"
    },
    {
      "x": -14,
      "y": 38,
      "z": 4,
      "name": "Rock_Stone"
    },
    {
      "x": -14,
      "y": 39,
      "z": 4,
      "name": "Rock_Stone"
    },
    {
      "x": -14,
      "y": 40,
      "z": 4,
      "name": "Rock_Stone"
    },
    {
      "x": -14,
      "y": 41,
      "z": 4,
      "name": "Rock_Stone"
    },
    {
      "x": -14,
      "y": 42,
      "z": 4,
      "name": "Rock_Stone"
    },
    {
      "x": -14,
      "y": 43,
      "z": 4,
      "name": "Rock_Stone"
    },
    {
      "x": -14,
      "y": 44,
      "z": 4,
      "name": "Rock_Stone"
    },
    {
      "x": -14,
      "y": 45,
      "z": 4,
      "name": "Rock_Stone"
    },
    {
      "x": -14,
      "y": 46,
      "z": 4,
      "name": "Rock_Stone"
    },
    {
      "x": -14,
      "y": 32,
      "z": 5,
      "name": "Rock_Stone"
    },
    {
      "x": -14,
      "y": 33,
      "z": 5,
      "name": "Rock_Stone"
    },
    {
      "x": -14,
      "y": 34,
      "z": 5,
      "name": "Rock_Stone"
    },
    {
      "x": -14,
      "y": 35,
      "z": 5,
      "name": "Rock_Stone"
    },
    {
      "x": -14,
      "y": 36,
      "z": 5,
      "name": "Rock_Stone"
    },
    {
      "x": -14,
      "y": 37,
      "z": 5,
      "name": "Rock_Stone"
    },
    {
      "x": -14,
      "y": 38,
      "z": 5,
      "name": "Rock_Stone"
    },
    {
      "x": -14,
      "y": 39,
      "z": 5,
      "name": "Rock_Stone"
    },
    {
      "x": -14,
      "y": 40,
      "z": 5,
      "name": "Rock_Stone"
    },
    {
      "x": -14,
      "y": 41,
      "z": 5,
      "name": "Rock_Stone"
    },
    {
      "x": -14,
      "y": 42,
      "z": 5,
      "name": "Rock_Stone"
    },
    {
      "x": -14,
      "y": 43,
      "z": 5,
      "name": "Rock_Stone"
    },
    {
      "x": -14,
      "y": 44,
      "z": 5,
      "name": "Rock_Stone"
    },
    {
      "x": -14,
      "y": 45,
      "z": 5,
      "name": "Rock_Stone"
    },
    {
      "x": -13,
      "y": 7,
      "z": -8,
      "name": "Rock_Stone"
    },
    {
      "x": -13,
      "y": 8,
      "z": -8,
      "name": "Rock_Stone"
    },
    {
      "x": -13,
      "y": 9,
      "z": -8,
      "name": "Rock_Stone"
    },
    {
      "x": -13,
      "y": 10,
      "z": -8,
      "name": "Rock_Stone"
    },
    {
      "x": -13,
      "y": 11,
      "z": -8,
      "name": "Rock_Stone"
    },
    {
      "x": -13,
      "y": 12,
      "z": -8,
      "name": "Rock_Stone"
    },
    {
      "x": -13,
      "y": 13,
      "z": -8,
      "name": "Rock_Stone"
    },
    {
      "x": -13,
      "y": 6,
      "z": -7,
      "name": "Rock_Stone"
    },
    {
      "x": -13,
      "y": 7,
      "z": -7,
      "name": "Rock_Stone"
    },
    {
      "x": -13,
      "y": 8,
      "z": -7,
      "name": "Rock_Stone"
    },
    {
      "x": -13,
      "y": 9,
      "z": -7,
      "name": "Rock_Stone"
    },
    {
      "x": -13,
      "y": 10,
      "z": -7,
      "name": "Rock_Stone"
    },
    {
      "x": -13,
      "y": 11,
      "z": -7,
      "name": "Rock_Stone"
    },
    {
      "x": -13,
      "y": 12,
      "z": -7,
      "name": "Rock_Stone"
    },
    {
      "x": -13,
      "y": 13,
      "z": -7,
      "name": "Rock_Stone"
    },
    {
      "x": -13,
      "y": 14,
      "z": -7,
      "name": "Rock_Stone"
    },
    {
      "x": -13,
      "y": 15,
      "z": -7,
      "name": "Rock_Stone"
    },
    {
      "x": -13,
      "y": 16,
      "z": -7,
      "name": "Rock_Stone"
    },
    {
      "x": -13,
      "y": 5,
      "z": -6,
      "name": "Rock_Stone"
    },
    {
      "x": -13,
      "y": 6,
      "z": -6,
      "name": "Rock_Stone"
    },
    {
      "x": -13,
      "y": 7,
      "z": -6,
      "name": "Rock_Stone"
    },
    {
      "x": -13,
      "y": 8,
      "z": -6,
      "name": "Rock_Stone"
    },
    {
      "x": -13,
      "y": 9,
      "z": -6,
      "name": "Rock_Stone"
    },
    {
      "x": -13,
      "y": 10,
      "z": -6,
      "name": "Rock_Stone"
    },
    {
      "x": -13,
      "y": 11,
      "z": -6,
      "name": "Rock_Stone"
    },
    {
      "x": -13,
      "y": 12,
      "z": -6,
      "name": "Rock_Stone"
    },
    {
      "x": -13,
      "y": 13,
      "z": -6,
      "name": "Rock_Stone"
    },
    {
      "x": -13,
      "y": 14,
      "z": -6,
      "name": "Rock_Stone"
    },
    {
      "x": -13,
      "y": 15,
      "z": -6,
      "name": "Rock_Stone"
    },
    {
      "x": -13,
      "y": 16,
      "z": -6,
      "name": "Rock_Stone"
    },
    {
      "x": -13,
      "y": 17,
      "z": -6,
      "name": "Rock_Stone"
    },
    {
      "x": -13,
      "y": 18,
      "z": -6,
      "name": "Rock_Stone"
    },
    {
      "x": -13,
      "y": 19,
      "z": -6,
      "name": "Rock_Stone"
    },
    {
      "x": -13,
      "y": 20,
      "z": -6,
      "name": "Rock_Stone"
    },
    {
      "x": -13,
      "y": 21,
      "z": -6,
      "name": "Rock_Stone"
    },
    {
      "x": -13,
      "y": 22,
      "z": -6,
      "name": "Soil_Dirt_Cold"
    },
    {
      "x": -13,
      "y": 23,
      "z": -6,
      "name": "Soil_Grass_Cold"
    },
    {
      "x": -13,
      "y": 5,
      "z": -5,
      "name": "Rock_Stone"
    },
    {
      "x": -13,
      "y": 6,
      "z": -5,
      "name": "Rock_Stone"
    },
    {
      "x": -13,
      "y": 7,
      "z": -5,
      "name": "Rock_Stone"
    },
    {
      "x": -13,
      "y": 8,
      "z": -5,
      "name": "Rock_Stone"
    },
    {
      "x": -13,
      "y": 9,
      "z": -5,
      "name": "Rock_Stone"
    },
    {
      "x": -13,
      "y": 10,
      "z": -5,
      "name": "Rock_Stone"
    },
    {
      "x": -13,
      "y": 11,
      "z": -5,
      "name": "Rock_Stone"
    },
    {
      "x": -13,
      "y": 12,
      "z": -5,
      "name": "Rock_Stone"
    },
    {
      "x": -13,
      "y": 13,
      "z": -5,
      "name": "Rock_Stone"
    },
    {
      "x": -13,
      "y": 14,
      "z": -5,
      "name": "Rock_Stone"
    },
    {
      "x": -13,
      "y": 15,
      "z": -5,
      "name": "Rock_Stone"
    },
    {
      "x": -13,
      "y": 16,
      "z": -5,
      "name": "Rock_Stone"
    },
    {
      "x": -13,
      "y": 17,
      "z": -5,
      "name": "Rock_Stone"
    },
    {
      "x": -13,
      "y": 18,
      "z": -5,
      "name": "Rock_Stone"
    },
    {
      "x": -13,
      "y": 19,
      "z": -5,
      "name": "Rock_Stone"
    },
    {
      "x": -13,
      "y": 20,
      "z": -5,
      "name": "Rock_Stone"
    },
    {
      "x": -13,
      "y": 21,
      "z": -5,
      "name": "Soil_Dirt_Cold"
    },
    {
      "x": -13,
      "y": 22,
      "z": -5,
      "name": "Soil_Dirt_Cold"
    },
    {
      "x": -13,
      "y": 23,
      "z": -5,
      "name": "Soil_Grass_Cold"
    },
    {
      "x": -13,
      "y": 3,
      "z": -4,
      "name": "Rock_Stone"
    },
    {
      "x": -13,
      "y": 4,
      "z": -4,
      "name": "Rock_Stone"
    },
    {
      "x": -13,
      "y": 5,
      "z": -4,
      "name": "Rock_Stone"
    },
    {
      "x": -13,
      "y": 6,
      "z": -4,
      "name": "Rock_Stone"
    },
    {
      "x": -13,
      "y": 7,
      "z": -4,
      "name": "Rock_Stone"
    },
    {
      "x": -13,
      "y": 8,
      "z": -4,
      "name": "Rock_Stone"
    },
    {
      "x": -13,
      "y": 9,
      "z": -4,
      "name": "Rock_Stone"
    },
    {
      "x": -13,
      "y": 10,
      "z": -4,
      "name": "Rock_Stone"
    },
    {
      "x": -13,
      "y": 11,
      "z": -4,
      "name": "Rock_Stone"
    },
    {
      "x": -13,
      "y": 12,
      "z": -4,
      "name": "Rock_Stone"
    },
    {
      "x": -13,
      "y": 13,
      "z": -4,
      "name": "Soil_Dirt_Cold"
    },
    {
      "x": -13,
      "y": 14,
      "z": -4,
      "name": "Rock_Stone"
    },
    {
      "x": -13,
      "y": 15,
      "z": -4,
      "name": "Rock_Stone"
    },
    {
      "x": -13,
      "y": 16,
      "z": -4,
      "name": "Rock_Stone"
    },
    {
      "x": -13,
      "y": 17,
      "z": -4,
      "name": "Rock_Stone"
    },
    {
      "x": -13,
      "y": 18,
      "z": -4,
      "name": "Soil_Dirt_Cold"
    },
    {
      "x": -13,
      "y": 19,
      "z": -4,
      "name": "Soil_Dirt_Cold"
    },
    {
      "x": -13,
      "y": 20,
      "z": -4,
      "name": "Soil_Dirt_Cold"
    },
    {
      "x": -13,
      "y": 21,
      "z": -4,
      "name": "Soil_Dirt_Cold"
    },
    {
      "x": -13,
      "y": 22,
      "z": -4,
      "name": "Soil_Grass_Cold"
    },
    {
      "x": -13,
      "y": 2,
      "z": -3,
      "name": "Rock_Stone"
    },
    {
      "x": -13,
      "y": 3,
      "z": -3,
      "name": "Rock_Stone"
    },
    {
      "x": -13,
      "y": 4,
      "z": -3,
      "name": "Rock_Stone"
    },
    {
      "x": -13,
      "y": 5,
      "z": -3,
      "name": "Rock_Stone"
    },
    {
      "x": -13,
      "y": 6,
      "z": -3,
      "name": "Rock_Stone"
    },
    {
      "x": -13,
      "y": 7,
      "z": -3,
      "name": "Rock_Stone"
    },
    {
      "x": -13,
      "y": 8,
      "z": -3,
      "name": "Rock_Stone"
    },
    {
      "x": -13,
      "y": 9,
      "z": -3,
      "name": "Rock_Stone"
    },
    {
      "x": -13,
      "y": 10,
      "z": -3,
      "name": "Rock_Stone"
    },
    {
      "x": -13,
      "y": 11,
      "z": -3,
      "name": "Rock_Stone"
    },
    {
      "x": -13,
      "y": 12,
      "z": -3,
      "name": "Rock_Stone"
    },
    {
      "x": -13,
      "y": 13,
      "z": -3,
      "name": "Rock_Stone"
    },
    {
      "x": -13,
      "y": 14,
      "z": -3,
      "name": "Rock_Stone"
    },
    {
      "x": -13,
      "y": 15,
      "z": -3,
      "name": "Rock_Stone"
    },
    {
      "x": -13,
      "y": 16,
      "z": -3,
      "name": "Soil_Dirt_Cold"
    },
    {
      "x": -13,
      "y": 17,
      "z": -3,
      "name": "Soil_Dirt_Cold"
    },
    {
      "x": -13,
      "y": 18,
      "z": -3,
      "name": "Soil_Dirt_Cold"
    },
    {
      "x": -13,
      "y": 19,
      "z": -3,
      "name": "Soil_Dirt_Cold"
    },
    {
      "x": -13,
      "y": 20,
      "z": -3,
      "name": "Rock_Stone"
    },
    {
      "x": -13,
      "y": 21,
      "z": -3,
      "name": "Rock_Stone"
    },
    {
      "x": -13,
      "y": 22,
      "z": -3,
      "name": "Rock_Stone"
    },
    {
      "x": -13,
      "y": 23,
      "z": -3,
      "name": "Rock_Stone"
    },
    {
      "x": -13,
      "y": 24,
      "z": -3,
      "name": "Rock_Stone"
    },
    {
      "x": -13,
      "y": 25,
      "z": -3,
      "name": "Rock_Stone"
    },
    {
      "x": -13,
      "y": 26,
      "z": -3,
      "name": "Rock_Stone"
    },
    {
      "x": -13,
      "y": 27,
      "z": -3,
      "name": "Rock_Stone"
    },
    {
      "x": -13,
      "y": 28,
      "z": -3,
      "name": "Rock_Stone"
    },
    {
      "x": -13,
      "y": 29,
      "z": -3,
      "name": "Rock_Stone"
    },
    {
      "x": -13,
      "y": 30,
      "z": -3,
      "name": "Rock_Stone"
    },
    {
      "x": -13,
      "y": 31,
      "z": -3,
      "name": "Rock_Stone"
    },
    {
      "x": -13,
      "y": 32,
      "z": -3,
      "name": "Rock_Stone"
    },
    {
      "x": -13,
      "y": 33,
      "z": -3,
      "name": "Rock_Stone"
    },
    {
      "x": -13,
      "y": 34,
      "z": -3,
      "name": "Rock_Stone"
    },
    {
      "x": -13,
      "y": 35,
      "z": -3,
      "name": "Rock_Stone"
    },
    {
      "x": -13,
      "y": 36,
      "z": -3,
      "name": "Rock_Stone"
    },
    {
      "x": -13,
      "y": 37,
      "z": -3,
      "name": "Rock_Stone"
    },
    {
      "x": -13,
      "y": 38,
      "z": -3,
      "name": "Rock_Stone"
    },
    {
      "x": -13,
      "y": 39,
      "z": -3,
      "name": "Rock_Stone"
    },
    {
      "x": -13,
      "y": 40,
      "z": -3,
      "name": "Rock_Stone"
    },
    {
      "x": -13,
      "y": 41,
      "z": -3,
      "name": "Rock_Stone"
    },
    {
      "x": -13,
      "y": 42,
      "z": -3,
      "name": "Rock_Stone"
    },
    {
      "x": -13,
      "y": 43,
      "z": -3,
      "name": "Rock_Stone"
    },
    {
      "x": -13,
      "y": 44,
      "z": -3,
      "name": "Rock_Stone"
    },
    {
      "x": -13,
      "y": 2,
      "z": -2,
      "name": "Rock_Stone"
    },
    {
      "x": -13,
      "y": 3,
      "z": -2,
      "name": "Rock_Stone"
    },
    {
      "x": -13,
      "y": 4,
      "z": -2,
      "name": "Rock_Stone"
    },
    {
      "x": -13,
      "y": 5,
      "z": -2,
      "name": "Rock_Stone"
    },
    {
      "x": -13,
      "y": 6,
      "z": -2,
      "name": "Rock_Stone"
    },
    {
      "x": -13,
      "y": 7,
      "z": -2,
      "name": "Rock_Stone"
    },
    {
      "x": -13,
      "y": 8,
      "z": -2,
      "name": "Rock_Stone"
    },
    {
      "x": -13,
      "y": 9,
      "z": -2,
      "name": "Rock_Stone"
    },
    {
      "x": -13,
      "y": 10,
      "z": -2,
      "name": "Rock_Stone"
    },
    {
      "x": -13,
      "y": 11,
      "z": -2,
      "name": "Rock_Stone"
    },
    {
      "x": -13,
      "y": 12,
      "z": -2,
      "name": "Rock_Stone"
    },
    {
      "x": -13,
      "y": 13,
      "z": -2,
      "name": "Rock_Stone"
    },
    {
      "x": -13,
      "y": 14,
      "z": -2,
      "name": "Rock_Stone"
    },
    {
      "x": -13,
      "y": 15,
      "z": -2,
      "name": "Rock_Stone"
    },
    {
      "x": -13,
      "y": 16,
      "z": -2,
      "name": "Rock_Stone"
    },
    {
      "x": -13,
      "y": 17,
      "z": -2,
      "name": "Rock_Stone"
    },
    {
      "x": -13,
      "y": 18,
      "z": -2,
      "name": "Rock_Stone"
    },
    {
      "x": -13,
      "y": 19,
      "z": -2,
      "name": "Rock_Stone"
    },
    {
      "x": -13,
      "y": 20,
      "z": -2,
      "name": "Rock_Stone"
    },
    {
      "x": -13,
      "y": 21,
      "z": -2,
      "name": "Rock_Stone"
    },
    {
      "x": -13,
      "y": 22,
      "z": -2,
      "name": "Rock_Stone"
    },
    {
      "x": -13,
      "y": 23,
      "z": -2,
      "name": "Rock_Stone"
    },
    {
      "x": -13,
      "y": 24,
      "z": -2,
      "name": "Rock_Stone"
    },
    {
      "x": -13,
      "y": 25,
      "z": -2,
      "name": "Rock_Stone"
    },
    {
      "x": -13,
      "y": 26,
      "z": -2,
      "name": "Rock_Stone"
    },
    {
      "x": -13,
      "y": 27,
      "z": -2,
      "name": "Rock_Stone"
    },
    {
      "x": -13,
      "y": 28,
      "z": -2,
      "name": "Rock_Stone"
    },
    {
      "x": -13,
      "y": 29,
      "z": -2,
      "name": "Rock_Stone"
    },
    {
      "x": -13,
      "y": 30,
      "z": -2,
      "name": "Rock_Stone"
    },
    {
      "x": -13,
      "y": 31,
      "z": -2,
      "name": "Rock_Stone"
    },
    {
      "x": -13,
      "y": 32,
      "z": -2,
      "name": "Rock_Stone"
    },
    {
      "x": -13,
      "y": 33,
      "z": -2,
      "name": "Rock_Stone"
    },
    {
      "x": -13,
      "y": 34,
      "z": -2,
      "name": "Rock_Stone"
    },
    {
      "x": -13,
      "y": 35,
      "z": -2,
      "name": "Rock_Stone"
    },
    {
      "x": -13,
      "y": 36,
      "z": -2,
      "name": "Rock_Stone"
    },
    {
      "x": -13,
      "y": 37,
      "z": -2,
      "name": "Rock_Stone"
    },
    {
      "x": -13,
      "y": 38,
      "z": -2,
      "name": "Rock_Stone"
    },
    {
      "x": -13,
      "y": 39,
      "z": -2,
      "name": "Rock_Stone"
    },
    {
      "x": -13,
      "y": 40,
      "z": -2,
      "name": "Rock_Stone"
    },
    {
      "x": -13,
      "y": 41,
      "z": -2,
      "name": "Rock_Stone"
    },
    {
      "x": -13,
      "y": 42,
      "z": -2,
      "name": "Rock_Stone"
    },
    {
      "x": -13,
      "y": 43,
      "z": -2,
      "name": "Rock_Stone"
    },
    {
      "x": -13,
      "y": 44,
      "z": -2,
      "name": "Rock_Stone"
    },
    {
      "x": -13,
      "y": 45,
      "z": -2,
      "name": "Rock_Stone"
    },
    {
      "x": -13,
      "y": 1,
      "z": -1,
      "name": "Rock_Stone"
    },
    {
      "x": -13,
      "y": 2,
      "z": -1,
      "name": "Rock_Stone"
    },
    {
      "x": -13,
      "y": 3,
      "z": -1,
      "name": "Rock_Stone"
    },
    {
      "x": -13,
      "y": 4,
      "z": -1,
      "name": "Rock_Stone"
    },
    {
      "x": -13,
      "y": 5,
      "z": -1,
      "name": "Rock_Stone"
    },
    {
      "x": -13,
      "y": 6,
      "z": -1,
      "name": "Rock_Stone"
    },
    {
      "x": -13,
      "y": 7,
      "z": -1,
      "name": "Rock_Stone"
    },
    {
      "x": -13,
      "y": 8,
      "z": -1,
      "name": "Rock_Stone"
    },
    {
      "x": -13,
      "y": 9,
      "z": -1,
      "name": "Rock_Stone"
    },
    {
      "x": -13,
      "y": 10,
      "z": -1,
      "name": "Rock_Stone"
    },
    {
      "x": -13,
      "y": 11,
      "z": -1,
      "name": "Rock_Stone"
    },
    {
      "x": -13,
      "y": 12,
      "z": -1,
      "name": "Rock_Stone"
    },
    {
      "x": -13,
      "y": 13,
      "z": -1,
      "name": "Rock_Stone"
    },
    {
      "x": -13,
      "y": 14,
      "z": -1,
      "name": "Rock_Stone"
    },
    {
      "x": -13,
      "y": 15,
      "z": -1,
      "name": "Rock_Stone"
    },
    {
      "x": -13,
      "y": 16,
      "z": -1,
      "name": "Rock_Stone"
    },
    {
      "x": -13,
      "y": 17,
      "z": -1,
      "name": "Rock_Stone"
    },
    {
      "x": -13,
      "y": 18,
      "z": -1,
      "name": "Rock_Stone"
    },
    {
      "x": -13,
      "y": 19,
      "z": -1,
      "name": "Rock_Stone"
    },
    {
      "x": -13,
      "y": 20,
      "z": -1,
      "name": "Rock_Stone"
    },
    {
      "x": -13,
      "y": 21,
      "z": -1,
      "name": "Rock_Stone"
    },
    {
      "x": -13,
      "y": 22,
      "z": -1,
      "name": "Rock_Stone"
    },
    {
      "x": -13,
      "y": 23,
      "z": -1,
      "name": "Rock_Stone"
    },
    {
      "x": -13,
      "y": 24,
      "z": -1,
      "name": "Rock_Stone"
    },
    {
      "x": -13,
      "y": 25,
      "z": -1,
      "name": "Rock_Stone"
    },
    {
      "x": -13,
      "y": 26,
      "z": -1,
      "name": "Rock_Stone"
    },
    {
      "x": -13,
      "y": 27,
      "z": -1,
      "name": "Rock_Stone"
    },
    {
      "x": -13,
      "y": 28,
      "z": -1,
      "name": "Rock_Stone"
    },
    {
      "x": -13,
      "y": 29,
      "z": -1,
      "name": "Rock_Stone"
    },
    {
      "x": -13,
      "y": 30,
      "z": -1,
      "name": "Rock_Stone"
    },
    {
      "x": -13,
      "y": 31,
      "z": -1,
      "name": "Rock_Stone"
    },
    {
      "x": -13,
      "y": 32,
      "z": -1,
      "name": "Rock_Stone"
    },
    {
      "x": -13,
      "y": 33,
      "z": -1,
      "name": "Rock_Stone"
    },
    {
      "x": -13,
      "y": 34,
      "z": -1,
      "name": "Rock_Stone"
    },
    {
      "x": -13,
      "y": 35,
      "z": -1,
      "name": "Rock_Stone"
    },
    {
      "x": -13,
      "y": 36,
      "z": -1,
      "name": "Rock_Stone"
    },
    {
      "x": -13,
      "y": 37,
      "z": -1,
      "name": "Rock_Stone"
    },
    {
      "x": -13,
      "y": 38,
      "z": -1,
      "name": "Rock_Stone"
    },
    {
      "x": -13,
      "y": 39,
      "z": -1,
      "name": "Rock_Stone"
    },
    {
      "x": -13,
      "y": 40,
      "z": -1,
      "name": "Rock_Stone"
    },
    {
      "x": -13,
      "y": 41,
      "z": -1,
      "name": "Rock_Stone"
    },
    {
      "x": -13,
      "y": 42,
      "z": -1,
      "name": "Rock_Stone"
    },
    {
      "x": -13,
      "y": 43,
      "z": -1,
      "name": "Rock_Stone"
    },
    {
      "x": -13,
      "y": 44,
      "z": -1,
      "name": "Rock_Stone"
    },
    {
      "x": -13,
      "y": 45,
      "z": -1,
      "name": "Rock_Stone"
    },
    {
      "x": -13,
      "y": 46,
      "z": -1,
      "name": "Rock_Stone"
    },
    {
      "x": -13,
      "y": 1,
      "z": 0,
      "name": "Rock_Stone"
    },
    {
      "x": -13,
      "y": 2,
      "z": 0,
      "name": "Rock_Stone"
    },
    {
      "x": -13,
      "y": 3,
      "z": 0,
      "name": "Rock_Stone"
    },
    {
      "x": -13,
      "y": 4,
      "z": 0,
      "name": "Rock_Stone"
    },
    {
      "x": -13,
      "y": 5,
      "z": 0,
      "name": "Rock_Stone"
    },
    {
      "x": -13,
      "y": 6,
      "z": 0,
      "name": "Rock_Stone"
    },
    {
      "x": -13,
      "y": 7,
      "z": 0,
      "name": "Rock_Stone"
    },
    {
      "x": -13,
      "y": 8,
      "z": 0,
      "name": "Rock_Stone"
    },
    {
      "x": -13,
      "y": 9,
      "z": 0,
      "name": "Rock_Stone"
    },
    {
      "x": -13,
      "y": 10,
      "z": 0,
      "name": "Rock_Stone"
    },
    {
      "x": -13,
      "y": 11,
      "z": 0,
      "name": "Rock_Stone"
    },
    {
      "x": -13,
      "y": 12,
      "z": 0,
      "name": "Rock_Stone"
    },
    {
      "x": -13,
      "y": 13,
      "z": 0,
      "name": "Rock_Stone"
    },
    {
      "x": -13,
      "y": 14,
      "z": 0,
      "name": "Rock_Stone"
    },
    {
      "x": -13,
      "y": 15,
      "z": 0,
      "name": "Rock_Stone"
    },
    {
      "x": -13,
      "y": 16,
      "z": 0,
      "name": "Rock_Stone"
    },
    {
      "x": -13,
      "y": 17,
      "z": 0,
      "name": "Rock_Stone"
    },
    {
      "x": -13,
      "y": 18,
      "z": 0,
      "name": "Rock_Stone"
    },
    {
      "x": -13,
      "y": 19,
      "z": 0,
      "name": "Rock_Stone"
    },
    {
      "x": -13,
      "y": 20,
      "z": 0,
      "name": "Rock_Stone"
    },
    {
      "x": -13,
      "y": 21,
      "z": 0,
      "name": "Rock_Stone"
    },
    {
      "x": -13,
      "y": 22,
      "z": 0,
      "name": "Rock_Stone"
    },
    {
      "x": -13,
      "y": 23,
      "z": 0,
      "name": "Rock_Stone"
    },
    {
      "x": -13,
      "y": 24,
      "z": 0,
      "name": "Rock_Stone"
    },
    {
      "x": -13,
      "y": 25,
      "z": 0,
      "name": "Rock_Stone"
    },
    {
      "x": -13,
      "y": 26,
      "z": 0,
      "name": "Rock_Stone"
    },
    {
      "x": -13,
      "y": 27,
      "z": 0,
      "name": "Rock_Stone"
    },
    {
      "x": -13,
      "y": 28,
      "z": 0,
      "name": "Rock_Stone"
    },
    {
      "x": -13,
      "y": 29,
      "z": 0,
      "name": "Rock_Stone"
    },
    {
      "x": -13,
      "y": 30,
      "z": 0,
      "name": "Rock_Stone"
    },
    {
      "x": -13,
      "y": 31,
      "z": 0,
      "name": "Rock_Stone"
    },
    {
      "x": -13,
      "y": 32,
      "z": 0,
      "name": "Rock_Stone"
    },
    {
      "x": -13,
      "y": 33,
      "z": 0,
      "name": "Rock_Stone"
    },
    {
      "x": -13,
      "y": 34,
      "z": 0,
      "name": "Rock_Stone"
    },
    {
      "x": -13,
      "y": 35,
      "z": 0,
      "name": "Rock_Stone"
    },
    {
      "x": -13,
      "y": 36,
      "z": 0,
      "name": "Rock_Stone"
    },
    {
      "x": -13,
      "y": 37,
      "z": 0,
      "name": "Rock_Stone"
    },
    {
      "x": -13,
      "y": 38,
      "z": 0,
      "name": "Rock_Stone"
    },
    {
      "x": -13,
      "y": 39,
      "z": 0,
      "name": "Rock_Stone"
    },
    {
      "x": -13,
      "y": 40,
      "z": 0,
      "name": "Rock_Stone"
    },
    {
      "x": -13,
      "y": 41,
      "z": 0,
      "name": "Rock_Stone"
    },
    {
      "x": -13,
      "y": 42,
      "z": 0,
      "name": "Rock_Stone"
    },
    {
      "x": -13,
      "y": 43,
      "z": 0,
      "name": "Rock_Stone"
    },
    {
      "x": -13,
      "y": 44,
      "z": 0,
      "name": "Rock_Stone"
    },
    {
      "x": -13,
      "y": 45,
      "z": 0,
      "name": "Rock_Stone"
    },
    {
      "x": -13,
      "y": 46,
      "z": 0,
      "name": "Rock_Stone"
    },
    {
      "x": -13,
      "y": 47,
      "z": 0,
      "name": "Rock_Stone"
    },
    {
      "x": -13,
      "y": 48,
      "z": 0,
      "name": "Rock_Stone"
    },
    {
      "x": -13,
      "y": 0,
      "z": 1,
      "name": "Rock_Stone"
    },
    {
      "x": -13,
      "y": 1,
      "z": 1,
      "name": "Rock_Stone"
    },
    {
      "x": -13,
      "y": 2,
      "z": 1,
      "name": "Rock_Stone"
    },
    {
      "x": -13,
      "y": 3,
      "z": 1,
      "name": "Rock_Stone"
    },
    {
      "x": -13,
      "y": 4,
      "z": 1,
      "name": "Rock_Stone"
    },
    {
      "x": -13,
      "y": 5,
      "z": 1,
      "name": "Rock_Stone"
    },
    {
      "x": -13,
      "y": 6,
      "z": 1,
      "name": "Rock_Stone"
    },
    {
      "x": -13,
      "y": 7,
      "z": 1,
      "name": "Rock_Stone"
    },
    {
      "x": -13,
      "y": 8,
      "z": 1,
      "name": "Rock_Stone"
    },
    {
      "x": -13,
      "y": 9,
      "z": 1,
      "name": "Rock_Stone"
    },
    {
      "x": -13,
      "y": 10,
      "z": 1,
      "name": "Rock_Stone"
    },
    {
      "x": -13,
      "y": 11,
      "z": 1,
      "name": "Rock_Stone"
    },
    {
      "x": -13,
      "y": 12,
      "z": 1,
      "name": "Rock_Stone"
    },
    {
      "x": -13,
      "y": 13,
      "z": 1,
      "name": "Rock_Stone"
    },
    {
      "x": -13,
      "y": 14,
      "z": 1,
      "name": "Rock_Stone"
    },
    {
      "x": -13,
      "y": 15,
      "z": 1,
      "name": "Rock_Stone"
    },
    {
      "x": -13,
      "y": 16,
      "z": 1,
      "name": "Rock_Stone"
    },
    {
      "x": -13,
      "y": 17,
      "z": 1,
      "name": "Rock_Stone"
    },
    {
      "x": -13,
      "y": 18,
      "z": 1,
      "name": "Rock_Stone"
    },
    {
      "x": -13,
      "y": 19,
      "z": 1,
      "name": "Rock_Stone"
    },
    {
      "x": -13,
      "y": 20,
      "z": 1,
      "name": "Rock_Stone"
    },
    {
      "x": -13,
      "y": 21,
      "z": 1,
      "name": "Rock_Stone"
    },
    {
      "x": -13,
      "y": 22,
      "z": 1,
      "name": "Rock_Stone"
    },
    {
      "x": -13,
      "y": 23,
      "z": 1,
      "name": "Rock_Stone"
    },
    {
      "x": -13,
      "y": 24,
      "z": 1,
      "name": "Rock_Stone"
    },
    {
      "x": -13,
      "y": 25,
      "z": 1,
      "name": "Rock_Stone"
    },
    {
      "x": -13,
      "y": 26,
      "z": 1,
      "name": "Rock_Stone"
    },
    {
      "x": -13,
      "y": 27,
      "z": 1,
      "name": "Rock_Stone"
    },
    {
      "x": -13,
      "y": 28,
      "z": 1,
      "name": "Rock_Stone"
    },
    {
      "x": -13,
      "y": 29,
      "z": 1,
      "name": "Rock_Stone"
    },
    {
      "x": -13,
      "y": 30,
      "z": 1,
      "name": "Rock_Stone"
    },
    {
      "x": -13,
      "y": 31,
      "z": 1,
      "name": "Rock_Stone"
    },
    {
      "x": -13,
      "y": 32,
      "z": 1,
      "name": "Rock_Stone"
    },
    {
      "x": -13,
      "y": 33,
      "z": 1,
      "name": "Rock_Stone"
    },
    {
      "x": -13,
      "y": 34,
      "z": 1,
      "name": "Rock_Stone"
    },
    {
      "x": -13,
      "y": 35,
      "z": 1,
      "name": "Rock_Stone"
    },
    {
      "x": -13,
      "y": 36,
      "z": 1,
      "name": "Rock_Stone"
    },
    {
      "x": -13,
      "y": 37,
      "z": 1,
      "name": "Rock_Stone"
    },
    {
      "x": -13,
      "y": 38,
      "z": 1,
      "name": "Rock_Stone"
    },
    {
      "x": -13,
      "y": 39,
      "z": 1,
      "name": "Rock_Stone"
    },
    {
      "x": -13,
      "y": 40,
      "z": 1,
      "name": "Rock_Stone"
    },
    {
      "x": -13,
      "y": 41,
      "z": 1,
      "name": "Rock_Stone"
    },
    {
      "x": -13,
      "y": 42,
      "z": 1,
      "name": "Rock_Stone"
    },
    {
      "x": -13,
      "y": 43,
      "z": 1,
      "name": "Rock_Stone"
    },
    {
      "x": -13,
      "y": 44,
      "z": 1,
      "name": "Rock_Stone"
    },
    {
      "x": -13,
      "y": 45,
      "z": 1,
      "name": "Rock_Stone"
    },
    {
      "x": -13,
      "y": 46,
      "z": 1,
      "name": "Rock_Stone"
    },
    {
      "x": -13,
      "y": 47,
      "z": 1,
      "name": "Rock_Stone"
    },
    {
      "x": -13,
      "y": 48,
      "z": 1,
      "name": "Rock_Stone"
    },
    {
      "x": -13,
      "y": 49,
      "z": 1,
      "name": "Rock_Stone"
    },
    {
      "x": -13,
      "y": 50,
      "z": 1,
      "name": "Rock_Stone"
    },
    {
      "x": -13,
      "y": 0,
      "z": 2,
      "name": "Rock_Stone"
    },
    {
      "x": -13,
      "y": 1,
      "z": 2,
      "name": "Rock_Stone"
    },
    {
      "x": -13,
      "y": 2,
      "z": 2,
      "name": "Rock_Stone"
    },
    {
      "x": -13,
      "y": 3,
      "z": 2,
      "name": "Rock_Stone"
    },
    {
      "x": -13,
      "y": 4,
      "z": 2,
      "name": "Rock_Stone"
    },
    {
      "x": -13,
      "y": 5,
      "z": 2,
      "name": "Rock_Stone"
    },
    {
      "x": -13,
      "y": 6,
      "z": 2,
      "name": "Rock_Stone"
    },
    {
      "x": -13,
      "y": 7,
      "z": 2,
      "name": "Rock_Stone"
    },
    {
      "x": -13,
      "y": 8,
      "z": 2,
      "name": "Rock_Stone"
    },
    {
      "x": -13,
      "y": 9,
      "z": 2,
      "name": "Rock_Stone"
    },
    {
      "x": -13,
      "y": 10,
      "z": 2,
      "name": "Rock_Stone"
    },
    {
      "x": -13,
      "y": 11,
      "z": 2,
      "name": "Rock_Stone"
    },
    {
      "x": -13,
      "y": 12,
      "z": 2,
      "name": "Rock_Stone"
    },
    {
      "x": -13,
      "y": 13,
      "z": 2,
      "name": "Rock_Stone"
    },
    {
      "x": -13,
      "y": 14,
      "z": 2,
      "name": "Rock_Stone"
    },
    {
      "x": -13,
      "y": 15,
      "z": 2,
      "name": "Rock_Stone"
    },
    {
      "x": -13,
      "y": 16,
      "z": 2,
      "name": "Rock_Stone"
    },
    {
      "x": -13,
      "y": 17,
      "z": 2,
      "name": "Rock_Stone"
    },
    {
      "x": -13,
      "y": 18,
      "z": 2,
      "name": "Rock_Stone"
    },
    {
      "x": -13,
      "y": 19,
      "z": 2,
      "name": "Rock_Stone"
    },
    {
      "x": -13,
      "y": 20,
      "z": 2,
      "name": "Rock_Stone"
    },
    {
      "x": -13,
      "y": 21,
      "z": 2,
      "name": "Rock_Stone"
    },
    {
      "x": -13,
      "y": 22,
      "z": 2,
      "name": "Rock_Stone"
    },
    {
      "x": -13,
      "y": 23,
      "z": 2,
      "name": "Rock_Stone"
    },
    {
      "x": -13,
      "y": 24,
      "z": 2,
      "name": "Rock_Stone"
    },
    {
      "x": -13,
      "y": 25,
      "z": 2,
      "name": "Rock_Stone"
    },
    {
      "x": -13,
      "y": 26,
      "z": 2,
      "name": "Rock_Stone"
    },
    {
      "x": -13,
      "y": 27,
      "z": 2,
      "name": "Rock_Stone"
    },
    {
      "x": -13,
      "y": 28,
      "z": 2,
      "name": "Rock_Stone"
    },
    {
      "x": -13,
      "y": 29,
      "z": 2,
      "name": "Rock_Stone"
    },
    {
      "x": -13,
      "y": 30,
      "z": 2,
      "name": "Rock_Stone"
    },
    {
      "x": -13,
      "y": 31,
      "z": 2,
      "name": "Rock_Stone"
    },
    {
      "x": -13,
      "y": 32,
      "z": 2,
      "name": "Rock_Stone"
    },
    {
      "x": -13,
      "y": 33,
      "z": 2,
      "name": "Rock_Stone"
    },
    {
      "x": -13,
      "y": 34,
      "z": 2,
      "name": "Rock_Stone"
    },
    {
      "x": -13,
      "y": 35,
      "z": 2,
      "name": "Rock_Stone"
    },
    {
      "x": -13,
      "y": 36,
      "z": 2,
      "name": "Rock_Stone"
    },
    {
      "x": -13,
      "y": 37,
      "z": 2,
      "name": "Rock_Stone"
    },
    {
      "x": -13,
      "y": 38,
      "z": 2,
      "name": "Rock_Stone"
    },
    {
      "x": -13,
      "y": 39,
      "z": 2,
      "name": "Rock_Stone"
    },
    {
      "x": -13,
      "y": 40,
      "z": 2,
      "name": "Rock_Stone"
    },
    {
      "x": -13,
      "y": 41,
      "z": 2,
      "name": "Rock_Stone"
    },
    {
      "x": -13,
      "y": 42,
      "z": 2,
      "name": "Rock_Stone"
    },
    {
      "x": -13,
      "y": 43,
      "z": 2,
      "name": "Rock_Stone"
    },
    {
      "x": -13,
      "y": 44,
      "z": 2,
      "name": "Rock_Stone"
    },
    {
      "x": -13,
      "y": 45,
      "z": 2,
      "name": "Rock_Stone"
    },
    {
      "x": -13,
      "y": 46,
      "z": 2,
      "name": "Rock_Stone"
    },
    {
      "x": -13,
      "y": 47,
      "z": 2,
      "name": "Rock_Stone"
    },
    {
      "x": -13,
      "y": 48,
      "z": 2,
      "name": "Rock_Stone"
    },
    {
      "x": -13,
      "y": 49,
      "z": 2,
      "name": "Rock_Stone"
    },
    {
      "x": -13,
      "y": 50,
      "z": 2,
      "name": "Rock_Stone"
    },
    {
      "x": -13,
      "y": 1,
      "z": 3,
      "name": "Rock_Stone"
    },
    {
      "x": -13,
      "y": 2,
      "z": 3,
      "name": "Rock_Stone"
    },
    {
      "x": -13,
      "y": 3,
      "z": 3,
      "name": "Rock_Stone"
    },
    {
      "x": -13,
      "y": 4,
      "z": 3,
      "name": "Rock_Stone"
    },
    {
      "x": -13,
      "y": 5,
      "z": 3,
      "name": "Rock_Stone"
    },
    {
      "x": -13,
      "y": 6,
      "z": 3,
      "name": "Rock_Stone"
    },
    {
      "x": -13,
      "y": 7,
      "z": 3,
      "name": "Rock_Stone"
    },
    {
      "x": -13,
      "y": 8,
      "z": 3,
      "name": "Rock_Stone"
    },
    {
      "x": -13,
      "y": 9,
      "z": 3,
      "name": "Rock_Stone"
    },
    {
      "x": -13,
      "y": 10,
      "z": 3,
      "name": "Rock_Stone"
    },
    {
      "x": -13,
      "y": 11,
      "z": 3,
      "name": "Rock_Stone"
    },
    {
      "x": -13,
      "y": 12,
      "z": 3,
      "name": "Rock_Stone"
    },
    {
      "x": -13,
      "y": 13,
      "z": 3,
      "name": "Rock_Stone"
    },
    {
      "x": -13,
      "y": 14,
      "z": 3,
      "name": "Rock_Stone"
    },
    {
      "x": -13,
      "y": 15,
      "z": 3,
      "name": "Rock_Stone"
    },
    {
      "x": -13,
      "y": 16,
      "z": 3,
      "name": "Rock_Stone"
    },
    {
      "x": -13,
      "y": 17,
      "z": 3,
      "name": "Rock_Stone"
    },
    {
      "x": -13,
      "y": 18,
      "z": 3,
      "name": "Rock_Stone"
    },
    {
      "x": -13,
      "y": 19,
      "z": 3,
      "name": "Rock_Stone"
    },
    {
      "x": -13,
      "y": 20,
      "z": 3,
      "name": "Rock_Stone"
    },
    {
      "x": -13,
      "y": 21,
      "z": 3,
      "name": "Rock_Stone"
    },
    {
      "x": -13,
      "y": 22,
      "z": 3,
      "name": "Rock_Stone"
    },
    {
      "x": -13,
      "y": 23,
      "z": 3,
      "name": "Rock_Stone"
    },
    {
      "x": -13,
      "y": 24,
      "z": 3,
      "name": "Rock_Stone"
    },
    {
      "x": -13,
      "y": 25,
      "z": 3,
      "name": "Rock_Stone"
    },
    {
      "x": -13,
      "y": 26,
      "z": 3,
      "name": "Rock_Stone"
    },
    {
      "x": -13,
      "y": 27,
      "z": 3,
      "name": "Rock_Stone"
    },
    {
      "x": -13,
      "y": 28,
      "z": 3,
      "name": "Rock_Stone"
    },
    {
      "x": -13,
      "y": 29,
      "z": 3,
      "name": "Rock_Stone"
    },
    {
      "x": -13,
      "y": 30,
      "z": 3,
      "name": "Rock_Stone"
    },
    {
      "x": -13,
      "y": 31,
      "z": 3,
      "name": "Rock_Stone"
    },
    {
      "x": -13,
      "y": 32,
      "z": 3,
      "name": "Rock_Stone"
    },
    {
      "x": -13,
      "y": 33,
      "z": 3,
      "name": "Rock_Stone"
    },
    {
      "x": -13,
      "y": 34,
      "z": 3,
      "name": "Rock_Stone"
    },
    {
      "x": -13,
      "y": 35,
      "z": 3,
      "name": "Rock_Stone"
    },
    {
      "x": -13,
      "y": 36,
      "z": 3,
      "name": "Rock_Stone"
    },
    {
      "x": -13,
      "y": 37,
      "z": 3,
      "name": "Rock_Stone"
    },
    {
      "x": -13,
      "y": 38,
      "z": 3,
      "name": "Rock_Stone"
    },
    {
      "x": -13,
      "y": 39,
      "z": 3,
      "name": "Rock_Stone"
    },
    {
      "x": -13,
      "y": 40,
      "z": 3,
      "name": "Rock_Stone"
    },
    {
      "x": -13,
      "y": 41,
      "z": 3,
      "name": "Rock_Stone"
    },
    {
      "x": -13,
      "y": 42,
      "z": 3,
      "name": "Rock_Stone"
    },
    {
      "x": -13,
      "y": 43,
      "z": 3,
      "name": "Rock_Stone"
    },
    {
      "x": -13,
      "y": 44,
      "z": 3,
      "name": "Rock_Stone"
    },
    {
      "x": -13,
      "y": 45,
      "z": 3,
      "name": "Rock_Stone"
    },
    {
      "x": -13,
      "y": 46,
      "z": 3,
      "name": "Rock_Stone"
    },
    {
      "x": -13,
      "y": 47,
      "z": 3,
      "name": "Rock_Stone"
    },
    {
      "x": -13,
      "y": 48,
      "z": 3,
      "name": "Rock_Stone"
    },
    {
      "x": -13,
      "y": 49,
      "z": 3,
      "name": "Rock_Stone"
    },
    {
      "x": -13,
      "y": 50,
      "z": 3,
      "name": "Rock_Stone"
    },
    {
      "x": -13,
      "y": 51,
      "z": 3,
      "name": "Rock_Stone"
    },
    {
      "x": -13,
      "y": 4,
      "z": 4,
      "name": "Rock_Stone"
    },
    {
      "x": -13,
      "y": 5,
      "z": 4,
      "name": "Rock_Stone"
    },
    {
      "x": -13,
      "y": 6,
      "z": 4,
      "name": "Rock_Stone"
    },
    {
      "x": -13,
      "y": 7,
      "z": 4,
      "name": "Rock_Stone"
    },
    {
      "x": -13,
      "y": 8,
      "z": 4,
      "name": "Rock_Stone"
    },
    {
      "x": -13,
      "y": 9,
      "z": 4,
      "name": "Rock_Stone"
    },
    {
      "x": -13,
      "y": 10,
      "z": 4,
      "name": "Rock_Stone"
    },
    {
      "x": -13,
      "y": 11,
      "z": 4,
      "name": "Rock_Stone"
    },
    {
      "x": -13,
      "y": 12,
      "z": 4,
      "name": "Rock_Stone"
    },
    {
      "x": -13,
      "y": 13,
      "z": 4,
      "name": "Rock_Stone"
    },
    {
      "x": -13,
      "y": 14,
      "z": 4,
      "name": "Rock_Stone"
    },
    {
      "x": -13,
      "y": 15,
      "z": 4,
      "name": "Rock_Stone"
    },
    {
      "x": -13,
      "y": 16,
      "z": 4,
      "name": "Rock_Stone"
    },
    {
      "x": -13,
      "y": 17,
      "z": 4,
      "name": "Rock_Stone"
    },
    {
      "x": -13,
      "y": 18,
      "z": 4,
      "name": "Rock_Stone"
    },
    {
      "x": -13,
      "y": 19,
      "z": 4,
      "name": "Rock_Stone"
    },
    {
      "x": -13,
      "y": 20,
      "z": 4,
      "name": "Rock_Stone"
    },
    {
      "x": -13,
      "y": 21,
      "z": 4,
      "name": "Rock_Stone"
    },
    {
      "x": -13,
      "y": 22,
      "z": 4,
      "name": "Rock_Stone"
    },
    {
      "x": -13,
      "y": 23,
      "z": 4,
      "name": "Rock_Stone"
    },
    {
      "x": -13,
      "y": 24,
      "z": 4,
      "name": "Rock_Stone"
    },
    {
      "x": -13,
      "y": 25,
      "z": 4,
      "name": "Rock_Stone"
    },
    {
      "x": -13,
      "y": 26,
      "z": 4,
      "name": "Rock_Stone"
    },
    {
      "x": -13,
      "y": 27,
      "z": 4,
      "name": "Rock_Stone"
    },
    {
      "x": -13,
      "y": 28,
      "z": 4,
      "name": "Rock_Stone"
    },
    {
      "x": -13,
      "y": 29,
      "z": 4,
      "name": "Rock_Stone"
    },
    {
      "x": -13,
      "y": 30,
      "z": 4,
      "name": "Rock_Stone"
    },
    {
      "x": -13,
      "y": 31,
      "z": 4,
      "name": "Rock_Stone"
    },
    {
      "x": -13,
      "y": 32,
      "z": 4,
      "name": "Rock_Stone"
    },
    {
      "x": -13,
      "y": 33,
      "z": 4,
      "name": "Rock_Stone"
    },
    {
      "x": -13,
      "y": 34,
      "z": 4,
      "name": "Rock_Stone"
    },
    {
      "x": -13,
      "y": 35,
      "z": 4,
      "name": "Rock_Stone"
    },
    {
      "x": -13,
      "y": 36,
      "z": 4,
      "name": "Rock_Stone"
    },
    {
      "x": -13,
      "y": 37,
      "z": 4,
      "name": "Rock_Stone"
    },
    {
      "x": -13,
      "y": 38,
      "z": 4,
      "name": "Rock_Stone"
    },
    {
      "x": -13,
      "y": 39,
      "z": 4,
      "name": "Rock_Stone"
    },
    {
      "x": -13,
      "y": 40,
      "z": 4,
      "name": "Rock_Stone"
    },
    {
      "x": -13,
      "y": 41,
      "z": 4,
      "name": "Rock_Stone"
    },
    {
      "x": -13,
      "y": 42,
      "z": 4,
      "name": "Rock_Stone"
    },
    {
      "x": -13,
      "y": 43,
      "z": 4,
      "name": "Rock_Stone"
    },
    {
      "x": -13,
      "y": 44,
      "z": 4,
      "name": "Rock_Stone"
    },
    {
      "x": -13,
      "y": 45,
      "z": 4,
      "name": "Rock_Stone"
    },
    {
      "x": -13,
      "y": 46,
      "z": 4,
      "name": "Rock_Stone"
    },
    {
      "x": -13,
      "y": 47,
      "z": 4,
      "name": "Rock_Stone"
    },
    {
      "x": -13,
      "y": 48,
      "z": 4,
      "name": "Rock_Stone"
    },
    {
      "x": -13,
      "y": 49,
      "z": 4,
      "name": "Rock_Stone"
    },
    {
      "x": -13,
      "y": 50,
      "z": 4,
      "name": "Rock_Stone"
    },
    {
      "x": -13,
      "y": 51,
      "z": 4,
      "name": "Rock_Stone"
    },
    {
      "x": -13,
      "y": 7,
      "z": 5,
      "name": "Rock_Stone"
    },
    {
      "x": -13,
      "y": 8,
      "z": 5,
      "name": "Rock_Stone"
    },
    {
      "x": -13,
      "y": 9,
      "z": 5,
      "name": "Rock_Stone"
    },
    {
      "x": -13,
      "y": 10,
      "z": 5,
      "name": "Rock_Stone"
    },
    {
      "x": -13,
      "y": 11,
      "z": 5,
      "name": "Rock_Stone"
    },
    {
      "x": -13,
      "y": 12,
      "z": 5,
      "name": "Rock_Stone"
    },
    {
      "x": -13,
      "y": 13,
      "z": 5,
      "name": "Rock_Stone"
    },
    {
      "x": -13,
      "y": 14,
      "z": 5,
      "name": "Rock_Stone"
    },
    {
      "x": -13,
      "y": 15,
      "z": 5,
      "name": "Rock_Stone"
    },
    {
      "x": -13,
      "y": 16,
      "z": 5,
      "name": "Rock_Stone"
    },
    {
      "x": -13,
      "y": 17,
      "z": 5,
      "name": "Rock_Stone"
    },
    {
      "x": -13,
      "y": 18,
      "z": 5,
      "name": "Rock_Stone"
    },
    {
      "x": -13,
      "y": 19,
      "z": 5,
      "name": "Rock_Stone"
    },
    {
      "x": -13,
      "y": 20,
      "z": 5,
      "name": "Rock_Stone"
    },
    {
      "x": -13,
      "y": 21,
      "z": 5,
      "name": "Rock_Stone"
    },
    {
      "x": -13,
      "y": 22,
      "z": 5,
      "name": "Rock_Stone"
    },
    {
      "x": -13,
      "y": 23,
      "z": 5,
      "name": "Rock_Stone"
    },
    {
      "x": -13,
      "y": 24,
      "z": 5,
      "name": "Rock_Stone"
    },
    {
      "x": -13,
      "y": 25,
      "z": 5,
      "name": "Rock_Stone"
    },
    {
      "x": -13,
      "y": 26,
      "z": 5,
      "name": "Rock_Stone"
    },
    {
      "x": -13,
      "y": 27,
      "z": 5,
      "name": "Rock_Stone"
    },
    {
      "x": -13,
      "y": 28,
      "z": 5,
      "name": "Rock_Stone"
    },
    {
      "x": -13,
      "y": 29,
      "z": 5,
      "name": "Rock_Stone"
    },
    {
      "x": -13,
      "y": 30,
      "z": 5,
      "name": "Rock_Stone"
    },
    {
      "x": -13,
      "y": 31,
      "z": 5,
      "name": "Rock_Stone"
    },
    {
      "x": -13,
      "y": 32,
      "z": 5,
      "name": "Rock_Stone"
    },
    {
      "x": -13,
      "y": 33,
      "z": 5,
      "name": "Rock_Stone"
    },
    {
      "x": -13,
      "y": 34,
      "z": 5,
      "name": "Rock_Stone"
    },
    {
      "x": -13,
      "y": 35,
      "z": 5,
      "name": "Rock_Stone"
    },
    {
      "x": -13,
      "y": 36,
      "z": 5,
      "name": "Rock_Stone"
    },
    {
      "x": -13,
      "y": 37,
      "z": 5,
      "name": "Rock_Stone"
    },
    {
      "x": -13,
      "y": 38,
      "z": 5,
      "name": "Rock_Stone"
    },
    {
      "x": -13,
      "y": 39,
      "z": 5,
      "name": "Rock_Stone"
    },
    {
      "x": -13,
      "y": 40,
      "z": 5,
      "name": "Rock_Stone"
    },
    {
      "x": -13,
      "y": 41,
      "z": 5,
      "name": "Rock_Stone"
    },
    {
      "x": -13,
      "y": 42,
      "z": 5,
      "name": "Rock_Stone"
    },
    {
      "x": -13,
      "y": 43,
      "z": 5,
      "name": "Rock_Stone"
    },
    {
      "x": -13,
      "y": 44,
      "z": 5,
      "name": "Rock_Stone"
    },
    {
      "x": -13,
      "y": 45,
      "z": 5,
      "name": "Rock_Stone"
    },
    {
      "x": -13,
      "y": 46,
      "z": 5,
      "name": "Rock_Stone"
    },
    {
      "x": -13,
      "y": 47,
      "z": 5,
      "name": "Rock_Stone"
    },
    {
      "x": -13,
      "y": 48,
      "z": 5,
      "name": "Rock_Stone"
    },
    {
      "x": -13,
      "y": 49,
      "z": 5,
      "name": "Rock_Stone"
    },
    {
      "x": -13,
      "y": 50,
      "z": 5,
      "name": "Rock_Stone"
    },
    {
      "x": -13,
      "y": 51,
      "z": 5,
      "name": "Rock_Stone"
    },
    {
      "x": -13,
      "y": 10,
      "z": 6,
      "name": "Rock_Stone"
    },
    {
      "x": -13,
      "y": 11,
      "z": 6,
      "name": "Rock_Stone"
    },
    {
      "x": -13,
      "y": 12,
      "z": 6,
      "name": "Rock_Stone"
    },
    {
      "x": -13,
      "y": 13,
      "z": 6,
      "name": "Rock_Stone"
    },
    {
      "x": -13,
      "y": 14,
      "z": 6,
      "name": "Rock_Stone"
    },
    {
      "x": -13,
      "y": 15,
      "z": 6,
      "name": "Rock_Stone"
    },
    {
      "x": -13,
      "y": 16,
      "z": 6,
      "name": "Rock_Stone"
    },
    {
      "x": -13,
      "y": 17,
      "z": 6,
      "name": "Rock_Stone"
    },
    {
      "x": -13,
      "y": 18,
      "z": 6,
      "name": "Rock_Stone"
    },
    {
      "x": -13,
      "y": 19,
      "z": 6,
      "name": "Rock_Stone"
    },
    {
      "x": -13,
      "y": 20,
      "z": 6,
      "name": "Rock_Stone"
    },
    {
      "x": -13,
      "y": 21,
      "z": 6,
      "name": "Rock_Stone"
    },
    {
      "x": -13,
      "y": 22,
      "z": 6,
      "name": "Rock_Stone"
    },
    {
      "x": -13,
      "y": 29,
      "z": 6,
      "name": "Rock_Stone"
    },
    {
      "x": -13,
      "y": 30,
      "z": 6,
      "name": "Rock_Stone"
    },
    {
      "x": -13,
      "y": 31,
      "z": 6,
      "name": "Rock_Stone"
    },
    {
      "x": -13,
      "y": 32,
      "z": 6,
      "name": "Rock_Stone"
    },
    {
      "x": -13,
      "y": 33,
      "z": 6,
      "name": "Rock_Stone"
    },
    {
      "x": -13,
      "y": 34,
      "z": 6,
      "name": "Rock_Stone"
    },
    {
      "x": -13,
      "y": 35,
      "z": 6,
      "name": "Rock_Stone"
    },
    {
      "x": -13,
      "y": 36,
      "z": 6,
      "name": "Rock_Stone"
    },
    {
      "x": -13,
      "y": 37,
      "z": 6,
      "name": "Rock_Stone"
    },
    {
      "x": -13,
      "y": 38,
      "z": 6,
      "name": "Rock_Stone"
    },
    {
      "x": -13,
      "y": 39,
      "z": 6,
      "name": "Rock_Stone"
    },
    {
      "x": -13,
      "y": 40,
      "z": 6,
      "name": "Rock_Stone"
    },
    {
      "x": -13,
      "y": 41,
      "z": 6,
      "name": "Rock_Stone"
    },
    {
      "x": -13,
      "y": 42,
      "z": 6,
      "name": "Rock_Stone"
    },
    {
      "x": -13,
      "y": 43,
      "z": 6,
      "name": "Rock_Stone"
    },
    {
      "x": -13,
      "y": 44,
      "z": 6,
      "name": "Rock_Stone"
    },
    {
      "x": -13,
      "y": 45,
      "z": 6,
      "name": "Rock_Stone"
    },
    {
      "x": -13,
      "y": 46,
      "z": 6,
      "name": "Rock_Stone"
    },
    {
      "x": -13,
      "y": 47,
      "z": 6,
      "name": "Rock_Stone"
    },
    {
      "x": -12,
      "y": 6,
      "z": -8,
      "name": "Rock_Stone"
    },
    {
      "x": -12,
      "y": 7,
      "z": -8,
      "name": "Rock_Stone"
    },
    {
      "x": -12,
      "y": 8,
      "z": -8,
      "name": "Rock_Stone"
    },
    {
      "x": -12,
      "y": 9,
      "z": -8,
      "name": "Rock_Stone"
    },
    {
      "x": -12,
      "y": 10,
      "z": -8,
      "name": "Rock_Stone"
    },
    {
      "x": -12,
      "y": 11,
      "z": -8,
      "name": "Rock_Stone"
    },
    {
      "x": -12,
      "y": 12,
      "z": -8,
      "name": "Rock_Stone"
    },
    {
      "x": -12,
      "y": 13,
      "z": -8,
      "name": "Rock_Stone"
    },
    {
      "x": -12,
      "y": 14,
      "z": -8,
      "name": "Rock_Stone"
    },
    {
      "x": -12,
      "y": 15,
      "z": -8,
      "name": "Rock_Stone"
    },
    {
      "x": -12,
      "y": 16,
      "z": -8,
      "name": "Rock_Stone"
    },
    {
      "x": -12,
      "y": 17,
      "z": -8,
      "name": "Rock_Stone"
    },
    {
      "x": -12,
      "y": 18,
      "z": -8,
      "name": "Rock_Stone"
    },
    {
      "x": -12,
      "y": 19,
      "z": -8,
      "name": "Rock_Stone"
    },
    {
      "x": -12,
      "y": 20,
      "z": -8,
      "name": "Rock_Stone"
    },
    {
      "x": -12,
      "y": 21,
      "z": -8,
      "name": "Soil_Dirt_Cold"
    },
    {
      "x": -12,
      "y": 22,
      "z": -8,
      "name": "Soil_Grass_Cold"
    },
    {
      "x": -12,
      "y": 3,
      "z": -7,
      "name": "Rock_Stone"
    },
    {
      "x": -12,
      "y": 4,
      "z": -7,
      "name": "Rock_Stone"
    },
    {
      "x": -12,
      "y": 5,
      "z": -7,
      "name": "Rock_Stone"
    },
    {
      "x": -12,
      "y": 6,
      "z": -7,
      "name": "Rock_Stone"
    },
    {
      "x": -12,
      "y": 7,
      "z": -7,
      "name": "Rock_Stone"
    },
    {
      "x": -12,
      "y": 8,
      "z": -7,
      "name": "Rock_Stone"
    },
    {
      "x": -12,
      "y": 9,
      "z": -7,
      "name": "Rock_Stone"
    },
    {
      "x": -12,
      "y": 10,
      "z": -7,
      "name": "Rock_Stone"
    },
    {
      "x": -12,
      "y": 11,
      "z": -7,
      "name": "Rock_Stone"
    },
    {
      "x": -12,
      "y": 12,
      "z": -7,
      "name": "Rock_Stone"
    },
    {
      "x": -12,
      "y": 13,
      "z": -7,
      "name": "Rock_Stone"
    },
    {
      "x": -12,
      "y": 14,
      "z": -7,
      "name": "Rock_Stone"
    },
    {
      "x": -12,
      "y": 15,
      "z": -7,
      "name": "Rock_Stone"
    },
    {
      "x": -12,
      "y": 16,
      "z": -7,
      "name": "Rock_Stone"
    },
    {
      "x": -12,
      "y": 17,
      "z": -7,
      "name": "Rock_Stone"
    },
    {
      "x": -12,
      "y": 18,
      "z": -7,
      "name": "Rock_Stone"
    },
    {
      "x": -12,
      "y": 19,
      "z": -7,
      "name": "Rock_Stone"
    },
    {
      "x": -12,
      "y": 20,
      "z": -7,
      "name": "Rock_Stone"
    },
    {
      "x": -12,
      "y": 21,
      "z": -7,
      "name": "Rock_Stone"
    },
    {
      "x": -12,
      "y": 22,
      "z": -7,
      "name": "Soil_Dirt_Cold"
    },
    {
      "x": -12,
      "y": 23,
      "z": -7,
      "name": "Soil_Grass_Cold"
    },
    {
      "x": -12,
      "y": 2,
      "z": -6,
      "name": "Rock_Stone"
    },
    {
      "x": -12,
      "y": 3,
      "z": -6,
      "name": "Rock_Stone"
    },
    {
      "x": -12,
      "y": 4,
      "z": -6,
      "name": "Rock_Stone"
    },
    {
      "x": -12,
      "y": 5,
      "z": -6,
      "name": "Rock_Stone"
    },
    {
      "x": -12,
      "y": 6,
      "z": -6,
      "name": "Rock_Stone"
    },
    {
      "x": -12,
      "y": 7,
      "z": -6,
      "name": "Rock_Stone"
    },
    {
      "x": -12,
      "y": 8,
      "z": -6,
      "name": "Rock_Stone"
    },
    {
      "x": -12,
      "y": 9,
      "z": -6,
      "name": "Rock_Stone"
    },
    {
      "x": -12,
      "y": 10,
      "z": -6,
      "name": "Rock_Stone"
    },
    {
      "x": -12,
      "y": 11,
      "z": -6,
      "name": "Rock_Stone"
    },
    {
      "x": -12,
      "y": 12,
      "z": -6,
      "name": "Rock_Stone"
    },
    {
      "x": -12,
      "y": 13,
      "z": -6,
      "name": "Rock_Stone"
    },
    {
      "x": -12,
      "y": 14,
      "z": -6,
      "name": "Rock_Stone"
    },
    {
      "x": -12,
      "y": 15,
      "z": -6,
      "name": "Rock_Stone"
    },
    {
      "x": -12,
      "y": 16,
      "z": -6,
      "name": "Rock_Stone"
    },
    {
      "x": -12,
      "y": 17,
      "z": -6,
      "name": "Rock_Stone"
    },
    {
      "x": -12,
      "y": 18,
      "z": -6,
      "name": "Rock_Stone"
    },
    {
      "x": -12,
      "y": 19,
      "z": -6,
      "name": "Rock_Stone"
    },
    {
      "x": -12,
      "y": 20,
      "z": -6,
      "name": "Rock_Stone"
    },
    {
      "x": -12,
      "y": 21,
      "z": -6,
      "name": "Rock_Stone"
    },
    {
      "x": -12,
      "y": 22,
      "z": -6,
      "name": "Soil_Dirt_Cold"
    },
    {
      "x": -12,
      "y": 23,
      "z": -6,
      "name": "Soil_Dirt_Cold"
    },
    {
      "x": -12,
      "y": 24,
      "z": -6,
      "name": "Soil_Grass_Cold"
    },
    {
      "x": -12,
      "y": 2,
      "z": -5,
      "name": "Rock_Stone"
    },
    {
      "x": -12,
      "y": 3,
      "z": -5,
      "name": "Rock_Stone"
    },
    {
      "x": -12,
      "y": 4,
      "z": -5,
      "name": "Rock_Stone"
    },
    {
      "x": -12,
      "y": 5,
      "z": -5,
      "name": "Rock_Stone"
    },
    {
      "x": -12,
      "y": 6,
      "z": -5,
      "name": "Rock_Stone"
    },
    {
      "x": -12,
      "y": 7,
      "z": -5,
      "name": "Rock_Stone"
    },
    {
      "x": -12,
      "y": 8,
      "z": -5,
      "name": "Rock_Stone"
    },
    {
      "x": -12,
      "y": 9,
      "z": -5,
      "name": "Rock_Stone"
    },
    {
      "x": -12,
      "y": 10,
      "z": -5,
      "name": "Rock_Stone"
    },
    {
      "x": -12,
      "y": 11,
      "z": -5,
      "name": "Rock_Stone"
    },
    {
      "x": -12,
      "y": 12,
      "z": -5,
      "name": "Rock_Stone"
    },
    {
      "x": -12,
      "y": 13,
      "z": -5,
      "name": "Rock_Stone"
    },
    {
      "x": -12,
      "y": 14,
      "z": -5,
      "name": "Rock_Stone"
    },
    {
      "x": -12,
      "y": 15,
      "z": -5,
      "name": "Rock_Stone"
    },
    {
      "x": -12,
      "y": 16,
      "z": -5,
      "name": "Rock_Stone"
    },
    {
      "x": -12,
      "y": 17,
      "z": -5,
      "name": "Rock_Stone"
    },
    {
      "x": -12,
      "y": 18,
      "z": -5,
      "name": "Rock_Stone"
    },
    {
      "x": -12,
      "y": 19,
      "z": -5,
      "name": "Rock_Stone"
    },
    {
      "x": -12,
      "y": 20,
      "z": -5,
      "name": "Rock_Stone"
    },
    {
      "x": -12,
      "y": 21,
      "z": -5,
      "name": "Rock_Stone"
    },
    {
      "x": -12,
      "y": 22,
      "z": -5,
      "name": "Soil_Dirt_Cold"
    },
    {
      "x": -12,
      "y": 23,
      "z": -5,
      "name": "Soil_Dirt_Cold"
    },
    {
      "x": -12,
      "y": 24,
      "z": -5,
      "name": "Soil_Grass_Cold"
    },
    {
      "x": -12,
      "y": 2,
      "z": -4,
      "name": "Rock_Stone"
    },
    {
      "x": -12,
      "y": 3,
      "z": -4,
      "name": "Rock_Stone"
    },
    {
      "x": -12,
      "y": 4,
      "z": -4,
      "name": "Rock_Stone"
    },
    {
      "x": -12,
      "y": 5,
      "z": -4,
      "name": "Rock_Stone"
    },
    {
      "x": -12,
      "y": 6,
      "z": -4,
      "name": "Rock_Stone"
    },
    {
      "x": -12,
      "y": 7,
      "z": -4,
      "name": "Rock_Stone"
    },
    {
      "x": -12,
      "y": 8,
      "z": -4,
      "name": "Rock_Stone"
    },
    {
      "x": -12,
      "y": 9,
      "z": -4,
      "name": "Rock_Stone"
    },
    {
      "x": -12,
      "y": 10,
      "z": -4,
      "name": "Rock_Stone"
    },
    {
      "x": -12,
      "y": 11,
      "z": -4,
      "name": "Rock_Stone"
    },
    {
      "x": -12,
      "y": 12,
      "z": -4,
      "name": "Rock_Stone"
    },
    {
      "x": -12,
      "y": 13,
      "z": -4,
      "name": "Rock_Stone"
    },
    {
      "x": -12,
      "y": 14,
      "z": -4,
      "name": "Rock_Stone"
    },
    {
      "x": -12,
      "y": 15,
      "z": -4,
      "name": "Rock_Stone"
    },
    {
      "x": -12,
      "y": 16,
      "z": -4,
      "name": "Rock_Stone"
    },
    {
      "x": -12,
      "y": 17,
      "z": -4,
      "name": "Rock_Stone"
    },
    {
      "x": -12,
      "y": 18,
      "z": -4,
      "name": "Rock_Stone"
    },
    {
      "x": -12,
      "y": 19,
      "z": -4,
      "name": "Rock_Stone"
    },
    {
      "x": -12,
      "y": 20,
      "z": -4,
      "name": "Rock_Stone"
    },
    {
      "x": -12,
      "y": 21,
      "z": -4,
      "name": "Rock_Stone"
    },
    {
      "x": -12,
      "y": 22,
      "z": -4,
      "name": "Rock_Stone"
    },
    {
      "x": -12,
      "y": 23,
      "z": -4,
      "name": "Rock_Stone"
    },
    {
      "x": -12,
      "y": 24,
      "z": -4,
      "name": "Rock_Stone"
    },
    {
      "x": -12,
      "y": 25,
      "z": -4,
      "name": "Rock_Stone"
    },
    {
      "x": -12,
      "y": 26,
      "z": -4,
      "name": "Rock_Stone"
    },
    {
      "x": -12,
      "y": 27,
      "z": -4,
      "name": "Rock_Stone"
    },
    {
      "x": -12,
      "y": 28,
      "z": -4,
      "name": "Rock_Stone"
    },
    {
      "x": -12,
      "y": 29,
      "z": -4,
      "name": "Rock_Stone"
    },
    {
      "x": -12,
      "y": 30,
      "z": -4,
      "name": "Rock_Stone"
    },
    {
      "x": -12,
      "y": 31,
      "z": -4,
      "name": "Rock_Stone"
    },
    {
      "x": -12,
      "y": 32,
      "z": -4,
      "name": "Rock_Stone"
    },
    {
      "x": -12,
      "y": 33,
      "z": -4,
      "name": "Rock_Stone"
    },
    {
      "x": -12,
      "y": 34,
      "z": -4,
      "name": "Rock_Stone"
    },
    {
      "x": -12,
      "y": 35,
      "z": -4,
      "name": "Rock_Stone"
    },
    {
      "x": -12,
      "y": 36,
      "z": -4,
      "name": "Rock_Stone"
    },
    {
      "x": -12,
      "y": 37,
      "z": -4,
      "name": "Rock_Stone"
    },
    {
      "x": -12,
      "y": 38,
      "z": -4,
      "name": "Rock_Stone"
    },
    {
      "x": -12,
      "y": 39,
      "z": -4,
      "name": "Rock_Stone"
    },
    {
      "x": -12,
      "y": 40,
      "z": -4,
      "name": "Rock_Stone"
    },
    {
      "x": -12,
      "y": 41,
      "z": -4,
      "name": "Rock_Stone"
    },
    {
      "x": -12,
      "y": 42,
      "z": -4,
      "name": "Rock_Stone"
    },
    {
      "x": -12,
      "y": 43,
      "z": -4,
      "name": "Rock_Stone"
    },
    {
      "x": -12,
      "y": 44,
      "z": -4,
      "name": "Rock_Stone"
    },
    {
      "x": -12,
      "y": 1,
      "z": -3,
      "name": "Rock_Stone"
    },
    {
      "x": -12,
      "y": 2,
      "z": -3,
      "name": "Rock_Stone"
    },
    {
      "x": -12,
      "y": 3,
      "z": -3,
      "name": "Rock_Stone"
    },
    {
      "x": -12,
      "y": 4,
      "z": -3,
      "name": "Rock_Stone"
    },
    {
      "x": -12,
      "y": 5,
      "z": -3,
      "name": "Rock_Stone"
    },
    {
      "x": -12,
      "y": 6,
      "z": -3,
      "name": "Rock_Stone"
    },
    {
      "x": -12,
      "y": 7,
      "z": -3,
      "name": "Rock_Stone"
    },
    {
      "x": -12,
      "y": 8,
      "z": -3,
      "name": "Rock_Stone"
    },
    {
      "x": -12,
      "y": 9,
      "z": -3,
      "name": "Rock_Stone"
    },
    {
      "x": -12,
      "y": 10,
      "z": -3,
      "name": "Rock_Stone"
    },
    {
      "x": -12,
      "y": 11,
      "z": -3,
      "name": "Rock_Stone"
    },
    {
      "x": -12,
      "y": 12,
      "z": -3,
      "name": "Rock_Stone"
    },
    {
      "x": -12,
      "y": 13,
      "z": -3,
      "name": "Rock_Stone"
    },
    {
      "x": -12,
      "y": 14,
      "z": -3,
      "name": "Rock_Stone"
    },
    {
      "x": -12,
      "y": 15,
      "z": -3,
      "name": "Rock_Stone"
    },
    {
      "x": -12,
      "y": 16,
      "z": -3,
      "name": "Soil_Dirt_Cold"
    },
    {
      "x": -12,
      "y": 17,
      "z": -3,
      "name": "Rock_Stone"
    },
    {
      "x": -12,
      "y": 18,
      "z": -3,
      "name": "Rock_Stone"
    },
    {
      "x": -12,
      "y": 19,
      "z": -3,
      "name": "Rock_Stone"
    },
    {
      "x": -12,
      "y": 20,
      "z": -3,
      "name": "Rock_Stone"
    },
    {
      "x": -12,
      "y": 21,
      "z": -3,
      "name": "Rock_Stone"
    },
    {
      "x": -12,
      "y": 22,
      "z": -3,
      "name": "Rock_Stone"
    },
    {
      "x": -12,
      "y": 23,
      "z": -3,
      "name": "Rock_Stone"
    },
    {
      "x": -12,
      "y": 24,
      "z": -3,
      "name": "Rock_Stone"
    },
    {
      "x": -12,
      "y": 25,
      "z": -3,
      "name": "Rock_Stone"
    },
    {
      "x": -12,
      "y": 26,
      "z": -3,
      "name": "Rock_Stone"
    },
    {
      "x": -12,
      "y": 27,
      "z": -3,
      "name": "Rock_Stone"
    },
    {
      "x": -12,
      "y": 28,
      "z": -3,
      "name": "Rock_Stone"
    },
    {
      "x": -12,
      "y": 29,
      "z": -3,
      "name": "Rock_Stone"
    },
    {
      "x": -12,
      "y": 30,
      "z": -3,
      "name": "Rock_Stone"
    },
    {
      "x": -12,
      "y": 31,
      "z": -3,
      "name": "Rock_Stone"
    },
    {
      "x": -12,
      "y": 32,
      "z": -3,
      "name": "Rock_Stone"
    },
    {
      "x": -12,
      "y": 33,
      "z": -3,
      "name": "Rock_Stone"
    },
    {
      "x": -12,
      "y": 34,
      "z": -3,
      "name": "Rock_Stone"
    },
    {
      "x": -12,
      "y": 35,
      "z": -3,
      "name": "Rock_Stone"
    },
    {
      "x": -12,
      "y": 36,
      "z": -3,
      "name": "Rock_Stone"
    },
    {
      "x": -12,
      "y": 37,
      "z": -3,
      "name": "Rock_Stone"
    },
    {
      "x": -12,
      "y": 38,
      "z": -3,
      "name": "Rock_Stone"
    },
    {
      "x": -12,
      "y": 39,
      "z": -3,
      "name": "Rock_Stone"
    },
    {
      "x": -12,
      "y": 40,
      "z": -3,
      "name": "Rock_Stone"
    },
    {
      "x": -12,
      "y": 41,
      "z": -3,
      "name": "Rock_Stone"
    },
    {
      "x": -12,
      "y": 42,
      "z": -3,
      "name": "Rock_Stone"
    },
    {
      "x": -12,
      "y": 43,
      "z": -3,
      "name": "Rock_Stone"
    },
    {
      "x": -12,
      "y": 44,
      "z": -3,
      "name": "Rock_Stone"
    },
    {
      "x": -12,
      "y": 45,
      "z": -3,
      "name": "Rock_Stone"
    },
    {
      "x": -12,
      "y": 46,
      "z": -3,
      "name": "Rock_Stone"
    },
    {
      "x": -12,
      "y": 47,
      "z": -3,
      "name": "Rock_Stone"
    },
    {
      "x": -12,
      "y": 48,
      "z": -3,
      "name": "Soil_Dirt_Cold"
    },
    {
      "x": -12,
      "y": 49,
      "z": -3,
      "name": "Soil_Dirt_Cold"
    },
    {
      "x": -12,
      "y": 50,
      "z": -3,
      "name": "Soil_Dirt_Cold"
    },
    {
      "x": -12,
      "y": 51,
      "z": -3,
      "name": "Soil_Dirt_Cold"
    },
    {
      "x": -12,
      "y": 52,
      "z": -3,
      "name": "Soil_Grass_Cold"
    },
    {
      "x": -12,
      "y": 0,
      "z": -2,
      "name": "Rock_Stone"
    },
    {
      "x": -12,
      "y": 1,
      "z": -2,
      "name": "Rock_Stone"
    },
    {
      "x": -12,
      "y": 2,
      "z": -2,
      "name": "Rock_Stone"
    },
    {
      "x": -12,
      "y": 3,
      "z": -2,
      "name": "Rock_Stone"
    },
    {
      "x": -12,
      "y": 4,
      "z": -2,
      "name": "Rock_Stone"
    },
    {
      "x": -12,
      "y": 5,
      "z": -2,
      "name": "Rock_Stone"
    },
    {
      "x": -12,
      "y": 6,
      "z": -2,
      "name": "Rock_Stone"
    },
    {
      "x": -12,
      "y": 7,
      "z": -2,
      "name": "Rock_Stone"
    },
    {
      "x": -12,
      "y": 8,
      "z": -2,
      "name": "Rock_Stone"
    },
    {
      "x": -12,
      "y": 9,
      "z": -2,
      "name": "Rock_Stone"
    },
    {
      "x": -12,
      "y": 10,
      "z": -2,
      "name": "Rock_Stone"
    },
    {
      "x": -12,
      "y": 11,
      "z": -2,
      "name": "Rock_Stone"
    },
    {
      "x": -12,
      "y": 12,
      "z": -2,
      "name": "Rock_Stone"
    },
    {
      "x": -12,
      "y": 13,
      "z": -2,
      "name": "Rock_Stone"
    },
    {
      "x": -12,
      "y": 14,
      "z": -2,
      "name": "Rock_Stone"
    },
    {
      "x": -12,
      "y": 15,
      "z": -2,
      "name": "Rock_Stone"
    },
    {
      "x": -12,
      "y": 16,
      "z": -2,
      "name": "Rock_Stone"
    },
    {
      "x": -12,
      "y": 17,
      "z": -2,
      "name": "Rock_Stone"
    },
    {
      "x": -12,
      "y": 18,
      "z": -2,
      "name": "Rock_Stone"
    },
    {
      "x": -12,
      "y": 19,
      "z": -2,
      "name": "Rock_Stone"
    },
    {
      "x": -12,
      "y": 20,
      "z": -2,
      "name": "Rock_Stone"
    },
    {
      "x": -12,
      "y": 21,
      "z": -2,
      "name": "Rock_Stone"
    },
    {
      "x": -12,
      "y": 22,
      "z": -2,
      "name": "Rock_Stone"
    },
    {
      "x": -12,
      "y": 23,
      "z": -2,
      "name": "Rock_Stone"
    },
    {
      "x": -12,
      "y": 24,
      "z": -2,
      "name": "Rock_Stone"
    },
    {
      "x": -12,
      "y": 25,
      "z": -2,
      "name": "Rock_Stone"
    },
    {
      "x": -12,
      "y": 26,
      "z": -2,
      "name": "Rock_Stone"
    },
    {
      "x": -12,
      "y": 27,
      "z": -2,
      "name": "Rock_Stone"
    },
    {
      "x": -12,
      "y": 28,
      "z": -2,
      "name": "Rock_Stone"
    },
    {
      "x": -12,
      "y": 29,
      "z": -2,
      "name": "Rock_Stone"
    },
    {
      "x": -12,
      "y": 30,
      "z": -2,
      "name": "Rock_Stone"
    },
    {
      "x": -12,
      "y": 31,
      "z": -2,
      "name": "Rock_Stone"
    },
    {
      "x": -12,
      "y": 32,
      "z": -2,
      "name": "Rock_Stone"
    },
    {
      "x": -12,
      "y": 33,
      "z": -2,
      "name": "Rock_Stone"
    },
    {
      "x": -12,
      "y": 34,
      "z": -2,
      "name": "Rock_Stone"
    },
    {
      "x": -12,
      "y": 35,
      "z": -2,
      "name": "Rock_Stone"
    },
    {
      "x": -12,
      "y": 36,
      "z": -2,
      "name": "Rock_Stone"
    },
    {
      "x": -12,
      "y": 37,
      "z": -2,
      "name": "Rock_Stone"
    },
    {
      "x": -12,
      "y": 38,
      "z": -2,
      "name": "Rock_Stone"
    },
    {
      "x": -12,
      "y": 39,
      "z": -2,
      "name": "Rock_Stone"
    },
    {
      "x": -12,
      "y": 40,
      "z": -2,
      "name": "Rock_Stone"
    },
    {
      "x": -12,
      "y": 41,
      "z": -2,
      "name": "Rock_Stone"
    },
    {
      "x": -12,
      "y": 42,
      "z": -2,
      "name": "Rock_Stone"
    },
    {
      "x": -12,
      "y": 43,
      "z": -2,
      "name": "Rock_Stone"
    },
    {
      "x": -12,
      "y": 44,
      "z": -2,
      "name": "Rock_Stone"
    },
    {
      "x": -12,
      "y": 45,
      "z": -2,
      "name": "Rock_Stone"
    },
    {
      "x": -12,
      "y": 46,
      "z": -2,
      "name": "Rock_Stone"
    },
    {
      "x": -12,
      "y": 47,
      "z": -2,
      "name": "Rock_Stone"
    },
    {
      "x": -12,
      "y": 48,
      "z": -2,
      "name": "Rock_Stone"
    },
    {
      "x": -12,
      "y": 49,
      "z": -2,
      "name": "Rock_Stone"
    },
    {
      "x": -12,
      "y": 50,
      "z": -2,
      "name": "Rock_Stone"
    },
    {
      "x": -12,
      "y": 51,
      "z": -2,
      "name": "Rock_Stone"
    },
    {
      "x": -12,
      "y": 52,
      "z": -2,
      "name": "Rock_Stone"
    },
    {
      "x": -12,
      "y": 53,
      "z": -2,
      "name": "Soil_Dirt_Cold"
    },
    {
      "x": -12,
      "y": 54,
      "z": -2,
      "name": "Soil_Dirt_Cold"
    },
    {
      "x": -12,
      "y": 55,
      "z": -2,
      "name": "Soil_Dirt_Cold"
    },
    {
      "x": -12,
      "y": 0,
      "z": -1,
      "name": "Rock_Stone"
    },
    {
      "x": -12,
      "y": 1,
      "z": -1,
      "name": "Rock_Stone"
    },
    {
      "x": -12,
      "y": 2,
      "z": -1,
      "name": "Rock_Stone"
    },
    {
      "x": -12,
      "y": 3,
      "z": -1,
      "name": "Rock_Stone"
    },
    {
      "x": -12,
      "y": 4,
      "z": -1,
      "name": "Rock_Stone"
    },
    {
      "x": -12,
      "y": 5,
      "z": -1,
      "name": "Rock_Stone"
    },
    {
      "x": -12,
      "y": 6,
      "z": -1,
      "name": "Rock_Stone"
    },
    {
      "x": -12,
      "y": 7,
      "z": -1,
      "name": "Rock_Stone"
    },
    {
      "x": -12,
      "y": 8,
      "z": -1,
      "name": "Rock_Stone"
    },
    {
      "x": -12,
      "y": 9,
      "z": -1,
      "name": "Rock_Stone"
    },
    {
      "x": -12,
      "y": 10,
      "z": -1,
      "name": "Rock_Stone"
    },
    {
      "x": -12,
      "y": 11,
      "z": -1,
      "name": "Rock_Stone"
    },
    {
      "x": -12,
      "y": 12,
      "z": -1,
      "name": "Rock_Stone"
    },
    {
      "x": -12,
      "y": 13,
      "z": -1,
      "name": "Rock_Stone"
    },
    {
      "x": -12,
      "y": 14,
      "z": -1,
      "name": "Rock_Stone"
    },
    {
      "x": -12,
      "y": 15,
      "z": -1,
      "name": "Rock_Stone"
    },
    {
      "x": -12,
      "y": 16,
      "z": -1,
      "name": "Rock_Stone"
    },
    {
      "x": -12,
      "y": 17,
      "z": -1,
      "name": "Rock_Stone"
    },
    {
      "x": -12,
      "y": 18,
      "z": -1,
      "name": "Rock_Stone"
    },
    {
      "x": -12,
      "y": 19,
      "z": -1,
      "name": "Rock_Stone"
    },
    {
      "x": -12,
      "y": 20,
      "z": -1,
      "name": "Rock_Stone"
    },
    {
      "x": -12,
      "y": 21,
      "z": -1,
      "name": "Rock_Stone"
    },
    {
      "x": -12,
      "y": 22,
      "z": -1,
      "name": "Rock_Stone"
    },
    {
      "x": -12,
      "y": 23,
      "z": -1,
      "name": "Rock_Stone"
    },
    {
      "x": -12,
      "y": 24,
      "z": -1,
      "name": "Rock_Stone"
    },
    {
      "x": -12,
      "y": 25,
      "z": -1,
      "name": "Rock_Stone"
    },
    {
      "x": -12,
      "y": 26,
      "z": -1,
      "name": "Rock_Stone"
    },
    {
      "x": -12,
      "y": 27,
      "z": -1,
      "name": "Rock_Stone"
    },
    {
      "x": -12,
      "y": 28,
      "z": -1,
      "name": "Rock_Stone"
    },
    {
      "x": -12,
      "y": 29,
      "z": -1,
      "name": "Rock_Stone"
    },
    {
      "x": -12,
      "y": 30,
      "z": -1,
      "name": "Rock_Stone"
    },
    {
      "x": -12,
      "y": 31,
      "z": -1,
      "name": "Rock_Stone"
    },
    {
      "x": -12,
      "y": 32,
      "z": -1,
      "name": "Rock_Stone"
    },
    {
      "x": -12,
      "y": 33,
      "z": -1,
      "name": "Rock_Stone"
    },
    {
      "x": -12,
      "y": 34,
      "z": -1,
      "name": "Rock_Stone"
    },
    {
      "x": -12,
      "y": 35,
      "z": -1,
      "name": "Rock_Stone"
    },
    {
      "x": -12,
      "y": 36,
      "z": -1,
      "name": "Rock_Stone"
    },
    {
      "x": -12,
      "y": 37,
      "z": -1,
      "name": "Rock_Stone"
    },
    {
      "x": -12,
      "y": 38,
      "z": -1,
      "name": "Rock_Stone"
    },
    {
      "x": -12,
      "y": 39,
      "z": -1,
      "name": "Rock_Stone"
    },
    {
      "x": -12,
      "y": 40,
      "z": -1,
      "name": "Rock_Stone"
    },
    {
      "x": -12,
      "y": 41,
      "z": -1,
      "name": "Rock_Stone"
    },
    {
      "x": -12,
      "y": 42,
      "z": -1,
      "name": "Rock_Stone"
    },
    {
      "x": -12,
      "y": 43,
      "z": -1,
      "name": "Rock_Stone"
    },
    {
      "x": -12,
      "y": 44,
      "z": -1,
      "name": "Rock_Stone"
    },
    {
      "x": -12,
      "y": 45,
      "z": -1,
      "name": "Rock_Stone"
    },
    {
      "x": -12,
      "y": 46,
      "z": -1,
      "name": "Rock_Stone"
    },
    {
      "x": -12,
      "y": 47,
      "z": -1,
      "name": "Rock_Stone"
    },
    {
      "x": -12,
      "y": 48,
      "z": -1,
      "name": "Rock_Stone"
    },
    {
      "x": -12,
      "y": 49,
      "z": -1,
      "name": "Rock_Stone"
    },
    {
      "x": -12,
      "y": 50,
      "z": -1,
      "name": "Rock_Stone"
    },
    {
      "x": -12,
      "y": 51,
      "z": -1,
      "name": "Rock_Stone"
    },
    {
      "x": -12,
      "y": 52,
      "z": -1,
      "name": "Rock_Stone"
    },
    {
      "x": -12,
      "y": 53,
      "z": -1,
      "name": "Rock_Stone"
    },
    {
      "x": -12,
      "y": 54,
      "z": -1,
      "name": "Rock_Stone"
    },
    {
      "x": -12,
      "y": 55,
      "z": -1,
      "name": "Rock_Stone"
    },
    {
      "x": -12,
      "y": 56,
      "z": -1,
      "name": "Rock_Stone"
    },
    {
      "x": -12,
      "y": 57,
      "z": -1,
      "name": "Soil_Dirt_Cold"
    },
    {
      "x": -12,
      "y": 58,
      "z": -1,
      "name": "Soil_Grass_Cold"
    },
    {
      "x": -12,
      "y": 0,
      "z": 0,
      "name": "Rock_Stone"
    },
    {
      "x": -12,
      "y": 1,
      "z": 0,
      "name": "Rock_Stone"
    },
    {
      "x": -12,
      "y": 2,
      "z": 0,
      "name": "Rock_Stone"
    },
    {
      "x": -12,
      "y": 3,
      "z": 0,
      "name": "Rock_Stone"
    },
    {
      "x": -12,
      "y": 4,
      "z": 0,
      "name": "Rock_Stone"
    },
    {
      "x": -12,
      "y": 5,
      "z": 0,
      "name": "Rock_Stone"
    },
    {
      "x": -12,
      "y": 6,
      "z": 0,
      "name": "Rock_Stone"
    },
    {
      "x": -12,
      "y": 7,
      "z": 0,
      "name": "Rock_Stone"
    },
    {
      "x": -12,
      "y": 8,
      "z": 0,
      "name": "Rock_Stone"
    },
    {
      "x": -12,
      "y": 9,
      "z": 0,
      "name": "Rock_Stone"
    },
    {
      "x": -12,
      "y": 10,
      "z": 0,
      "name": "Rock_Stone"
    },
    {
      "x": -12,
      "y": 11,
      "z": 0,
      "name": "Rock_Stone"
    },
    {
      "x": -12,
      "y": 12,
      "z": 0,
      "name": "Rock_Stone"
    },
    {
      "x": -12,
      "y": 13,
      "z": 0,
      "name": "Rock_Stone"
    },
    {
      "x": -12,
      "y": 14,
      "z": 0,
      "name": "Rock_Stone"
    },
    {
      "x": -12,
      "y": 15,
      "z": 0,
      "name": "Rock_Stone"
    },
    {
      "x": -12,
      "y": 16,
      "z": 0,
      "name": "Rock_Stone"
    },
    {
      "x": -12,
      "y": 17,
      "z": 0,
      "name": "Rock_Stone"
    },
    {
      "x": -12,
      "y": 18,
      "z": 0,
      "name": "Rock_Stone"
    },
    {
      "x": -12,
      "y": 19,
      "z": 0,
      "name": "Rock_Stone"
    },
    {
      "x": -12,
      "y": 20,
      "z": 0,
      "name": "Rock_Stone"
    },
    {
      "x": -12,
      "y": 21,
      "z": 0,
      "name": "Rock_Stone"
    },
    {
      "x": -12,
      "y": 22,
      "z": 0,
      "name": "Rock_Stone"
    },
    {
      "x": -12,
      "y": 23,
      "z": 0,
      "name": "Rock_Stone"
    },
    {
      "x": -12,
      "y": 24,
      "z": 0,
      "name": "Rock_Stone"
    },
    {
      "x": -12,
      "y": 25,
      "z": 0,
      "name": "Rock_Stone"
    },
    {
      "x": -12,
      "y": 26,
      "z": 0,
      "name": "Rock_Stone"
    },
    {
      "x": -12,
      "y": 27,
      "z": 0,
      "name": "Rock_Stone"
    },
    {
      "x": -12,
      "y": 28,
      "z": 0,
      "name": "Rock_Stone"
    },
    {
      "x": -12,
      "y": 29,
      "z": 0,
      "name": "Rock_Stone"
    },
    {
      "x": -12,
      "y": 30,
      "z": 0,
      "name": "Rock_Stone"
    },
    {
      "x": -12,
      "y": 31,
      "z": 0,
      "name": "Rock_Stone"
    },
    {
      "x": -12,
      "y": 32,
      "z": 0,
      "name": "Rock_Stone"
    },
    {
      "x": -12,
      "y": 33,
      "z": 0,
      "name": "Rock_Stone"
    },
    {
      "x": -12,
      "y": 34,
      "z": 0,
      "name": "Rock_Stone"
    },
    {
      "x": -12,
      "y": 35,
      "z": 0,
      "name": "Rock_Stone"
    },
    {
      "x": -12,
      "y": 36,
      "z": 0,
      "name": "Rock_Stone"
    },
    {
      "x": -12,
      "y": 37,
      "z": 0,
      "name": "Rock_Stone"
    },
    {
      "x": -12,
      "y": 38,
      "z": 0,
      "name": "Rock_Stone"
    },
    {
      "x": -12,
      "y": 39,
      "z": 0,
      "name": "Rock_Stone"
    },
    {
      "x": -12,
      "y": 40,
      "z": 0,
      "name": "Rock_Stone"
    },
    {
      "x": -12,
      "y": 41,
      "z": 0,
      "name": "Rock_Stone"
    },
    {
      "x": -12,
      "y": 42,
      "z": 0,
      "name": "Rock_Stone"
    },
    {
      "x": -12,
      "y": 43,
      "z": 0,
      "name": "Rock_Stone"
    },
    {
      "x": -12,
      "y": 44,
      "z": 0,
      "name": "Rock_Stone"
    },
    {
      "x": -12,
      "y": 45,
      "z": 0,
      "name": "Rock_Stone"
    },
    {
      "x": -12,
      "y": 46,
      "z": 0,
      "name": "Rock_Stone"
    },
    {
      "x": -12,
      "y": 47,
      "z": 0,
      "name": "Rock_Stone"
    },
    {
      "x": -12,
      "y": 48,
      "z": 0,
      "name": "Rock_Stone"
    },
    {
      "x": -12,
      "y": 49,
      "z": 0,
      "name": "Rock_Stone"
    },
    {
      "x": -12,
      "y": 50,
      "z": 0,
      "name": "Rock_Stone"
    },
    {
      "x": -12,
      "y": 51,
      "z": 0,
      "name": "Rock_Stone"
    },
    {
      "x": -12,
      "y": 52,
      "z": 0,
      "name": "Rock_Stone"
    },
    {
      "x": -12,
      "y": 53,
      "z": 0,
      "name": "Rock_Stone"
    },
    {
      "x": -12,
      "y": 54,
      "z": 0,
      "name": "Rock_Stone"
    },
    {
      "x": -12,
      "y": 55,
      "z": 0,
      "name": "Rock_Stone"
    },
    {
      "x": -12,
      "y": 56,
      "z": 0,
      "name": "Rock_Stone"
    },
    {
      "x": -12,
      "y": 57,
      "z": 0,
      "name": "Rock_Stone"
    },
    {
      "x": -12,
      "y": 58,
      "z": 0,
      "name": "Soil_Dirt_Cold"
    },
    {
      "x": -12,
      "y": 59,
      "z": 0,
      "name": "Soil_Grass_Cold"
    },
    {
      "x": -12,
      "y": 0,
      "z": 1,
      "name": "Rock_Stone"
    },
    {
      "x": -12,
      "y": 1,
      "z": 1,
      "name": "Rock_Stone"
    },
    {
      "x": -12,
      "y": 2,
      "z": 1,
      "name": "Rock_Stone"
    },
    {
      "x": -12,
      "y": 3,
      "z": 1,
      "name": "Rock_Stone"
    },
    {
      "x": -12,
      "y": 4,
      "z": 1,
      "name": "Rock_Stone"
    },
    {
      "x": -12,
      "y": 5,
      "z": 1,
      "name": "Rock_Stone"
    },
    {
      "x": -12,
      "y": 6,
      "z": 1,
      "name": "Rock_Stone"
    },
    {
      "x": -12,
      "y": 7,
      "z": 1,
