{
  "version": 8,
  "blockIdVersion": 11,
  "anchorX": 0,
  "anchorY": 0,
  "anchorZ": 0,
  "blocks": [
    {
      "x": -6,
      "y": -71,
      "z": 2,
      "name": "Rock_Stone"
    },
    {
      "x": -6,
      "y": -70,
      "z": 2,
      "name": "Rock_Stone"
    },
    {
      "x": -6,
      "y": -69,
      "z": 2,
      "name": "Rock_Stone"
    },
    {
      "x": -6,
      "y": -68,
      "z": 2,
      "name": "Rock_Stone"
    },
    {
      "x": -6,
      "y": -67,
      "z": 2,
      "name": "Rock_Stone"
    },
    {
      "x": -6,
      "y": -66,
      "z": 2,
      "name": "Rock_Stone"
    },
    {
      "x": -6,
      "y": -65,
      "z": 2,
      "name": "Rock_Stone"
    },
    {
      "x": -6,
      "y": -64,
      "z": 2,
      "name": "Rock_Stone"
    },
    {
      "x": -6,
      "y": -63,
      "z": 2,
      "name": "Rock_Stone"
    },
    {
      "x": -6,
      "y": -62,
      "z": 2,
      "name": "Rock_Stone"
    },
    {
      "x": -6,
      "y": -61,
      "z": 2,
      "name": "Rock_Stone"
    },
    {
      "x": -6,
      "y": -60,
      "z": 2,
      "name": "Rock_Stone"
    },
    {
      "x": -6,
      "y": -59,
      "z": 2,
      "name": "Rock_Stone"
    },
    {
      "x": -6,
      "y": -58,
      "z": 2,
      "name": "Rock_Stone"
    },
    {
      "x": -6,
      "y": -57,
      "z": 2,
      "name": "Rock_Stone"
    },
    {
      "x": -6,
      "y": -56,
      "z": 2,
      "name": "Rock_Stone"
    },
    {
      "x": -6,
      "y": -55,
      "z": 2,
      "name": "Rock_Stone"
    },
    {
      "x": -6,
      "y": -54,
      "z": 2,
      "name": "Rock_Stone"
    },
    {
      "x": -6,
      "y": -53,
      "z": 2,
      "name": "Rock_Stone"
    },
    {
      "x": -6,
      "y": -52,
      "z": 2,
      "name": "Rock_Stone"
    },
    {
      "x": -6,
      "y": -51,
      "z": 2,
      "name": "Rock_Stone"
    },
    {
      "x": -6,
      "y": -50,
      "z": 2,
      "name": "Rock_Stone"
    },
    {
      "x": -6,
      "y": -49,
      "z": 2,
      "name": "Rock_Stone"
    },
    {
      "x": -6,
      "y": -48,
      "z": 2,
      "name": "Rock_Stone"
    },
    {
      "x": -6,
      "y": -47,
      "z": 2,
      "name": "Rock_Stone"
    },
    {
      "x": -6,
      "y": -46,
      "z": 2,
      "name": "Rock_Stone"
    },
    {
      "x": -6,
      "y": -45,
      "z": 2,
      "name": "Rock_Stone"
    },
    {
      "x": -6,
      "y": -44,
      "z": 2,
      "name": "Rock_Stone"
    },
    {
      "x": -6,
      "y": -43,
      "z": 2,
      "name": "Rock_Stone"
    },
    {
      "x": -6,
      "y": -42,
      "z": 2,
      "name": "Rock_Stone"
    },
    {
      "x": -6,
      "y": -41,
      "z": 2,
      "name": "Rock_Stone"
    },
    {
      "x": -6,
      "y": -40,
      "z": 2,
      "name": "Rock_Stone"
    },
    {
      "x": -6,
      "y": -70,
      "z": 3,
      "name": "Rock_Stone"
    },
    {
      "x": -6,
      "y": -69,
      "z": 3,
      "name": "Rock_Stone"
    },
    {
      "x": -6,
      "y": -68,
      "z": 3,
      "name": "Rock_Stone"
    },
    {
      "x": -6,
      "y": -67,
      "z": 3,
      "name": "Rock_Stone"
    },
    {
      "x": -6,
      "y": -66,
      "z": 3,
      "name": "Rock_Stone"
    },
    {
      "x": -6,
      "y": -65,
      "z": 3,
      "name": "Rock_Stone"
    },
    {
      "x": -6,
      "y": -64,
      "z": 3,
      "name": "Rock_Stone"
    },
    {
      "x": -6,
      "y": -63,
      "z": 3,
      "name": "Rock_Stone"
    },
    {
      "x": -6,
      "y": -62,
      "z": 3,
      "name": "Rock_Stone"
    },
    {
      "x": -6,
      "y": -61,
      "z": 3,
      "name": "Rock_Stone"
    },
    {
      "x": -6,
      "y": -60,
      "z": 3,
      "name": "Rock_Stone"
    },
    {
      "x": -6,
      "y": -59,
      "z": 3,
      "name": "Rock_Stone"
    },
    {
      "x": -6,
      "y": -58,
      "z": 3,
      "name": "Rock_Stone"
    },
    {
      "x": -6,
      "y": -57,
      "z": 3,
      "name": "Rock_Stone"
    },
    {
      "x": -6,
      "y": -56,
      "z": 3,
      "name": "Rock_Stone"
    },
    {
      "x": -6,
      "y": -55,
      "z": 3,
      "name": "Rock_Stone"
    },
    {
      "x": -6,
      "y": -54,
      "z": 3,
      "name": "Rock_Stone"
    },
    {
      "x": -6,
      "y": -53,
      "z": 3,
      "name": "Rock_Stone"
    },
    {
      "x": -6,
      "y": -52,
      "z": 3,
      "name": "Rock_Stone"
    },
    {
      "x": -6,
      "y": -51,
      "z": 3,
      "name": "Rock_Stone"
    },
    {
      "x": -6,
      "y": -50,
      "z": 3,
      "name": "Rock_Stone"
    },
    {
      "x": -6,
      "y": -49,
      "z": 3,
      "name": "Rock_Stone"
    },
    {
      "x": -6,
      "y": -48,
      "z": 3,
      "name": "Rock_Stone"
    },
    {
      "x": -6,
      "y": -47,
      "z": 3,
      "name": "Rock_Stone"
    },
    {
      "x": -6,
      "y": -46,
      "z": 3,
      "name": "Rock_Stone"
    },
    {
      "x": -6,
      "y": -45,
      "z": 3,
      "name": "Rock_Stone"
    },
    {
      "x": -6,
      "y": -44,
      "z": 3,
      "name": "Rock_Stone"
    },
    {
      "x": -6,
      "y": -70,
      "z": 4,
      "name": "Rock_Stone"
    },
    {
      "x": -6,
      "y": -69,
      "z": 4,
      "name": "Rock_Stone"
    },
    {
      "x": -6,
      "y": -68,
      "z": 4,
      "name": "Rock_Stone"
    },
    {
      "x": -6,
      "y": -67,
      "z": 4,
      "name": "Rock_Stone"
    },
    {
      "x": -6,
      "y": -66,
      "z": 4,
      "name": "Rock_Stone"
    },
    {
      "x": -6,
      "y": -65,
      "z": 4,
      "name": "Rock_Stone"
    },
    {
      "x": -6,
      "y": -64,
      "z": 4,
      "name": "Rock_Stone"
    },
    {
      "x": -6,
      "y": -63,
      "z": 4,
      "name": "Rock_Stone"
    },
    {
      "x": -6,
      "y": -62,
      "z": 4,
      "name": "Rock_Stone"
    },
    {
      "x": -6,
      "y": -61,
      "z": 4,
      "name": "Rock_Stone"
    },
    {
      "x": -6,
      "y": -60,
      "z": 4,
      "name": "Rock_Stone"
    },
    {
      "x": -6,
      "y": -59,
      "z": 4,
      "name": "Rock_Stone"
    },
    {
      "x": -6,
      "y": -58,
      "z": 4,
      "name": "Rock_Stone"
    },
    {
      "x": -6,
      "y": -57,
      "z": 4,
      "name": "Rock_Stone"
    },
    {
      "x": -6,
      "y": -56,
      "z": 4,
      "name": "Rock_Stone"
    },
    {
      "x": -5,
      "y": -72,
      "z": 0,
      "name": "Rock_Stone"
    },
    {
      "x": -5,
      "y": -71,
      "z": 0,
      "name": "Rock_Stone"
    },
    {
      "x": -5,
      "y": -70,
      "z": 0,
      "name": "Rock_Stone"
    },
    {
      "x": -5,
      "y": -69,
      "z": 0,
      "name": "Rock_Stone"
    },
    {
      "x": -5,
      "y": -68,
      "z": 0,
      "name": "Rock_Stone"
    },
    {
      "x": -5,
      "y": -67,
      "z": 0,
      "name": "Rock_Stone"
    },
    {
      "x": -5,
      "y": -66,
      "z": 0,
      "name": "Rock_Stone"
    },
    {
      "x": -5,
      "y": -65,
      "z": 0,
      "name": "Rock_Stone"
    },
    {
      "x": -5,
      "y": -64,
      "z": 0,
      "name": "Rock_Stone"
    },
    {
      "x": -5,
      "y": -63,
      "z": 0,
      "name": "Rock_Stone"
    },
    {
      "x": -5,
      "y": -62,
      "z": 0,
      "name": "Rock_Stone"
    },
    {
      "x": -5,
      "y": -61,
      "z": 0,
      "name": "Rock_Stone"
    },
    {
      "x": -5,
      "y": -60,
      "z": 0,
      "name": "Rock_Stone"
    },
    {
      "x": -5,
      "y": -59,
      "z": 0,
      "name": "Rock_Stone"
    },
    {
      "x": -5,
      "y": -58,
      "z": 0,
      "name": "Rock_Stone"
    },
    {
      "x": -5,
      "y": -57,
      "z": 0,
      "name": "Rock_Stone"
    },
    {
      "x": -5,
      "y": -56,
      "z": 0,
      "name": "Rock_Stone"
    },
    {
      "x": -5,
      "y": -55,
      "z": 0,
      "name": "Rock_Stone"
    },
    {
      "x": -5,
      "y": -54,
      "z": 0,
      "name": "Rock_Stone"
    },
    {
      "x": -5,
      "y": -53,
      "z": 0,
      "name": "Rock_Stone"
    },
    {
      "x": -5,
      "y": -52,
      "z": 0,
      "name": "Rock_Stone"
    },
    {
      "x": -5,
      "y": -51,
      "z": 0,
      "name": "Rock_Stone"
    },
    {
      "x": -5,
      "y": -50,
      "z": 0,
      "name": "Rock_Stone"
    },
    {
      "x": -5,
      "y": -49,
      "z": 0,
      "name": "Rock_Stone"
    },
    {
      "x": -5,
      "y": -48,
      "z": 0,
      "name": "Rock_Stone"
    },
    {
      "x": -5,
      "y": -47,
      "z": 0,
      "name": "Rock_Stone"
    },
    {
      "x": -5,
      "y": -46,
      "z": 0,
      "name": "Rock_Stone"
    },
    {
      "x": -5,
      "y": -45,
      "z": 0,
      "name": "Rock_Stone"
    },
    {
      "x": -5,
      "y": -44,
      "z": 0,
      "name": "Rock_Stone"
    },
    {
      "x": -5,
      "y": -43,
      "z": 0,
      "name": "Rock_Stone"
    },
    {
      "x": -5,
      "y": -42,
      "z": 0,
      "name": "Rock_Stone"
    },
    {
      "x": -5,
      "y": -41,
      "z": 0,
      "name": "Rock_Stone"
    },
    {
      "x": -5,
      "y": -40,
      "z": 0,
      "name": "Rock_Stone"
    },
    {
      "x": -5,
      "y": -39,
      "z": 0,
      "name": "Rock_Stone"
    },
    {
      "x": -5,
      "y": -38,
      "z": 0,
      "name": "Rock_Stone"
    },
    {
      "x": -5,
      "y": -37,
      "z": 0,
      "name": "Rock_Stone"
    },
    {
      "x": -5,
      "y": -36,
      "z": 0,
      "name": "Rock_Stone"
    },
    {
      "x": -5,
      "y": -35,
      "z": 0,
      "name": "Rock_Stone"
    },
    {
      "x": -5,
      "y": -34,
      "z": 0,
      "name": "Rock_Stone"
    },
    {
      "x": -5,
      "y": -33,
      "z": 0,
      "name": "Rock_Stone"
    },
    {
      "x": -5,
      "y": -32,
      "z": 0,
      "name": "Rock_Stone"
    },
    {
      "x": -5,
      "y": -31,
      "z": 0,
      "name": "Rock_Stone"
    },
    {
      "x": -5,
      "y": -30,
      "z": 0,
      "name": "Rock_Stone"
    },
    {
      "x": -5,
      "y": -29,
      "z": 0,
      "name": "Rock_Stone"
    },
    {
      "x": -5,
      "y": -28,
      "z": 0,
      "name": "Rock_Stone"
    },
    {
      "x": -5,
      "y": -27,
      "z": 0,
      "name": "Rock_Stone"
    },
    {
      "x": -5,
      "y": -26,
      "z": 0,
      "name": "Rock_Stone"
    },
    {
      "x": -5,
      "y": -25,
      "z": 0,
      "name": "Rock_Stone"
    },
    {
      "x": -5,
      "y": -24,
      "z": 0,
      "name": "Rock_Stone"
    },
    {
      "x": -5,
      "y": -23,
      "z": 0,
      "name": "Rock_Stone"
    },
    {
      "x": -5,
      "y": -22,
      "z": 0,
      "name": "Rock_Stone"
    },
    {
      "x": -5,
      "y": -73,
      "z": 1,
      "name": "Rock_Stone"
    },
    {
      "x": -5,
      "y": -72,
      "z": 1,
      "name": "Rock_Stone"
    },
    {
      "x": -5,
      "y": -71,
      "z": 1,
      "name": "Rock_Stone"
    },
    {
      "x": -5,
      "y": -70,
      "z": 1,
      "name": "Rock_Stone"
    },
    {
      "x": -5,
      "y": -69,
      "z": 1,
      "name": "Rock_Stone"
    },
    {
      "x": -5,
      "y": -68,
      "z": 1,
      "name": "Rock_Stone"
    },
    {
      "x": -5,
      "y": -67,
      "z": 1,
      "name": "Rock_Stone"
    },
    {
      "x": -5,
      "y": -66,
      "z": 1,
      "name": "Rock_Stone"
    },
    {
      "x": -5,
      "y": -65,
      "z": 1,
      "name": "Rock_Stone"
    },
    {
      "x": -5,
      "y": -64,
      "z": 1,
      "name": "Rock_Stone"
    },
    {
      "x": -5,
      "y": -63,
      "z": 1,
      "name": "Rock_Stone"
    },
    {
      "x": -5,
      "y": -62,
      "z": 1,
      "name": "Rock_Stone"
    },
    {
      "x": -5,
      "y": -61,
      "z": 1,
      "name": "Rock_Stone"
    },
    {
      "x": -5,
      "y": -60,
      "z": 1,
      "name": "Rock_Stone"
    },
    {
      "x": -5,
      "y": -59,
      "z": 1,
      "name": "Rock_Stone"
    },
    {
      "x": -5,
      "y": -58,
      "z": 1,
      "name": "Rock_Stone"
    },
    {
      "x": -5,
      "y": -57,
      "z": 1,
      "name": "Rock_Stone"
    },
    {
      "x": -5,
      "y": -56,
      "z": 1,
      "name": "Rock_Stone"
    },
    {
      "x": -5,
      "y": -55,
      "z": 1,
      "name": "Rock_Stone"
    },
    {
      "x": -5,
      "y": -54,
      "z": 1,
      "name": "Rock_Stone"
    },
    {
      "x": -5,
      "y": -53,
      "z": 1,
      "name": "Rock_Stone"
    },
    {
      "x": -5,
      "y": -52,
      "z": 1,
      "name": "Rock_Stone"
    },
    {
      "x": -5,
      "y": -51,
      "z": 1,
      "name": "Rock_Stone"
    },
    {
      "x": -5,
      "y": -50,
      "z": 1,
      "name": "Rock_Stone"
    },
    {
      "x": -5,
      "y": -49,
      "z": 1,
      "name": "Rock_Stone"
    },
    {
      "x": -5,
      "y": -48,
      "z": 1,
      "name": "Rock_Stone"
    },
    {
      "x": -5,
      "y": -47,
      "z": 1,
      "name": "Rock_Stone"
    },
    {
      "x": -5,
      "y": -46,
      "z": 1,
      "name": "Rock_Stone"
    },
    {
      "x": -5,
      "y": -45,
      "z": 1,
      "name": "Rock_Stone"
    },
    {
      "x": -5,
      "y": -44,
      "z": 1,
      "name": "Rock_Stone"
    },
    {
      "x": -5,
      "y": -43,
      "z": 1,
      "name": "Rock_Stone"
    },
    {
      "x": -5,
      "y": -42,
      "z": 1,
      "name": "Rock_Stone"
    },
    {
      "x": -5,
      "y": -41,
      "z": 1,
      "name": "Rock_Stone"
    },
    {
      "x": -5,
      "y": -40,
      "z": 1,
      "name": "Rock_Stone"
    },
    {
      "x": -5,
      "y": -39,
      "z": 1,
      "name": "Rock_Stone"
    },
    {
      "x": -5,
      "y": -38,
      "z": 1,
      "name": "Rock_Stone"
    },
    {
      "x": -5,
      "y": -37,
      "z": 1,
      "name": "Rock_Stone"
    },
    {
      "x": -5,
      "y": -36,
      "z": 1,
      "name": "Rock_Stone"
    },
    {
      "x": -5,
      "y": -35,
      "z": 1,
      "name": "Rock_Stone"
    },
    {
      "x": -5,
      "y": -34,
      "z": 1,
      "name": "Rock_Stone"
    },
    {
      "x": -5,
      "y": -33,
      "z": 1,
      "name": "Rock_Stone"
    },
    {
      "x": -5,
      "y": -32,
      "z": 1,
      "name": "Rock_Stone"
    },
    {
      "x": -5,
      "y": -31,
      "z": 1,
      "name": "Rock_Stone"
    },
    {
      "x": -5,
      "y": -30,
      "z": 1,
      "name": "Rock_Stone"
    },
    {
      "x": -5,
      "y": -29,
      "z": 1,
      "name": "Rock_Stone"
    },
    {
      "x": -5,
      "y": -28,
      "z": 1,
      "name": "Rock_Stone"
    },
    {
      "x": -5,
      "y": -27,
      "z": 1,
      "name": "Rock_Stone"
    },
    {
      "x": -5,
      "y": -26,
      "z": 1,
      "name": "Rock_Stone"
    },
    {
      "x": -5,
      "y": -25,
      "z": 1,
      "name": "Rock_Stone"
    },
    {
      "x": -5,
      "y": -24,
      "z": 1,
      "name": "Rock_Stone"
    },
    {
      "x": -5,
      "y": -23,
      "z": 1,
      "name": "Rock_Stone"
    },
    {
      "x": -5,
      "y": -22,
      "z": 1,
      "name": "Rock_Stone"
    },
    {
      "x": -5,
      "y": -21,
      "z": 1,
      "name": "Rock_Stone"
    },
    {
      "x": -5,
      "y": -20,
      "z": 1,
      "name": "Rock_Stone"
    },
    {
      "x": -5,
      "y": -19,
      "z": 1,
      "name": "Rock_Stone"
    },
    {
      "x": -5,
      "y": -18,
      "z": 1,
      "name": "Rock_Stone"
    },
    {
      "x": -5,
      "y": -17,
      "z": 1,
      "name": "Rock_Stone"
    },
    {
      "x": -5,
      "y": -16,
      "z": 1,
      "name": "Rock_Stone"
    },
    {
      "x": -5,
      "y": -73,
      "z": 2,
      "name": "Rock_Stone"
    },
    {
      "x": -5,
      "y": -72,
      "z": 2,
      "name": "Rock_Stone"
    },
    {
      "x": -5,
      "y": -71,
      "z": 2,
      "name": "Rock_Stone"
    },
    {
      "x": -5,
      "y": -70,
      "z": 2,
      "name": "Rock_Stone"
    },
    {
      "x": -5,
      "y": -69,
      "z": 2,
      "name": "Rock_Stone"
    },
    {
      "x": -5,
      "y": -68,
      "z": 2,
      "name": "Rock_Stone"
    },
    {
      "x": -5,
      "y": -67,
      "z": 2,
      "name": "Rock_Stone"
    },
    {
      "x": -5,
      "y": -66,
      "z": 2,
      "name": "Rock_Stone"
    },
    {
      "x": -5,
      "y": -65,
      "z": 2,
      "name": "Rock_Stone"
    },
    {
      "x": -5,
      "y": -64,
      "z": 2,
      "name": "Rock_Stone"
    },
    {
      "x": -5,
      "y": -63,
      "z": 2,
      "name": "Rock_Stone"
    },
    {
      "x": -5,
      "y": -62,
      "z": 2,
      "name": "Rock_Stone"
    },
    {
      "x": -5,
      "y": -61,
      "z": 2,
      "name": "Rock_Stone"
    },
    {
      "x": -5,
      "y": -60,
      "z": 2,
      "name": "Rock_Stone"
    },
    {
      "x": -5,
      "y": -59,
      "z": 2,
      "name": "Rock_Stone"
    },
    {
      "x": -5,
      "y": -58,
      "z": 2,
      "name": "Rock_Stone"
    },
    {
      "x": -5,
      "y": -57,
      "z": 2,
      "name": "Rock_Stone"
    },
    {
      "x": -5,
      "y": -56,
      "z": 2,
      "name": "Rock_Stone"
    },
    {
      "x": -5,
      "y": -55,
      "z": 2,
      "name": "Rock_Stone"
    },
    {
      "x": -5,
      "y": -54,
      "z": 2,
      "name": "Rock_Stone"
    },
    {
      "x": -5,
      "y": -53,
      "z": 2,
      "name": "Rock_Stone"
    },
    {
      "x": -5,
      "y": -52,
      "z": 2,
      "name": "Rock_Stone"
    },
    {
      "x": -5,
      "y": -51,
      "z": 2,
      "name": "Rock_Stone"
    },
    {
      "x": -5,
      "y": -50,
      "z": 2,
      "name": "Rock_Stone"
    },
    {
      "x": -5,
      "y": -49,
      "z": 2,
      "name": "Rock_Stone"
    },
    {
      "x": -5,
      "y": -48,
      "z": 2,
      "name": "Rock_Stone"
    },
    {
      "x": -5,
      "y": -47,
      "z": 2,
      "name": "Rock_Stone"
    },
    {
      "x": -5,
      "y": -46,
      "z": 2,
      "name": "Rock_Stone"
    },
    {
      "x": -5,
      "y": -45,
      "z": 2,
      "name": "Rock_Stone"
    },
    {
      "x": -5,
      "y": -44,
      "z": 2,
      "name": "Rock_Stone"
    },
    {
      "x": -5,
      "y": -43,
      "z": 2,
      "name": "Rock_Stone"
    },
    {
      "x": -5,
      "y": -42,
      "z": 2,
      "name": "Rock_Stone"
    },
    {
      "x": -5,
      "y": -41,
      "z": 2,
      "name": "Rock_Stone"
    },
    {
      "x": -5,
      "y": -40,
      "z": 2,
      "name": "Rock_Stone"
    },
    {
      "x": -5,
      "y": -39,
      "z": 2,
      "name": "Rock_Stone"
    },
    {
      "x": -5,
      "y": -38,
      "z": 2,
      "name": "Rock_Stone"
    },
    {
      "x": -5,
      "y": -37,
      "z": 2,
      "name": "Rock_Stone"
    },
    {
      "x": -5,
      "y": -36,
      "z": 2,
      "name": "Rock_Stone"
    },
    {
      "x": -5,
      "y": -35,
      "z": 2,
      "name": "Rock_Stone"
    },
    {
      "x": -5,
      "y": -34,
      "z": 2,
      "name": "Rock_Stone"
    },
    {
      "x": -5,
      "y": -33,
      "z": 2,
      "name": "Rock_Stone"
    },
    {
      "x": -5,
      "y": -32,
      "z": 2,
      "name": "Rock_Stone"
    },
    {
      "x": -5,
      "y": -31,
      "z": 2,
      "name": "Rock_Stone"
    },
    {
      "x": -5,
      "y": -30,
      "z": 2,
      "name": "Rock_Stone"
    },
    {
      "x": -5,
      "y": -29,
      "z": 2,
      "name": "Rock_Stone"
    },
    {
      "x": -5,
      "y": -28,
      "z": 2,
      "name": "Rock_Stone"
    },
    {
      "x": -5,
      "y": -27,
      "z": 2,
      "name": "Rock_Stone"
    },
    {
      "x": -5,
      "y": -26,
      "z": 2,
      "name": "Rock_Stone"
    },
    {
      "x": -5,
      "y": -25,
      "z": 2,
      "name": "Rock_Stone"
    },
    {
      "x": -5,
      "y": -24,
      "z": 2,
      "name": "Rock_Stone"
    },
    {
      "x": -5,
      "y": -23,
      "z": 2,
      "name": "Rock_Stone"
    },
    {
      "x": -5,
      "y": -22,
      "z": 2,
      "name": "Rock_Stone"
    },
    {
      "x": -5,
      "y": -21,
      "z": 2,
      "name": "Rock_Stone"
    },
    {
      "x": -5,
      "y": -20,
      "z": 2,
      "name": "Rock_Stone"
    },
    {
      "x": -5,
      "y": -19,
      "z": 2,
      "name": "Rock_Stone"
    },
    {
      "x": -5,
      "y": -18,
      "z": 2,
      "name": "Rock_Stone"
    },
    {
      "x": -5,
      "y": -17,
      "z": 2,
      "name": "Rock_Stone"
    },
    {
      "x": -5,
      "y": -16,
      "z": 2,
      "name": "Rock_Stone"
    },
    {
      "x": -5,
      "y": -73,
      "z": 3,
      "name": "Rock_Stone"
    },
    {
      "x": -5,
      "y": -72,
      "z": 3,
      "name": "Rock_Stone"
    },
    {
      "x": -5,
      "y": -71,
      "z": 3,
      "name": "Rock_Stone"
    },
    {
      "x": -5,
      "y": -70,
      "z": 3,
      "name": "Rock_Stone"
    },
    {
      "x": -5,
      "y": -69,
      "z": 3,
      "name": "Rock_Stone"
    },
    {
      "x": -5,
      "y": -68,
      "z": 3,
      "name": "Rock_Stone"
    },
    {
      "x": -5,
      "y": -67,
      "z": 3,
      "name": "Rock_Stone"
    },
    {
      "x": -5,
      "y": -66,
      "z": 3,
      "name": "Rock_Stone"
    },
    {
      "x": -5,
      "y": -65,
      "z": 3,
      "name": "Rock_Stone"
    },
    {
      "x": -5,
      "y": -64,
      "z": 3,
      "name": "Rock_Stone"
    },
    {
      "x": -5,
      "y": -63,
      "z": 3,
      "name": "Rock_Stone"
    },
    {
      "x": -5,
      "y": -62,
      "z": 3,
      "name": "Rock_Stone"
    },
    {
      "x": -5,
      "y": -61,
      "z": 3,
      "name": "Rock_Stone"
    },
    {
      "x": -5,
      "y": -60,
      "z": 3,
      "name": "Rock_Stone"
    },
    {
      "x": -5,
      "y": -59,
      "z": 3,
      "name": "Rock_Stone"
    },
    {
      "x": -5,
      "y": -58,
      "z": 3,
      "name": "Rock_Stone"
    },
    {
      "x": -5,
      "y": -57,
      "z": 3,
      "name": "Rock_Stone"
    },
    {
      "x": -5,
      "y": -56,
      "z": 3,
      "name": "Rock_Stone"
    },
    {
      "x": -5,
      "y": -55,
      "z": 3,
      "name": "Rock_Stone"
    },
    {
      "x": -5,
      "y": -54,
      "z": 3,
      "name": "Rock_Stone"
    },
    {
      "x": -5,
      "y": -53,
      "z": 3,
      "name": "Rock_Stone"
    },
    {
      "x": -5,
      "y": -52,
      "z": 3,
      "name": "Rock_Stone"
    },
    {
      "x": -5,
      "y": -51,
      "z": 3,
      "name": "Rock_Stone"
    },
    {
      "x": -5,
      "y": -50,
      "z": 3,
      "name": "Rock_Stone"
    },
    {
      "x": -5,
      "y": -49,
      "z": 3,
      "name": "Rock_Stone"
    },
    {
      "x": -5,
      "y": -48,
      "z": 3,
      "name": "Rock_Stone"
    },
    {
      "x": -5,
      "y": -47,
      "z": 3,
      "name": "Rock_Stone"
    },
    {
      "x": -5,
      "y": -46,
      "z": 3,
      "name": "Rock_Stone"
    },
    {
      "x": -5,
      "y": -45,
      "z": 3,
      "name": "Rock_Stone"
    },
    {
      "x": -5,
      "y": -44,
      "z": 3,
      "name": "Rock_Stone"
    },
    {
      "x": -5,
      "y": -43,
      "z": 3,
      "name": "Rock_Stone"
    },
    {
      "x": -5,
      "y": -42,
      "z": 3,
      "name": "Rock_Stone"
    },
    {
      "x": -5,
      "y": -41,
      "z": 3,
      "name": "Rock_Stone"
    },
    {
      "x": -5,
      "y": -40,
      "z": 3,
      "name": "Rock_Stone"
    },
    {
      "x": -5,
      "y": -39,
      "z": 3,
      "name": "Rock_Stone"
    },
    {
      "x": -5,
      "y": -38,
      "z": 3,
      "name": "Rock_Stone"
    },
    {
      "x": -5,
      "y": -37,
      "z": 3,
      "name": "Rock_Stone"
    },
    {
      "x": -5,
      "y": -36,
      "z": 3,
      "name": "Rock_Stone"
    },
    {
      "x": -5,
      "y": -35,
      "z": 3,
      "name": "Rock_Stone"
    },
    {
      "x": -5,
      "y": -34,
      "z": 3,
      "name": "Rock_Stone"
    },
    {
      "x": -5,
      "y": -33,
      "z": 3,
      "name": "Rock_Stone"
    },
    {
      "x": -5,
      "y": -32,
      "z": 3,
      "name": "Rock_Stone"
    },
    {
      "x": -5,
      "y": -31,
      "z": 3,
      "name": "Rock_Stone"
    },
    {
      "x": -5,
      "y": -30,
      "z": 3,
      "name": "Rock_Stone"
    },
    {
      "x": -5,
      "y": -29,
      "z": 3,
      "name": "Rock_Stone"
    },
    {
      "x": -5,
      "y": -28,
      "z": 3,
      "name": "Rock_Stone"
    },
    {
      "x": -5,
      "y": -27,
      "z": 3,
      "name": "Rock_Stone"
    },
    {
      "x": -5,
      "y": -26,
      "z": 3,
      "name": "Rock_Stone"
    },
    {
      "x": -5,
      "y": -25,
      "z": 3,
      "name": "Rock_Stone"
    },
    {
      "x": -5,
      "y": -24,
      "z": 3,
      "name": "Rock_Stone"
    },
    {
      "x": -5,
      "y": -23,
      "z": 3,
      "name": "Rock_Stone"
    },
    {
      "x": -5,
      "y": -22,
      "z": 3,
      "name": "Rock_Stone"
    },
    {
      "x": -5,
      "y": -21,
      "z": 3,
      "name": "Rock_Stone"
    },
    {
      "x": -5,
      "y": -20,
      "z": 3,
      "name": "Rock_Stone"
    },
    {
      "x": -5,
      "y": -19,
      "z": 3,
      "name": "Rock_Stone"
    },
    {
      "x": -5,
      "y": -18,
      "z": 3,
      "name": "Rock_Stone"
    },
    {
      "x": -5,
      "y": -73,
      "z": 4,
      "name": "Rock_Stone"
    },
    {
      "x": -5,
      "y": -72,
      "z": 4,
      "name": "Rock_Stone"
    },
    {
      "x": -5,
      "y": -71,
      "z": 4,
      "name": "Rock_Stone"
    },
    {
      "x": -5,
      "y": -70,
      "z": 4,
      "name": "Rock_Stone"
    },
    {
      "x": -5,
      "y": -69,
      "z": 4,
      "name": "Rock_Stone"
    },
    {
      "x": -5,
      "y": -68,
      "z": 4,
      "name": "Rock_Stone"
    },
    {
      "x": -5,
      "y": -67,
      "z": 4,
      "name": "Rock_Stone"
    },
    {
      "x": -5,
      "y": -66,
      "z": 4,
      "name": "Rock_Stone"
    },
    {
      "x": -5,
      "y": -65,
      "z": 4,
      "name": "Rock_Stone"
    },
    {
      "x": -5,
      "y": -64,
      "z": 4,
      "name": "Rock_Stone"
    },
    {
      "x": -5,
      "y": -63,
      "z": 4,
      "name": "Rock_Stone"
    },
    {
      "x": -5,
      "y": -62,
      "z": 4,
      "name": "Rock_Stone"
    },
    {
      "x": -5,
      "y": -61,
      "z": 4,
      "name": "Rock_Stone"
    },
    {
      "x": -5,
      "y": -60,
      "z": 4,
      "name": "Rock_Stone"
    },
    {
      "x": -5,
      "y": -59,
      "z": 4,
      "name": "Rock_Stone"
    },
    {
      "x": -5,
      "y": -58,
      "z": 4,
      "name": "Rock_Stone"
    },
    {
      "x": -5,
      "y": -57,
      "z": 4,
      "name": "Rock_Stone"
    },
    {
      "x": -5,
      "y": -56,
      "z": 4,
      "name": "Rock_Stone"
    },
    {
      "x": -5,
      "y": -55,
      "z": 4,
      "name": "Rock_Stone"
    },
    {
      "x": -5,
      "y": -54,
      "z": 4,
      "name": "Rock_Stone"
    },
    {
      "x": -5,
      "y": -53,
      "z": 4,
      "name": "Rock_Stone"
    },
    {
      "x": -5,
      "y": -52,
      "z": 4,
      "name": "Rock_Stone"
    },
    {
      "x": -5,
      "y": -51,
      "z": 4,
      "name": "Rock_Stone"
    },
    {
      "x": -5,
      "y": -50,
      "z": 4,
      "name": "Rock_Stone"
    },
    {
      "x": -5,
      "y": -49,
      "z": 4,
      "name": "Rock_Stone"
    },
    {
      "x": -5,
      "y": -48,
      "z": 4,
      "name": "Rock_Stone"
    },
    {
      "x": -5,
      "y": -47,
      "z": 4,
      "name": "Rock_Stone"
    },
    {
      "x": -5,
      "y": -46,
      "z": 4,
      "name": "Rock_Stone"
    },
    {
      "x": -5,
      "y": -45,
      "z": 4,
      "name": "Rock_Stone"
    },
    {
      "x": -5,
      "y": -44,
      "z": 4,
      "name": "Rock_Stone"
    },
    {
      "x": -5,
      "y": -43,
      "z": 4,
      "name": "Rock_Stone"
    },
    {
      "x": -5,
      "y": -42,
      "z": 4,
      "name": "Rock_Stone"
    },
    {
      "x": -5,
      "y": -41,
      "z": 4,
      "name": "Rock_Stone"
    },
    {
      "x": -5,
      "y": -40,
      "z": 4,
      "name": "Rock_Stone"
    },
    {
      "x": -5,
      "y": -39,
      "z": 4,
      "name": "Rock_Stone"
    },
    {
      "x": -5,
      "y": -38,
      "z": 4,
      "name": "Rock_Stone"
    },
    {
      "x": -5,
      "y": -37,
      "z": 4,
      "name": "Rock_Stone"
    },
    {
      "x": -5,
      "y": -36,
      "z": 4,
      "name": "Rock_Stone"
    },
    {
      "x": -5,
      "y": -35,
      "z": 4,
      "name": "Rock_Stone"
    },
    {
      "x": -5,
      "y": -34,
      "z": 4,
      "name": "Rock_Stone"
    },
    {
      "x": -5,
      "y": -33,
      "z": 4,
      "name": "Rock_Stone"
    },
    {
      "x": -5,
      "y": -32,
      "z": 4,
      "name": "Rock_Stone"
    },
    {
      "x": -5,
      "y": -31,
      "z": 4,
      "name": "Rock_Stone"
    },
    {
      "x": -5,
      "y": -30,
      "z": 4,
      "name": "Rock_Stone"
    },
    {
      "x": -5,
      "y": -29,
      "z": 4,
      "name": "Rock_Stone"
    },
    {
      "x": -5,
      "y": -28,
      "z": 4,
      "name": "Rock_Stone"
    },
    {
      "x": -5,
      "y": -27,
      "z": 4,
      "name": "Rock_Stone"
    },
    {
      "x": -5,
      "y": -26,
      "z": 4,
      "name": "Rock_Stone"
    },
    {
      "x": -5,
      "y": -25,
      "z": 4,
      "name": "Rock_Stone"
    },
    {
      "x": -5,
      "y": -24,
      "z": 4,
      "name": "Rock_Stone"
    },
    {
      "x": -5,
      "y": -23,
      "z": 4,
      "name": "Rock_Stone"
    },
    {
      "x": -5,
      "y": -22,
      "z": 4,
      "name": "Rock_Stone"
    },
    {
      "x": -5,
      "y": -21,
      "z": 4,
      "name": "Rock_Stone"
    },
    {
      "x": -5,
      "y": -20,
      "z": 4,
      "name": "Rock_Stone"
    },
    {
      "x": -5,
      "y": -71,
      "z": 5,
      "name": "Rock_Stone"
    },
    {
      "x": -5,
      "y": -70,
      "z": 5,
      "name": "Rock_Stone"
    },
    {
      "x": -5,
      "y": -69,
      "z": 5,
      "name": "Rock_Stone"
    },
    {
      "x": -5,
      "y": -68,
      "z": 5,
      "name": "Rock_Stone"
    },
    {
      "x": -5,
      "y": -67,
      "z": 5,
      "name": "Rock_Stone"
    },
    {
      "x": -5,
      "y": -66,
      "z": 5,
      "name": "Rock_Stone"
    },
    {
      "x": -5,
      "y": -65,
      "z": 5,
      "name": "Rock_Stone"
    },
    {
      "x": -5,
      "y": -64,
      "z": 5,
      "name": "Rock_Stone"
    },
    {
      "x": -5,
      "y": -63,
      "z": 5,
      "name": "Rock_Stone"
    },
    {
      "x": -5,
      "y": -62,
      "z": 5,
      "name": "Rock_Stone"
    },
    {
      "x": -5,
      "y": -61,
      "z": 5,
      "name": "Rock_Stone"
    },
    {
      "x": -5,
      "y": -60,
      "z": 5,
      "name": "Rock_Stone"
    },
    {
      "x": -5,
      "y": -59,
      "z": 5,
      "name": "Rock_Stone"
    },
    {
      "x": -5,
      "y": -58,
      "z": 5,
      "name": "Rock_Stone"
    },
    {
      "x": -5,
      "y": -57,
      "z": 5,
      "name": "Rock_Stone"
    },
    {
      "x": -5,
      "y": -56,
      "z": 5,
      "name": "Rock_Stone"
    },
    {
      "x": -5,
      "y": -55,
      "z": 5,
      "name": "Rock_Stone"
    },
    {
      "x": -5,
      "y": -54,
      "z": 5,
      "name": "Rock_Stone"
    },
    {
      "x": -5,
      "y": -53,
      "z": 5,
      "name": "Rock_Stone"
    },
    {
      "x": -5,
      "y": -52,
      "z": 5,
      "name": "Rock_Stone"
    },
    {
      "x": -5,
      "y": -51,
      "z": 5,
      "name": "Rock_Stone"
    },
    {
      "x": -5,
      "y": -50,
      "z": 5,
      "name": "Rock_Stone"
    },
    {
      "x": -5,
      "y": -49,
      "z": 5,
      "name": "Rock_Stone"
    },
    {
      "x": -5,
      "y": -48,
      "z": 5,
      "name": "Rock_Stone"
    },
    {
      "x": -5,
      "y": -47,
      "z": 5,
      "name": "Rock_Stone"
    },
    {
      "x": -5,
      "y": -46,
      "z": 5,
      "name": "Rock_Stone"
    },
    {
      "x": -5,
      "y": -45,
      "z": 5,
      "name": "Rock_Stone"
    },
    {
      "x": -5,
      "y": -44,
      "z": 5,
      "name": "Rock_Stone"
    },
    {
      "x": -5,
      "y": -43,
      "z": 5,
      "name": "Rock_Stone"
    },
    {
      "x": -5,
      "y": -42,
      "z": 5,
      "name": "Rock_Stone"
    },
    {
      "x": -5,
      "y": -41,
      "z": 5,
      "name": "Rock_Stone"
    },
    {
      "x": -5,
      "y": -40,
      "z": 5,
      "name": "Rock_Stone"
    },
    {
      "x": -5,
      "y": -39,
      "z": 5,
      "name": "Rock_Stone"
    },
    {
      "x": -5,
      "y": -38,
      "z": 5,
      "name": "Rock_Stone"
    },
    {
      "x": -4,
      "y": -73,
      "z": -1,
      "name": "Rock_Stone"
    },
    {
      "x": -4,
      "y": -72,
      "z": -1,
      "name": "Rock_Stone"
    },
    {
      "x": -4,
      "y": -71,
      "z": -1,
      "name": "Rock_Stone"
    },
    {
      "x": -4,
      "y": -70,
      "z": -1,
      "name": "Rock_Stone"
    },
    {
      "x": -4,
      "y": -69,
      "z": -1,
      "name": "Rock_Stone"
    },
    {
      "x": -4,
      "y": -68,
      "z": -1,
      "name": "Rock_Stone"
    },
    {
      "x": -4,
      "y": -67,
      "z": -1,
      "name": "Rock_Stone"
    },
    {
      "x": -4,
      "y": -66,
      "z": -1,
      "name": "Rock_Stone"
    },
    {
      "x": -4,
      "y": -65,
      "z": -1,
      "name": "Rock_Stone"
    },
    {
      "x": -4,
      "y": -64,
      "z": -1,
      "name": "Rock_Stone"
    },
    {
      "x": -4,
      "y": -63,
      "z": -1,
      "name": "Rock_Stone"
    },
    {
      "x": -4,
      "y": -62,
      "z": -1,
      "name": "Rock_Stone"
    },
    {
      "x": -4,
      "y": -61,
      "z": -1,
      "name": "Rock_Stone"
    },
    {
      "x": -4,
      "y": -60,
      "z": -1,
      "name": "Rock_Stone"
    },
    {
      "x": -4,
      "y": -59,
      "z": -1,
      "name": "Rock_Stone"
    },
    {
      "x": -4,
      "y": -58,
      "z": -1,
      "name": "Rock_Stone"
    },
    {
      "x": -4,
      "y": -57,
      "z": -1,
      "name": "Rock_Stone"
    },
    {
      "x": -4,
      "y": -56,
      "z": -1,
      "name": "Rock_Stone"
    },
    {
      "x": -4,
      "y": -55,
      "z": -1,
      "name": "Rock_Stone"
    },
    {
      "x": -4,
      "y": -54,
      "z": -1,
      "name": "Rock_Stone"
    },
    {
      "x": -4,
      "y": -53,
      "z": -1,
      "name": "Rock_Stone"
    },
    {
      "x": -4,
      "y": -52,
      "z": -1,
      "name": "Rock_Stone"
    },
    {
      "x": -4,
      "y": -51,
      "z": -1,
      "name": "Rock_Stone"
    },
    {
      "x": -4,
      "y": -50,
      "z": -1,
      "name": "Rock_Stone"
    },
    {
      "x": -4,
      "y": -49,
      "z": -1,
      "name": "Rock_Stone"
    },
    {
      "x": -4,
      "y": -48,
      "z": -1,
      "name": "Rock_Stone"
    },
    {
      "x": -4,
      "y": -47,
      "z": -1,
      "name": "Rock_Stone"
    },
    {
      "x": -4,
      "y": -46,
      "z": -1,
      "name": "Rock_Stone"
    },
    {
      "x": -4,
      "y": -45,
      "z": -1,
      "name": "Rock_Stone"
    },
    {
      "x": -4,
      "y": -44,
      "z": -1,
      "name": "Rock_Stone"
    },
    {
      "x": -4,
      "y": -43,
      "z": -1,
      "name": "Rock_Stone"
    },
    {
      "x": -4,
      "y": -42,
      "z": -1,
      "name": "Rock_Stone"
    },
    {
      "x": -4,
      "y": -41,
      "z": -1,
      "name": "Rock_Stone"
    },
    {
      "x": -4,
      "y": -40,
      "z": -1,
      "name": "Rock_Stone"
    },
    {
      "x": -4,
      "y": -39,
      "z": -1,
      "name": "Rock_Stone"
    },
    {
      "x": -4,
      "y": -38,
      "z": -1,
      "name": "Rock_Stone"
    },
    {
      "x": -4,
      "y": -37,
      "z": -1,
      "name": "Rock_Stone"
    },
    {
      "x": -4,
      "y": -36,
      "z": -1,
      "name": "Rock_Stone"
    },
    {
      "x": -4,
      "y": -35,
      "z": -1,
      "name": "Rock_Stone"
    },
    {
      "x": -4,
      "y": -34,
      "z": -1,
      "name": "Rock_Stone"
    },
    {
      "x": -4,
      "y": -33,
      "z": -1,
      "name": "Rock_Stone"
    },
    {
      "x": -4,
      "y": -32,
      "z": -1,
      "name": "Rock_Stone"
    },
    {
      "x": -4,
      "y": -31,
      "z": -1,
      "name": "Rock_Stone"
    },
    {
      "x": -4,
      "y": -30,
      "z": -1,
      "name": "Rock_Stone"
    },
    {
      "x": -4,
      "y": -29,
      "z": -1,
      "name": "Rock_Stone"
    },
    {
      "x": -4,
      "y": -28,
      "z": -1,
      "name": "Rock_Stone"
    },
    {
      "x": -4,
      "y": -27,
      "z": -1,
      "name": "Rock_Stone"
    },
    {
      "x": -4,
      "y": -26,
      "z": -1,
      "name": "Rock_Stone"
    },
    {
      "x": -4,
      "y": -25,
      "z": -1,
      "name": "Rock_Stone"
    },
    {
      "x": -4,
      "y": -24,
      "z": -1,
      "name": "Rock_Stone"
    },
    {
      "x": -4,
      "y": -74,
      "z": 0,
      "name": "Rock_Stone"
    },
    {
      "x": -4,
      "y": -73,
      "z": 0,
      "name": "Rock_Stone"
    },
    {
      "x": -4,
      "y": -72,
      "z": 0,
      "name": "Rock_Stone"
    },
    {
      "x": -4,
      "y": -71,
      "z": 0,
      "name": "Rock_Stone"
    },
    {
      "x": -4,
      "y": -70,
      "z": 0,
      "name": "Rock_Stone"
    },
    {
      "x": -4,
      "y": -69,
      "z": 0,
      "name": "Rock_Stone"
    },
    {
      "x": -4,
      "y": -68,
      "z": 0,
      "name": "Rock_Stone"
    },
    {
      "x": -4,
      "y": -67,
      "z": 0,
      "name": "Rock_Stone"
    },
    {
      "x": -4,
      "y": -66,
      "z": 0,
      "name": "Rock_Stone"
    },
    {
      "x": -4,
      "y": -65,
      "z": 0,
      "name": "Rock_Stone"
    },
    {
      "x": -4,
      "y": -64,
      "z": 0,
      "name": "Rock_Stone"
    },
    {
      "x": -4,
      "y": -63,
      "z": 0,
      "name": "Rock_Stone"
    },
    {
      "x": -4,
      "y": -62,
      "z": 0,
      "name": "Rock_Stone"
    },
    {
      "x": -4,
      "y": -61,
      "z": 0,
      "name": "Rock_Stone"
    },
    {
      "x": -4,
      "y": -60,
      "z": 0,
      "name": "Rock_Stone"
    },
    {
      "x": -4,
      "y": -59,
      "z": 0,
      "name": "Rock_Stone"
    },
    {
      "x": -4,
      "y": -58,
      "z": 0,
      "name": "Rock_Stone"
    },
    {
      "x": -4,
      "y": -57,
      "z": 0,
      "name": "Rock_Stone"
    },
    {
      "x": -4,
      "y": -56,
      "z": 0,
      "name": "Rock_Stone"
    },
    {
      "x": -4,
      "y": -55,
      "z": 0,
      "name": "Rock_Stone"
    },
    {
      "x": -4,
      "y": -54,
      "z": 0,
      "name": "Rock_Stone"
    },
    {
      "x": -4,
      "y": -53,
      "z": 0,
      "name": "Rock_Stone"
    },
    {
      "x": -4,
      "y": -52,
      "z": 0,
      "name": "Rock_Stone"
    },
    {
      "x": -4,
      "y": -51,
      "z": 0,
      "name": "Rock_Stone"
    },
    {
      "x": -4,
      "y": -50,
      "z": 0,
      "name": "Rock_Stone"
    },
    {
      "x": -4,
      "y": -49,
      "z": 0,
      "name": "Rock_Stone"
    },
    {
      "x": -4,
      "y": -48,
      "z": 0,
      "name": "Rock_Stone"
    },
    {
      "x": -4,
      "y": -47,
      "z": 0,
      "name": "Rock_Stone"
    },
    {
      "x": -4,
      "y": -46,
      "z": 0,
      "name": "Rock_Stone"
    },
    {
      "x": -4,
      "y": -45,
      "z": 0,
      "name": "Rock_Stone"
    },
    {
      "x": -4,
      "y": -44,
      "z": 0,
      "name": "Rock_Stone"
    },
    {
      "x": -4,
      "y": -43,
      "z": 0,
      "name": "Rock_Stone"
    },
    {
      "x": -4,
      "y": -42,
      "z": 0,
      "name": "Rock_Stone"
    },
    {
      "x": -4,
      "y": -41,
      "z": 0,
      "name": "Rock_Stone"
    },
    {
      "x": -4,
      "y": -40,
      "z": 0,
      "name": "Rock_Stone"
    },
    {
      "x": -4,
      "y": -39,
      "z": 0,
      "name": "Rock_Stone"
    },
    {
      "x": -4,
      "y": -38,
      "z": 0,
      "name": "Rock_Stone"
    },
    {
      "x": -4,
      "y": -37,
      "z": 0,
      "name": "Rock_Stone"
    },
    {
      "x": -4,
      "y": -36,
      "z": 0,
      "name": "Rock_Stone"
    },
    {
      "x": -4,
      "y": -35,
      "z": 0,
      "name": "Rock_Stone"
    },
    {
      "x": -4,
      "y": -34,
      "z": 0,
      "name": "Rock_Stone"
    },
    {
      "x": -4,
      "y": -33,
      "z": 0,
      "name": "Rock_Stone"
    },
    {
      "x": -4,
      "y": -32,
      "z": 0,
      "name": "Rock_Stone"
    },
    {
      "x": -4,
      "y": -31,
      "z": 0,
      "name": "Rock_Stone"
    },
    {
      "x": -4,
      "y": -30,
      "z": 0,
      "name": "Rock_Stone"
    },
    {
      "x": -4,
      "y": -29,
      "z": 0,
      "name": "Rock_Stone"
    },
    {
      "x": -4,
      "y": -28,
      "z": 0,
      "name": "Rock_Stone"
    },
    {
      "x": -4,
      "y": -27,
      "z": 0,
      "name": "Rock_Stone"
    },
    {
      "x": -4,
      "y": -26,
      "z": 0,
      "name": "Rock_Stone"
    },
    {
      "x": -4,
      "y": -25,
      "z": 0,
      "name": "Rock_Stone"
    },
    {
      "x": -4,
      "y": -24,
      "z": 0,
      "name": "Rock_Stone"
    },
    {
      "x": -4,
      "y": -23,
      "z": 0,
      "name": "Rock_Stone"
    },
    {
      "x": -4,
      "y": -22,
      "z": 0,
      "name": "Rock_Stone"
    },
    {
      "x": -4,
      "y": -21,
      "z": 0,
      "name": "Rock_Stone"
    },
    {
      "x": -4,
      "y": -20,
      "z": 0,
      "name": "Rock_Stone"
    },
    {
      "x": -4,
      "y": -19,
      "z": 0,
      "name": "Rock_Stone"
    },
    {
      "x": -4,
      "y": -18,
      "z": 0,
      "name": "Rock_Stone"
    },
    {
      "x": -4,
      "y": -17,
      "z": 0,
      "name": "Rock_Stone"
    },
    {
      "x": -4,
      "y": -16,
      "z": 0,
      "name": "Rock_Stone"
    },
    {
      "x": -4,
      "y": -15,
      "z": 0,
      "name": "Rock_Stone"
    },
    {
      "x": -4,
      "y": -14,
      "z": 0,
      "name": "Rock_Stone"
    },
    {
      "x": -4,
      "y": -13,
      "z": 0,
      "name": "Rock_Stone"
    },
    {
      "x": -4,
      "y": -12,
      "z": 0,
      "name": "Rock_Stone"
    },
    {
      "x": -4,
      "y": -11,
      "z": 0,
      "name": "Rock_Stone"
    },
    {
      "x": -4,
      "y": -10,
      "z": 0,
      "name": "Rock_Stone"
    },
    {
      "x": -4,
      "y": -9,
      "z": 0,
      "name": "Rock_Stone"
    },
    {
      "x": -4,
      "y": -8,
      "z": 0,
      "name": "Rock_Stone"
    },
    {
      "x": -4,
      "y": -7,
      "z": 0,
      "name": "Soil_Dirt_Cold"
    },
    {
      "x": -4,
      "y": -6,
      "z": 0,
      "name": "Soil_Dirt_Cold"
    },
    {
      "x": -4,
      "y": -5,
      "z": 0,
      "name": "Soil_Dirt_Cold"
    },
    {
      "x": -4,
      "y": -74,
      "z": 1,
      "name": "Rock_Stone"
    },
    {
      "x": -4,
      "y": -73,
      "z": 1,
      "name": "Rock_Stone"
    },
    {
      "x": -4,
      "y": -72,
      "z": 1,
      "name": "Rock_Stone"
    },
    {
      "x": -4,
      "y": -71,
      "z": 1,
      "name": "Rock_Stone"
    },
    {
      "x": -4,
      "y": -70,
      "z": 1,
      "name": "Rock_Stone"
    },
    {
      "x": -4,
      "y": -69,
      "z": 1,
      "name": "Rock_Stone"
    },
    {
      "x": -4,
      "y": -68,
      "z": 1,
      "name": "Rock_Stone"
    },
    {
      "x": -4,
      "y": -67,
      "z": 1,
      "name": "Rock_Stone"
    },
    {
      "x": -4,
      "y": -66,
      "z": 1,
      "name": "Rock_Stone"
    },
    {
      "x": -4,
      "y": -65,
      "z": 1,
      "name": "Rock_Stone"
    },
    {
      "x": -4,
      "y": -64,
      "z": 1,
      "name": "Rock_Stone"
    },
    {
      "x": -4,
      "y": -63,
      "z": 1,
      "name": "Rock_Stone"
    },
    {
      "x": -4,
      "y": -62,
      "z": 1,
      "name": "Rock_Stone"
    },
    {
      "x": -4,
      "y": -61,
      "z": 1,
      "name": "Rock_Stone"
    },
    {
      "x": -4,
      "y": -60,
      "z": 1,
      "name": "Rock_Stone"
    },
    {
      "x": -4,
      "y": -59,
      "z": 1,
      "name": "Rock_Stone"
    },
    {
      "x": -4,
      "y": -58,
      "z": 1,
      "name": "Rock_Stone"
    },
    {
      "x": -4,
      "y": -57,
      "z": 1,
      "name": "Rock_Stone"
    },
    {
      "x": -4,
      "y": -56,
      "z": 1,
      "name": "Rock_Stone"
    },
    {
      "x": -4,
      "y": -55,
      "z": 1,
      "name": "Rock_Stone"
    },
    {
      "x": -4,
      "y": -54,
      "z": 1,
      "name": "Rock_Stone"
    },
    {
      "x": -4,
      "y": -53,
      "z": 1,
      "name": "Rock_Stone"
    },
    {
      "x": -4,
      "y": -52,
      "z": 1,
      "name": "Rock_Stone"
    },
    {
      "x": -4,
      "y": -51,
      "z": 1,
      "name": "Rock_Stone"
    },
    {
      "x": -4,
      "y": -50,
      "z": 1,
      "name": "Rock_Stone"
    },
    {
      "x": -4,
      "y": -49,
      "z": 1,
      "name": "Rock_Stone"
    },
    {
      "x": -4,
      "y": -48,
      "z": 1,
      "name": "Rock_Stone"
    },
    {
      "x": -4,
      "y": -47,
      "z": 1,
      "name": "Rock_Stone"
    },
    {
      "x": -4,
      "y": -46,
      "z": 1,
      "name": "Rock_Stone"
    },
    {
      "x": -4,
      "y": -45,
      "z": 1,
      "name": "Rock_Stone"
    },
    {
      "x": -4,
      "y": -44,
      "z": 1,
      "name": "Rock_Stone"
    },
    {
      "x": -4,
      "y": -43,
      "z": 1,
      "name": "Rock_Stone"
    },
    {
      "x": -4,
      "y": -42,
      "z": 1,
      "name": "Rock_Stone"
    },
    {
      "x": -4,
      "y": -41,
      "z": 1,
      "name": "Rock_Stone"
    },
    {
      "x": -4,
      "y": -40,
      "z": 1,
      "name": "Rock_Stone"
    },
    {
      "x": -4,
      "y": -39,
      "z": 1,
      "name": "Rock_Stone"
    },
    {
      "x": -4,
      "y": -38,
      "z": 1,
      "name": "Rock_Stone"
    },
    {
      "x": -4,
      "y": -37,
      "z": 1,
      "name": "Rock_Stone"
    },
    {
      "x": -4,
      "y": -36,
      "z": 1,
      "name": "Rock_Stone"
    },
    {
      "x": -4,
      "y": -35,
      "z": 1,
      "name": "Rock_Stone"
    },
    {
      "x": -4,
      "y": -34,
      "z": 1,
      "name": "Rock_Stone"
    },
    {
      "x": -4,
      "y": -33,
      "z": 1,
      "name": "Rock_Stone"
    },
    {
      "x": -4,
      "y": -32,
      "z": 1,
      "name": "Rock_Stone"
    },
    {
      "x": -4,
      "y": -31,
      "z": 1,
      "name": "Rock_Stone"
    },
    {
      "x": -4,
      "y": -30,
      "z": 1,
      "name": "Rock_Stone"
    },
    {
      "x": -4,
      "y": -29,
      "z": 1,
      "name": "Rock_Stone"
    },
    {
      "x": -4,
      "y": -28,
      "z": 1,
      "name": "Rock_Stone"
    },
    {
      "x": -4,
      "y": -27,
      "z": 1,
      "name": "Rock_Stone"
    },
    {
      "x": -4,
      "y": -26,
      "z": 1,
      "name": "Rock_Stone"
    },
    {
      "x": -4,
      "y": -25,
      "z": 1,
      "name": "Rock_Stone"
    },
    {
      "x": -4,
      "y": -24,
      "z": 1,
      "name": "Rock_Stone"
    },
    {
      "x": -4,
      "y": -23,
      "z": 1,
      "name": "Rock_Stone"
    },
    {
      "x": -4,
      "y": -22,
      "z": 1,
      "name": "Rock_Stone"
    },
    {
      "x": -4,
      "y": -21,
      "z": 1,
      "name": "Rock_Stone"
    },
    {
      "x": -4,
      "y": -20,
      "z": 1,
      "name": "Rock_Stone"
    },
    {
      "x": -4,
      "y": -19,
      "z": 1,
      "name": "Rock_Stone"
    },
    {
      "x": -4,
      "y": -18,
      "z": 1,
      "name": "Rock_Stone"
    },
    {
      "x": -4,
      "y": -17,
      "z": 1,
      "name": "Rock_Stone"
    },
    {
      "x": -4,
      "y": -16,
      "z": 1,
      "name": "Rock_Stone"
    },
    {
      "x": -4,
      "y": -15,
      "z": 1,
      "name": "Rock_Stone"
    },
    {
      "x": -4,
      "y": -14,
      "z": 1,
      "name": "Rock_Stone"
    },
    {
      "x": -4,
      "y": -13,
      "z": 1,
      "name": "Rock_Stone"
    },
    {
      "x": -4,
      "y": -12,
      "z": 1,
      "name": "Rock_Stone"
    },
    {
      "x": -4,
      "y": -11,
      "z": 1,
      "name": "Rock_Stone"
    },
    {
      "x": -4,
      "y": -10,
      "z": 1,
      "name": "Rock_Stone"
    },
    {
      "x": -4,
      "y": -9,
      "z": 1,
      "name": "Rock_Stone"
    },
    {
      "x": -4,
      "y": -8,
      "z": 1,
      "name": "Rock_Stone"
    },
    {
      "x": -4,
      "y": -7,
      "z": 1,
      "name": "Rock_Stone"
    },
    {
      "x": -4,
      "y": -6,
      "z": 1,
      "name": "Rock_Stone"
    },
    {
      "x": -4,
      "y": -5,
      "z": 1,
      "name": "Soil_Dirt_Cold"
    },
    {
      "x": -4,
      "y": -4,
      "z": 1,
      "name": "Soil_Dirt_Cold"
    },
    {
      "x": -4,
      "y": -75,
      "z": 2,
      "name": "Rock_Stone"
    },
    {
      "x": -4,
      "y": -74,
      "z": 2,
      "name": "Rock_Stone"
    },
    {
      "x": -4,
      "y": -73,
      "z": 2,
      "name": "Rock_Stone"
    },
    {
      "x": -4,
      "y": -72,
      "z": 2,
      "name": "Rock_Stone"
    },
    {
      "x": -4,
      "y": -71,
      "z": 2,
      "name": "Rock_Stone"
    },
    {
      "x": -4,
      "y": -70,
      "z": 2,
      "name": "Rock_Stone"
    },
    {
      "x": -4,
      "y": -69,
      "z": 2,
      "name": "Rock_Stone"
    },
    {
      "x": -4,
      "y": -68,
      "z": 2,
      "name": "Rock_Stone"
    },
    {
      "x": -4,
      "y": -67,
      "z": 2,
      "name": "Rock_Stone"
    },
    {
      "x": -4,
      "y": -66,
      "z": 2,
      "name": "Rock_Stone"
    },
    {
      "x": -4,
      "y": -65,
      "z": 2,
      "name": "Rock_Stone"
    },
    {
      "x": -4,
      "y": -64,
      "z": 2,
      "name": "Rock_Stone"
    },
    {
      "x": -4,
      "y": -63,
      "z": 2,
      "name": "Rock_Stone"
    },
    {
      "x": -4,
      "y": -62,
      "z": 2,
      "name": "Rock_Stone"
    },
    {
      "x": -4,
      "y": -61,
      "z": 2,
      "name": "Rock_Stone"
    },
    {
      "x": -4,
      "y": -60,
      "z": 2,
      "name": "Rock_Stone"
    },
    {
      "x": -4,
      "y": -59,
      "z": 2,
      "name": "Rock_Stone"
    },
    {
      "x": -4,
      "y": -58,
      "z": 2,
      "name": "Rock_Stone"
    },
    {
      "x": -4,
      "y": -57,
      "z": 2,
      "name": "Rock_Stone"
    },
    {
      "x": -4,
      "y": -56,
      "z": 2,
      "name": "Rock_Stone"
    },
    {
      "x": -4,
      "y": -55,
      "z": 2,
      "name": "Rock_Stone"
    },
    {
      "x": -4,
      "y": -54,
      "z": 2,
      "name": "Rock_Stone"
    },
    {
      "x": -4,
      "y": -53,
      "z": 2,
      "name": "Rock_Stone"
    },
    {
      "x": -4,
      "y": -52,
      "z": 2,
      "name": "Rock_Stone"
    },
    {
      "x": -4,
      "y": -51,
      "z": 2,
      "name": "Rock_Stone"
    },
    {
      "x": -4,
      "y": -50,
      "z": 2,
      "name": "Rock_Stone"
    },
    {
      "x": -4,
      "y": -49,
      "z": 2,
      "name": "Rock_Stone"
    },
    {
      "x": -4,
      "y": -48,
      "z": 2,
      "name": "Rock_Stone"
    },
    {
      "x": -4,
      "y": -47,
      "z": 2,
      "name": "Rock_Stone"
    },
    {
      "x": -4,
      "y": -46,
      "z": 2,
      "name": "Rock_Stone"
    },
    {
      "x": -4,
      "y": -45,
      "z": 2,
      "name": "Rock_Stone"
    },
    {
      "x": -4,
      "y": -44,
      "z": 2,
      "name": "Rock_Stone"
    },
    {
      "x": -4,
      "y": -43,
      "z": 2,
      "name": "Rock_Stone"
    },
    {
      "x": -4,
      "y": -42,
      "z": 2,
      "name": "Rock_Stone"
    },
    {
      "x": -4,
      "y": -41,
      "z": 2,
      "name": "Rock_Stone"
    },
    {
      "x": -4,
      "y": -40,
      "z": 2,
      "name": "Rock_Stone"
    },
    {
      "x": -4,
      "y": -39,
      "z": 2,
      "name": "Rock_Stone"
    },
    {
      "x": -4,
      "y": -38,
      "z": 2,
      "name": "Rock_Stone"
    },
    {
      "x": -4,
      "y": -37,
      "z": 2,
      "name": "Rock_Stone"
    },
    {
      "x": -4,
      "y": -36,
      "z": 2,
      "name": "Rock_Stone"
    },
    {
      "x": -4,
      "y": -35,
      "z": 2,
      "name": "Rock_Stone"
    },
    {
      "x": -4,
      "y": -34,
      "z": 2,
      "name": "Rock_Stone"
    },
    {
      "x": -4,
      "y": -33,
      "z": 2,
      "name": "Rock_Stone"
    },
    {
      "x": -4,
      "y": -32,
      "z": 2,
      "name": "Rock_Stone"
    },
    {
      "x": -4,
      "y": -31,
      "z": 2,
      "name": "Rock_Stone"
    },
    {
      "x": -4,
      "y": -30,
      "z": 2,
      "name": "Rock_Stone"
    },
    {
      "x": -4,
      "y": -29,
      "z": 2,
      "name": "Rock_Stone"
    },
    {
      "x": -4,
      "y": -28,
      "z": 2,
      "name": "Rock_Stone"
    },
    {
      "x": -4,
      "y": -27,
      "z": 2,
      "name": "Rock_Stone"
    },
    {
      "x": -4,
      "y": -26,
      "z": 2,
      "name": "Rock_Stone"
    },
    {
      "x": -4,
      "y": -25,
      "z": 2,
      "name": "Rock_Stone"
    },
    {
      "x": -4,
      "y": -24,
      "z": 2,
      "name": "Rock_Stone"
    },
    {
      "x": -4,
      "y": -23,
      "z": 2,
      "name": "Rock_Stone"
    },
    {
      "x": -4,
      "y": -22,
      "z": 2,
      "name": "Rock_Stone"
    },
    {
      "x": -4,
      "y": -21,
      "z": 2,
      "name": "Rock_Stone"
    },
    {
      "x": -4,
      "y": -20,
      "z": 2,
      "name": "Rock_Stone"
    },
    {
      "x": -4,
      "y": -19,
      "z": 2,
      "name": "Rock_Stone"
    },
    {
      "x": -4,
      "y": -18,
      "z": 2,
      "name": "Rock_Stone"
    },
    {
      "x": -4,
      "y": -17,
      "z": 2,
      "name": "Rock_Stone"
    },
    {
      "x": -4,
      "y": -16,
      "z": 2,
      "name": "Rock_Stone"
    },
    {
      "x": -4,
      "y": -15,
      "z": 2,
      "name": "Rock_Stone"
    },
    {
      "x": -4,
      "y": -14,
      "z": 2,
      "name": "Rock_Stone"
    },
    {
      "x": -4,
      "y": -13,
      "z": 2,
      "name": "Rock_Stone"
    },
    {
      "x": -4,
      "y": -12,
      "z": 2,
      "name": "Rock_Stone"
    },
    {
      "x": -4,
      "y": -11,
      "z": 2,
      "name": "Rock_Stone"
    },
    {
      "x": -4,
      "y": -10,
      "z": 2,
      "name": "Rock_Stone"
    },
    {
      "x": -4,
      "y": -9,
      "z": 2,
      "name": "Rock_Stone"
    },
    {
      "x": -4,
      "y": -8,
      "z": 2,
      "name": "Rock_Stone"
    },
    {
      "x": -4,
      "y": -7,
      "z": 2,
      "name": "Rock_Stone"
    },
    {
      "x": -4,
      "y": -6,
      "z": 2,
      "name": "Rock_Stone"
    },
    {
      "x": -4,
      "y": -5,
      "z": 2,
      "name": "Rock_Stone"
    },
    {
      "x": -4,
      "y": -4,
      "z": 2,
      "name": "Soil_Grass_Cold"
    },
    {
      "x": -4,
      "y": -74,
      "z": 3,
      "name": "Rock_Stone"
    },
    {
      "x": -4,
      "y": -73,
      "z": 3,
      "name": "Rock_Stone"
    },
    {
      "x": -4,
      "y": -72,
      "z": 3,
      "name": "Rock_Stone"
    },
    {
      "x": -4,
      "y": -71,
      "z": 3,
      "name": "Rock_Stone"
    },
    {
      "x": -4,
      "y": -70,
      "z": 3,
      "name": "Rock_Stone"
    },
    {
      "x": -4,
      "y": -69,
      "z": 3,
      "name": "Rock_Stone"
    },
    {
      "x": -4,
      "y": -68,
      "z": 3,
      "name": "Rock_Stone"
    },
    {
      "x": -4,
      "y": -67,
      "z": 3,
      "name": "Rock_Stone"
    },
    {
      "x": -4,
      "y": -66,
      "z": 3,
      "name": "Rock_Stone"
    },
    {
      "x": -4,
      "y": -65,
      "z": 3,
      "name": "Rock_Stone"
    },
    {
      "x": -4,
      "y": -64,
      "z": 3,
      "name": "Rock_Stone"
    },
    {
      "x": -4,
      "y": -63,
      "z": 3,
      "name": "Rock_Stone"
    },
    {
      "x": -4,
      "y": -62,
      "z": 3,
      "name": "Rock_Stone"
    },
    {
      "x": -4,
      "y": -61,
      "z": 3,
      "name": "Rock_Stone"
    },
    {
      "x": -4,
      "y": -60,
      "z": 3,
      "name": "Rock_Stone"
    },
    {
      "x": -4,
      "y": -59,
      "z": 3,
      "name": "Rock_Stone"
    },
    {
      "x": -4,
      "y": -58,
      "z": 3,
      "name": "Rock_Stone"
    },
    {
      "x": -4,
      "y": -57,
      "z": 3,
      "name": "Rock_Stone"
    },
    {
      "x": -4,
      "y": -56,
      "z": 3,
      "name": "Rock_Stone"
    },
    {
      "x": -4,
      "y": -55,
      "z": 3,
      "name": "Rock_Stone"
    },
    {
      "x": -4,
      "y": -54,
      "z": 3,
      "name": "Rock_Stone"
    },
    {
      "x": -4,
      "y": -53,
      "z": 3,
      "name": "Rock_Stone"
    },
    {
      "x": -4,
      "y": -52,
      "z": 3,
      "name": "Rock_Stone"
    },
    {
      "x": -4,
      "y": -51,
      "z": 3,
      "name": "Rock_Stone"
    },
    {
      "x": -4,
      "y": -50,
      "z": 3,
      "name": "Rock_Stone"
    },
    {
      "x": -4,
      "y": -49,
      "z": 3,
      "name": "Rock_Stone"
    },
    {
      "x": -4,
      "y": -48,
      "z": 3,
      "name": "Rock_Stone"
    },
    {
      "x": -4,
      "y": -47,
      "z": 3,
      "name": "Rock_Stone"
    },
    {
      "x": -4,
      "y": -46,
      "z": 3,
      "name": "Rock_Stone"
    },
    {
      "x": -4,
      "y": -45,
      "z": 3,
      "name": "Rock_Stone"
    },
    {
      "x": -4,
      "y": -44,
      "z": 3,
      "name": "Rock_Stone"
    },
    {
      "x": -4,
      "y": -43,
      "z": 3,
      "name": "Rock_Stone"
    },
    {
      "x": -4,
      "y": -42,
      "z": 3,
      "name": "Rock_Stone"
    },
    {
      "x": -4,
      "y": -41,
      "z": 3,
      "name": "Rock_Stone"
    },
    {
      "x": -4,
      "y": -40,
      "z": 3,
      "name": "Rock_Stone"
    },
    {
      "x": -4,
      "y": -39,
      "z": 3,
      "name": "Rock_Stone"
    },
    {
      "x": -4,
      "y": -38,
      "z": 3,
      "name": "Rock_Stone"
    },
    {
      "x": -4,
      "y": -37,
      "z": 3,
      "name": "Rock_Stone"
    },
    {
      "x": -4,
      "y": -36,
      "z": 3,
      "name": "Rock_Stone"
    },
    {
      "x": -4,
      "y": -35,
      "z": 3,
      "name": "Rock_Stone"
    },
    {
      "x": -4,
      "y": -34,
      "z": 3,
      "name": "Rock_Stone"
    },
    {
      "x": -4,
      "y": -33,
      "z": 3,
      "name": "Rock_Stone"
    },
    {
      "x": -4,
      "y": -32,
      "z": 3,
      "name": "Rock_Stone"
    },
    {
      "x": -4,
      "y": -31,
      "z": 3,
      "name": "Rock_Stone"
    },
    {
      "x": -4,
      "y": -30,
      "z": 3,
      "name": "Rock_Stone"
    },
    {
      "x": -4,
      "y": -29,
      "z": 3,
      "name": "Rock_Stone"
    },
    {
      "x": -4,
      "y": -28,
      "z": 3,
      "name": "Rock_Stone"
    },
    {
      "x": -4,
      "y": -27,
      "z": 3,
      "name": "Rock_Stone"
    },
    {
      "x": -4,
      "y": -26,
      "z": 3,
      "name": "Rock_Stone"
    },
    {
      "x": -4,
      "y": -25,
      "z": 3,
      "name": "Rock_Stone"
    },
    {
      "x": -4,
      "y": -24,
      "z": 3,
      "name": "Rock_Stone"
    },
    {
      "x": -4,
      "y": -23,
      "z": 3,
      "name": "Rock_Stone"
    },
    {
      "x": -4,
      "y": -22,
      "z": 3,
      "name": "Rock_Stone"
    },
    {
      "x": -4,
      "y": -21,
      "z": 3,
      "name": "Rock_Stone"
    },
    {
      "x": -4,
      "y": -20,
      "z": 3,
      "name": "Rock_Stone"
    },
    {
      "x": -4,
      "y": -19,
      "z": 3,
      "name": "Rock_Stone"
    },
    {
      "x": -4,
      "y": -18,
      "z": 3,
      "name": "Rock_Stone"
    },
    {
      "x": -4,
      "y": -17,
      "z": 3,
      "name": "Rock_Stone"
    },
    {
      "x": -4,
      "y": -16,
      "z": 3,
      "name": "Rock_Stone"
    },
    {
      "x": -4,
      "y": -15,
      "z": 3,
      "name": "Rock_Stone"
    },
    {
      "x": -4,
      "y": -14,
      "z": 3,
      "name": "Rock_Stone"
    },
    {
      "x": -4,
      "y": -13,
      "z": 3,
      "name": "Rock_Stone"
    },
    {
      "x": -4,
      "y": -12,
      "z": 3,
      "name": "Rock_Stone"
    },
    {
      "x": -4,
      "y": -11,
      "z": 3,
      "name": "Rock_Stone"
    },
    {
      "x": -4,
      "y": -10,
      "z": 3,
      "name": "Rock_Stone"
    },
    {
      "x": -4,
      "y": -9,
      "z": 3,
      "name": "Rock_Stone"
    },
    {
      "x": -4,
      "y": -8,
      "z": 3,
      "name": "Rock_Stone"
    },
    {
      "x": -4,
      "y": -7,
      "z": 3,
      "name": "Rock_Stone"
    },
    {
      "x": -4,
      "y": -6,
      "z": 3,
      "name": "Rock_Stone"
    },
    {
      "x": -4,
      "y": -5,
      "z": 3,
      "name": "Soil_Dirt_Cold"
    },
    {
      "x": -4,
      "y": -4,
      "z": 3,
      "name": "Soil_Grass_Cold"
    },
    {
      "x": -4,
      "y": -74,
      "z": 4,
      "name": "Rock_Stone"
    },
    {
      "x": -4,
      "y": -73,
      "z": 4,
      "name": "Rock_Stone"
    },
    {
      "x": -4,
      "y": -72,
      "z": 4,
      "name": "Rock_Stone"
    },
    {
      "x": -4,
      "y": -71,
      "z": 4,
      "name": "Rock_Stone"
    },
    {
      "x": -4,
      "y": -70,
      "z": 4,
      "name": "Rock_Stone"
    },
    {
      "x": -4,
      "y": -69,
      "z": 4,
      "name": "Rock_Stone"
    },
    {
      "x": -4,
      "y": -68,
      "z": 4,
      "name": "Rock_Stone"
    },
    {
      "x": -4,
      "y": -67,
      "z": 4,
      "name": "Rock_Stone"
    },
    {
      "x": -4,
      "y": -66,
      "z": 4,
      "name": "Rock_Stone"
    },
    {
      "x": -4,
      "y": -65,
      "z": 4,
      "name": "Rock_Stone"
    },
    {
      "x": -4,
      "y": -64,
      "z": 4,
      "name": "Rock_Stone"
    },
    {
      "x": -4,
      "y": -63,
      "z": 4,
      "name": "Rock_Stone"
    },
    {
      "x": -4,
      "y": -62,
      "z": 4,
      "name": "Rock_Stone"
    },
    {
      "x": -4,
      "y": -61,
      "z": 4,
      "name": "Rock_Stone"
    },
    {
      "x": -4,
      "y": -60,
      "z": 4,
      "name": "Rock_Stone"
    },
    {
      "x": -4,
      "y": -59,
      "z": 4,
      "name": "Rock_Stone"
    },
    {
      "x": -4,
      "y": -58,
      "z": 4,
      "name": "Rock_Stone"
    },
    {
      "x": -4,
      "y": -57,
      "z": 4,
      "name": "Rock_Stone"
    },
    {
      "x": -4,
      "y": -56,
      "z": 4,
      "name": "Rock_Stone"
    },
    {
      "x": -4,
      "y": -55,
      "z": 4,
      "name": "Rock_Stone"
    },
    {
      "x": -4,
      "y": -54,
      "z": 4,
      "name": "Rock_Stone"
    },
    {
      "x": -4,
      "y": -53,
      "z": 4,
      "name": "Rock_Stone"
    },
    {
      "x": -4,
      "y": -52,
      "z": 4,
      "name": "Rock_Stone"
    },
    {
      "x": -4,
      "y": -51,
      "z": 4,
      "name": "Rock_Stone"
    },
    {
      "x": -4,
      "y": -50,
      "z": 4,
      "name": "Rock_Stone"
    },
    {
      "x": -4,
      "y": -49,
      "z": 4,
      "name": "Rock_Stone"
    },
    {
      "x": -4,
      "y": -48,
      "z": 4,
      "name": "Rock_Stone"
    },
    {
      "x": -4,
      "y": -47,
      "z": 4,
      "name": "Rock_Stone"
    },
    {
      "x": -4,
      "y": -46,
      "z": 4,
      "name": "Rock_Stone"
    },
    {
      "x": -4,
      "y": -45,
      "z": 4,
      "name": "Rock_Stone"
    },
    {
      "x": -4,
      "y": -44,
      "z": 4,
      "name": "Rock_Stone"
    },
    {
      "x": -4,
      "y": -43,
      "z": 4,
      "name": "Rock_Stone"
    },
    {
      "x": -4,
      "y": -42,
      "z": 4,
      "name": "Rock_Stone"
    },
    {
      "x": -4,
      "y": -41,
      "z": 4,
      "name": "Rock_Stone"
    },
    {
      "x": -4,
      "y": -40,
      "z": 4,
      "name": "Rock_Stone"
    },
    {
      "x": -4,
      "y": -39,
      "z": 4,
      "name": "Rock_Stone"
    },
    {
      "x": -4,
      "y": -38,
      "z": 4,
      "name": "Rock_Stone"
    },
    {
      "x": -4,
      "y": -37,
      "z": 4,
      "name": "Rock_Stone"
    },
    {
      "x": -4,
      "y": -36,
      "z": 4,
      "name": "Rock_Stone"
    },
    {
      "x": -4,
      "y": -35,
      "z": 4,
      "name": "Rock_Stone"
    },
    {
      "x": -4,
      "y": -34,
      "z": 4,
      "name": "Rock_Stone"
    },
    {
      "x": -4,
      "y": -33,
      "z": 4,
      "name": "Rock_Stone"
    },
    {
      "x": -4,
      "y": -32,
      "z": 4,
      "name": "Rock_Stone"
    },
    {
      "x": -4,
      "y": -31,
      "z": 4,
      "name": "Rock_Stone"
    },
    {
      "x": -4,
      "y": -30,
      "z": 4,
      "name": "Rock_Stone"
    },
    {
      "x": -4,
      "y": -29,
      "z": 4,
      "name": "Rock_Stone"
    },
    {
      "x": -4,
      "y": -28,
      "z": 4,
      "name": "Rock_Stone"
    },
    {
      "x": -4,
      "y": -27,
      "z": 4,
      "name": "Rock_Stone"
    },
    {
      "x": -4,
      "y": -26,
      "z": 4,
      "name": "Rock_Stone"
    },
    {
      "x": -4,
      "y": -25,
      "z": 4,
      "name": "Rock_Stone"
    },
    {
      "x": -4,
      "y": -24,
      "z": 4,
      "name": "Rock_Stone"
    },
    {
      "x": -4,
      "y": -23,
      "z": 4,
      "name": "Rock_Stone"
    },
    {
      "x": -4,
      "y": -22,
      "z": 4,
      "name": "Rock_Stone"
    },
    {
      "x": -4,
      "y": -21,
      "z": 4,
      "name": "Rock_Stone"
    },
    {
      "x": -4,
      "y": -20,
      "z": 4,
      "name": "Rock_Stone"
    },
    {
      "x": -4,
      "y": -19,
      "z": 4,
      "name": "Rock_Stone"
    },
    {
      "x": -4,
      "y": -18,
      "z": 4,
      "name": "Rock_Stone"
    },
    {
      "x": -4,
      "y": -17,
      "z": 4,
      "name": "Rock_Stone"
    },
    {
      "x": -4,
      "y": -16,
      "z": 4,
      "name": "Rock_Stone"
    },
    {
      "x": -4,
      "y": -15,
      "z": 4,
      "name": "Rock_Stone"
    },
    {
      "x": -4,
      "y": -14,
      "z": 4,
      "name": "Rock_Stone"
    },
    {
      "x": -4,
      "y": -13,
      "z": 4,
      "name": "Soil_Dirt_Cold"
    },
    {
      "x": -4,
      "y": -12,
      "z": 4,
      "name": "Soil_Dirt_Cold"
    },
    {
      "x": -4,
      "y": -11,
      "z": 4,
      "name": "Soil_Dirt_Cold"
    },
    {
      "x": -4,
      "y": -10,
      "z": 4,
      "name": "Soil_Dirt_Cold"
    },
    {
      "x": -4,
      "y": -9,
      "z": 4,
      "name": "Soil_Dirt_Cold"
    },
    {
      "x": -4,
      "y": -8,
      "z": 4,
      "name": "Soil_Dirt_Cold"
    },
    {
      "x": -4,
      "y": -7,
      "z": 4,
      "name": "Soil_Dirt_Cold"
    },
    {
      "x": -4,
      "y": -6,
      "z": 4,
      "name": "Soil_Grass_Cold"
    },
    {
      "x": -4,
      "y": -73,
      "z": 5,
      "name": "Rock_Stone"
    },
    {
      "x": -4,
      "y": -72,
      "z": 5,
      "name": "Rock_Stone"
    },
    {
      "x": -4,
      "y": -71,
      "z": 5,
      "name": "Rock_Stone"
    },
    {
      "x": -4,
      "y": -70,
      "z": 5,
      "name": "Rock_Stone"
    },
    {
      "x": -4,
      "y": -69,
      "z": 5,
      "name": "Rock_Stone"
    },
    {
      "x": -4,
      "y": -68,
      "z": 5,
      "name": "Rock_Stone"
    },
    {
      "x": -4,
      "y": -67,
      "z": 5,
      "name": "Rock_Stone"
    },
    {
      "x": -4,
      "y": -66,
      "z": 5,
      "name": "Rock_Stone"
    },
    {
      "x": -4,
      "y": -65,
      "z": 5,
      "name": "Rock_Stone"
    },
    {
      "x": -4,
      "y": -64,
      "z": 5,
      "name": "Rock_Stone"
    },
    {
      "x": -4,
      "y": -63,
      "z": 5,
      "name": "Rock_Stone"
    },
    {
      "x": -4,
      "y": -62,
      "z": 5,
      "name": "Rock_Stone"
    },
    {
      "x": -4,
      "y": -61,
      "z": 5,
      "name": "Rock_Stone"
    },
    {
      "x": -4,
      "y": -60,
      "z": 5,
      "name": "Rock_Stone"
    },
    {
      "x": -4,
      "y": -59,
      "z": 5,
      "name": "Rock_Stone"
    },
    {
      "x": -4,
      "y": -58,
      "z": 5,
      "name": "Rock_Stone"
    },
    {
      "x": -4,
      "y": -57,
      "z": 5,
      "name": "Rock_Stone"
    },
    {
      "x": -4,
      "y": -56,
      "z": 5,
      "name": "Rock_Stone"
    },
    {
      "x": -4,
      "y": -55,
      "z": 5,
      "name": "Rock_Stone"
    },
    {
      "x": -4,
      "y": -54,
      "z": 5,
      "name": "Rock_Stone"
    },
    {
      "x": -4,
      "y": -53,
      "z": 5,
      "name": "Rock_Stone"
    },
    {
      "x": -4,
      "y": -52,
      "z": 5,
      "name": "Rock_Stone"
    },
    {
      "x": -4,
      "y": -51,
      "z": 5,
      "name": "Rock_Stone"
    },
    {
      "x": -4,
      "y": -50,
      "z": 5,
      "name": "Rock_Stone"
    },
    {
      "x": -4,
      "y": -49,
      "z": 5,
      "name": "Rock_Stone"
    },
    {
      "x": -4,
      "y": -48,
      "z": 5,
      "name": "Rock_Stone"
    },
    {
      "x": -4,
      "y": -47,
      "z": 5,
      "name": "Rock_Stone"
    },
    {
      "x": -4,
      "y": -46,
      "z": 5,
      "name": "Rock_Stone"
    },
    {
      "x": -4,
      "y": -45,
      "z": 5,
      "name": "Rock_Stone"
    },
    {
      "x": -4,
      "y": -44,
      "z": 5,
      "name": "Rock_Stone"
    },
    {
      "x": -4,
      "y": -43,
      "z": 5,
      "name": "Rock_Stone"
    },
    {
      "x": -4,
      "y": -42,
      "z": 5,
      "name": "Rock_Stone"
    },
    {
      "x": -4,
      "y": -41,
      "z": 5,
      "name": "Rock_Stone"
    },
    {
      "x": -4,
      "y": -40,
      "z": 5,
      "name": "Rock_Stone"
    },
    {
      "x": -4,
      "y": -39,
      "z": 5,
      "name": "Rock_Stone"
    },
    {
      "x": -4,
      "y": -38,
      "z": 5,
      "name": "Rock_Stone"
    },
    {
      "x": -4,
      "y": -37,
      "z": 5,
      "name": "Rock_Stone"
    },
    {
      "x": -4,
      "y": -36,
      "z": 5,
      "name": "Rock_Stone"
    },
    {
      "x": -4,
      "y": -35,
      "z": 5,
      "name": "Rock_Stone"
    },
    {
      "x": -4,
      "y": -34,
      "z": 5,
      "name": "Rock_Stone"
    },
    {
      "x": -4,
      "y": -33,
      "z": 5,
      "name": "Rock_Stone"
    },
    {
      "x": -4,
      "y": -32,
      "z": 5,
      "name": "Rock_Stone"
    },
    {
      "x": -4,
      "y": -31,
      "z": 5,
      "name": "Rock_Stone"
    },
    {
      "x": -4,
      "y": -30,
      "z": 5,
      "name": "Rock_Stone"
    },
    {
      "x": -4,
      "y": -29,
      "z": 5,
      "name": "Rock_Stone"
    },
    {
      "x": -4,
      "y": -28,
      "z": 5,
      "name": "Rock_Stone"
    },
    {
      "x": -4,
      "y": -27,
      "z": 5,
      "name": "Rock_Stone"
    },
    {
      "x": -4,
      "y": -26,
      "z": 5,
      "name": "Rock_Stone"
    },
    {
      "x": -4,
      "y": -25,
      "z": 5,
      "name": "Rock_Stone"
    },
    {
      "x": -4,
      "y": -24,
      "z": 5,
      "name": "Rock_Stone"
    },
    {
      "x": -4,
      "y": -23,
      "z": 5,
      "name": "Rock_Stone"
    },
    {
      "x": -4,
      "y": -22,
      "z": 5,
      "name": "Rock_Stone"
    },
    {
      "x": -4,
      "y": -21,
      "z": 5,
      "name": "Rock_Stone"
    },
    {
      "x": -4,
      "y": -20,
      "z": 5,
      "name": "Rock_Stone"
    },
    {
      "x": -4,
      "y": -19,
      "z": 5,
      "name": "Rock_Stone"
    },
    {
      "x": -4,
      "y": -18,
      "z": 5,
      "name": "Rock_Stone"
    },
    {
      "x": -4,
      "y": -17,
      "z": 5,
      "name": "Soil_Dirt_Cold"
    },
    {
      "x": -4,
      "y": -16,
      "z": 5,
      "name": "Soil_Dirt_Cold"
    },
    {
      "x": -4,
      "y": -15,
      "z": 5,
      "name": "Soil_Dirt_Cold"
    },
    {
      "x": -4,
      "y": -14,
      "z": 5,
      "name": "Soil_Dirt_Cold"
    },
    {
      "x": -4,
      "y": -56,
      "z": 6,
      "name": "Rock_Stone"
    },
    {
      "x": -4,
      "y": -55,
      "z": 6,
      "name": "Rock_Stone"
    },
    {
      "x": -4,
      "y": -54,
      "z": 6,
      "name": "Rock_Stone"
    },
    {
      "x": -4,
      "y": -53,
      "z": 6,
      "name": "Rock_Stone"
    },
    {
      "x": -4,
      "y": -52,
      "z": 6,
      "name": "Rock_Stone"
    },
    {
      "x": -4,
      "y": -51,
      "z": 6,
      "name": "Rock_Stone"
    },
    {
      "x": -4,
      "y": -50,
      "z": 6,
      "name": "Rock_Stone"
    },
    {
      "x": -4,
      "y": -49,
      "z": 6,
      "name": "Rock_Stone"
    },
    {
      "x": -4,
      "y": -48,
      "z": 6,
      "name": "Rock_Stone"
    },
    {
      "x": -4,
      "y": -47,
      "z": 6,
      "name": "Rock_Stone"
    },
    {
      "x": -4,
      "y": -46,
      "z": 6,
      "name": "Rock_Stone"
    },
    {
      "x": -4,
      "y": -45,
      "z": 6,
      "name": "Rock_Stone"
    },
    {
      "x": -4,
      "y": -44,
      "z": 6,
      "name": "Rock_Stone"
    },
    {
      "x": -4,
      "y": -43,
      "z": 6,
      "name": "Rock_Stone"
    },
    {
      "x": -4,
      "y": -42,
      "z": 6,
      "name": "Rock_Stone"
    },
    {
      "x": -4,
      "y": -41,
      "z": 6,
      "name": "Rock_Stone"
    },
    {
      "x": -4,
      "y": -40,
      "z": 6,
      "name": "Rock_Stone"
    },
    {
      "x": -3,
      "y": -72,
      "z": -2,
      "name": "Rock_Stone"
    },
    {
      "x": -3,
      "y": -71,
      "z": -2,
      "name": "Rock_Stone"
    },
    {
      "x": -3,
      "y": -70,
      "z": -2,
      "name": "Rock_Stone"
    },
    {
      "x": -3,
      "y": -69,
      "z": -2,
      "name": "Rock_Stone"
    },
    {
      "x": -3,
      "y": -68,
      "z": -2,
      "name": "Rock_Stone"
    },
    {
      "x": -3,
      "y": -67,
      "z": -2,
      "name": "Rock_Stone"
    },
    {
      "x": -3,
      "y": -66,
      "z": -2,
      "name": "Rock_Stone"
    },
    {
      "x": -3,
      "y": -65,
      "z": -2,
      "name": "Rock_Stone"
    },
    {
      "x": -3,
      "y": -64,
      "z": -2,
      "name": "Rock_Stone"
    },
    {
      "x": -3,
      "y": -63,
      "z": -2,
      "name": "Rock_Stone"
    },
    {
      "x": -3,
      "y": -62,
      "z": -2,
      "name": "Rock_Stone"
    },
    {
      "x": -3,
      "y": -61,
      "z": -2,
      "name": "Rock_Stone"
    },
    {
      "x": -3,
      "y": -60,
      "z": -2,
      "name": "Rock_Stone"
    },
    {
      "x": -3,
      "y": -59,
      "z": -2,
      "name": "Rock_Stone"
    },
    {
      "x": -3,
      "y": -58,
      "z": -2,
      "name": "Rock_Stone"
    },
    {
      "x": -3,
      "y": -57,
      "z": -2,
      "name": "Rock_Stone"
    },
    {
      "x": -3,
      "y": -56,
      "z": -2,
      "name": "Rock_Stone"
    },
    {
      "x": -3,
      "y": -55,
      "z": -2,
      "name": "Rock_Stone"
    },
    {
      "x": -3,
      "y": -54,
      "z": -2,
      "name": "Rock_Stone"
    },
    {
      "x": -3,
      "y": -53,
      "z": -2,
      "name": "Rock_Stone"
    },
    {
      "x": -3,
      "y": -52,
      "z": -2,
      "name": "Rock_Stone"
    },
    {
      "x": -3,
      "y": -51,
      "z": -2,
      "name": "Rock_Stone"
    },
    {
      "x": -3,
      "y": -50,
      "z": -2,
      "name": "Rock_Stone"
    },
    {
      "x": -3,
      "y": -49,
      "z": -2,
      "name": "Rock_Stone"
    },
    {
      "x": -3,
      "y": -48,
      "z": -2,
      "name": "Rock_Stone"
    },
    {
      "x": -3,
      "y": -47,
      "z": -2,
      "name": "Rock_Stone"
    },
    {
      "x": -3,
      "y": -46,
      "z": -2,
      "name": "Rock_Stone"
    },
    {
      "x": -3,
      "y": -45,
      "z": -2,
      "name": "Rock_Stone"
    },
    {
      "x": -3,
      "y": -44,
      "z": -2,
      "name": "Rock_Stone"
    },
    {
      "x": -3,
      "y": -43,
      "z": -2,
      "name": "Rock_Stone"
    },
    {
      "x": -3,
      "y": -42,
      "z": -2,
      "name": "Rock_Stone"
    },
    {
      "x": -3,
      "y": -41,
      "z": -2,
      "name": "Rock_Stone"
    },
    {
      "x": -3,
      "y": -40,
      "z": -2,
      "name": "Rock_Stone"
    },
    {
      "x": -3,
      "y": -39,
      "z": -2,
      "name": "Rock_Stone"
    },
    {
      "x": -3,
      "y": -38,
      "z": -2,
      "name": "Rock_Stone"
    },
    {
      "x": -3,
      "y": -37,
      "z": -2,
      "name": "Rock_Stone"
    },
    {
      "x": -3,
      "y": -36,
      "z": -2,
      "name": "Rock_Stone"
    },
    {
      "x": -3,
      "y": -35,
      "z": -2,
      "name": "Rock_Stone"
    },
    {
      "x": -3,
      "y": -34,
      "z": -2,
      "name": "Rock_Stone"
    },
    {
      "x": -3,
      "y": -33,
      "z": -2,
      "name": "Rock_Stone"
    },
    {
      "x": -3,
      "y": -32,
      "z": -2,
      "name": "Rock_Stone"
    },
    {
      "x": -3,
      "y": -31,
      "z": -2,
      "name": "Rock_Stone"
    },
    {
      "x": -3,
      "y": -30,
      "z": -2,
      "name": "Rock_Stone"
    },
    {
      "x": -3,
      "y": -29,
      "z": -2,
      "name": "Rock_Stone"
    },
    {
      "x": -3,
      "y": -28,
      "z": -2,
      "name": "Rock_Stone"
    },
    {
      "x": -3,
      "y": -27,
      "z": -2,
      "name": "Rock_Stone"
    },
    {
      "x": -3,
      "y": -26,
      "z": -2,
      "name": "Rock_Stone"
    },
    {
      "x": -3,
      "y": -25,
      "z": -2,
      "name": "Rock_Stone"
    },
    {
      "x": -3,
      "y": -24,
      "z": -2,
      "name": "Rock_Stone"
    },
    {
      "x": -3,
      "y": -74,
      "z": -1,
      "name": "Rock_Stone"
    },
    {
      "x": -3,
      "y": -73,
      "z": -1,
      "name": "Rock_Stone"
    },
    {
      "x": -3,
      "y": -72,
      "z": -1,
      "name": "Rock_Stone"
    },
    {
      "x": -3,
      "y": -71,
      "z": -1,
      "name": "Rock_Stone"
    },
    {
      "x": -3,
      "y": -70,
      "z": -1,
      "name": "Rock_Stone"
    },
    {
      "x": -3,
      "y": -69,
      "z": -1,
      "name": "Rock_Stone"
    },
    {
      "x": -3,
      "y": -68,
      "z": -1,
      "name": "Rock_Stone"
    },
    {
      "x": -3,
      "y": -67,
      "z": -1,
      "name": "Rock_Stone"
    },
    {
      "x": -3,
      "y": -66,
      "z": -1,
      "name": "Rock_Stone"
    },
    {
      "x": -3,
      "y": -65,
      "z": -1,
      "name": "Rock_Stone"
    },
    {
      "x": -3,
      "y": -64,
      "z": -1,
      "name": "Rock_Stone"
    },
    {
      "x": -3,
      "y": -63,
      "z": -1,
      "name": "Rock_Stone"
    },
    {
      "x": -3,
      "y": -62,
      "z": -1,
      "name": "Rock_Stone"
    },
    {
      "x": -3,
      "y": -61,
      "z": -1,
      "name": "Rock_Stone"
    },
    {
      "x": -3,
      "y": -60,
      "z": -1,
      "name": "Rock_Stone"
    },
    {
      "x": -3,
      "y": -59,
      "z": -1,
      "name": "Rock_Stone"
    },
    {
      "x": -3,
      "y": -58,
      "z": -1,
      "name": "Rock_Stone"
    },
    {
      "x": -3,
      "y": -57,
      "z": -1,
      "name": "Rock_Stone"
    },
    {
      "x": -3,
      "y": -56,
      "z": -1,
      "name": "Rock_Stone"
    },
    {
      "x": -3,
      "y": -55,
      "z": -1,
      "name": "Rock_Stone"
    },
    {
      "x": -3,
      "y": -54,
      "z": -1,
      "name": "Rock_Stone"
    },
    {
      "x": -3,
      "y": -53,
      "z": -1,
      "name": "Rock_Stone"
    },
    {
      "x": -3,
      "y": -52,
      "z": -1,
      "name": "Rock_Stone"
    },
    {
      "x": -3,
      "y": -51,
      "z": -1,
      "name": "Rock_Stone"
    },
    {
      "x": -3,
      "y": -50,
      "z": -1,
      "name": "Rock_Stone"
    },
    {
      "x": -3,
      "y": -49,
      "z": -1,
      "name": "Rock_Stone"
    },
    {
      "x": -3,
      "y": -48,
      "z": -1,
      "name": "Rock_Stone"
    },
    {
      "x": -3,
      "y": -47,
      "z": -1,
      "name": "Rock_Stone"
    },
    {
      "x": -3,
      "y": -46,
      "z": -1,
      "name": "Rock_Stone"
    },
    {
      "x": -3,
      "y": -45,
      "z": -1,
      "name": "Rock_Stone"
    },
    {
      "x": -3,
      "y": -44,
      "z": -1,
      "name": "Rock_Stone"
    },
    {
      "x": -3,
      "y": -43,
      "z": -1,
      "name": "Rock_Stone"
    },
    {
      "x": -3,
      "y": -42,
      "z": -1,
      "name": "Rock_Stone"
    },
    {
      "x": -3,
      "y": -41,
      "z": -1,
      "name": "Rock_Stone"
    },
    {
      "x": -3,
      "y": -40,
      "z": -1,
      "name": "Rock_Stone"
    },
    {
      "x": -3,
      "y": -39,
      "z": -1,
      "name": "Rock_Stone"
    },
    {
      "x": -3,
      "y": -38,
      "z": -1,
      "name": "Rock_Stone"
    },
    {
      "x": -3,
      "y": -37,
      "z": -1,
      "name": "Rock_Stone"
    },
    {
      "x": -3,
      "y": -36,
      "z": -1,
      "name": "Rock_Stone"
    },
    {
      "x": -3,
      "y": -35,
      "z": -1,
      "name": "Rock_Stone"
    },
    {
      "x": -3,
      "y": -34,
      "z": -1,
      "name": "Rock_Stone"
    },
    {
      "x": -3,
      "y": -33,
      "z": -1,
      "name": "Rock_Stone"
    },
    {
      "x": -3,
      "y": -32,
      "z": -1,
      "name": "Rock_Stone"
    },
    {
      "x": -3,
      "y": -31,
      "z": -1,
      "name": "Rock_Stone"
    },
    {
      "x": -3,
      "y": -30,
      "z": -1,
      "name": "Rock_Stone"
    },
    {
      "x": -3,
      "y": -29,
      "z": -1,
      "name": "Rock_Stone"
    },
    {
      "x": -3,
      "y": -28,
      "z": -1,
      "name": "Rock_Stone"
    },
    {
      "x": -3,
      "y": -27,
      "z": -1,
      "name": "Rock_Stone"
    },
    {
      "x": -3,
      "y": -26,
      "z": -1,
      "name": "Rock_Stone"
    },
    {
      "x": -3,
      "y": -25,
      "z": -1,
      "name": "Rock_Stone"
    },
    {
      "x": -3,
      "y": -24,
      "z": -1,
      "name": "Rock_Stone"
    },
    {
      "x": -3,
      "y": -23,
      "z": -1,
      "name": "Rock_Stone"
    },
    {
      "x": -3,
      "y": -22,
      "z": -1,
      "name": "Rock_Stone"
    },
    {
      "x": -3,
      "y": -21,
      "z": -1,
      "name": "Rock_Stone"
    },
    {
      "x": -3,
      "y": -20,
      "z": -1,
      "name": "Rock_Stone"
    },
    {
      "x": -3,
      "y": -19,
      "z": -1,
      "name": "Rock_Stone"
    },
    {
      "x": -3,
      "y": -18,
      "z": -1,
      "name": "Rock_Stone"
    },
    {
      "x": -3,
      "y": -17,
      "z": -1,
      "name": "Rock_Stone"
    },
    {
      "x": -3,
      "y": -16,
      "z": -1,
      "name": "Rock_Stone"
    },
    {
      "x": -3,
      "y": -15,
      "z": -1,
      "name": "Soil_Dirt_Cold"
    },
    {
      "x": -3,
      "y": -14,
      "z": -1,
      "name": "Soil_Dirt_Cold"
    },
    {
      "x": -3,
      "y": -13,
      "z": -1,
      "name": "Soil_Dirt_Cold"
    },
    {
      "x": -3,
      "y": -12,
      "z": -1,
      "name": "Soil_Dirt_Cold"
    },
    {
      "x": -3,
      "y": -11,
      "z": -1,
      "name": "Soil_Dirt_Cold"
    },
    {
      "x": -3,
      "y": -10,
      "z": -1,
      "name": "Soil_Dirt_Cold"
    },
    {
      "x": -3,
      "y": -9,
      "z": -1,
      "name": "Soil_Dirt_Cold"
    },
    {
      "x": -3,
      "y": -8,
      "z": -1,
      "name": "Soil_Dirt_Cold"
    },
    {
      "x": -3,
      "y": -7,
      "z": -1,
      "name": "Soil_Dirt_Cold"
    },
    {
      "x": -3,
      "y": -6,
      "z": -1,
      "name": "Soil_Dirt_Cold"
    },
    {
      "x": -3,
      "y": -74,
      "z": 0,
      "name": "Rock_Stone"
    },
    {
      "x": -3,
      "y": -73,
      "z": 0,
      "name": "Rock_Stone"
    },
    {
      "x": -3,
      "y": -72,
      "z": 0,
      "name": "Rock_Stone"
    },
    {
      "x": -3,
      "y": -71,
      "z": 0,
      "name": "Rock_Stone"
    },
    {
      "x": -3,
      "y": -70,
      "z": 0,
      "name": "Rock_Stone"
    },
    {
      "x": -3,
      "y": -69,
      "z": 0,
      "name": "Rock_Stone"
    },
    {
      "x": -3,
      "y": -68,
      "z": 0,
      "name": "Rock_Stone"
    },
    {
      "x": -3,
      "y": -67,
      "z": 0,
      "name": "Rock_Stone"
    },
    {
      "x": -3,
      "y": -66,
      "z": 0,
      "name": "Rock_Stone"
    },
    {
      "x": -3,
      "y": -65,
      "z": 0,
      "name": "Rock_Stone"
    },
    {
      "x": -3,
      "y": -64,
      "z": 0,
      "name": "Rock_Stone"
    },
    {
      "x": -3,
      "y": -63,
      "z": 0,
      "name": "Rock_Stone"
    },
    {
      "x": -3,
      "y": -62,
      "z": 0,
      "name": "Rock_Stone"
    },
    {
      "x": -3,
      "y": -61,
      "z": 0,
      "name": "Rock_Stone"
    },
    {
      "x": -3,
      "y": -60,
      "z": 0,
      "name": "Rock_Stone"
    },
    {
      "x": -3,
      "y": -59,
      "z": 0,
      "name": "Rock_Stone"
    },
    {
      "x": -3,
      "y": -58,
      "z": 0,
      "name": "Rock_Stone"
    },
    {
      "x": -3,
      "y": -57,
      "z": 0,
      "name": "Rock_Stone"
    },
    {
      "x": -3,
      "y": -56,
      "z": 0,
      "name": "Rock_Stone"
    },
    {
      "x": -3,
      "y": -55,
      "z": 0,
      "name": "Rock_Stone"
    },
    {
      "x": -3,
      "y": -54,
      "z": 0,
      "name": "Rock_Stone"
    },
    {
      "x": -3,
      "y": -53,
      "z": 0,
      "name": "Rock_Stone"
    },
    {
      "x": -3,
      "y": -52,
      "z": 0,
      "name": "Rock_Stone"
    },
    {
      "x": -3,
      "y": -51,
      "z": 0,
      "name": "Rock_Stone"
    },
    {
      "x": -3,
      "y": -50,
      "z": 0,
      "name": "Rock_Stone"
    },
    {
      "x": -3,
      "y": -49,
      "z": 0,
      "name": "Rock_Stone"
    },
    {
      "x": -3,
      "y": -48,
      "z": 0,
      "name": "Rock_Stone"
    },
    {
      "x": -3,
      "y": -47,
      "z": 0,
      "name": "Rock_Stone"
    },
    {
      "x": -3,
      "y": -46,
      "z": 0,
      "name": "Rock_Stone"
    },
    {
      "x": -3,
      "y": -45,
      "z": 0,
      "name": "Rock_Stone"
    },
    {
      "x": -3,
      "y": -44,
      "z": 0,
      "name": "Rock_Stone"
    },
    {
      "x": -3,
      "y": -43,
      "z": 0,
      "name": "Rock_Stone"
    },
    {
      "x": -3,
      "y": -42,
      "z": 0,
      "name": "Rock_Stone"
    },
    {
      "x": -3,
      "y": -41,
      "z": 0,
      "name": "Rock_Stone"
    },
    {
      "x": -3,
      "y": -40,
      "z": 0,
      "name": "Rock_Stone"
    },
    {
      "x": -3,
      "y": -39,
      "z": 0,
      "name": "Rock_Stone"
    },
    {
      "x": -3,
      "y": -38,
      "z": 0,
      "name": "Rock_Stone"
    },
    {
      "x": -3,
      "y": -37,
      "z": 0,
      "name": "Rock_Stone"
    },
    {
      "x": -3,
      "y": -36,
      "z": 0,
      "name": "Rock_Stone"
    },
    {
      "x": -3,
      "y": -35,
      "z": 0,
      "name": "Rock_Stone"
    },
    {
      "x": -3,
      "y": -34,
      "z": 0,
      "name": "Rock_Stone"
    },
    {
      "x": -3,
      "y": -33,
      "z": 0,
      "name": "Rock_Stone"
    },
    {
      "x": -3,
      "y": -32,
      "z": 0,
      "name": "Rock_Stone"
    },
    {
      "x": -3,
      "y": -31,
      "z": 0,
      "name": "Rock_Stone"
    },
    {
      "x": -3,
      "y": -30,
      "z": 0,
      "name": "Rock_Stone"
    },
    {
      "x": -3,
      "y": -29,
      "z": 0,
      "name": "Rock_Stone"
    },
    {
      "x": -3,
      "y": -28,
      "z": 0,
      "name": "Rock_Stone"
    },
    {
      "x": -3,
      "y": -27,
      "z": 0,
      "name": "Rock_Stone"
    },
    {
      "x": -3,
      "y": -26,
      "z": 0,
      "name": "Rock_Stone"
    },
    {
      "x": -3,
      "y": -25,
      "z": 0,
      "name": "Rock_Stone"
    },
    {
      "x": -3,
      "y": -24,
      "z": 0,
      "name": "Rock_Stone"
    },
    {
      "x": -3,
      "y": -23,
      "z": 0,
      "name": "Rock_Stone"
    },
    {
      "x": -3,
      "y": -22,
      "z": 0,
      "name": "Rock_Stone"
    },
    {
      "x": -3,
      "y": -21,
      "z": 0,
      "name": "Rock_Stone"
    },
    {
      "x": -3,
      "y": -20,
      "z": 0,
      "name": "Rock_Stone"
    },
    {
      "x": -3,
      "y": -19,
      "z": 0,
      "name": "Rock_Stone"
    },
    {
      "x": -3,
      "y": -18,
      "z": 0,
      "name": "Rock_Stone"
    },
    {
      "x": -3,
      "y": -17,
      "z": 0,
      "name": "Rock_Stone"
    },
    {
      "x": -3,
      "y": -16,
      "z": 0,
      "name": "Rock_Stone"
    },
    {
      "x": -3,
      "y": -15,
      "z": 0,
      "name": "Rock_Stone"
    },
    {
      "x": -3,
      "y": -14,
      "z": 0,
      "name": "Rock_Stone"
    },
    {
      "x": -3,
      "y": -13,
      "z": 0,
      "name": "Rock_Stone"
    },
    {
      "x": -3,
      "y": -12,
      "z": 0,
      "name": "Rock_Stone"
    },
    {
      "x": -3,
      "y": -11,
      "z": 0,
      "name": "Rock_Stone"
    },
    {
      "x": -3,
      "y": -10,
      "z": 0,
      "name": "Rock_Stone"
    },
    {
      "x": -3,
      "y": -9,
      "z": 0,
      "name": "Rock_Stone"
    },
    {
      "x": -3,
      "y": -8,
      "z": 0,
      "name": "Rock_Stone"
    },
    {
      "x": -3,
      "y": -7,
      "z": 0,
      "name": "Rock_Stone"
    },
    {
      "x": -3,
      "y": -6,
      "z": 0,
      "name": "Rock_Stone"
    },
    {
      "x": -3,
      "y": -5,
      "z": 0,
      "name": "Soil_Dirt_Cold"
    },
    {
      "x": -3,
      "y": -4,
      "z": 0,
      "name": "Soil_Dirt_Cold"
    },
    {
      "x": -3,
      "y": -3,
      "z": 0,
      "name": "Soil_Dirt_Cold"
    },
    {
      "x": -3,
      "y": -75,
      "z": 1,
      "name": "Rock_Stone"
    },
    {
      "x": -3,
      "y": -74,
      "z": 1,
      "name": "Rock_Stone"
    },
    {
      "x": -3,
      "y": -73,
      "z": 1,
      "name": "Rock_Stone"
    },
    {
      "x": -3,
      "y": -72,
      "z": 1,
      "name": "Rock_Stone"
    },
    {
      "x": -3,
      "y": -71,
      "z": 1,
      "name": "Rock_Stone"
    },
    {
      "x": -3,
      "y": -70,
      "z": 1,
      "name": "Rock_Stone"
    },
    {
      "x": -3,
      "y": -69,
      "z": 1,
      "name": "Rock_Stone"
    },
    {
      "x": -3,
      "y": -68,
      "z": 1,
      "name": "Rock_Stone"
    },
    {
      "x": -3,
      "y": -67,
      "z": 1,
      "name": "Rock_Stone"
    },
    {
      "x": -3,
      "y": -66,
      "z": 1,
      "name": "Rock_Stone"
    },
    {
      "x": -3,
      "y": -65,
      "z": 1,
      "name": "Rock_Stone"
    },
    {
      "x": -3,
      "y": -64,
      "z": 1,
      "name": "Rock_Stone"
    },
    {
      "x": -3,
      "y": -63,
      "z": 1,
      "name": "Rock_Stone"
    },
    {
      "x": -3,
      "y": -62,
      "z": 1,
      "name": "Rock_Stone"
    },
    {
      "x": -3,
      "y": -61,
      "z": 1,
      "name": "Rock_Stone"
    },
    {
      "x": -3,
      "y": -60,
      "z": 1,
      "name": "Rock_Stone"
    },
    {
      "x": -3,
      "y": -59,
      "z": 1,
      "name": "Rock_Stone"
    },
    {
      "x": -3,
      "y": -58,
      "z": 1,
      "name": "Rock_Stone"
    },
    {
      "x": -3,
      "y": -57,
      "z": 1,
      "name": "Rock_Stone"
    },
    {
      "x": -3,
      "y": -56,
      "z": 1,
      "name": "Rock_Stone"
    },
    {
      "x": -3,
      "y": -55,
      "z": 1,
      "name": "Rock_Stone"
    },
    {
      "x": -3,
      "y": -54,
      "z": 1,
      "name": "Rock_Stone"
    },
    {
      "x": -3,
      "y": -53,
      "z": 1,
      "name": "Rock_Stone"
    },
    {
      "x": -3,
      "y": -52,
      "z": 1,
      "name": "Rock_Stone"
    },
    {
      "x": -3,
      "y": -51,
      "z": 1,
      "name": "Rock_Stone"
    },
    {
      "x": -3,
      "y": -50,
      "z": 1,
      "name": "Rock_Stone"
    },
    {
      "x": -3,
      "y": -49,
      "z": 1,
      "name": "Rock_Stone"
    },
    {
      "x": -3,
      "y": -48,
      "z": 1,
      "name": "Rock_Stone"
    },
    {
      "x": -3,
      "y": -47,
      "z": 1,
      "name": "Rock_Stone"
    },
    {
      "x": -3,
      "y": -46,
      "z": 1,
      "name": "Rock_Stone"
    },
    {
      "x": -3,
      "y": -45,
      "z": 1,
      "name": "Rock_Stone"
    },
    {
      "x": -3,
      "y": -44,
      "z": 1,
      "name": "Rock_Stone"
    },
    {
      "x": -3,
      "y": -43,
      "z": 1,
      "name": "Rock_Stone"
    },
    {
      "x": -3,
      "y": -42,
      "z": 1,
      "name": "Rock_Stone"
    },
    {
      "x": -3,
      "y": -41,
      "z": 1,
      "name": "Rock_Stone"
    },
    {
      "x": -3,
      "y": -40,
      "z": 1,
      "name": "Rock_Stone"
    },
    {
      "x": -3,
      "y": -39,
      "z": 1,
      "name": "Rock_Stone"
    },
    {
      "x": -3,
      "y": -38,
      "z": 1,
      "name": "Rock_Stone"
    },
    {
      "x": -3,
      "y": -37,
      "z": 1,
      "name": "Rock_Stone"
    },
    {
      "x": -3,
      "y": -36,
      "z": 1,
      "name": "Rock_Stone"
    },
    {
      "x": -3,
      "y": -35,
      "z": 1,
      "name": "Rock_Stone"
    },
    {
      "x": -3,
      "y": -34,
      "z": 1,
      "name": "Rock_Stone"
    },
    {
      "x": -3,
      "y": -33,
      "z": 1,
      "name": "Rock_Stone"
    },
    {
      "x": -3,
      "y": -32,
      "z": 1,
      "name": "Rock_Stone"
    },
    {
      "x": -3,
      "y": -31,
      "z": 1,
      "name": "Rock_Stone"
    },
    {
      "x": -3,
      "y": -30,
      "z": 1,
      "name": "Rock_Stone"
    },
    {
      "x": -3,
      "y": -29,
      "z": 1,
      "name": "Rock_Stone"
    },
    {
      "x": -3,
      "y": -28,
      "z": 1,
      "name": "Rock_Stone"
    },
    {
      "x": -3,
      "y": -27,
      "z": 1,
      "name": "Rock_Stone"
    },
    {
      "x": -3,
      "y": -26,
      "z": 1,
      "name": "Rock_Stone"
    },
    {
      "x": -3,
      "y": -25,
      "z": 1,
      "name": "Rock_Stone"
    },
    {
      "x": -3,
      "y": -24,
      "z": 1,
      "name": "Rock_Stone"
    },
    {
      "x": -3,
      "y": -23,
      "z": 1,
      "name": "Rock_Stone"
    },
    {
      "x": -3,
      "y": -22,
      "z": 1,
      "name": "Rock_Stone"
    },
    {
      "x": -3,
      "y": -21,
      "z": 1,
      "name": "Rock_Stone"
    },
    {
      "x": -3,
      "y": -20,
      "z": 1,
      "name": "Rock_Stone"
    },
    {
      "x": -3,
      "y": -19,
      "z": 1,
      "name": "Rock_Stone"
    },
    {
      "x": -3,
      "y": -18,
      "z": 1,
      "name": "Rock_Stone"
    },
    {
      "x": -3,
      "y": -17,
      "z": 1,
      "name": "Rock_Stone"
    },
    {
      "x": -3,
      "y": -16,
      "z": 1,
      "name": "Rock_Stone"
    },
    {
      "x": -3,
      "y": -15,
      "z": 1,
      "name": "Rock_Stone"
    },
    {
      "x": -3,
      "y": -14,
      "z": 1,
      "name": "Rock_Stone"
    },
    {
      "x": -3,
      "y": -13,
      "z": 1,
      "name": "Rock_Stone"
    },
    {
      "x": -3,
      "y": -12,
      "z": 1,
      "name": "Rock_Stone"
    },
    {
      "x": -3,
      "y": -11,
      "z": 1,
      "name": "Rock_Stone"
    },
    {
      "x": -3,
      "y": -10,
      "z": 1,
      "name": "Rock_Stone"
    },
    {
      "x": -3,
      "y": -9,
      "z": 1,
      "name": "Rock_Stone"
    },
    {
      "x": -3,
      "y": -8,
      "z": 1,
      "name": "Rock_Stone"
    },
    {
      "x": -3,
      "y": -7,
      "z": 1,
      "name": "Rock_Stone"
    },
    {
      "x": -3,
      "y": -6,
      "z": 1,
      "name": "Rock_Stone"
    },
    {
      "x": -3,
      "y": -5,
      "z": 1,
      "name": "Rock_Stone"
    },
    {
      "x": -3,
      "y": -4,
      "z": 1,
      "name": "Rock_Stone"
    },
    {
      "x": -3,
      "y": -3,
      "z": 1,
      "name": "Soil_Dirt_Cold"
    },
    {
      "x": -3,
      "y": -2,
      "z": 1,
      "name": "Soil_Dirt_Cold"
    },
    {
      "x": -3,
      "y": -1,
      "z": 1,
      "name": "Soil_Grass_Cold"
    },
    {
      "x": -3,
      "y": -75,
      "z": 2,
      "name": "Rock_Stone"
    },
    {
      "x": -3,
      "y": -74,
      "z": 2,
      "name": "Rock_Stone"
    },
    {
      "x": -3,
      "y": -73,
      "z": 2,
      "name": "Rock_Stone"
    },
    {
      "x": -3,
      "y": -72,
      "z": 2,
      "name": "Rock_Stone"
    },
    {
      "x": -3,
      "y": -71,
      "z": 2,
      "name": "Rock_Stone"
    },
    {
      "x": -3,
      "y": -70,
      "z": 2,
      "name": "Rock_Stone"
    },
    {
      "x": -3,
      "y": -69,
      "z": 2,
      "name": "Rock_Stone"
    },
    {
      "x": -3,
      "y": -68,
      "z": 2,
      "name": "Rock_Stone"
    },
    {
      "x": -3,
      "y": -67,
      "z": 2,
      "name": "Rock_Stone"
    },
    {
      "x": -3,
      "y": -66,
      "z": 2,
      "name": "Rock_Stone"
    },
    {
      "x": -3,
      "y": -65,
      "z": 2,
      "name": "Rock_Stone"
    },
    {
      "x": -3,
      "y": -64,
      "z": 2,
      "name": "Rock_Stone"
    },
    {
      "x": -3,
      "y": -63,
      "z": 2,
      "name": "Rock_Stone"
    },
    {
      "x": -3,
      "y": -62,
      "z": 2,
      "name": "Rock_Stone"
    },
    {
      "x": -3,
      "y": -61,
      "z": 2,
      "name": "Rock_Stone"
    },
    {
      "x": -3,
      "y": -60,
      "z": 2,
      "name": "Rock_Stone"
    },
    {
      "x": -3,
      "y": -59,
      "z": 2,
      "name": "Rock_Stone"
    },
    {
      "x": -3,
      "y": -58,
      "z": 2,
      "name": "Rock_Stone"
    },
    {
      "x": -3,
      "y": -57,
      "z": 2,
      "name": "Rock_Stone"
    },
    {
      "x": -3,
      "y": -56,
      "z": 2,
      "name": "Rock_Stone"
    },
    {
      "x": -3,
      "y": -55,
      "z": 2,
      "name": "Rock_Stone"
    },
    {
      "x": -3,
      "y": -54,
      "z": 2,
      "name": "Rock_Stone"
    },
    {
      "x": -3,
      "y": -53,
      "z": 2,
      "name": "Rock_Stone"
    },
    {
      "x": -3,
      "y": -52,
      "z": 2,
      "name": "Rock_Stone"
    },
    {
      "x": -3,
      "y": -51,
      "z": 2,
      "name": "Rock_Stone"
    },
    {
      "x": -3,
      "y": -50,
      "z": 2,
      "name": "Rock_Stone"
    },
    {
      "x": -3,
      "y": -49,
      "z": 2,
      "name": "Rock_Stone"
    },
    {
      "x": -3,
      "y": -48,
      "z": 2,
      "name": "Rock_Stone"
    },
    {
      "x": -3,
      "y": -47,
      "z": 2,
      "name": "Rock_Stone"
    },
    {
      "x": -3,
      "y": -46,
      "z": 2,
      "name": "Rock_Stone"
    },
    {
      "x": -3,
      "y": -45,
      "z": 2,
      "name": "Rock_Stone"
    },
    {
      "x": -3,
      "y": -44,
      "z": 2,
      "name": "Rock_Stone"
    },
    {
      "x": -3,
      "y": -43,
      "z": 2,
      "name": "Rock_Stone"
    },
    {
      "x": -3,
      "y": -42,
      "z": 2,
      "name": "Rock_Stone"
    },
    {
      "x": -3,
      "y": -41,
      "z": 2,
      "name": "Rock_Stone"
    },
    {
      "x": -3,
      "y": -40,
      "z": 2,
      "name": "Rock_Stone"
    },
    {
      "x": -3,
      "y": -39,
      "z": 2,
      "name": "Rock_Stone"
    },
    {
      "x": -3,
      "y": -38,
      "z": 2,
      "name": "Rock_Stone"
    },
    {
      "x": -3,
      "y": -37,
      "z": 2,
      "name": "Rock_Stone"
    },
    {
      "x": -3,
      "y": -36,
      "z": 2,
      "name": "Rock_Stone"
    },
    {
      "x": -3,
      "y": -35,
      "z": 2,
      "name": "Rock_Stone"
    },
    {
      "x": -3,
      "y": -34,
      "z": 2,
      "name": "Rock_Stone"
    },
    {
