{
  "version": 8,
  "blockIdVersion": 11,
  "anchorX": 0,
  "anchorY": 0,
  "anchorZ": 0,
  "blocks": [
    {
      "x": -2,
      "y": 14,
      "z": 0,
      "name": "Plant_Leaves_Bamboo_Teal"
    },
    {
      "x": -2,
      "y": 15,
      "z": 0,
      "name": "Plant_Leaves_Bamboo_Teal"
    },
    {
      "x": -1,
      "y": 14,
      "z": -2,
      "name": "Plant_Leaves_Bamboo_Teal"
    },
    {
      "x": -1,
      "y": 14,
      "z": -1,
      "name": "Plant_Leaves_Bamboo_Teal"
    },
    {
      "x": -1,
      "y": 15,
      "z": -1,
      "name": "Plant_Leaves_Bamboo_Teal"
    },
    {
      "x": -1,
      "y": 16,
      "z": -1,
      "name": "Plant_Leaves_Bamboo_Teal"
    },
    {
      "x": -1,
      "y": 12,
      "z": 0,
      "name": "Plant_Leaves_Bamboo_Teal"
    },
    {
      "x": -1,
      "y": 14,
      "z": 0,
      "name": "Plant_Leaves_Bamboo_Teal"
    },
    {
      "x": -1,
      "y": 15,
      "z": 0,
      "name": "Plant_Leaves_Bamboo_Teal"
    },
    {
      "x": -1,
      "y": 16,
      "z": 0,
      "name": "Plant_Leaves_Bamboo_Teal"
    },
    {
      "x": -1,
      "y": 17,
      "z": 0,
      "name": "Plant_Leaves_Bamboo_Teal"
    },
    {
      "x": -1,
      "y": 12,
      "z": 1,
      "name": "Plant_Leaves_Bamboo_Teal"
    },
    {
      "x": -1,
      "y": 13,
      "z": 1,
      "name": "Plant_Leaves_Bamboo_Teal"
    },
    {
      "x": -1,
      "y": 14,
      "z": 1,
      "name": "Plant_Leaves_Bamboo_Teal"
    },
    {
      "x": -1,
      "y": 15,
      "z": 1,
      "name": "Plant_Leaves_Bamboo_Teal"
    },
    {
      "x": -1,
      "y": 16,
      "z": 1,
      "name": "Plant_Leaves_Bamboo_Teal"
    },
    {
      "x": 0,
      "y": 14,
      "z": -2,
      "name": "Plant_Leaves_Bamboo_Teal"
    },
    {
      "x": 0,
      "y": 15,
      "z": -2,
      "name": "Plant_Leaves_Bamboo_Teal"
    },
    {
      "x": 0,
      "y": 11,
      "z": -1,
      "name": "Plant_Leaves_Bamboo_Teal"
    },
    {
      "x": 0,
      "y": 12,
      "z": -1,
      "name": "Plant_Leaves_Bamboo_Teal"
    },
    {
      "x": 0,
      "y": 13,
      "z": -1,
      "name": "Plant_Leaves_Bamboo_Teal"
    },
    {
      "x": 0,
      "y": 14,
      "z": -1,
      "name": "Plant_Leaves_Bamboo_Teal"
    },
    {
      "x": 0,
      "y": 15,
      "z": -1,
      "name": "Plant_Leaves_Bamboo_Teal"
    },
    {
      "x": 0,
      "y": 16,
      "z": -1,
      "name": "Plant_Leaves_Bamboo_Teal"
    },
    {
      "x": 0,
      "y": 17,
      "z": -1,
      "name": "Plant_Leaves_Bamboo_Teal"
    },
    {
      "x": 0,
      "y": 18,
      "z": -1,
      "name": "Plant_Leaves_Bamboo_Teal"
    },
    {
      "x": 0,
      "y": 19,
      "z": -1,
      "name": "Plant_Leaves_Bamboo_Teal"
    },
    {
      "x": 0,
      "y": 0,
      "z": 0,
      "name": "Wood_Bamboo_Branch_Long_Teal"
    },
    {
      "x": 0,
      "y": 1,
      "z": 0,
      "name": "Wood_Bamboo_Branch_Long_Teal"
    },
    {
      "x": 0,
      "y": 2,
      "z": 0,
      "name": "Wood_Bamboo_Branch_Long_Teal"
    },
    {
      "x": 0,
      "y": 3,
      "z": 0,
      "name": "Wood_Bamboo_Branch_Long_Teal"
    },
    {
      "x": 0,
      "y": 4,
      "z": 0,
      "name": "Wood_Bamboo_Branch_Long_Teal"
    },
    {
      "x": 0,
      "y": 5,
      "z": 0,
      "name": "Wood_Bamboo_Branch_Long_Teal"
    },
    {
      "x": 0,
      "y": 6,
      "z": 0,
      "name": "Wood_Bamboo_Branch_Long_Teal"
    },
    {
      "x": 0,
      "y": 7,
      "z": 0,
      "name": "Wood_Bamboo_Branch_Long_Teal"
    },
    {
      "x": 0,
      "y": 8,
      "z": 0,
      "name": "Wood_Bamboo_Branch_Long_Teal"
    },
    {
      "x": 0,
      "y": 9,
      "z": 0,
      "name": "Wood_Bamboo_Branch_Long_Teal"
    },
    {
      "x": 0,
      "y": 10,
      "z": 0,
      "name": "Wood_Bamboo_Branch_Long_Teal"
    },
    {
      "x": 0,
      "y": 11,
      "z": 0,
      "name": "Wood_Bamboo_Branch_Long_Teal"
    },
    {
      "x": 0,
      "y": 12,
      "z": 0,
      "name": "Wood_Bamboo_Branch_Long_Teal"
    },
    {
      "x": 0,
      "y": 13,
      "z": 0,
      "name": "Wood_Bamboo_Branch_Long_Teal"
    },
    {
      "x": 0,
      "y": 14,
      "z": 0,
      "name": "Wood_Bamboo_Branch_Long_Teal"
    },
    {
      "x": 0,
      "y": 15,
      "z": 0,
      "name": "Wood_Bamboo_Branch_Long_Teal"
    },
    {
      "x": 0,
      "y": 16,
      "z": 0,
      "name": "Wood_Bamboo_Branch_Long_Teal"
    },
    {
      "x": 0,
      "y": 17,
      "z": 0,
      "name": "Wood_Bamboo_Branch_Long_Teal"
    },
    {
      "x": 0,
      "y": 18,
      "z": 0,
      "name": "Plant_Leaves_Bamboo_Teal"
    },
    {
      "x": 0,
      "y": 19,
      "z": 0,
      "name": "Plant_Leaves_Bamboo_Teal"
    },
    {
      "x": 0,
      "y": 7,
      "z": 1,
      "name": "Plant_Leaves_Bamboo_Teal"
    },
    {
      "x": 0,
      "y": 8,
      "z": 1,
      "name": "Plant_Leaves_Bamboo_Teal"
    },
    {
      "x": 0,
      "y": 12,
      "z": 1,
      "name": "Plant_Leaves_Bamboo_Teal"
    },
    {
      "x": 0,
      "y": 13,
      "z": 1,
      "name": "Plant_Leaves_Bamboo_Teal"
    },
    {
      "x": 0,
      "y": 14,
      "z": 1,
      "name": "Plant_Leaves_Bamboo_Teal"
    },
    {
      "x": 0,
      "y": 15,
      "z": 1,
      "name": "Plant_Leaves_Bamboo_Teal"
    },
    {
      "x": 0,
      "y": 16,
      "z": 1,
      "name": "Plant_Leaves_Bamboo_Teal"
    },
    {
      "x": 0,
      "y": 17,
      "z": 1,
      "name": "Plant_Leaves_Bamboo_Teal"
    },
    {
      "x": 0,
      "y": 18,
      "z": 1,
      "name": "Plant_Leaves_Bamboo_Teal"
    },
    {
      "x": 0,
      "y": 12,
      "z": 2,
      "name": "Plant_Leaves_Bamboo_Teal"
    },
    {
      "x": 0,
      "y": 13,
      "z": 2,
      "name": "Plant_Leaves_Bamboo_Teal"
    },
    {
      "x": 0,
      "y": 14,
      "z": 2,
      "name": "Plant_Leaves_Bamboo_Teal"
    },
    {
      "x": 0,
      "y": 15,
      "z": 2,
      "name": "Plant_Leaves_Bamboo_Teal"
    },
    {
      "x": 1,
      "y": 10,
      "z": -1,
      "name": "Plant_Leaves_Bamboo_Teal"
    },
    {
      "x": 1,
      "y": 11,
      "z": -1,
      "name": "Plant_Leaves_Bamboo_Teal"
    },
    {
      "x": 1,
      "y": 13,
      "z": -1,
      "name": "Plant_Leaves_Bamboo_Teal"
    },
    {
      "x": 1,
      "y": 14,
      "z": -1,
      "name": "Plant_Leaves_Bamboo_Teal"
    },
    {
      "x": 1,
      "y": 15,
      "z": -1,
      "name": "Plant_Leaves_Bamboo_Teal"
    },
    {
      "x": 1,
      "y": 17,
      "z": -1,
      "name": "Plant_Leaves_Bamboo_Teal"
    },
    {
      "x": 1,
      "y": 7,
      "z": 0,
      "name": "Plant_Leaves_Bamboo_Teal"
    },
    {
      "x": 1,
      "y": 11,
      "z": 0,
      "name": "Wood_Bamboo_Branch_Long_Teal",
      "rotation": 5
    },
    {
      "x": 1,
      "y": 13,
      "z": 0,
      "name": "Plant_Leaves_Bamboo_Teal"
    },
    {
      "x": 1,
      "y": 14,
      "z": 0,
      "name": "Plant_Leaves_Bamboo_Teal"
    },
    {
      "x": 1,
      "y": 15,
      "z": 0,
      "name": "Plant_Leaves_Bamboo_Teal"
    },
    {
      "x": 1,
      "y": 16,
      "z": 0,
      "name": "Plant_Leaves_Bamboo_Teal"
    },
    {
      "x": 1,
      "y": 17,
      "z": 0,
      "name": "Plant_Leaves_Bamboo_Teal"
    },
    {
      "x": 1,
      "y": 18,
      "z": 0,
      "name": "Plant_Leaves_Bamboo_Teal"
    },
    {
      "x": 1,
      "y": 11,
      "z": 1,
      "name": "Plant_Leaves_Bamboo_Teal"
    },
    {
      "x": 1,
      "y": 13,
      "z": 1,
      "name": "Plant_Leaves_Bamboo_Teal"
    },
    {
      "x": 1,
      "y": 14,
      "z": 1,
      "name": "Plant_Leaves_Bamboo_Teal"
    },
    {
      "x": 1,
      "y": 15,
      "z": 1,
      "name": "Plant_Leaves_Bamboo_Teal"
    },
    {
      "x": 1,
      "y": 16,
      "z": 1,
      "name": "Plant_Leaves_Bamboo_Teal"
    },
    {
      "x": 1,
      "y": 17,
      "z": 1,
      "name": "Plant_Leaves_Bamboo_Teal"
    },
    {
      "x": 2,
      "y": 15,
      "z": -1,
      "name": "Plant_Leaves_Bamboo_Teal"
    },
    {
      "x": 2,
      "y": 9,
      "z": 0,
      "name": "Plant_Leaves_Bamboo_Teal"
    },
    {
      "x": 2,
      "y": 10,
      "z": 0,
      "name": "Plant_Leaves_Bamboo_Teal"
    },
    {
      "x": 2,
      "y": 11,
      "z": 0,
      "name": "Plant_Leaves_Bamboo_Teal"
    },
    {
      "x": 2,
      "y": 12,
      "z": 0,
      "name": "Plant_Leaves_Bamboo_Teal"
    },
    {
      "x": 2,
      "y": 13,
      "z": 0,
      "name": "Plant_Leaves_Bamboo_Teal"
    },
    {
      "x": 2,
      "y": 14,
      "z": 0,
      "name": "Plant_Leaves_Bamboo_Teal"
    },
    {
      "x": 2,
      "y": 15,
      "z": 0,
      "name": "Plant_Leaves_Bamboo_Teal"
    },
    {
      "x": 2,
      "y": 11,
      "z": 1,
      "name": "Plant_Leaves_Bamboo_Teal"
    },
    {
      "x": 2,
      "y": 15,
      "z": 1,
      "name": "Plant_Leaves_Bamboo_Teal"
    },
    {
      "x": 3,
      "y": 11,
      "z": 0,
      "name": "Plant_Leaves_Bamboo_Teal"
    }
  ],
  "fluids": [
    {
      "x": -2,
      "y": 14,
      "z": 0,
      "name": "Empty",
      "level": 0
    },
    {
      "x": -2,
      "y": 15,
      "z": 0,
      "name": "Empty",
      "level": 0
    },
    {
      "x": -1,
      "y": 14,
      "z": -2,
      "name": "Empty",
      "level": 0
    },
    {
      "x": -1,
      "y": 14,
      "z": -1,
      "name": "Empty",
      "level": 0
    },
    {
      "x": -1,
      "y": 15,
      "z": -1,
      "name": "Empty",
      "level": 0
    },
    {
      "x": -1,
      "y": 16,
      "z": -1,
      "name": "Empty",
      "level": 0
    },
    {
      "x": -1,
      "y": 12,
      "z": 0,
      "name": "Empty",
      "level": 0
    },
    {
      "x": -1,
      "y": 14,
      "z": 0,
      "name": "Empty",
      "level": 0
    },
    {
      "x": -1,
      "y": 15,
      "z": 0,
      "name": "Empty",
      "level": 0
    },
    {
      "x": -1,
      "y": 16,
      "z": 0,
      "name": "Empty",
      "level": 0
    },
    {
      "x": -1,
      "y": 17,
      "z": 0,
      "name": "Empty",
      "level": 0
    },
    {
      "x": -1,
      "y": 12,
      "z": 1,
      "name": "Empty",
      "level": 0
    },
    {
      "x": -1,
      "y": 13,
      "z": 1,
      "name": "Empty",
      "level": 0
    },
    {
      "x": -1,
      "y": 14,
      "z": 1,
      "name": "Empty",
      "level": 0
    },
    {
      "x": -1,
      "y": 15,
      "z": 1,
      "name": "Empty",
      "level": 0
    },
    {
      "x": -1,
      "y": 16,
      "z": 1,
      "name": "Empty",
      "level": 0
    },
    {
      "x": 0,
      "y": 14,
      "z": -2,
      "name": "Empty",
      "level": 0
    },
    {
      "x": 0,
      "y": 15,
      "z": -2,
      "name": "Empty",
      "level": 0
    },
    {
      "x": 0,
      "y": 11,
      "z": -1,
      "name": "Empty",
      "level": 0
    },
    {
      "x": 0,
      "y": 12,
      "z": -1,
      "name": "Empty",
      "level": 0
    },
    {
      "x": 0,
      "y": 13,
      "z": -1,
      "name": "Empty",
      "level": 0
    },
    {
      "x": 0,
      "y": 14,
      "z": -1,
      "name": "Empty",
      "level": 0
    },
    {
      "x": 0,
      "y": 15,
      "z": -1,
      "name": "Empty",
      "level": 0
    },
    {
      "x": 0,
      "y": 16,
      "z": -1,
      "name": "Empty",
      "level": 0
    },
    {
      "x": 0,
      "y": 17,
      "z": -1,
      "name": "Empty",
      "level": 0
    },
    {
      "x": 0,
      "y": 18,
      "z": -1,
      "name": "Empty",
      "level": 0
    },
    {
      "x": 0,
      "y": 19,
      "z": -1,
      "name": "Empty",
      "level": 0
    },
    {
      "x": 0,
      "y": 0,
      "z": 0,
      "name": "Empty",
      "level": 0
    },
    {
      "x": 0,
      "y": 1,
      "z": 0,
      "name": "Empty",
      "level": 0
    },
    {
      "x": 0,
      "y": 2,
      "z": 0,
      "name": "Empty",
      "level": 0
    },
    {
      "x": 0,
      "y": 3,
      "z": 0,
      "name": "Empty",
      "level": 0
    },
    {
      "x": 0,
      "y": 4,
      "z": 0,
      "name": "Empty",
      "level": 0
    },
    {
      "x": 0,
      "y": 5,
      "z": 0,
      "name": "Empty",
      "level": 0
    },
    {
      "x": 0,
      "y": 6,
      "z": 0,
      "name": "Empty",
      "level": 0
    },
    {
      "x": 0,
      "y": 7,
      "z": 0,
      "name": "Empty",
      "level": 0
    },
    {
      "x": 0,
      "y": 8,
      "z": 0,
      "name": "Empty",
      "level": 0
    },
    {
      "x": 0,
      "y": 9,
      "z": 0,
      "name": "Empty",
      "level": 0
    },
    {
      "x": 0,
      "y": 10,
      "z": 0,
      "name": "Empty",
      "level": 0
    },
    {
      "x": 0,
      "y": 11,
      "z": 0,
      "name": "Empty",
      "level": 0
    },
    {
      "x": 0,
      "y": 12,
      "z": 0,
      "name": "Empty",
      "level": 0
    },
    {
      "x": 0,
      "y": 13,
      "z": 0,
      "name": "Empty",
      "level": 0
    },
    {
      "x": 0,
      "y": 14,
      "z": 0,
      "name": "Empty",
      "level": 0
    },
    {
      "x": 0,
      "y": 15,
      "z": 0,
      "name": "Empty",
      "level": 0
    },
    {
      "x": 0,
      "y": 16,
      "z": 0,
      "name": "Empty",
      "level": 0
    },
    {
      "x": 0,
      "y": 17,
      "z": 0,
      "name": "Empty",
      "level": 0
    },
    {
      "x": 0,
      "y": 18,
      "z": 0,
      "name": "Empty",
      "level": 0
    },
    {
      "x": 0,
      "y": 19,
      "z": 0,
      "name": "Empty",
      "level": 0
    },
    {
      "x": 0,
      "y": 7,
      "z": 1,
      "name": "Empty",
      "level": 0
    },
    {
      "x": 0,
      "y": 8,
      "z": 1,
      "name": "Empty",
      "level": 0
    },
    {
      "x": 0,
      "y": 12,
      "z": 1,
      "name": "Empty",
      "level": 0
    },
    {
      "x": 0,
      "y": 13,
      "z": 1,
      "name": "Empty",
      "level": 0
    },
    {
      "x": 0,
      "y": 14,
      "z": 1,
      "name": "Empty",
      "level": 0
    },
    {
      "x": 0,
      "y": 15,
      "z": 1,
      "name": "Empty",
      "level": 0
    },
    {
      "x": 0,
      "y": 16,
      "z": 1,
      "name": "Empty",
      "level": 0
    },
    {
      "x": 0,
      "y": 17,
      "z": 1,
      "name": "Empty",
      "level": 0
    },
    {
      "x": 0,
      "y": 18,
      "z": 1,
      "name": "Empty",
      "level": 0
    },
    {
      "x": 0,
      "y": 12,
      "z": 2,
      "name": "Empty",
      "level": 0
    },
    {
      "x": 0,
      "y": 13,
      "z": 2,
      "name": "Empty",
      "level": 0
    },
    {
      "x": 0,
      "y": 14,
      "z": 2,
      "name": "Empty",
      "level": 0
    },
    {
      "x": 0,
      "y": 15,
      "z": 2,
      "name": "Empty",
      "level": 0
    },
    {
      "x": 1,
      "y": 10,
      "z": -1,
      "name": "Empty",
      "level": 0
    },
    {
      "x": 1,
      "y": 11,
      "z": -1,
      "name": "Empty",
      "level": 0
    },
    {
      "x": 1,
      "y": 13,
      "z": -1,
      "name": "Empty",
      "level": 0
    },
    {
      "x": 1,
      "y": 14,
      "z": -1,
      "name": "Empty",
      "level": 0
    },
    {
      "x": 1,
      "y": 15,
      "z": -1,
      "name": "Empty",
      "level": 0
    },
    {
      "x": 1,
      "y": 17,
      "z": -1,
      "name": "Empty",
      "level": 0
    },
    {
      "x": 1,
      "y": 7,
      "z": 0,
      "name": "Empty",
      "level": 0
    },
    {
      "x": 1,
      "y": 11,
      "z": 0,
      "name": "Empty",
      "level": 0
    },
    {
      "x": 1,
      "y": 13,
      "z": 0,
      "name": "Empty",
      "level": 0
    },
    {
      "x": 1,
      "y": 14,
      "z": 0,
      "name": "Empty",
      "level": 0
    },
    {
      "x": 1,
      "y": 15,
      "z": 0,
      "name": "Empty",
      "level": 0
    },
    {
      "x": 1,
      "y": 16,
      "z": 0,
      "name": "Empty",
      "level": 0
    },
    {
      "x": 1,
      "y": 17,
      "z": 0,
      "name": "Empty",
      "level": 0
    },
    {
      "x": 1,
      "y": 18,
      "z": 0,
      "name": "Empty",
      "level": 0
    },
    {
      "x": 1,
      "y": 11,
      "z": 1,
      "name": "Empty",
      "level": 0
    },
    {
      "x": 1,
      "y": 13,
      "z": 1,
      "name": "Empty",
      "level": 0
    },
    {
      "x": 1,
      "y": 14,
      "z": 1,
      "name": "Empty",
      "level": 0
    },
    {
      "x": 1,
      "y": 15,
      "z": 1,
      "name": "Empty",
      "level": 0
    },
    {
      "x": 1,
      "y": 16,
      "z": 1,
      "name": "Empty",
      "level": 0
    },
    {
      "x": 1,
      "y": 17,
      "z": 1,
      "name": "Empty",
      "level": 0
    },
    {
      "x": 2,
      "y": 15,
      "z": -1,
      "name": "Empty",
      "level": 0
    },
    {
      "x": 2,
      "y": 9,
      "z": 0,
      "name": "Empty",
      "level": 0
    },
    {
      "x": 2,
      "y": 10,
      "z": 0,
      "name": "Empty",
      "level": 0
    },
    {
      "x": 2,
      "y": 11,
      "z": 0,
      "name": "Empty",
      "level": 0
    },
    {
      "x": 2,
      "y": 12,
      "z": 0,
      "name": "Empty",
      "level": 0
    },
    {
      "x": 2,
      "y": 13,
      "z": 0,
      "name": "Empty",
      "level": 0
    },
    {
      "x": 2,
      "y": 14,
      "z": 0,
      "name": "Empty",
      "level": 0
    },
    {
      "x": 2,
      "y": 15,
      "z": 0,
      "name": "Empty",
      "level": 0
    },
    {
      "x": 2,
      "y": 11,
      "z": 1,
      "name": "Empty",
      "level": 0
    },
    {
      "x": 2,
      "y": 15,
      "z": 1,
      "name": "Empty",
      "level": 0
    },
    {
      "x": 3,
      "y": 11,
      "z": 0,
      "name": "Empty",
      "level": 0
    }
  ]
}