{
  "version": 8,
  "blockIdVersion": 11,
  "anchorX": 0,
  "anchorY": 6,
  "anchorZ": 0,
  "blocks": [
    {
      "x": -4,
      "y": 0,
      "z": -4,
      "name": "Rock_Crystal_Pink_Block"
    },
    {
      "x": -4,
      "y": 1,
      "z": -4,
      "name": "Rock_Crystal_Pink_Block"
    },
    {
      "x": -4,
      "y": 2,
      "z": -4,
      "name": "Rock_Crystal_Pink_Block",
      "rotation": 4
    },
    {
      "x": -4,
      "y": 2,
      "z": -3,
      "name": "Rock_Crystal_Pink_Block",
      "rotation": 5
    },
    {
      "x": -4,
      "y": 3,
      "z": -3,
      "name": "Rock_Crystal_Pink_Block",
      "rotation": 4
    },
    {
      "x": -4,
      "y": 3,
      "z": -2,
      "name": "Rock_Crystal_Pink_Block",
      "rotation": 5
    },
    {
      "x": -4,
      "y": 4,
      "z": -2,
      "name": "Rock_Crystal_Pink_Block",
      "rotation": 5
    },
    {
      "x": -4,
      "y": 4,
      "z": -1,
      "name": "Rock_Crystal_Pink_Block",
      "rotation": 5
    },
    {
      "x": -3,
      "y": 1,
      "z": -4,
      "name": "Rock_Crystal_Pink_Block"
    },
    {
      "x": -3,
      "y": 2,
      "z": -4,
      "name": "Rock_Crystal_Pink_Block",
      "rotation": 4
    },
    {
      "x": -3,
      "y": 3,
      "z": -4,
      "name": "Rock_Crystal_Pink_Block",
      "rotation": 4
    },
    {
      "x": -3,
      "y": 1,
      "z": -3,
      "name": "Rock_Crystal_Pink_Block"
    },
    {
      "x": -3,
      "y": 2,
      "z": -3,
      "name": "Rock_Crystal_Pink_Block"
    },
    {
      "x": -3,
      "y": 3,
      "z": -3,
      "name": "Rock_Crystal_Pink_Block"
    },
    {
      "x": -3,
      "y": 4,
      "z": -3,
      "name": "Rock_Crystal_Pink_Block",
      "rotation": 4
    },
    {
      "x": -3,
      "y": 2,
      "z": -2,
      "name": "Rock_Crystal_Pink_Block"
    },
    {
      "x": -3,
      "y": 3,
      "z": -2,
      "name": "Rock_Crystal_Pink_Block"
    },
    {
      "x": -3,
      "y": 4,
      "z": -2,
      "name": "Rock_Crystal_Pink_Block",
      "rotation": 5
    },
    {
      "x": -3,
      "y": 5,
      "z": -2,
      "name": "Rock_Crystal_Pink_Block"
    },
    {
      "x": -3,
      "y": 3,
      "z": -1,
      "name": "Rock_Crystal_Pink_Block"
    },
    {
      "x": -3,
      "y": 4,
      "z": -1,
      "name": "Rock_Crystal_Pink_Block",
      "rotation": 5
    },
    {
      "x": -3,
      "y": 5,
      "z": -1,
      "name": "Rock_Crystal_Pink_Block"
    },
    {
      "x": -3,
      "y": 3,
      "z": 0,
      "name": "Rock_Crystal_Pink_Block",
      "rotation": 4
    },
    {
      "x": -3,
      "y": 4,
      "z": 0,
      "name": "Rock_Crystal_Pink_Block",
      "rotation": 5
    },
    {
      "x": -2,
      "y": 3,
      "z": -4,
      "name": "Rock_Crystal_Pink_Block",
      "rotation": 4
    },
    {
      "x": -2,
      "y": 4,
      "z": -4,
      "name": "Rock_Crystal_Pink_Block",
      "rotation": 4
    },
    {
      "x": -2,
      "y": 2,
      "z": -3,
      "name": "Rock_Crystal_Pink_Block",
      "rotation": 5
    },
    {
      "x": -2,
      "y": 3,
      "z": -3,
      "name": "Rock_Crystal_Pink_Block"
    },
    {
      "x": -2,
      "y": 4,
      "z": -3,
      "name": "Rock_Crystal_Pink_Block",
      "rotation": 4
    },
    {
      "x": -2,
      "y": 5,
      "z": -3,
      "name": "Rock_Crystal_Pink_Block"
    },
    {
      "x": -2,
      "y": 1,
      "z": -2,
      "name": "Rock_Crystal_Pink_Block"
    },
    {
      "x": -2,
      "y": 2,
      "z": -2,
      "name": "Rock_Crystal_Pink_Block",
      "rotation": 5
    },
    {
      "x": -2,
      "y": 3,
      "z": -2,
      "name": "Rock_Crystal_Pink_Block"
    },
    {
      "x": -2,
      "y": 4,
      "z": -2,
      "name": "Rock_Crystal_Pink_Block",
      "rotation": 4
    },
    {
      "x": -2,
      "y": 5,
      "z": -2,
      "name": "Rock_Crystal_Pink_Block"
    },
    {
      "x": -2,
      "y": 6,
      "z": -2,
      "name": "Rock_Crystal_Pink_Block",
      "rotation": 4
    },
    {
      "x": -2,
      "y": 1,
      "z": -1,
      "name": "Rock_Crystal_Pink_Block"
    },
    {
      "x": -2,
      "y": 2,
      "z": -1,
      "name": "Rock_Crystal_Pink_Block",
      "rotation": 4
    },
    {
      "x": -2,
      "y": 3,
      "z": -1,
      "name": "Rock_Crystal_Pink_Block",
      "rotation": 5
    },
    {
      "x": -2,
      "y": 4,
      "z": -1,
      "name": "Rock_Crystal_Pink_Block"
    },
    {
      "x": -2,
      "y": 5,
      "z": -1,
      "name": "Rock_Crystal_Pink_Block",
      "rotation": 4
    },
    {
      "x": -2,
      "y": 6,
      "z": -1,
      "name": "Rock_Crystal_Pink_Block",
      "rotation": 4
    },
    {
      "x": -2,
      "y": 3,
      "z": 0,
      "name": "Rock_Crystal_Pink_Block"
    },
    {
      "x": -2,
      "y": 4,
      "z": 0,
      "name": "Rock_Crystal_Pink_Block",
      "rotation": 4
    },
    {
      "x": -2,
      "y": 5,
      "z": 0,
      "name": "Rock_Crystal_Pink_Block",
      "rotation": 4
    },
    {
      "x": -2,
      "y": 6,
      "z": 0,
      "name": "Rock_Crystal_Pink_Block",
      "rotation": 4
    },
    {
      "x": -2,
      "y": 4,
      "z": 1,
      "name": "Rock_Crystal_Pink_Block",
      "rotation": 4
    },
    {
      "x": -2,
      "y": 5,
      "z": 1,
      "name": "Rock_Crystal_Pink_Block",
      "rotation": 4
    },
    {
      "x": -2,
      "y": 6,
      "z": 1,
      "name": "Rock_Crystal_Pink_Block",
      "rotation": 4
    },
    {
      "x": -2,
      "y": 5,
      "z": 2,
      "name": "Empty"
    },
    {
      "x": -1,
      "y": 3,
      "z": -3,
      "name": "Rock_Crystal_Pink_Block",
      "rotation": 5
    },
    {
      "x": -1,
      "y": 4,
      "z": -3,
      "name": "Rock_Crystal_Pink_Block",
      "rotation": 4
    },
    {
      "x": -1,
      "y": 5,
      "z": -3,
      "name": "Rock_Crystal_Pink_Block"
    },
    {
      "x": -1,
      "y": 6,
      "z": -3,
      "name": "Rock_Crystal_Pink_Block"
    },
    {
      "x": -1,
      "y": 3,
      "z": -2,
      "name": "Rock_Crystal_Pink_Block"
    },
    {
      "x": -1,
      "y": 4,
      "z": -2,
      "name": "Rock_Crystal_Pink_Block",
      "rotation": 4
    },
    {
      "x": -1,
      "y": 5,
      "z": -2,
      "name": "Rock_Crystal_Pink_Block"
    },
    {
      "x": -1,
      "y": 6,
      "z": -2,
      "name": "Rock_Crystal_Pink_Block",
      "rotation": 4
    },
    {
      "x": -1,
      "y": 7,
      "z": -2,
      "name": "Rock_Crystal_Pink_Block"
    },
    {
      "x": -1,
      "y": 3,
      "z": -1,
      "name": "Rock_Crystal_Pink_Block"
    },
    {
      "x": -1,
      "y": 4,
      "z": -1,
      "name": "Rock_Crystal_Pink_Block"
    },
    {
      "x": -1,
      "y": 5,
      "z": -1,
      "name": "Rock_Crystal_Pink_Block",
      "rotation": 4
    },
    {
      "x": -1,
      "y": 6,
      "z": -1,
      "name": "Rock_Crystal_Pink_Block"
    },
    {
      "x": -1,
      "y": 7,
      "z": -1,
      "name": "Rock_Crystal_Pink_Block",
      "rotation": 4
    },
    {
      "x": -1,
      "y": 2,
      "z": 0,
      "name": "Rock_Crystal_Pink_Block"
    },
    {
      "x": -1,
      "y": 3,
      "z": 0,
      "name": "Rock_Crystal_Pink_Block"
    },
    {
      "x": -1,
      "y": 4,
      "z": 0,
      "name": "Rock_Crystal_Pink_Block"
    },
    {
      "x": -1,
      "y": 5,
      "z": 0,
      "name": "Rock_Crystal_Pink_Block",
      "rotation": 4
    },
    {
      "x": -1,
      "y": 6,
      "z": 0,
      "name": "Rock_Crystal_Pink_Block",
      "rotation": 4
    },
    {
      "x": -1,
      "y": 7,
      "z": 0,
      "name": "Rock_Crystal_Pink_Block",
      "rotation": 5
    },
    {
      "x": -1,
      "y": 3,
      "z": 1,
      "name": "Rock_Crystal_Pink_Block"
    },
    {
      "x": -1,
      "y": 4,
      "z": 1,
      "name": "Rock_Crystal_Pink_Block",
      "rotation": 4
    },
    {
      "x": -1,
      "y": 5,
      "z": 1,
      "name": "Rock_Crystal_Pink_Block"
    },
    {
      "x": -1,
      "y": 6,
      "z": 1,
      "name": "Rock_Crystal_Pink_Block",
      "rotation": 4
    },
    {
      "x": -1,
      "y": 7,
      "z": 1,
      "name": "Rock_Crystal_Pink_Block",
      "rotation": 4
    },
    {
      "x": -1,
      "y": 8,
      "z": 1,
      "name": "Rock_Crystal_Pink_Block",
      "rotation": 5
    },
    {
      "x": -1,
      "y": 9,
      "z": 1,
      "name": "Rock_Crystal_Pink_Block"
    },
    {
      "x": -1,
      "y": 3,
      "z": 2,
      "name": "Empty"
    },
    {
      "x": -1,
      "y": 4,
      "z": 2,
      "name": "Empty"
    },
    {
      "x": -1,
      "y": 5,
      "z": 2,
      "name": "Empty"
    },
    {
      "x": 0,
      "y": 6,
      "z": -3,
      "name": "Rock_Crystal_Pink_Block"
    },
    {
      "x": 0,
      "y": 4,
      "z": -2,
      "name": "Rock_Crystal_Pink_Block",
      "rotation": 4
    },
    {
      "x": 0,
      "y": 5,
      "z": -2,
      "name": "Rock_Crystal_Pink_Block"
    },
    {
      "x": 0,
      "y": 6,
      "z": -2,
      "name": "Rock_Crystal_Pink_Block",
      "rotation": 4
    },
    {
      "x": 0,
      "y": 7,
      "z": -2,
      "name": "Rock_Crystal_Pink_Block",
      "rotation": 4
    },
    {
      "x": 0,
      "y": 4,
      "z": -1,
      "name": "Rock_Crystal_Pink_Block"
    },
    {
      "x": 0,
      "y": 5,
      "z": -1,
      "name": "Rock_Crystal_Pink_Block",
      "rotation": 4
    },
    {
      "x": 0,
      "y": 6,
      "z": -1,
      "name": "Rock_Crystal_Pink_Block"
    },
    {
      "x": 0,
      "y": 7,
      "z": -1,
      "name": "Rock_Crystal_Pink_Block",
      "rotation": 4
    },
    {
      "x": 0,
      "y": 8,
      "z": -1,
      "name": "Rock_Crystal_Pink_Block",
      "rotation": 4
    },
    {
      "x": 0,
      "y": 3,
      "z": 0,
      "name": "Rock_Crystal_Pink_Block"
    },
    {
      "x": 0,
      "y": 4,
      "z": 0,
      "name": "Rock_Crystal_Pink_Block"
    },
    {
      "x": 0,
      "y": 5,
      "z": 0,
      "name": "Rock_Crystal_Pink_Block",
      "rotation": 4
    },
    {
      "x": 0,
      "y": 6,
      "z": 0,
      "name": "Rock_Crystal_Pink_Block",
      "rotation": 4
    },
    {
      "x": 0,
      "y": 7,
      "z": 0,
      "name": "Rock_Crystal_Pink_Block",
      "rotation": 5
    },
    {
      "x": 0,
      "y": 8,
      "z": 0,
      "name": "Rock_Crystal_Pink_Block"
    },
    {
      "x": 0,
      "y": 9,
      "z": 0,
      "name": "Rock_Crystal_Pink_Block"
    },
    {
      "x": 0,
      "y": 3,
      "z": 1,
      "name": "Empty"
    },
    {
      "x": 0,
      "y": 4,
      "z": 1,
      "name": "Rock_Crystal_Pink_Block"
    },
    {
      "x": 0,
      "y": 5,
      "z": 1,
      "name": "Rock_Crystal_Pink_Block"
    },
    {
      "x": 0,
      "y": 6,
      "z": 1,
      "name": "Rock_Crystal_Pink_Block",
      "rotation": 4
    },
    {
      "x": 0,
      "y": 7,
      "z": 1,
      "name": "Rock_Crystal_Pink_Block"
    },
    {
      "x": 0,
      "y": 8,
      "z": 1,
      "name": "Rock_Crystal_Pink_Block",
      "rotation": 4
    },
    {
      "x": 0,
      "y": 9,
      "z": 1,
      "name": "Rock_Crystal_Pink_Block"
    },
    {
      "x": 0,
      "y": 4,
      "z": 2,
      "name": "Empty"
    },
    {
      "x": 0,
      "y": 5,
      "z": 2,
      "name": "Empty"
    },
    {
      "x": 0,
      "y": 8,
      "z": 2,
      "name": "Rock_Crystal_Pink_Block",
      "rotation": 4
    },
    {
      "x": 0,
      "y": 9,
      "z": 2,
      "name": "Rock_Crystal_Pink_Block",
      "rotation": 5
    },
    {
      "x": 0,
      "y": 10,
      "z": 2,
      "name": "Rock_Crystal_Pink_Block",
      "rotation": 5
    },
    {
      "x": 0,
      "y": 5,
      "z": 3,
      "name": "Empty"
    },
    {
      "x": 1,
      "y": 6,
      "z": -2,
      "name": "Rock_Crystal_Pink_Block",
      "rotation": 5
    },
    {
      "x": 1,
      "y": 7,
      "z": -2,
      "name": "Rock_Crystal_Pink_Block",
      "rotation": 4
    },
    {
      "x": 1,
      "y": 5,
      "z": -1,
      "name": "Rock_Crystal_Pink_Block"
    },
    {
      "x": 1,
      "y": 6,
      "z": -1,
      "name": "Rock_Crystal_Pink_Block",
      "rotation": 5
    },
    {
      "x": 1,
      "y": 7,
      "z": -1,
      "name": "Rock_Crystal_Pink_Block",
      "rotation": 5
    },
    {
      "x": 1,
      "y": 8,
      "z": -1,
      "name": "Rock_Crystal_Pink_Block",
      "rotation": 4
    },
    {
      "x": 1,
      "y": 9,
      "z": -1,
      "name": "Rock_Crystal_Pink_Block",
      "rotation": 4
    },
    {
      "x": 1,
      "y": 3,
      "z": 0,
      "name": "Empty"
    },
    {
      "x": 1,
      "y": 4,
      "z": 0,
      "name": "Empty"
    },
    {
      "x": 1,
      "y": 5,
      "z": 0,
      "name": "Rock_Crystal_Pink_Block"
    },
    {
      "x": 1,
      "y": 6,
      "z": 0,
      "name": "Rock_Crystal_Pink_Block",
      "rotation": 5
    },
    {
      "x": 1,
      "y": 7,
      "z": 0,
      "name": "Rock_Crystal_Pink_Block",
      "rotation": 4
    },
    {
      "x": 1,
      "y": 8,
      "z": 0,
      "name": "Rock_Crystal_Pink_Block",
      "rotation": 5
    },
    {
      "x": 1,
      "y": 9,
      "z": 0,
      "name": "Rock_Crystal_Pink_Block",
      "rotation": 4
    },
    {
      "x": 1,
      "y": 3,
      "z": 1,
      "name": "Empty"
    },
    {
      "x": 1,
      "y": 4,
      "z": 1,
      "name": "Empty"
    },
    {
      "x": 1,
      "y": 5,
      "z": 1,
      "name": "Empty"
    },
    {
      "x": 1,
      "y": 6,
      "z": 1,
      "name": "Rock_Crystal_Pink_Block",
      "rotation": 4
    },
    {
      "x": 1,
      "y": 7,
      "z": 1,
      "name": "Rock_Crystal_Pink_Block",
      "rotation": 4
    },
    {
      "x": 1,
      "y": 8,
      "z": 1,
      "name": "Rock_Crystal_Pink_Block"
    },
    {
      "x": 1,
      "y": 9,
      "z": 1,
      "name": "Rock_Crystal_Pink_Block",
      "rotation": 5
    },
    {
      "x": 1,
      "y": 10,
      "z": 1,
      "name": "Rock_Crystal_Pink_Block"
    },
    {
      "x": 1,
      "y": 4,
      "z": 2,
      "name": "Empty"
    },
    {
      "x": 1,
      "y": 5,
      "z": 2,
      "name": "Empty"
    },
    {
      "x": 1,
      "y": 8,
      "z": 2,
      "name": "Rock_Crystal_Pink_Block",
      "rotation": 4
    },
    {
      "x": 1,
      "y": 9,
      "z": 2,
      "name": "Rock_Crystal_Pink_Block",
      "rotation": 4
    },
    {
      "x": 1,
      "y": 10,
      "z": 2,
      "name": "Rock_Crystal_Pink_Block",
      "rotation": 4
    },
    {
      "x": 1,
      "y": 11,
      "z": 2,
      "name": "Rock_Crystal_Pink_Block"
    },
    {
      "x": 1,
      "y": 5,
      "z": 3,
      "name": "Empty"
    },
    {
      "x": 2,
      "y": 5,
      "z": -1,
      "name": "Empty"
    },
    {
      "x": 2,
      "y": 5,
      "z": 0,
      "name": "Empty"
    },
    {
      "x": 2,
      "y": 9,
      "z": 0,
      "name": "Rock_Crystal_Pink_Block",
      "rotation": 5
    },
    {
      "x": 2,
      "y": 10,
      "z": 0,
      "name": "Rock_Crystal_Pink_Block",
      "rotation": 4
    },
    {
      "x": 2,
      "y": 4,
      "z": 1,
      "name": "Empty"
    },
    {
      "x": 2,
      "y": 5,
      "z": 1,
      "name": "Empty"
    },
    {
      "x": 2,
      "y": 8,
      "z": 1,
      "name": "Rock_Crystal_Pink_Block",
      "rotation": 5
    },
    {
      "x": 2,
      "y": 9,
      "z": 1,
      "name": "Rock_Crystal_Pink_Block",
      "rotation": 5
    },
    {
      "x": 2,
      "y": 10,
      "z": 1,
      "name": "Rock_Crystal_Pink_Block",
      "rotation": 5
    },
    {
      "x": 2,
      "y": 11,
      "z": 1,
      "name": "Rock_Crystal_Pink_Block",
      "rotation": 4
    },
    {
      "x": 2,
      "y": 4,
      "z": 2,
      "name": "Empty"
    },
    {
      "x": 2,
      "y": 5,
      "z": 2,
      "name": "Empty"
    },
    {
      "x": 2,
      "y": 10,
      "z": 2,
      "name": "Rock_Crystal_Pink_Block",
      "rotation": 4
    },
    {
      "x": 2,
      "y": 11,
      "z": 2,
      "name": "Rock_Crystal_Pink_Block",
      "rotation": 5
    },
    {
      "x": 2,
      "y": 12,
      "z": 2,
      "name": "Rock_Crystal_Pink_Block"
    },
    {
      "x": 2,
      "y": 5,
      "z": 3,
      "name": "Empty"
    },
    {
      "x": 2,
      "y": 11,
      "z": 3,
      "name": "Rock_Crystal_Pink_Block",
      "rotation": 4
    },
    {
      "x": 2,
      "y": 12,
      "z": 3,
      "name": "Rock_Crystal_Pink_Block",
      "rotation": 4
    },
    {
      "x": 2,
      "y": 13,
      "z": 3,
      "name": "Rock_Crystal_Pink_Block"
    },
    {
      "x": 3,
      "y": 5,
      "z": -1,
      "name": "Empty"
    },
    {
      "x": 3,
      "y": 5,
      "z": 0,
      "name": "Empty"
    },
    {
      "x": 3,
      "y": 5,
      "z": 1,
      "name": "Empty"
    },
    {
      "x": 3,
      "y": 11,
      "z": 1,
      "name": "Rock_Crystal_Pink_Block"
    },
    {
      "x": 3,
      "y": 12,
      "z": 1,
      "name": "Rock_Crystal_Pink_Block",
      "rotation": 4
    },
    {
      "x": 3,
      "y": 5,
      "z": 2,
      "name": "Empty"
    },
    {
      "x": 3,
      "y": 11,
      "z": 2,
      "name": "Rock_Crystal_Pink_Block"
    },
    {
      "x": 3,
      "y": 12,
      "z": 2,
      "name": "Rock_Crystal_Pink_Block",
      "rotation": 5
    },
    {
      "x": 3,
      "y": 13,
      "z": 2,
      "name": "Rock_Crystal_Pink_Block"
    },
    {
      "x": 3,
      "y": 5,
      "z": 3,
      "name": "Empty"
    },
    {
      "x": 3,
      "y": 12,
      "z": 3,
      "name": "Rock_Crystal_Pink_Block",
      "rotation": 4
    },
    {
      "x": 3,
      "y": 13,
      "z": 3,
      "name": "Rock_Crystal_Pink_Block"
    },
    {
      "x": 3,
      "y": 14,
      "z": 3,
      "name": "Rock_Crystal_Pink_Block"
    },
    {
      "x": 3,
      "y": 5,
      "z": 4,
      "name": "Empty"
    },
    {
      "x": 4,
      "y": 5,
      "z": 3,
      "name": "Empty"
    },
    {
      "x": 4,
      "y": 5,
      "z": 4,
      "name": "Empty"
    }
  ]
}