{
  "version": 8,
  "blockIdVersion": 11,
  "anchorX": 0,
  "anchorY": 3,
  "anchorZ": 0,
  "blocks": [
    {
      "x": -2,
      "y": 0,
      "z": -1,
      "name": "Rock_Calcite"
    },
    {
      "x": -2,
      "y": 1,
      "z": -1,
      "name": "Rock_Calcite"
    },
    {
      "x": -2,
      "y": 2,
      "z": -1,
      "name": "Rock_Calcite"
    },
    {
      "x": -2,
      "y": 3,
      "z": -1,
      "name": "Rock_Calcite"
    },
    {
      "x": -2,
      "y": 0,
      "z": 0,
      "name": "Rock_Calcite"
    },
    {
      "x": -2,
      "y": 1,
      "z": 0,
      "name": "Rock_Calcite"
    },
    {
      "x": -2,
      "y": 2,
      "z": 0,
      "name": "Rock_Calcite"
    },
    {
      "x": -2,
      "y": 3,
      "z": 0,
      "name": "Rock_Calcite"
    },
    {
      "x": -2,
      "y": 0,
      "z": 1,
      "name": "Rock_Calcite"
    },
    {
      "x": -2,
      "y": 1,
      "z": 1,
      "name": "Rock_Calcite"
    },
    {
      "x": -2,
      "y": 2,
      "z": 1,
      "name": "Rock_Calcite"
    },
    {
      "x": -2,
      "y": 3,
      "z": 1,
      "name": "Rock_Calcite"
    },
    {
      "x": -2,
      "y": 0,
      "z": 2,
      "name": "Rock_Calcite"
    },
    {
      "x": -2,
      "y": 1,
      "z": 2,
      "name": "Rock_Calcite"
    },
    {
      "x": -2,
      "y": 2,
      "z": 2,
      "name": "Rock_Calcite"
    },
    {
      "x": -2,
      "y": 3,
      "z": 2,
      "name": "Rock_Calcite"
    },
    {
      "x": -1,
      "y": 0,
      "z": -2,
      "name": "Rock_Calcite"
    },
    {
      "x": -1,
      "y": 1,
      "z": -2,
      "name": "Rock_Calcite"
    },
    {
      "x": -1,
      "y": 2,
      "z": -2,
      "name": "Rock_Calcite"
    },
    {
      "x": -1,
      "y": 3,
      "z": -2,
      "name": "Rock_Calcite"
    },
    {
      "x": -1,
      "y": 4,
      "z": -2,
      "name": "Rock_Calcite"
    },
    {
      "x": -1,
      "y": 0,
      "z": -1,
      "name": "Rock_Calcite"
    },
    {
      "x": -1,
      "y": 1,
      "z": -1,
      "name": "Rock_Calcite"
    },
    {
      "x": -1,
      "y": 2,
      "z": -1,
      "name": "Rock_Calcite"
    },
    {
      "x": -1,
      "y": 3,
      "z": -1,
      "name": "Rock_Calcite"
    },
    {
      "x": -1,
      "y": 4,
      "z": -1,
      "name": "Rock_Calcite"
    },
    {
      "x": -1,
      "y": 5,
      "z": -1,
      "name": "Rock_Calcite"
    },
    {
      "x": -1,
      "y": 0,
      "z": 0,
      "name": "Rock_Calcite"
    },
    {
      "x": -1,
      "y": 1,
      "z": 0,
      "name": "Rock_Calcite"
    },
    {
      "x": -1,
      "y": 2,
      "z": 0,
      "name": "Rock_Calcite"
    },
    {
      "x": -1,
      "y": 3,
      "z": 0,
      "name": "Rock_Calcite"
    },
    {
      "x": -1,
      "y": 4,
      "z": 0,
      "name": "Rock_Calcite"
    },
    {
      "x": -1,
      "y": 5,
      "z": 0,
      "name": "Rock_Calcite"
    },
    {
      "x": -1,
      "y": 0,
      "z": 1,
      "name": "Rock_Calcite"
    },
    {
      "x": -1,
      "y": 1,
      "z": 1,
      "name": "Rock_Calcite"
    },
    {
      "x": -1,
      "y": 2,
      "z": 1,
      "name": "Rock_Calcite"
    },
    {
      "x": -1,
      "y": 3,
      "z": 1,
      "name": "Rock_Calcite"
    },
    {
      "x": -1,
      "y": 4,
      "z": 1,
      "name": "Rock_Calcite"
    },
    {
      "x": -1,
      "y": 0,
      "z": 2,
      "name": "Rock_Calcite"
    },
    {
      "x": -1,
      "y": 1,
      "z": 2,
      "name": "Rock_Calcite"
    },
    {
      "x": -1,
      "y": 2,
      "z": 2,
      "name": "Rock_Calcite"
    },
    {
      "x": -1,
      "y": 3,
      "z": 2,
      "name": "Rock_Calcite"
    },
    {
      "x": -1,
      "y": 0,
      "z": 3,
      "name": "Rock_Calcite"
    },
    {
      "x": -1,
      "y": 1,
      "z": 3,
      "name": "Rock_Calcite"
    },
    {
      "x": -1,
      "y": 2,
      "z": 3,
      "name": "Rock_Calcite"
    },
    {
      "x": -1,
      "y": 3,
      "z": 3,
      "name": "Rock_Calcite"
    },
    {
      "x": 0,
      "y": 0,
      "z": -2,
      "name": "Rock_Calcite"
    },
    {
      "x": 0,
      "y": 1,
      "z": -2,
      "name": "Rock_Calcite"
    },
    {
      "x": 0,
      "y": 2,
      "z": -2,
      "name": "Rock_Calcite"
    },
    {
      "x": 0,
      "y": 3,
      "z": -2,
      "name": "Rock_Calcite"
    },
    {
      "x": 0,
      "y": 4,
      "z": -2,
      "name": "Rock_Calcite"
    },
    {
      "x": 0,
      "y": 0,
      "z": -1,
      "name": "Rock_Calcite"
    },
    {
      "x": 0,
      "y": 1,
      "z": -1,
      "name": "Rock_Calcite"
    },
    {
      "x": 0,
      "y": 2,
      "z": -1,
      "name": "Rock_Calcite"
    },
    {
      "x": 0,
      "y": 3,
      "z": -1,
      "name": "Rock_Calcite"
    },
    {
      "x": 0,
      "y": 4,
      "z": -1,
      "name": "Rock_Calcite"
    },
    {
      "x": 0,
      "y": 5,
      "z": -1,
      "name": "Rock_Calcite"
    },
    {
      "x": 0,
      "y": 6,
      "z": -1,
      "name": "Rock_Calcite"
    },
    {
      "x": 0,
      "y": 7,
      "z": -1,
      "name": "Plant_Moss_Rug_Blue",
      "support": 15
    },
    {
      "x": 0,
      "y": 0,
      "z": 0,
      "name": "Rock_Calcite"
    },
    {
      "x": 0,
      "y": 1,
      "z": 0,
      "name": "Rock_Calcite"
    },
    {
      "x": 0,
      "y": 2,
      "z": 0,
      "name": "Rock_Calcite"
    },
    {
      "x": 0,
      "y": 3,
      "z": 0,
      "name": "Rock_Calcite"
    },
    {
      "x": 0,
      "y": 4,
      "z": 0,
      "name": "Rock_Calcite"
    },
    {
      "x": 0,
      "y": 5,
      "z": 0,
      "name": "Rock_Calcite"
    },
    {
      "x": 0,
      "y": 6,
      "z": 0,
      "name": "Plant_Moss_Rug_Blue",
      "support": 15
    },
    {
      "x": 0,
      "y": 0,
      "z": 1,
      "name": "Rock_Calcite"
    },
    {
      "x": 0,
      "y": 1,
      "z": 1,
      "name": "Rock_Calcite"
    },
    {
      "x": 0,
      "y": 2,
      "z": 1,
      "name": "Rock_Calcite"
    },
    {
      "x": 0,
      "y": 3,
      "z": 1,
      "name": "Rock_Calcite"
    },
    {
      "x": 0,
      "y": 4,
      "z": 1,
      "name": "Rock_Calcite"
    },
    {
      "x": 0,
      "y": 0,
      "z": 2,
      "name": "Rock_Calcite"
    },
    {
      "x": 0,
      "y": 1,
      "z": 2,
      "name": "Rock_Calcite"
    },
    {
      "x": 0,
      "y": 2,
      "z": 2,
      "name": "Rock_Calcite"
    },
    {
      "x": 0,
      "y": 3,
      "z": 2,
      "name": "Rock_Calcite"
    },
    {
      "x": 0,
      "y": 0,
      "z": 3,
      "name": "Rock_Calcite"
    },
    {
      "x": 0,
      "y": 1,
      "z": 3,
      "name": "Rock_Calcite"
    },
    {
      "x": 0,
      "y": 2,
      "z": 3,
      "name": "Rock_Calcite"
    },
    {
      "x": 0,
      "y": 3,
      "z": 3,
      "name": "Rock_Calcite"
    },
    {
      "x": 1,
      "y": 0,
      "z": -2,
      "name": "Rock_Calcite"
    },
    {
      "x": 1,
      "y": 1,
      "z": -2,
      "name": "Rock_Calcite"
    },
    {
      "x": 1,
      "y": 2,
      "z": -2,
      "name": "Rock_Calcite"
    },
    {
      "x": 1,
      "y": 3,
      "z": -2,
      "name": "Rock_Calcite"
    },
    {
      "x": 1,
      "y": 0,
      "z": -1,
      "name": "Rock_Calcite"
    },
    {
      "x": 1,
      "y": 1,
      "z": -1,
      "name": "Rock_Calcite"
    },
    {
      "x": 1,
      "y": 2,
      "z": -1,
      "name": "Rock_Calcite"
    },
    {
      "x": 1,
      "y": 3,
      "z": -1,
      "name": "Rock_Calcite"
    },
    {
      "x": 1,
      "y": 4,
      "z": -1,
      "name": "Rock_Calcite"
    },
    {
      "x": 1,
      "y": 0,
      "z": 0,
      "name": "Rock_Calcite"
    },
    {
      "x": 1,
      "y": 1,
      "z": 0,
      "name": "Rock_Calcite"
    },
    {
      "x": 1,
      "y": 2,
      "z": 0,
      "name": "Rock_Calcite"
    },
    {
      "x": 1,
      "y": 3,
      "z": 0,
      "name": "Rock_Calcite"
    },
    {
      "x": 1,
      "y": 4,
      "z": 0,
      "name": "Rock_Calcite"
    },
    {
      "x": 1,
      "y": 0,
      "z": 1,
      "name": "Rock_Calcite"
    },
    {
      "x": 1,
      "y": 1,
      "z": 1,
      "name": "Rock_Calcite"
    },
    {
      "x": 1,
      "y": 2,
      "z": 1,
      "name": "Rock_Calcite"
    },
    {
      "x": 1,
      "y": 3,
      "z": 1,
      "name": "Rock_Calcite"
    },
    {
      "x": 1,
      "y": 4,
      "z": 1,
      "name": "Rock_Calcite"
    },
    {
      "x": 1,
      "y": 0,
      "z": 2,
      "name": "Rock_Calcite"
    },
    {
      "x": 1,
      "y": 1,
      "z": 2,
      "name": "Rock_Calcite"
    },
    {
      "x": 1,
      "y": 2,
      "z": 2,
      "name": "Rock_Calcite"
    },
    {
      "x": 1,
      "y": 3,
      "z": 2,
      "name": "Rock_Calcite"
    },
    {
      "x": 2,
      "y": 0,
      "z": -1,
      "name": "Rock_Calcite"
    },
    {
      "x": 2,
      "y": 1,
      "z": -1,
      "name": "Rock_Calcite"
    },
    {
      "x": 2,
      "y": 2,
      "z": -1,
      "name": "Rock_Calcite"
    },
    {
      "x": 2,
      "y": 3,
      "z": -1,
      "name": "Rock_Calcite"
    },
    {
      "x": 2,
      "y": 0,
      "z": 0,
      "name": "Rock_Calcite"
    },
    {
      "x": 2,
      "y": 1,
      "z": 0,
      "name": "Rock_Calcite"
    },
    {
      "x": 2,
      "y": 2,
      "z": 0,
      "name": "Rock_Calcite"
    },
    {
      "x": 2,
      "y": 3,
      "z": 0,
      "name": "Rock_Calcite"
    },
    {
      "x": 2,
      "y": 0,
      "z": 1,
      "name": "Rock_Calcite"
    },
    {
      "x": 2,
      "y": 1,
      "z": 1,
      "name": "Rock_Calcite"
    },
    {
      "x": 2,
      "y": 2,
      "z": 1,
      "name": "Rock_Calcite"
    },
    {
      "x": 2,
      "y": 3,
      "z": 1,
      "name": "Rock_Calcite"
    }
  ],
  "fluids": [
    {
      "x": -2,
      "y": 0,
      "z": -1,
      "name": "Empty",
      "level": 0
    },
    {
      "x": -2,
      "y": 1,
      "z": -1,
      "name": "Empty",
      "level": 0
    },
    {
      "x": -2,
      "y": 2,
      "z": -1,
      "name": "Empty",
      "level": 0
    },
    {
      "x": -2,
      "y": 3,
      "z": -1,
      "name": "Empty",
      "level": 0
    },
    {
      "x": -2,
      "y": 0,
      "z": 0,
      "name": "Empty",
      "level": 0
    },
    {
      "x": -2,
      "y": 1,
      "z": 0,
      "name": "Empty",
      "level": 0
    },
    {
      "x": -2,
      "y": 2,
      "z": 0,
      "name": "Empty",
      "level": 0
    },
    {
      "x": -2,
      "y": 3,
      "z": 0,
      "name": "Empty",
      "level": 0
    },
    {
      "x": -2,
      "y": 0,
      "z": 1,
      "name": "Empty",
      "level": 0
    },
    {
      "x": -2,
      "y": 1,
      "z": 1,
      "name": "Empty",
      "level": 0
    },
    {
      "x": -2,
      "y": 2,
      "z": 1,
      "name": "Empty",
      "level": 0
    },
    {
      "x": -2,
      "y": 3,
      "z": 1,
      "name": "Empty",
      "level": 0
    },
    {
      "x": -2,
      "y": 0,
      "z": 2,
      "name": "Empty",
      "level": 0
    },
    {
      "x": -2,
      "y": 1,
      "z": 2,
      "name": "Empty",
      "level": 0
    },
    {
      "x": -2,
      "y": 2,
      "z": 2,
      "name": "Empty",
      "level": 0
    },
    {
      "x": -2,
      "y": 3,
      "z": 2,
      "name": "Empty",
      "level": 0
    },
    {
      "x": -1,
      "y": 0,
      "z": -2,
      "name": "Empty",
      "level": 0
    },
    {
      "x": -1,
      "y": 1,
      "z": -2,
      "name": "Empty",
      "level": 0
    },
    {
      "x": -1,
      "y": 2,
      "z": -2,
      "name": "Empty",
      "level": 0
    },
    {
      "x": -1,
      "y": 3,
      "z": -2,
      "name": "Empty",
      "level": 0
    },
    {
      "x": -1,
      "y": 4,
      "z": -2,
      "name": "Empty",
      "level": 0
    },
    {
      "x": -1,
      "y": 0,
      "z": -1,
      "name": "Empty",
      "level": 0
    },
    {
      "x": -1,
      "y": 1,
      "z": -1,
      "name": "Empty",
      "level": 0
    },
    {
      "x": -1,
      "y": 2,
      "z": -1,
      "name": "Empty",
      "level": 0
    },
    {
      "x": -1,
      "y": 3,
      "z": -1,
      "name": "Empty",
      "level": 0
    },
    {
      "x": -1,
      "y": 4,
      "z": -1,
      "name": "Empty",
      "level": 0
    },
    {
      "x": -1,
      "y": 5,
      "z": -1,
      "name": "Empty",
      "level": 0
    },
    {
      "x": -1,
      "y": 0,
      "z": 0,
      "name": "Empty",
      "level": 0
    },
    {
      "x": -1,
      "y": 1,
      "z": 0,
      "name": "Empty",
      "level": 0
    },
    {
      "x": -1,
      "y": 2,
      "z": 0,
      "name": "Empty",
      "level": 0
    },
    {
      "x": -1,
      "y": 3,
      "z": 0,
      "name": "Empty",
      "level": 0
    },
    {
      "x": -1,
      "y": 4,
      "z": 0,
      "name": "Empty",
      "level": 0
    },
    {
      "x": -1,
      "y": 5,
      "z": 0,
      "name": "Empty",
      "level": 0
    },
    {
      "x": -1,
      "y": 0,
      "z": 1,
      "name": "Empty",
      "level": 0
    },
    {
      "x": -1,
      "y": 1,
      "z": 1,
      "name": "Empty",
      "level": 0
    },
    {
      "x": -1,
      "y": 2,
      "z": 1,
      "name": "Empty",
      "level": 0
    },
    {
      "x": -1,
      "y": 3,
      "z": 1,
      "name": "Empty",
      "level": 0
    },
    {
      "x": -1,
      "y": 4,
      "z": 1,
      "name": "Empty",
      "level": 0
    },
    {
      "x": -1,
      "y": 0,
      "z": 2,
      "name": "Empty",
      "level": 0
    },
    {
      "x": -1,
      "y": 1,
      "z": 2,
      "name": "Empty",
      "level": 0
    },
    {
      "x": -1,
      "y": 2,
      "z": 2,
      "name": "Empty",
      "level": 0
    },
    {
      "x": -1,
      "y": 3,
      "z": 2,
      "name": "Empty",
      "level": 0
    },
    {
      "x": -1,
      "y": 0,
      "z": 3,
      "name": "Empty",
      "level": 0
    },
    {
      "x": -1,
      "y": 1,
      "z": 3,
      "name": "Empty",
      "level": 0
    },
    {
      "x": -1,
      "y": 2,
      "z": 3,
      "name": "Empty",
      "level": 0
    },
    {
      "x": -1,
      "y": 3,
      "z": 3,
      "name": "Empty",
      "level": 0
    },
    {
      "x": 0,
      "y": 0,
      "z": -2,
      "name": "Empty",
      "level": 0
    },
    {
      "x": 0,
      "y": 1,
      "z": -2,
      "name": "Empty",
      "level": 0
    },
    {
      "x": 0,
      "y": 2,
      "z": -2,
      "name": "Empty",
      "level": 0
    },
    {
      "x": 0,
      "y": 3,
      "z": -2,
      "name": "Empty",
      "level": 0
    },
    {
      "x": 0,
      "y": 4,
      "z": -2,
      "name": "Empty",
      "level": 0
    },
    {
      "x": 0,
      "y": 0,
      "z": -1,
      "name": "Empty",
      "level": 0
    },
    {
      "x": 0,
      "y": 1,
      "z": -1,
      "name": "Empty",
      "level": 0
    },
    {
      "x": 0,
      "y": 2,
      "z": -1,
      "name": "Empty",
      "level": 0
    },
    {
      "x": 0,
      "y": 3,
      "z": -1,
      "name": "Empty",
      "level": 0
    },
    {
      "x": 0,
      "y": 4,
      "z": -1,
      "name": "Empty",
      "level": 0
    },
    {
      "x": 0,
      "y": 5,
      "z": -1,
      "name": "Empty",
      "level": 0
    },
    {
      "x": 0,
      "y": 6,
      "z": -1,
      "name": "Empty",
      "level": 0
    },
    {
      "x": 0,
      "y": 7,
      "z": -1,
      "name": "Empty",
      "level": 0
    },
    {
      "x": 0,
      "y": 0,
      "z": 0,
      "name": "Empty",
      "level": 0
    },
    {
      "x": 0,
      "y": 1,
      "z": 0,
      "name": "Empty",
      "level": 0
    },
    {
      "x": 0,
      "y": 2,
      "z": 0,
      "name": "Empty",
      "level": 0
    },
    {
      "x": 0,
      "y": 3,
      "z": 0,
      "name": "Empty",
      "level": 0
    },
    {
      "x": 0,
      "y": 4,
      "z": 0,
      "name": "Empty",
      "level": 0
    },
    {
      "x": 0,
      "y": 5,
      "z": 0,
      "name": "Empty",
      "level": 0
    },
    {
      "x": 0,
      "y": 6,
      "z": 0,
      "name": "Empty",
      "level": 0
    },
    {
      "x": 0,
      "y": 0,
      "z": 1,
      "name": "Empty",
      "level": 0
    },
    {
      "x": 0,
      "y": 1,
      "z": 1,
      "name": "Empty",
      "level": 0
    },
    {
      "x": 0,
      "y": 2,
      "z": 1,
      "name": "Empty",
      "level": 0
    },
    {
      "x": 0,
      "y": 3,
      "z": 1,
      "name": "Empty",
      "level": 0
    },
    {
      "x": 0,
      "y": 4,
      "z": 1,
      "name": "Empty",
      "level": 0
    },
    {
      "x": 0,
      "y": 0,
      "z": 2,
      "name": "Empty",
      "level": 0
    },
    {
      "x": 0,
      "y": 1,
      "z": 2,
      "name": "Empty",
      "level": 0
    },
    {
      "x": 0,
      "y": 2,
      "z": 2,
      "name": "Empty",
      "level": 0
    },
    {
      "x": 0,
      "y": 3,
      "z": 2,
      "name": "Empty",
      "level": 0
    },
    {
      "x": 0,
      "y": 0,
      "z": 3,
      "name": "Empty",
      "level": 0
    },
    {
      "x": 0,
      "y": 1,
      "z": 3,
      "name": "Empty",
      "level": 0
    },
    {
      "x": 0,
      "y": 2,
      "z": 3,
      "name": "Empty",
      "level": 0
    },
    {
      "x": 0,
      "y": 3,
      "z": 3,
      "name": "Empty",
      "level": 0
    },
    {
      "x": 1,
      "y": 0,
      "z": -2,
      "name": "Empty",
      "level": 0
    },
    {
      "x": 1,
      "y": 1,
      "z": -2,
      "name": "Empty",
      "level": 0
    },
    {
      "x": 1,
      "y": 2,
      "z": -2,
      "name": "Empty",
      "level": 0
    },
    {
      "x": 1,
      "y": 3,
      "z": -2,
      "name": "Empty",
      "level": 0
    },
    {
      "x": 1,
      "y": 0,
      "z": -1,
      "name": "Empty",
      "level": 0
    },
    {
      "x": 1,
      "y": 1,
      "z": -1,
      "name": "Empty",
      "level": 0
    },
    {
      "x": 1,
      "y": 2,
      "z": -1,
      "name": "Empty",
      "level": 0
    },
    {
      "x": 1,
      "y": 3,
      "z": -1,
      "name": "Empty",
      "level": 0
    },
    {
      "x": 1,
      "y": 4,
      "z": -1,
      "name": "Empty",
      "level": 0
    },
    {
      "x": 1,
      "y": 0,
      "z": 0,
      "name": "Empty",
      "level": 0
    },
    {
      "x": 1,
      "y": 1,
      "z": 0,
      "name": "Empty",
      "level": 0
    },
    {
      "x": 1,
      "y": 2,
      "z": 0,
      "name": "Empty",
      "level": 0
    },
    {
      "x": 1,
      "y": 3,
      "z": 0,
      "name": "Empty",
      "level": 0
    },
    {
      "x": 1,
      "y": 4,
      "z": 0,
      "name": "Empty",
      "level": 0
    },
    {
      "x": 1,
      "y": 0,
      "z": 1,
      "name": "Empty",
      "level": 0
    },
    {
      "x": 1,
      "y": 1,
      "z": 1,
      "name": "Empty",
      "level": 0
    },
    {
      "x": 1,
      "y": 2,
      "z": 1,
      "name": "Empty",
      "level": 0
    },
    {
      "x": 1,
      "y": 3,
      "z": 1,
      "name": "Empty",
      "level": 0
    },
    {
      "x": 1,
      "y": 4,
      "z": 1,
      "name": "Empty",
      "level": 0
    },
    {
      "x": 1,
      "y": 0,
      "z": 2,
      "name": "Empty",
      "level": 0
    },
    {
      "x": 1,
      "y": 1,
      "z": 2,
      "name": "Empty",
      "level": 0
    },
    {
      "x": 1,
      "y": 2,
      "z": 2,
      "name": "Empty",
      "level": 0
    },
    {
      "x": 1,
      "y": 3,
      "z": 2,
      "name": "Empty",
      "level": 0
    },
    {
      "x": 2,
      "y": 0,
      "z": -1,
      "name": "Empty",
      "level": 0
    },
    {
      "x": 2,
      "y": 1,
      "z": -1,
      "name": "Empty",
      "level": 0
    },
    {
      "x": 2,
      "y": 2,
      "z": -1,
      "name": "Empty",
      "level": 0
    },
    {
      "x": 2,
      "y": 3,
      "z": -1,
      "name": "Empty",
      "level": 0
    },
    {
      "x": 2,
      "y": 0,
      "z": 0,
      "name": "Empty",
      "level": 0
    },
    {
      "x": 2,
      "y": 1,
      "z": 0,
      "name": "Empty",
      "level": 0
    },
    {
      "x": 2,
      "y": 2,
      "z": 0,
      "name": "Empty",
      "level": 0
    },
    {
      "x": 2,
      "y": 3,
      "z": 0,
      "name": "Empty",
      "level": 0
    },
    {
      "x": 2,
      "y": 0,
      "z": 1,
      "name": "Empty",
      "level": 0
    },
    {
      "x": 2,
      "y": 1,
      "z": 1,
      "name": "Empty",
      "level": 0
    },
    {
      "x": 2,
      "y": 2,
      "z": 1,
      "name": "Empty",
      "level": 0
    },
    {
      "x": 2,
      "y": 3,
      "z": 1,
      "name": "Empty",
      "level": 0
    }
  ]
}